Workbook

Sheet base global
A1: 2 | B1: 3 | C1: 4 | D1: 7 | E1: 8 | F1: 9 | G1: 10 | H1: 11 | I1: 12 | J1: 13 | K1: 14 | L1: 15 | M1: 16 | N1: 17 | O1: 18 | P1: 19 | Q1: Unnamed: 16 | R1: 20 | S1: 21 | T1: 22 | U1: Unnamed: 20 | V1: 23 | W1: 24 | X1: 25 | Y1: 26 | Z1: 27 | AA1: 28 | AB1: 29 | AC1: 30 | AD1: 31 | AE1: 32 | AF1: 33 | AG1: 34 | AH1: 35 | AI1: 36 | AJ1: 37 | AK1: 38 | AL1: 39 | AM1: 40 | AN1: 41 | AO1: 42 | AP1: 43 | AQ1: 44 | AR1: 45 | AS1: 46 | AT1: 47 | AU1: 48 | AV1: 49 | AW1: 50 | AX1: 51 | AY1: 52 | AZ1: 53 | BA1: 54 | BB1: 55 | BC1: 56 | BD1: 57 | BE1: 58 | BF1: 59 | BG1: 60 | BH1: 61 | BI1: 62 | BJ1: 63 | BK1: 64 | BL1: 65 | BM1: 66 | BN1: 67 | BO1: 68 | BP1: 69 | BQ1: 70 | BR1: 71 | BS1: 72 | BT1: 73 | BU1: 74 | BV1: 75 | BW1: 76 | BX1: 77 | BY1: 78 | BZ1: 79 | CA1: 80 | CB1: 81 | CC1: 82 | CD1: 83 | CE1: 84 | CF1: 85 | CG1: 86 | CH1: 87 | CI1: 88 | CJ1: 89 | CK1: 90 | CL1: 91 | CM1: 92 | CN1: 93 | CO1: 94 | CP1: 95 | CQ1: 96 | CR1: 97 | CS1: 98 | CT1: 99 | CU1: 100 | CV1: 101 | CW1: 102 | CX1: 103 | CY1: 104 | CZ1: 105 | DA1: 106 | DB1: 107 | DC1: Unnamed: 106 | DD1: Unnamed: 107 | DE1: Unnamed: 108 | DF1: Unnamed: 109 | DG1: Unnamed: 110 | DH1: Unnamed: 111 | DI1: 122 | DJ1: 123 | DK1: 124
I2: AÑOS INTERVENCIÓN | V2: BENEFICIARIOS | BE2: VENTAS HISTORIAL | CP2: VENTAS PORTIPO DE COMPROMABNTE (OBTENIDO SISPAC 2023 DEL REPORTE MATRIZ GENERAL DE VENTAS) | CW2: VENTAS POR TIPO DE COMPROMABNTE año 2024 | DC2: VENTAS POR TIPO DE COMPROMABNTE año 2025 -12.01.26)
V3: 2018 | W3: 2019 | Z3: 2020 | AC3: 2021 | AF3: 2022 | AI3: 2023 | AL3: 2024 | AO3: 2025 (Ciierre de Agosto 2025) | AS3: 2020 | AU3: 2021 | AW3: 2022 | AY3: 2023 | BA3: 2024 | BC3: 2025 (cierre agosto 2025) | BE3: 2018 | BF3: 2019 | BK3: 2020 | BP3: 2021 | BU3: 2022 | BZ3: 2023 | CE3: 2024 | CK3: 2025 (Cierre de 12.01.26) | CP3: 2023 detallado por tipo comprobante
A4: Nombre de la Organización | B4: PRODUCTO DOM | C4: PRODUCTO 1 | D4: SEDE | E4: Ubigeo | F4: DEPARTAMENTO | G4: Provincia | H4: Distrito | I4: 2018 | J4: 2019 | K4: 2020 | L4: 2021 | M4: 2022 | N4: 2023 | O4: 2024 | P4: 2025 | Q4: SERVICIO | R4: AÑOS DE INTERVENCION | S4: AÑOS DE INTERVENCIÓN DESDE 2018 AL 2024 | T4: INTERVENCIÓN 2019 al 2025 | U4: INTERVENCIÓN 2020 al 2026 | V4: TOTAL BENF 2018 | W4: BENF MASC 2019 | X4: BENF FEM 2019 | Y4: TOTAL BENF 2019 | Z4: BENF MASC 2020 | AA4: BENF FEM 2020 | AB4: TOTAL BENF 2020 | AC4: BENF MASC 2021 | AD4: BENF FEM 2021 | AE4: TOTAL BENF 2021 | AF4: BENF MASC 2022 | AG4: BENF FEM 2022 | AH4: TOTAL BENF 2022 | AI4: BENF MASC 2023 | AJ4: BENF FEM 2023 | AK4: TOTAL BENF 2023 | AL4: BENF MASC 2024 | AM4: BENF FEM 2024 | AN4: TOTAL BENF 2024 | AO4: BENF MASC 2025 | AP4: BENF FEM 2025 | AQ4: TOTAL BENF 2025 | AR4: BENEFICIADOS ULTIMO AÑO | AS4: ASISTENCIA TÉCNICA 2020 | AT4: TALLERES 2020 | AU4: ASISTENCIA TÉCNICA 2021 | AV4: TALLERES 2021 | AW4: ASISTENCIA TÉCNICA 2022 | AX4: TALLERES 2022 | AY4: ASISTENCIA TÉCNICA 2023 | AZ4: TALLERES 2023 | BA4: ASISTENCIA TÉCNICA 2024 | BB4: TALLERES 2024 | BC4: ASISTENCIA TÉCNICA 2025 | BD4: TALLERES 2025 | BE4: VENTAS TOTALES 2018 | BF4: VENTAS NACIONALES 2019 | BG4: VENTAS INTERNACIONALES 2019 | BH4: VENTAS TOTALES 2019 | BI4: INCREMENTOS VENTAS EN 2019 | BJ4: INCREMENTOS VENTAS EN 20192 | BK4: VENTAS NACIONALES 2020 | BL4: VENTAS INTERNACIONALES 2020 | BM4: VENTAS TOTALES 2020 | BN4: INCREMENTOS VENTAS EN 2020 | BO4: DIFERENCIA VENTA 2020-2019 | BP4: VENTAS NACIONALES 2021 | BQ4: VENTAS INTERNACIONALES 2021 | BR4: VENTAS TOTALES 2021 | BS4: INCREMENTOS VENTAS EN 20201 | BT4: DIFERENCIA VENTA 2021-2020 | BU4: V. EJEC NACIONALES 2022 | BV4: V. EJEC EXPORTACION 2022 | BW4: VENTAS TOTALES 2022 | BX4: INCREMENTOS VENTAS EN 22022 | BY4: DIFERENCIA VENTAS 2022-2021 | BZ4: V. EJEC NACIONALES 2023 | CA4: V. EJEC EXPORTACION 2023 | CB4: VENTAS TOTALES 2023 | CC4: INCREMENTOS VENTAS EN 2023 | CD4: DIFERENCIA VENTAS 2023-2022 | CE4: V. EJEC NACIONALES 2024 | CF4: V. EJEC EXPORTACION 2024 | CG4: VENTAS TOTALES 2024 | CH4: INCREMENTOS VENTAS EN 2024 | CI4: DIFERENCIA VENTAS 2024-2023 | CJ4: TOTAL VENTAS 2018 AL 2025 | CK4: V. EJEC NACIONALES 2025 | CL4: V. EJEC EXPORTACION 2025 | CM4: VENTAS TOTALES 2025 | CN4: INCREMENTOS VENTAS EN 2025 | CO4: DIFERENCIA VENTAS 2025-2024 | CP4: Boleta de Venta 2023 | CQ4: Declaracion Jurada 2023 | CR4: Documento de Entrega Cooperativo (DEC) 2023 | CS4: Factura 2023 | CT4: Guia de Remision 2023 | CU4: Liquidacion de Compra 2023 | CV4: Total Ventas 2023 (De comprobantes) (*) | CW4: Boleta de Venta 2024 | CX4: Declaración Jurada 2024 | CY4: Factura 2024 | CZ4: Guía de Remisión 2024 | DA4: Liquidación de Compra 2024 | DB4: Total general 2024 | DC4: Boleta de Venta 2025 | DD4: Declaración Jurada 2025 | DE4: Factura 2025 | DF4: Guía de Remisión 2025 | DG4: Liquidación de Compra 2025 | DH4: Total general 2025 | DI4: RUC | DJ4: NOMBRE SUNAT | DK4: Tipo de Organización* (Asociación/Cooperativa/CCNN, Comunidad Campesina y otros.)
A5: Cooperativa Agraria Cafetalera Montaña Azul LTDA. - Coopacma | B5: CAFÉ | C5: CAFÉ | D5: Amazonas | E5: 010706 | F5: Amazonas | G5: Utcubamba | H5: Lonya Grande | I5: 1 | J5: 1 | K5: 1 | Q5: PAC | R5: 2018-2019-2020 | S5: 3 | T5: SI | U5: SI | V5: 106 | W5: 72 | X5: 34 | Y5: 106 | Z5: 68 | AA5: 31 | AB5: 99 | AC5: 0 | AD5: 0 | AE5: 0 | AF5: 0 | AG5: 0 | AH5: 0 | AI5: 0 | AJ5: 0 | AK5: 0 | AL5: 0 | AM5: 0 | AN5: 0 | AO5: 0 | AP5: 0 | AQ5: 0 | AR5: 99 | AS5: 0 | AT5: 9 | AU5: 0 | AV5: 0 | AW5: 0 | AX5: 0 | AY5: 0 | AZ5: 0 | BA5: 0 | BB5: 0 | BC5: 0 | BD5: 0 | BE5: 0 | BF5: 0 | BG5: 83583.84 | BH5: 83583.84 | BI5: #REF! | BJ5: #REF! | BK5: 3460.24 | BL5: 0 | BM5: 3460.24 | BN5: #REF! | BO5: #REF! | BP5: 0 | BQ5: 0 | BR5: 0 | BS5: #REF! | BU5: 0 | BV5: 0 | BW5: 0 | BX5: #REF! | BY5: #REF! | BZ5: 0 | CA5: 0 | CB5: 0 | CC5: #REF! | CD5: 0 | CE5: 0 | CF5: 0 | CG5: 0 | CH5: #REF! | CI5: 0 | CJ5: #REF! | CK5: 0 | CL5: 0 | CM5: 0 | CN5: #REF! | CO5: 0 | CP5: 0 | CQ5: 0 | CR5: 0 | CS5: 0 | CT5: 0 | CU5: 0 | CV5: 0 | CW5: 0 | CX5: 0 | CY5: 0 | CZ5: 0 | DA5: 0 | DB5: 0 | DC5: 0 | DD5: 0 | DE5: 0 | DF5: 0 | DG5: 0 | DH5: 0 | DI5: 20600200756 | DJ5: COOPERATIVA AGRARIA CAFETALERA MONTAÑA AZUL LTDA. - COOPACMA | DK5: 02 Cooperativa
A6: Asociación de Productores de Café Organico y Cafes Especiales -Aprocoyce Amazonas | B6: CAFÉ | C6: CAFÉ | D6: Amazonas | E6: 010601 | F6: Amazonas | G6: Rodriguez de Mendoza | H6: San Nicolas | J6: 1 | K6: 1 | L6: 1 | M6: 1 | N6: 1 | Q6: PAC | R6: 2019-2020-2021-2022-2023 | S6: 5 | T6: SI | U6: SI | V6: 0 | W6: 50 | X6: 33 | Y6: 83 | Z6: 222 | AA6: 135 | AB6: 357 | AC6: 208 | AD6: 150 | AE6: 358 | AF6: 208 | AG6: 150 | AH6: 358 | AI6: 208 | AJ6: 150 | AK6: 358 | AL6: 0 | AM6: 0 | AN6: 0 | AO6: 0 | AP6: 0 | AQ6: 0 | AR6: 358 | AS6: 0 | AT6: 0 | AU6: 27 | AV6: 8 | AW6: 41 | AX6: 7 | AY6: 32 | AZ6: 6 | BA6: 0 | BB6: 0 | BC6: 0 | BD6: 0 | BE6: 0 | BF6: 4171009.2 | BG6: 0 | BH6: 4171009.2 | BI6: #REF! | BJ6: #REF! | BK6: 741888.91 | BL6: 0 | BM6: 741888.91 | BN6: #REF! | BO6: #REF! | BP6: 4099294.7 | BQ6: 0 | BR6: 4099294.7 | BS6: #REF! | BU6: 1820885 | BV6: 0 | BW6: 1820885 | BX6: #REF! | BY6: #REF! | BZ6: 4179472.3 | CA6: 0 | CB6: 4179472.3 | CC6: #REF! | CD6: -1820885 | CE6: 0 | CF6: 0 | CG6: 0 | CH6: #REF! | CI6: -4179472.3 | CJ6: #REF! | CK6: 0 | CL6: 0 | CM6: 0 | CN6: #REF! | CO6: 0 | CP6: 0 | CQ6: 0 | CR6: 0 | CS6: 4179472.3 | CT6: 0 | CU6: 0 | CV6: 4179472.3 | CW6: 0 | CX6: 0 | CY6: 0 | CZ6: 0 | DA6: 0 | DB6: 0 | DC6: 0 | DD6: 0 | DE6: 0 | DF6: 0 | DG6: 0 | DH6: 0 | DI6: 20539241665 | DJ6: ASOCIACION DE PRODUCTORES DE CAFES ORGANICOS Y CAFES ESPECIALES DE AMAZONAS | DK6: 01 Asociación
A7: Asociación de Productores y Exportadores de Café Rodriguez de Mendoza-Aproexport | B7: CAFÉ | C7: CAFÉ | D7: Amazonas | E7: 010601 | F7: Amazonas | G7: Rodriguez de Mendoza | H7: San Nicolas | J7: 1 | Q7: PAC | R7: 2019 | S7: 1 | T7: SI | U7: NO | V7: 0 | W7: 231 | X7: 149 | Y7: 380 | Z7: 0 | AA7: 0 | AB7: 0 | AC7: 0 | AD7: 0 | AE7: 0 | AF7: 0 | AG7: 0 | AH7: 0 | AI7: 0 | AJ7: 0 | AK7: 0 | AL7: 0 | AM7: 0 | AN7: 0 | AO7: 0 | AP7: 0 | AQ7: 0 | AR7: 380 | AS7: 0 | AT7: 0 | AU7: 0 | AV7: 0 | AW7: 0 | AX7: 0 | AY7: 0 | AZ7: 0 | BA7: 0 | BB7: 0 | BC7: 0 | BD7: 0 | BE7: 0 | BF7: 0 | BG7: 0 | BH7: 0 | BI7: #REF! | BJ7: #REF! | BK7: 0 | BL7: 0 | BM7: 0 | BN7: #REF! | BO7: #REF! | BP7: 0 | BQ7: 0 | BR7: 0 | BS7: #REF! | BU7: 0 | BV7: 0 | BW7: 0 | BX7: #REF! | BY7: #REF! | BZ7: 0 | CA7: 0 | CB7: 0 | CC7: #REF! | CD7: 0 | CE7: 0 | CF7: 0 | CG7: 0 | CH7: #REF! | CI7: 0 | CJ7: #REF! | CK7: 0 | CL7: 0 | CM7: 0 | CN7: #REF! | CO7: 0 | CP7: 0 | CQ7: 0 | CR7: 0 | CS7: 0 | CT7: 0 | CU7: 0 | CV7: 0 | CW7: 0 | CX7: 0 | CY7: 0 | CZ7: 0 | DA7: 0 | DB7: 0 | DC7: 0 | DD7: 0 | DE7: 0 | DF7: 0 | DG7: 0 | DH7: 0 | DI7: 20539205600 | DJ7: ASOCIACION DE PRODUCTORES Y EXPORTADORES DE CAFE RODRIGUEZ DE MENDOZA | DK7: 01 Asociación
A8: Cooperativa Agraria Cafetalera Alta Montaña | B8: CAFÉ | C8: CAFÉ | D8: Amazonas | E8: 010604 | F8: Amazonas | G8: Rodriguez de Mendoza | H8: Huambo | I8: 1 | J8: 1 | K8: 1 | L8: 1 | M8: 1 | N8: 1 | Q8: PAC | R8: 2018-2019-2020-2021-2022-2023 | S8: 6 | T8: SI | U8: SI | V8: 150 | W8: 0 | X8: 0 | Y8: 0 | Z8: 108 | AA8: 42 | AB8: 150 | AC8: 205 | AD8: 119 | AE8: 324 | AF8: 205 | AG8: 119 | AH8: 324 | AI8: 205 | AJ8: 119 | AK8: 324 | AL8: 0 | AM8: 0 | AN8: 0 | AO8: 0 | AP8: 0 | AQ8: 0 | AR8: 324 | AS8: 0 | AT8: 0 | AU8: 25 | AV8: 9 | AW8: 41 | AX8: 7 | AY8: 32 | AZ8: 6 | BA8: 0 | BB8: 0 | BC8: 0 | BD8: 0 | BE8: 0 | BF8: 409100 | BG8: 0 | BH8: 409100 | BI8: #REF! | BJ8: #REF! | BK8: 325000 | BL8: 0 | BM8: 325000 | BN8: #REF! | BO8: #REF! | BP8: 1224192.5 | BQ8: 398235.92 | BR8: 1622428.4 | BS8: #REF! | BU8: 820950 | BV8: 0 | BW8: 820950 | BX8: #REF! | BY8: #REF! | BZ8: 165821.2 | CA8: 0 | CB8: 165821.2 | CC8: #REF! | CD8: -820950 | CE8: 0 | CF8: 0 | CG8: 0 | CH8: #REF! | CI8: -165821.2 | CJ8: #REF! | CK8: 0 | CL8: 0 | CM8: 0 | CN8: #REF! | CO8: 0 | CP8: 9793.4 | CQ8: 0 | CR8: 0 | CS8: 156027.8 | CT8: 0 | CU8: 0 | CV8: 165821.2 | CW8: 0 | CX8: 0 | CY8: 0 | CZ8: 0 | DA8: 0 | DB8: 0 | DC8: 0 | DD8: 0 | DE8: 0 | DF8: 0 | DG8: 0 | DH8: 0 | DI8: 20603320621 | DJ8: COOPERATIVA AGRARIA CAFETALERA ALTA MONTAÑA | DK8: 02 Cooperativa
A9: Asociacion de Productores Agropecuarios la Flor de Café | B9: CAFÉ | C9: CAFÉ | D9: Amazonas | E9: 010601 | F9: Amazonas | G9: Rodriguez de Mendoza | H9: San Nicolas | J9: 1 | K9: 1 | L9: 1 | M9: 1 | N9: 1 | Q9: PAC | R9: 2019-2020-2021-2022-2023 | S9: 5 | T9: SI | U9: SI | V9: 0 | W9: 210 | X9: 113 | Y9: 323 | Z9: 210 | AA9: 113 | AB9: 323 | AC9: 274 | AD9: 137 | AE9: 411 | AF9: 274 | AG9: 137 | AH9: 411 | AI9: 274 | AJ9: 137 | AK9: 411 | AL9: 0 | AM9: 0 | AN9: 0 | AO9: 0 | AP9: 0 | AQ9: 0 | AR9: 411 | AS9: 0 | AT9: 0 | AU9: 26 | AV9: 8 | AW9: 43 | AX9: 7 | AY9: 32 | AZ9: 6 | BA9: 0 | BB9: 0 | BC9: 0 | BD9: 0 | BE9: 0 | BF9: 6041471.5 | BG9: 0 | BH9: 6041471.5 | BI9: #REF! | BJ9: #REF! | BK9: 523737.39 | BL9: 0 | BM9: 523737.39 | BN9: #REF! | BO9: #REF! | BP9: 3394807.7 | BQ9: 0 | BR9: 3394807.7 | BS9: #REF! | BU9: 4076542 | BV9: 446118 | BW9: 4522660 | BX9: #REF! | BY9: #REF! | BZ9: 5733612.8 | CA9: 984023.42 | CB9: 6717636.2 | CC9: #REF! | CD9: -4522660 | CE9: 0 | CF9: 0 | CG9: 0 | CH9: #REF! | CI9: -6717636.2 | CJ9: #REF! | CK9: 0 | CL9: 0 | CM9: 0 | CN9: #REF! | CO9: 0 | CP9: 0 | CQ9: 0 | CR9: 0 | CS9: 6717636.2 | CT9: 0 | CU9: 0 | CV9: 6717636.2 | CW9: 0 | CX9: 0 | CY9: 0 | CZ9: 0 | DA9: 0 | DB9: 0 | DC9: 0 | DD9: 0 | DE9: 0 | DF9: 0 | DG9: 0 | DH9: 0 | DI9: 20480762895 | DJ9: ASOCIACION DE PRODUCTORES AGROPECUARIOS LA FLOR DE CAFÉ | DK9: 01 Asociación
A10: Cooperativa de Servicios Multiples - APROCAM | B10: CACAO | C10: CACAO | D10: Amazonas | E10: 010201 | F10: Amazonas | G10: Bagua | H10: Bagua | I10: 1 | J10: 1 | K10: 1 | L10: 1 | M10: 1 | N10: 1 | Q10: PAC | R10: 2018-2019-2020-2021-2022-2023 | S10: 6 | T10: SI | U10: SI | V10: 418 | W10: 353 | X10: 65 | Y10: 418 | Z10: 357 | AA10: 66 | AB10: 423 | AC10: 201 | AD10: 43 | AE10: 244 | AF10: 201 | AG10: 43 | AH10: 244 | AI10: 201 | AJ10: 43 | AK10: 244 | AL10: 0 | AM10: 0 | AN10: 0 | AO10: 0 | AP10: 0 | AQ10: 0 | AR10: 244 | AS10: 0 | AT10: 0 | AU10: 35 | AV10: 7 | AW10: 32 | AX10: 5 | AY10: 39 | AZ10: 7 | BA10: 0 | BB10: 0 | BC10: 0 | BD10: 0 | BE10: 279033.24 | BF10: 0 | BG10: 1026216.8 | BH10: 1026216.8 | BI10: #REF! | BJ10: #REF! | BK10: 101917.7 | BL10: 284025.07 | BM10: 385942.77 | BN10: #REF! | BO10: #REF! | BP10: 78859.15 | BQ10: 2033180.4 | BR10: 2112039.5 | BS10: #REF! | BU10: 65644.73 | BV10: 1189543.9 | BW10: 1255188.6 | BX10: #REF! | BY10: #REF! | BZ10: 114467.98 | CA10: 1092156.7 | CB10: 1206624.7 | CC10: #REF! | CD10: -1255188.6 | CE10: 0 | CF10: 0 | CG10: 0 | CH10: #REF! | CI10: -1206624.7 | CJ10: #REF! | CK10: 0 | CL10: 0 | CM10: 0 | CN10: #REF! | CO10: 0 | CP10: 34067.084 | CQ10: 0 | CR10: 0 | CS10: 1172557.6 | CT10: 0 | CU10: 0 | CV10: 1206624.7 | CW10: 0 | CX10: 0 | CY10: 0 | CZ10: 0 | DA10: 0 | DB10: 0 | DC10: 0 | DD10: 0 | DE10: 0 | DF10: 0 | DG10: 0 | DH10: 0 | DI10: 20480458550 | DJ10: COOPERATIVA AGRARIA APROCAM | DK10: 02 Cooperativa
A11: Cooperativa Central de Productores Agropecuarios de Amazonas - CEPROAA | B11: CACAO | C11: CACAO | D11: Amazonas | E11: 010702 | F11: Amazonas | G11: Utcubamba | H11: Cajaruro | I11: 1 | J11: 1 | K11: 1 | L11: 1 | M11: 1 | N11: 1 | Q11: PAC | R11: 2018-2019-2020-2021-2022-2023 | S11: 6 | T11: SI | U11: SI | V11: 344 | W11: 272 | X11: 71 | Y11: 343 | Z11: 266 | AA11: 71 | AB11: 337 | AC11: 271 | AD11: 71 | AE11: 342 | AF11: 271 | AG11: 71 | AH11: 342 | AI11: 271 | AJ11: 71 | AK11: 342 | AL11: 0 | AM11: 0 | AN11: 0 | AO11: 0 | AP11: 0 | AQ11: 0 | AR11: 342 | AS11: 0 | AT11: 0 | AU11: 24 | AV11: 7 | AW11: 28 | AX11: 7 | AY11: 39 | AZ11: 6 | BA11: 0 | BB11: 0 | BC11: 0 | BD11: 0 | BE11: 0 | BF11: 0 | BG11: 1072102.3 | BH11: 1072102.3 | BI11: #REF! | BJ11: #REF! | BK11: 454472.63 | BL11: 0 | BM11: 454472.63 | BN11: #REF! | BO11: #REF! | BP11: 1609560.4 | BQ11: 0 | BR11: 1609560.4 | BS11: #REF! | BU11: 1731876.8 | BV11: 0 | BW11: 1731876.8 | BX11: #REF! | BY11: #REF! | BZ11: 1545263.1 | CA11: 0 | CB11: 1545263.1 | CC11: #REF! | CD11: -1731876.8 | CE11: 0 | CF11: 0 | CG11: 0 | CH11: #REF! | CI11: -1545263.1 | CJ11: #REF! | CK11: 0 | CL11: 0 | CM11: 0 | CN11: #REF! | CO11: 0 | CP11: 9912.9964 | CQ11: 0 | CR11: 820166.58 | CS11: 715183.52 | CT11: 0 | CU11: 0 | CV11: 1545263.1 | CW11: 0 | CX11: 0 | CY11: 0 | CZ11: 0 | DA11: 0 | DB11: 0 | DC11: 0 | DD11: 0 | DE11: 0 | DF11: 0 | DG11: 0 | DH11: 0 | DI11: 20479917141 | DJ11: COOPERATIVA AGRARIA CENTRAL DE PRODUCTORES DE AMAZONAS | DK11: 02 Cooperativa
A12: Asociacion de Productores Agropecuarios Luis Solibarria | B12: CACAO | C12: CACAO | D12: Amazonas | E12: 010701 | F12: Amazonas | G12: Utcubamba | H12: Bagua Grande | I12: 1 | J12: 1 | Q12: PAC | R12: 2018-2019 | S12: 2 | T12: SI | U12: NO | V12: 147 | W12: 120 | X12: 25 | Y12: 145 | Z12: 0 | AA12: 0 | AB12: 0 | AC12: 0 | AD12: 0 | AE12: 0 | AF12: 0 | AG12: 0 | AH12: 0 | AI12: 0 | AJ12: 0 | AK12: 0 | AL12: 0 | AM12: 0 | AN12: 0 | AO12: 0 | AP12: 0 | AQ12: 0 | AR12: 145 | AS12: 0 | AT12: 0 | AU12: 0 | AV12: 0 | AW12: 0 | AX12: 0 | AY12: 0 | AZ12: 0 | BA12: 0 | BB12: 0 | BC12: 0 | BD12: 0 | BE12: 0 | BF12: 0 | BG12: 0 | BH12: 0 | BI12: #REF! | BJ12: #REF! | BK12: 0 | BL12: 0 | BM12: 0 | BN12: #REF! | BO12: #REF! | BP12: 0 | BQ12: 0 | BR12: 0 | BS12: #REF! | BU12: 0 | BV12: 0 | BW12: 0 | BX12: #REF! | BY12: #REF! | BZ12: 0 | CA12: 0 | CB12: 0 | CC12: #REF! | CD12: 0 | CE12: 0 | CF12: 0 | CG12: 0 | CH12: #REF! | CI12: 0 | CJ12: #REF! | CK12: 0 | CL12: 0 | CM12: 0 | CN12: #REF! | CO12: 0 | CP12: 0 | CQ12: 0 | CR12: 0 | CS12: 0 | CT12: 0 | CU12: 0 | CV12: 0 | CW12: 0 | CX12: 0 | CY12: 0 | CZ12: 0 | DA12: 0 | DB12: 0 | DC12: 0 | DD12: 0 | DE12: 0 | DF12: 0 | DG12: 0 | DH12: 0 | DI12: 20479856258 | DJ12: ASOCIACION DE PRODUCTORES AGROPECUARIOS LUIS SOLIBARRIA | DK12: 01 Asociación
A13: Cooperativa Agraria Cafetalera Bagua Grande LTDA | B13: CAFÉ | C13: CAFÉ | D13: Amazonas | E13: 010701 | F13: Amazonas | G13: Utcubamba | H13: Bagua Grande | I13: 1 | J13: 1 | K13: 1 | N13: 1 | O13: 1 | Q13: PAC | R13: 2018-2019-2020-2023-2024 | S13: 5 | T13: SI | U13: SI | V13: 592 | W13: 498 | X13: 91 | Y13: 589 | Z13: 296 | AA13: 58 | AB13: 354 | AC13: 0 | AD13: 0 | AE13: 0 | AF13: 0 | AG13: 0 | AH13: 0 | AI13: 596 | AJ13: 94 | AK13: 690 | AL13: 263 | AM13: 46 | AN13: 309 | AO13: 0 | AP13: 0 | AQ13: 0 | AR13: 309 | AS13: 0 | AT13: 9 | AU13: 0 | AV13: 0 | AW13: 0 | AX13: 0 | AY13: 45 | AZ13: 6 | BA13: 30 | BB13: 5 | BC13: 0 | BD13: 0 | BE13: 448800 | BF13: 0 | BG13: 1768356.9 | BH13: 1768356.9 | BI13: #REF! | BJ13: #REF! | BK13: 443003.7 | BL13: 1384395.9 | BM13: 1827399.6 | BN13: #REF! | BO13: #REF! | BP13: 0 | BQ13: 0 | BR13: 0 | BS13: #REF! | BU13: 0 | BV13: 0 | BW13: 0 | BX13: #REF! | BY13: #REF! | BZ13: 0 | CA13: 5910875.3 | CB13: 5910875.3 | CC13: #REF! | CD13: 0 | CE13: 264948.69 | CF13: 8889133.3 | CG13: 9154082 | CH13: #REF! | CI13: -5910875.3 | CJ13: #REF! | CK13: 0 | CL13: 0 | CM13: 0 | CN13: #REF! | CO13: -9154082 | CP13: 0 | CQ13: 0 | CR13: 0 | CS13: 5910875.3 | CT13: 0 | CU13: 0 | CV13: 5910875.3 | CW13: 0 | CX13: 0 | CY13: 9154082 | CZ13: 0 | DA13: 0 | DB13: 9154082 | DC13: 0 | DD13: 0 | DE13: 0 | DF13: 0 | DG13: 0 | DH13: 0 | DI13: 20170142773 | DJ13: COOPERATIVA AGRARIA CAFETALERA BAGUA GRANDE LIMITADA | DK13: 02 Cooperativa
A14: Asociacion de Productores Agropecuarios Valle Verde de Rodriguez de Mendoza | B14: CAFÉ | C14: CAFÉ | D14: Amazonas | E14: 010601 | F14: Amazonas | G14: Rodriguez de Mendoza | H14: San Nicolas | I14: 1 | J14: 1 | Q14: PAC | R14: 2018-2019 | S14: 2 | T14: SI | U14: NO | V14: 427 | W14: 0 | X14: 0 | Y14: 0 | Z14: 0 | AA14: 0 | AB14: 0 | AC14: 0 | AD14: 0 | AE14: 0 | AF14: 0 | AG14: 0 | AH14: 0 | AI14: 0 | AJ14: 0 | AK14: 0 | AL14: 0 | AM14: 0 | AN14: 0 | AO14: 0 | AP14: 0 | AQ14: 0 | AR14: 427 | AS14: 0 | AT14: 0 | AU14: 0 | AV14: 0 | AW14: 0 | AX14: 0 | AY14: 0 | AZ14: 0 | BA14: 0 | BB14: 0 | BC14: 0 | BD14: 0 | BE14: 0 | BF14: 0 | BG14: 0 | BH14: 0 | BI14: #REF! | BJ14: #REF! | BK14: 0 | BL14: 0 | BM14: 0 | BN14: #REF! | BO14: #REF! | BP14: 0 | BQ14: 0 | BR14: 0 | BS14: #REF! | BU14: 0 | BV14: 0 | BW14: 0 | BX14: #REF! | BY14: #REF! | BZ14: 0 | CA14: 0 | CB14: 0 | CC14: #REF! | CD14: 0 | CE14: 0 | CF14: 0 | CG14: 0 | CH14: #REF! | CI14: 0 | CJ14: #REF! | CK14: 0 | CL14: 0 | CM14: 0 | CN14: #REF! | CO14: 0 | CP14: 0 | CQ14: 0 | CR14: 0 | CS14: 0 | CT14: 0 | CU14: 0 | CV14: 0 | CW14: 0 | CX14: 0 | CY14: 0 | CZ14: 0 | DA14: 0 | DB14: 0 | DC14: 0 | DD14: 0 | DE14: 0 | DF14: 0 | DG14: 0 | DH14: 0 | DI14: 20600682386 | DJ14: ASOCIACION DE PRODUCTORES AGROPECUARIOS VALLE VERDE DE RODRIGUEZ DE MENDOZA | DK14: 01 Asociación
A15: Asociacion de Productores Agropecuarios Luis Solibarria | B15: CACAO | C15: CACAO | D15: Amazonas | E15: 010701 | F15: Amazonas | G15: Utcubamba | H15: Bagua Grande | L15: 1 | M15: 1 | Q15: PAC | R15: 2021-2022 | S15: 2 | T15: SI | U15: SI | V15: 0 | W15: 0 | X15: 0 | Y15: 0 | Z15: 0 | AA15: 0 | AB15: 0 | AC15: 121 | AD15: 25 | AE15: 146 | AF15: 121 | AG15: 25 | AH15: 146 | AI15: 0 | AJ15: 0 | AK15: 0 | AL15: 0 | AM15: 0 | AN15: 0 | AO15: 0 | AP15: 0 | AQ15: 0 | AR15: 146 | AS15: 0 | AT15: 0 | AU15: 16 | AV15: 2 | AW15: 23 | AX15: 6 | AY15: 0 | AZ15: 0 | BA15: 0 | BB15: 0 | BC15: 0 | BD15: 0 | BE15: 0 | BF15: 0 | BG15: 0 | BH15: 0 | BI15: #REF! | BJ15: #REF! | BK15: 0 | BL15: 0 | BM15: 0 | BN15: #REF! | BO15: #REF! | BP15: 0 | BQ15: 0 | BR15: 0 | BS15: #REF! | BU15: 0 | BV15: 0 | BW15: 0 | BX15: #REF! | BY15: #REF! | BZ15: 0 | CA15: 0 | CB15: 0 | CC15: #REF! | CD15: 0 | CE15: 0 | CF15: 0 | CG15: 0 | CH15: #REF! | CI15: 0 | CJ15: #REF! | CK15: 0 | CL15: 0 | CM15: 0 | CN15: #REF! | CO15: 0 | CP15: 0 | CQ15: 0 | CR15: 0 | CS15: 0 | CT15: 0 | CU15: 0 | CV15: 0 | CW15: 0 | CX15: 0 | CY15: 0 | CZ15: 0 | DA15: 0 | DB15: 0 | DC15: 0 | DD15: 0 | DE15: 0 | DF15: 0 | DG15: 0 | DH15: 0 | DI15: 20479856258 | DJ15: ASOCIACION DE PRODUCTORES AGROPECUARIOS LUIS SOLIBARRIA | DK15: 01 Asociación
A16: Cooperativa Agraria Cafetalera Productora Comercial Exportadora Cafe Andes Amazonicos LTDA | B16: CAFÉ | C16: CAFÉ | D16: Amazonas | E16: 010706 | F16: Amazonas | G16: Utcubamba | H16: Lonya Grande | L16: 1 | M16: 1 | Q16: PAC | R16: 2021-2022 | S16: 2 | T16: SI | U16: SI | V16: 0 | W16: 0 | X16: 0 | Y16: 0 | Z16: 0 | AA16: 0 | AB16: 0 | AC16: 179 | AD16: 45 | AE16: 224 | AF16: 179 | AG16: 45 | AH16: 224 | AI16: 0 | AJ16: 0 | AK16: 0 | AL16: 0 | AM16: 0 | AN16: 0 | AO16: 0 | AP16: 0 | AQ16: 0 | AR16: 224 | AS16: 0 | AT16: 0 | AU16: 12 | AV16: 8 | AW16: 54 | AX16: 8 | AY16: 0 | AZ16: 0 | BA16: 0 | BB16: 0 | BC16: 0 | BD16: 0 | BE16: 0 | BF16: 0 | BG16: 0 | BH16: 0 | BI16: #REF! | BJ16: #REF! | BK16: 0 | BL16: 0 | BM16: 0 | BN16: #REF! | BO16: #REF! | BP16: 250823.36 | BQ16: 0 | BR16: 250823.36 | BS16: #REF! | BU16: 0 | BV16: 0 | BW16: 0 | BX16: #REF! | BY16: #REF! | BZ16: 0 | CA16: 0 | CB16: 0 | CC16: #REF! | CD16: 0 | CE16: 0 | CF16: 0 | CG16: 0 | CH16: #REF! | CI16: 0 | CJ16: #REF! | CK16: 0 | CL16: 0 | CM16: 0 | CN16: #REF! | CO16: 0 | CP16: 0 | CQ16: 0 | CR16: 0 | CS16: 0 | CT16: 0 | CU16: 0 | CV16: 0 | CW16: 0 | CX16: 0 | CY16: 0 | CZ16: 0 | DA16: 0 | DB16: 0 | DC16: 0 | DD16: 0 | DE16: 0 | DF16: 0 | DG16: 0 | DH16: 0 | DI16: 20600001109 | DJ16: COOPERATIVA AGRARIA CAFETALERA PRODUCTORA COMERCIAL EXPORTADORA CAFE ANDES AMAZONICOS LTDA | DK16: 02 Cooperativa
A17: Cooperativa de Servicios Multiples Juan Marco el Palto | B17: CAFÉ | C17: CAFÉ | D17: Amazonas | E17: 010706 | F17: Amazonas | G17: Utcubamba | H17: Lonya Grande | L17: 1 | M17: 1 | N17: 1 | Q17: PAC | R17: 2021-2022-2023 | S17: 3 | T17: SI | U17: SI | V17: 0 | W17: 0 | X17: 0 | Y17: 0 | Z17: 0 | AA17: 0 | AB17: 0 | AC17: 224 | AD17: 68 | AE17: 292 | AF17: 224 | AG17: 68 | AH17: 292 | AI17: 224 | AJ17: 68 | AK17: 292 | AL17: 0 | AM17: 0 | AN17: 0 | AO17: 0 | AP17: 0 | AQ17: 0 | AR17: 292 | AS17: 0 | AT17: 0 | AU17: 10 | AV17: 8 | AW17: 60 | AX17: 8 | AY17: 44 | AZ17: 6 | BA17: 0 | BB17: 0 | BC17: 0 | BD17: 0 | BE17: 0 | BF17: 0 | BG17: 0 | BH17: 0 | BI17: #REF! | BJ17: #REF! | BK17: 0 | BL17: 0 | BM17: 0 | BN17: #REF! | BO17: #REF! | BP17: 0 | BQ17: 1177220.5 | BR17: 1177220.5 | BS17: #REF! | BU17: 117797.43 | BV17: 3107691.5 | BW17: 3225488.9 | BX17: #REF! | BY17: #REF! | BZ17: 45403.05 | CA17: 3044784.1 | CB17: 3090187.2 | CC17: #REF! | CD17: -3225488.9 | CE17: 0 | CF17: 0 | CG17: 0 | CH17: #REF! | CI17: -3090187.2 | CJ17: #REF! | CK17: 0 | CL17: 0 | CM17: 0 | CN17: #REF! | CO17: 0 | CP17: 0 | CQ17: 0 | CR17: 0 | CS17: 3090187.2 | CT17: 0 | CU17: 0 | CV17: 3090187.2 | CW17: 0 | CX17: 0 | CY17: 0 | CZ17: 0 | DA17: 0 | DB17: 0 | DC17: 0 | DD17: 0 | DE17: 0 | DF17: 0 | DG17: 0 | DH17: 0 | DI17: 20479622699 | DJ17: COOPERATIVA AGRARIA JUAN MARCO EL PALTO | DK17: 02 Cooperativa
A18: Sedir-Servicio para el Desarrollo Integral Rural | B18: PALTA | C18: PALTA | D18: Ancash | E18: 021805 | F18: Ancash | G18: Santa | H18: Moro | I18: 1 | Q18: PAC | R18: 2018 | S18: 1 | T18: NO | U18: NO | V18: 34 | W18: 0 | X18: 0 | Y18: 0 | Z18: 0 | AA18: 0 | AB18: 0 | AC18: 0 | AD18: 0 | AE18: 0 | AF18: 0 | AG18: 0 | AH18: 0 | AI18: 0 | AJ18: 0 | AK18: 0 | AL18: 0 | AM18: 0 | AN18: 0 | AO18: 0 | AP18: 0 | AQ18: 0 | AR18: 34 | AS18: 0 | AT18: 0 | AU18: 0 | AV18: 0 | AW18: 0 | AX18: 0 | AY18: 0 | AZ18: 0 | BA18: 0 | BB18: 0 | BC18: 0 | BD18: 0 | BE18: 0 | BF18: 0 | BG18: 0 | BH18: 0 | BI18: #REF! | BJ18: #REF! | BK18: 0 | BL18: 0 | BM18: 0 | BN18: #REF! | BO18: #REF! | BP18: 0 | BQ18: 0 | BR18: 0 | BS18: #REF! | BU18: 0 | BV18: 0 | BW18: 0 | BX18: #REF! | BY18: #REF! | BZ18: 0 | CA18: 0 | CB18: 0 | CC18: #REF! | CD18: 0 | CE18: 0 | CF18: 0 | CG18: 0 | CH18: #REF! | CI18: 0 | CJ18: #REF! | CK18: 0 | CL18: 0 | CM18: 0 | CN18: #REF! | CO18: 0 | CP18: 0 | CQ18: 0 | CR18: 0 | CS18: 0 | CT18: 0 | CU18: 0 | CV18: 0 | CW18: 0 | CX18: 0 | CY18: 0 | CZ18: 0 | DA18: 0 | DB18: 0 | DC18: 0 | DD18: 0 | DE18: 0 | DF18: 0 | DG18: 0 | DH18: 0 | DI18: 20541732706 | DJ18: SERVICIO PARA EL DESARROLLO INTEGRAL RURAL | DK18: 01 Asociación
A19: Asociacion de Productores de Manzano Organico de Pariacoto | B19: MANZANA | C19: MANZANA | D19: Ancash | E19: 020110 | F19: Ancash | G19: Huaraz | H19: Pariacoto | I19: 1 | Q19: PAC | R19: 2018 | S19: 1 | T19: NO | U19: NO | V19: 15 | W19: 0 | X19: 0 | Y19: 0 | Z19: 0 | AA19: 0 | AB19: 0 | AC19: 0 | AD19: 0 | AE19: 0 | AF19: 0 | AG19: 0 | AH19: 0 | AI19: 0 | AJ19: 0 | AK19: 0 | AL19: 0 | AM19: 0 | AN19: 0 | AO19: 0 | AP19: 0 | AQ19: 0 | AR19: 15 | AS19: 0 | AT19: 0 | AU19: 0 | AV19: 0 | AW19: 0 | AX19: 0 | AY19: 0 | AZ19: 0 | BA19: 0 | BB19: 0 | BC19: 0 | BD19: 0 | BE19: 0 | BF19: 0 | BG19: 0 | BH19: 0 | BI19: #REF! | BJ19: #REF! | BK19: 0 | BL19: 0 | BM19: 0 | BN19: #REF! | BO19: #REF! | BP19: 0 | BQ19: 0 | BR19: 0 | BS19: #REF! | BU19: 0 | BV19: 0 | BW19: 0 | BX19: #REF! | BY19: #REF! | BZ19: 0 | CA19: 0 | CB19: 0 | CC19: #REF! | CD19: 0 | CE19: 0 | CF19: 0 | CG19: 0 | CH19: #REF! | CI19: 0 | CJ19: #REF! | CK19: 0 | CL19: 0 | CM19: 0 | CN19: #REF! | CO19: 0 | CP19: 0 | CQ19: 0 | CR19: 0 | CS19: 0 | CT19: 0 | CU19: 0 | CV19: 0 | CW19: 0 | CX19: 0 | CY19: 0 | CZ19: 0 | DA19: 0 | DB19: 0 | DC19: 0 | DD19: 0 | DE19: 0 | DF19: 0 | DG19: 0 | DH19: 0 | DI19: 20600862074 | DJ19: ASOCIACIÓN DE PRODUCTORES DE MANZANO ORGANICO DEL DISTRITO DE PARIACOTO | DK19: 01 Asociación
A20: Asociacion de Productores Ecologicos Agrarios del Distrito de Quiches | B20: ROMERO | C20: ROMERO | D20: Ancash | E20: 021901 | F20: Ancash | G20: Sihuas | H20: Sihuas | I20: 1 | Q20: PAC | R20: 2018 | S20: 1 | T20: NO | U20: NO | V20: 82 | W20: 0 | X20: 0 | Y20: 0 | Z20: 0 | AA20: 0 | AB20: 0 | AC20: 0 | AD20: 0 | AE20: 0 | AF20: 0 | AG20: 0 | AH20: 0 | AI20: 0 | AJ20: 0 | AK20: 0 | AL20: 0 | AM20: 0 | AN20: 0 | AO20: 0 | AP20: 0 | AQ20: 0 | AR20: 82 | AS20: 0 | AT20: 0 | AU20: 0 | AV20: 0 | AW20: 0 | AX20: 0 | AY20: 0 | AZ20: 0 | BA20: 0 | BB20: 0 | BC20: 0 | BD20: 0 | BE20: 0 | BF20: 0 | BG20: 0 | BH20: 0 | BI20: #REF! | BJ20: #REF! | BK20: 0 | BL20: 0 | BM20: 0 | BN20: #REF! | BO20: #REF! | BP20: 0 | BQ20: 0 | BR20: 0 | BS20: #REF! | BU20: 0 | BV20: 0 | BW20: 0 | BX20: #REF! | BY20: #REF! | BZ20: 0 | CA20: 0 | CB20: 0 | CC20: #REF! | CD20: 0 | CE20: 0 | CF20: 0 | CG20: 0 | CH20: #REF! | CI20: 0 | CJ20: #REF! | CK20: 0 | CL20: 0 | CM20: 0 | CN20: #REF! | CO20: 0 | CP20: 0 | CQ20: 0 | CR20: 0 | CS20: 0 | CT20: 0 | CU20: 0 | CV20: 0 | CW20: 0 | CX20: 0 | CY20: 0 | CZ20: 0 | DA20: 0 | DB20: 0 | DC20: 0 | DD20: 0 | DE20: 0 | DF20: 0 | DG20: 0 | DH20: 0 | DI20: 20602544495 | DJ20: ASOCIACION DE PRODUCTORES ECOLOGICOS AGRARIOS DEL DISTRITO DE QUICHES PROVINCIA DE SIHUAS-ANCASH | DK20: 01 Asociación
A21: Asociacion de Productores y Comerciantes de Tara de Puchka | B21: TARA | C21: TARA | D21: Ancash | E21: 021016 | F21: Ancash | G21: Huari | H21: Uco | I21: 1 | Q21: PAC | R21: 2018 | S21: 1 | T21: NO | U21: NO | V21: 39 | W21: 0 | X21: 0 | Y21: 0 | Z21: 0 | AA21: 0 | AB21: 0 | AC21: 0 | AD21: 0 | AE21: 0 | AF21: 0 | AG21: 0 | AH21: 0 | AI21: 0 | AJ21: 0 | AK21: 0 | AL21: 0 | AM21: 0 | AN21: 0 | AO21: 0 | AP21: 0 | AQ21: 0 | AR21: 39 | AS21: 0 | AT21: 0 | AU21: 0 | AV21: 0 | AW21: 0 | AX21: 0 | AY21: 0 | AZ21: 0 | BA21: 0 | BB21: 0 | BC21: 0 | BD21: 0 | BE21: 0 | BF21: 0 | BG21: 0 | BH21: 0 | BI21: #REF! | BJ21: #REF! | BK21: 0 | BL21: 0 | BM21: 0 | BN21: #REF! | BO21: #REF! | BP21: 0 | BQ21: 0 | BR21: 0 | BS21: #REF! | BU21: 0 | BV21: 0 | BW21: 0 | BX21: #REF! | BY21: #REF! | BZ21: 0 | CA21: 0 | CB21: 0 | CC21: #REF! | CD21: 0 | CE21: 0 | CF21: 0 | CG21: 0 | CH21: #REF! | CI21: 0 | CJ21: #REF! | CK21: 0 | CL21: 0 | CM21: 0 | CN21: #REF! | CO21: 0 | CP21: 0 | CQ21: 0 | CR21: 0 | CS21: 0 | CT21: 0 | CU21: 0 | CV21: 0 | CW21: 0 | CX21: 0 | CY21: 0 | CZ21: 0 | DA21: 0 | DB21: 0 | DC21: 0 | DD21: 0 | DE21: 0 | DF21: 0 | DG21: 0 | DH21: 0 | DI21: 20534142146 | DJ21: ASOCIACION DE PRODUCTORES Y COMERCIANTES DE TARA DE PUCHKA | DK21: 01 Asociación
A22: Grupo Asociado Productores de Caraz | B22: FLORES | C22: FLORES | D22: Ancash | E22: 021201 | F22: Ancash | G22: Huaylas | H22: Caraz | I22: 1 | Q22: PAC | R22: 2018 | S22: 1 | T22: NO | U22: NO | V22: 4 | W22: 0 | X22: 0 | Y22: 0 | Z22: 0 | AA22: 0 | AB22: 0 | AC22: 0 | AD22: 0 | AE22: 0 | AF22: 0 | AG22: 0 | AH22: 0 | AI22: 0 | AJ22: 0 | AK22: 0 | AL22: 0 | AM22: 0 | AN22: 0 | AO22: 0 | AP22: 0 | AQ22: 0 | AR22: 4 | AS22: 0 | AT22: 0 | AU22: 0 | AV22: 0 | AW22: 0 | AX22: 0 | AY22: 0 | AZ22: 0 | BA22: 0 | BB22: 0 | BC22: 0 | BD22: 0 | BE22: 0 | BF22: 0 | BG22: 0 | BH22: 0 | BI22: #REF! | BJ22: #REF! | BK22: 0 | BL22: 0 | BM22: 0 | BN22: #REF! | BO22: #REF! | BP22: 0 | BQ22: 0 | BR22: 0 | BS22: #REF! | BU22: 0 | BV22: 0 | BW22: 0 | BX22: #REF! | BY22: #REF! | BZ22: 0 | CA22: 0 | CB22: 0 | CC22: #REF! | CD22: 0 | CE22: 0 | CF22: 0 | CG22: 0 | CH22: #REF! | CI22: 0 | CJ22: #REF! | CK22: 0 | CL22: 0 | CM22: 0 | CN22: #REF! | CO22: 0 | CP22: 0 | CQ22: 0 | CR22: 0 | CS22: 0 | CT22: 0 | CU22: 0 | CV22: 0 | CW22: 0 | CX22: 0 | CY22: 0 | CZ22: 0 | DA22: 0 | DB22: 0 | DC22: 0 | DD22: 0 | DE22: 0 | DF22: 0 | DG22: 0 | DH22: 0 | DI22: SIN RUC | DJ22: ND | DK22: 01 Asociación
A23: Cooperativa de Productores Agroecologicos la Perla de los Andes-Callejon de Huaylas Ancash | B23: TARWI | C23: TARWI | D23: Ancash | E23: 021201 | F23: Ancash | G23: Huaylas | H23: Caraz | I23: 1 | J23: 1 | K23: 1 | L23: 1 | M23: 1 | N23: 1 | Q23: PAC | R23: 2018-2019-2020-2021-2022-2023 | S23: 6 | T23: SI | U23: SI | V23: 521 | W23: 79 | X23: 17 | Y23: 96 | Z23: 213 | AA23: 60 | AB23: 273 | AC23: 215 | AD23: 58 | AE23: 273 | AF23: 59 | AG23: 18 | AH23: 77 | AI23: 59 | AJ23: 18 | AK23: 77 | AL23: 0 | AM23: 0 | AN23: 0 | AO23: 0 | AP23: 0 | AQ23: 0 | AR23: 77 | AS23: 18 | AT23: 6 | AU23: 36 | AV23: 7 | AW23: 25 | AX23: 6 | AY23: 36 | AZ23: 2 | BA23: 0 | BB23: 0 | BC23: 0 | BD23: 0 | BE23: 0 | BF23: 11802.35 | BG23: 0 | BH23: 11802.35 | BI23: #REF! | BJ23: #REF! | BK23: 109219.27 | BL23: 0 | BM23: 109219.27 | BN23: #REF! | BO23: #REF! | BP23: 131381.75 | BQ23: 0 | BR23: 131381.75 | BS23: #REF! | BU23: 129764.41 | BV23: 0 | BW23: 129764.41 | BX23: #REF! | BY23: #REF! | BZ23: 141145.57 | CA23: 0 | CB23: 141145.57 | CC23: #REF! | CD23: -129764.41 | CE23: 0 | CF23: 0 | CG23: 0 | CH23: #REF! | CI23: -141145.57 | CJ23: #REF! | CK23: 0 | CL23: 0 | CM23: 0 | CN23: #REF! | CO23: 0 | CP23: 0 | CQ23: 0 | CR23: 0 | CS23: 141147 | CT23: 0 | CU23: 0 | CV23: 141147 | CW23: 0 | CX23: 0 | CY23: 0 | CZ23: 0 | DA23: 0 | DB23: 0 | DC23: 0 | DD23: 0 | DE23: 0 | DF23: 0 | DG23: 0 | DH23: 0 | DI23: 20603223421 | DJ23: COOPERATIVA DE PRODUCTORES AGROECOLOGICOS LA PERLA DE LOS ANDES-CALLEJON DE HUAYLAS ANCASH | DK23: 02 Cooperativa
A24: Asociación de Semillaristas de Maiz Choclo Virgen de las Mercedes del Distrito de Chingas | B24: MAÍZ | C24: MAÍZ BLANCO GIGANTE | D24: Ancash | E24: 020304 | F24: Ancash | G24: Antonio Raymondi | H24: Chingas | I24: 1 | J24: 1 | K24: 1 | L24: 1 | M24: 1 | N24: 1 | Q24: PAC | R24: 2018-2019-2020-2021-2022-2023 | S24: 6 | T24: SI | U24: SI | V24: 28 | W24: 23 | X24: 3 | Y24: 26 | Z24: 23 | AA24: 3 | AB24: 26 | AC24: 20 | AD24: 3 | AE24: 23 | AF24: 20 | AG24: 3 | AH24: 23 | AI24: 20 | AJ24: 3 | AK24: 23 | AL24: 0 | AM24: 0 | AN24: 0 | AO24: 0 | AP24: 0 | AQ24: 0 | AR24: 23 | AS24: 3 | AT24: 0 | AU24: 44 | AV24: 8 | AW24: 25 | AX24: 5 | AY24: 34 | AZ24: 4 | BA24: 0 | BB24: 0 | BC24: 0 | BD24: 0 | BE24: 0 | BF24: 0 | BG24: 0 | BH24: 0 | BI24: #REF! | BJ24: #REF! | BK24: 13830 | BL24: 0 | BM24: 13830 | BN24: #REF! | BO24: #REF! | BP24: 378700 | BQ24: 0 | BR24: 378700 | BS24: #REF! | BU24: 452800 | BV24: 0 | BW24: 452800 | BX24: #REF! | BY24: #REF! | BZ24: 564965 | CA24: 0 | CB24: 564965 | CC24: #REF! | CD24: -452800 | CE24: 0 | CF24: 0 | CG24: 0 | CH24: #REF! | CI24: -564965 | CJ24: #REF! | CK24: 0 | CL24: 0 | CM24: 0 | CN24: #REF! | CO24: 0 | CP24: 0 | CQ24: 564965 | CR24: 0 | CS24: 0 | CT24: 0 | CU24: 0 | CV24: 564965 | CW24: 0 | CX24: 0 | CY24: 0 | CZ24: 0 | DA24: 0 | DB24: 0 | DC24: 0 | DD24: 0 | DE24: 0 | DF24: 0 | DG24: 0 | DH24: 0 | DI24: 20601547458 | DJ24: ASOCIACION DE SEMILLARISTAS DE MAIZ CHOCLO VIRGEN DE LA MERCEDES DEL DISTRITO DE CHINGAS | DK24: 01 Asociación
A25: Asociacion de Productores de Paltos Moro | B25: PALTA | C25: PALTA | D25: Ancash | E25: 021805 | F25: Ancash | G25: Santa | H25: Moro | J25: 1 | Q25: PAC | R25: 2019 | S25: 1 | T25: SI | U25: NO | V25: 0 | W25: 33 | X25: 2 | Y25: 35 | Z25: 0 | AA25: 0 | AB25: 0 | AC25: 0 | AD25: 0 | AE25: 0 | AF25: 0 | AG25: 0 | AH25: 0 | AI25: 0 | AJ25: 0 | AK25: 0 | AL25: 0 | AM25: 0 | AN25: 0 | AO25: 0 | AP25: 0 | AQ25: 0 | AR25: 35 | AS25: 0 | AT25: 0 | AU25: 0 | AV25: 0 | AW25: 0 | AX25: 0 | AY25: 0 | AZ25: 0 | BA25: 0 | BB25: 0 | BC25: 0 | BD25: 0 | BE25: 0 | BF25: 260411.15 | BG25: 0 | BH25: 260411.15 | BI25: #REF! | BJ25: #REF! | BK25: 0 | BL25: 0 | BM25: 0 | BN25: #REF! | BO25: #REF! | BP25: 0 | BQ25: 0 | BR25: 0 | BS25: #REF! | BU25: 0 | BV25: 0 | BW25: 0 | BX25: #REF! | BY25: #REF! | BZ25: 0 | CA25: 0 | CB25: 0 | CC25: #REF! | CD25: 0 | CE25: 0 | CF25: 0 | CG25: 0 | CH25: #REF! | CI25: 0 | CJ25: #REF! | CK25: 0 | CL25: 0 | CM25: 0 | CN25: #REF! | CO25: 0 | CP25: 0 | CQ25: 0 | CR25: 0 | CS25: 0 | CT25: 0 | CU25: 0 | CV25: 0 | CW25: 0 | CX25: 0 | CY25: 0 | CZ25: 0 | DA25: 0 | DB25: 0 | DC25: 0 | DD25: 0 | DE25: 0 | DF25: 0 | DG25: 0 | DH25: 0 | DI25: 20603736703 | DJ25: ASOCIACION DE PRODUCTORES DE PALTOS MORO - APROPALMO | DK25: 01 Asociación
A26: Cooperativa Agraria Valle Fortaleza-Coavaf | B26: DURAZNO | C26: DURAZNO | D26: Ancash | E26: 020503 | F26: Ancash | G26: Bolognesi | H26: Antonio Raymondi | L26: 1 | Q26: PAC | R26: 2021 | S26: 1 | T26: SI | U26: SI | V26: 0 | W26: 0 | X26: 0 | Y26: 0 | Z26: 0 | AA26: 0 | AB26: 0 | AC26: 64 | AD26: 10 | AE26: 74 | AF26: 0 | AG26: 0 | AH26: 0 | AI26: 0 | AJ26: 0 | AK26: 0 | AL26: 0 | AM26: 0 | AN26: 0 | AO26: 0 | AP26: 0 | AQ26: 0 | AR26: 74 | AS26: 0 | AT26: 0 | AU26: 52 | AV26: 8 | AW26: 0 | AX26: 0 | AY26: 0 | AZ26: 0 | BA26: 0 | BB26: 0 | BC26: 0 | BD26: 0 | BE26: 0 | BF26: 0 | BG26: 0 | BH26: 0 | BI26: #REF! | BJ26: #REF! | BK26: 0 | BL26: 0 | BM26: 0 | BN26: #REF! | BO26: #REF! | BP26: 183225 | BQ26: 0 | BR26: 183225 | BS26: #REF! | BU26: 0 | BV26: 0 | BW26: 0 | BX26: #REF! | BY26: #REF! | BZ26: 0 | CA26: 0 | CB26: 0 | CC26: #REF! | CD26: 0 | CE26: 0 | CF26: 0 | CG26: 0 | CH26: #REF! | CI26: 0 | CJ26: #REF! | CK26: 0 | CL26: 0 | CM26: 0 | CN26: #REF! | CO26: 0 | CP26: 0 | CQ26: 0 | CR26: 0 | CS26: 0 | CT26: 0 | CU26: 0 | CV26: 0 | CW26: 0 | CX26: 0 | CY26: 0 | CZ26: 0 | DA26: 0 | DB26: 0 | DC26: 0 | DD26: 0 | DE26: 0 | DF26: 0 | DG26: 0 | DH26: 0 | DI26: 20600276221 | DJ26: COOPERATIVA AGRARIA VALLE FORTALEZA - COAVAFF | DK26: 02 Cooperativa
A27: Asociacion de Productores Agroecologicos de Pariacoto Promoviendo Vida Saludable - Apaprovis | B27: PALTA | C27: PALTA | D27: Ancash | E27: 020110 | F27: Ancash | G27: Huaraz | H27: Pariacoto | L27: 1 | M27: 1 | N27: 1 | O27: 1 | Q27: PAC | R27: 2021-2022-2023-2024 | S27: 4 | T27: SI | U27: SI | V27: 0 | W27: 0 | X27: 0 | Y27: 0 | Z27: 0 | AA27: 0 | AB27: 0 | AC27: 20 | AD27: 6 | AE27: 26 | AF27: 20 | AG27: 6 | AH27: 26 | AI27: 20 | AJ27: 6 | AK27: 26 | AL27: 20 | AM27: 6 | AN27: 26 | AO27: 0 | AP27: 0 | AQ27: 0 | AR27: 26 | AS27: 0 | AT27: 0 | AU27: 67 | AV27: 10 | AW27: 16 | AX27: 5 | AY27: 38 | AZ27: 1 | BA27: 30 | BB27: 0 | BC27: 0 | BD27: 0 | BE27: 0 | BF27: 0 | BG27: 0 | BH27: 0 | BI27: #REF! | BJ27: #REF! | BK27: 0 | BL27: 0 | BM27: 0 | BN27: #REF! | BO27: #REF! | BP27: 211492.7 | BQ27: 0 | BR27: 211492.7 | BS27: #REF! | BU27: 52556.7 | BV27: 0 | BW27: 52556.7 | BX27: #REF! | BY27: #REF! | BZ27: 77420.7 | CA27: 0 | CB27: 77420.7 | CC27: #REF! | CD27: -52556.7 | CE27: 48724 | CF27: 0 | CG27: 48724 | CH27: #REF! | CI27: -77420.7 | CJ27: #REF! | CK27: 0 | CL27: 0 | CM27: 0 | CN27: #REF! | CO27: -48724 | CP27: 0 | CQ27: 77420.7 | CR27: 0 | CS27: 0 | CT27: 0 | CU27: 0 | CV27: 77420.7 | CW27: 0 | CX27: 48724 | CY27: 0 | CZ27: 0 | DA27: 0 | DB27: 48724 | DC27: 0 | DD27: 0 | DE27: 0 | DF27: 0 | DG27: 0 | DH27: 0 | DI27: 20605197583 | DJ27: ASOCIACION DE PRODUCTORES AGROECOLOGICOS DE PARIACOTO PROMOVIENDO VIDA SALUDABLE - APAPROVIS | DK27: 01 Asociación
A28: Cooperativa Agraria Purifor | B28: PALTA | C28: PALTA | D28: Ancash | E28: 020507 | F28: Ancash | G28: Bolognesi | H28: Colquioc | M28: 1 | N28: 1 | O28: 1 | P28: 1 | Q28: PAC | R28: 2022-2023-2024 - 2025 | S28: 4 | T28: SI | U28: SI | V28: 0 | W28: 0 | X28: 0 | Y28: 0 | Z28: 0 | AA28: 0 | AB28: 0 | AC28: 0 | AD28: 0 | AE28: 0 | AF28: 57 | AG28: 29 | AH28: 86 | AI28: 57 | AJ28: 29 | AK28: 86 | AL28: 61 | AM28: 25 | AN28: 86 | AO28: 59 | AP28: 25 | AQ28: 84 | AR28: 84 | AS28: 0 | AT28: 0 | AU28: 0 | AV28: 0 | AW28: 19 | AX28: 5 | AY28: 38 | AZ28: 0 | BA28: 31 | BB28: 3 | BC28: 12 | BD28: 0 | BE28: 0 | BF28: 0 | BG28: 0 | BH28: 0 | BI28: #REF! | BJ28: #REF! | BK28: 0 | BL28: 0 | BM28: 0 | BN28: #REF! | BO28: #REF! | BP28: 0 | BQ28: 0 | BR28: 0 | BS28: #REF! | BU28: 351529.15 | BV28: 0 | BW28: 351529.15 | BX28: #REF! | BY28: #REF! | BZ28: 100445.5 | CA28: 0 | CB28: 100445.5 | CC28: #REF! | CD28: -351529.15 | CE28: 362155.2 | CF28: 0 | CG28: 362155.2 | CH28: #REF! | CI28: -100445.5 | CJ28: #REF! | CK28: 488080 | CL28: 0 | CM28: 488080 | CN28: #REF! | CO28: -362155.2 | CP28: 0 | CQ28: 100445.5 | CR28: 0 | CS28: 0 | CT28: 0 | CU28: 0 | CV28: 100445.5 | CW28: 0 | CX28: 362155.2 | CY28: 0 | CZ28: 0 | DA28: 0 | DB28: 362155.2 | DC28: 0 | DD28: 470180 | DE28: 0 | DF28: 17900 | DG28: 0 | DH28: 488080 | DI28: 20407808666 | DJ28: COOPERATIVA AGRARIA PURIFOR - COOP PURIFOR | DK28: 02 Cooperativa
A29: Cooperativa Agraria Andina de Santa Cruz LTDA. | B29: KIWICHA | C29: KIWICHA | D29: Ancash | E29: 021208 | F29: Ancash | G29: Huaylas | H29: Santa Cruz | M29: 1 | O29: 1 | P29: 1 | Q29: PAC | R29: 2022-2024 - 2025 | S29: 3 | T29: SI | U29: SI | V29: 0 | W29: 0 | X29: 0 | Y29: 0 | Z29: 0 | AA29: 0 | AB29: 0 | AC29: 0 | AD29: 0 | AE29: 0 | AF29: 9 | AG29: 10 | AH29: 19 | AI29: 0 | AJ29: 0 | AK29: 0 | AL29: 8 | AM29: 10 | AN29: 18 | AO29: 10 | AP29: 17 | AQ29: 27 | AR29: 27 | AS29: 0 | AT29: 0 | AU29: 0 | AV29: 0 | AW29: 22 | AX29: 6 | AY29: 0 | AZ29: 0 | BA29: 28 | BB29: 0 | BC29: 31 | BD29: 0 | BE29: 0 | BF29: 0 | BG29: 0 | BH29: 0 | BI29: #REF! | BJ29: #REF! | BK29: 0 | BL29: 0 | BM29: 0 | BN29: #REF! | BO29: #REF! | BP29: 0 | BQ29: 0 | BR29: 0 | BS29: #REF! | BU29: 29700 | BV29: 0 | BW29: 29700 | BX29: #REF! | BY29: #REF! | BZ29: 0 | CA29: 0 | CB29: 0 | CC29: #REF! | CD29: -29700 | CE29: 65663.1 | CF29: 0 | CG29: 65663.1 | CH29: #REF! | CI29: 0 | CJ29: #REF! | CK29: 28801.99 | CL29: 0 | CM29: 28801.99 | CN29: #REF! | CO29: -65663.1 | CP29: 0 | CQ29: 0 | CR29: 0 | CS29: 0 | CT29: 0 | CU29: 0 | CV29: 0 | CW29: 0 | CX29: 65663.1 | CY29: 0 | CZ29: 0 | DA29: 0 | DB29: 65663.1 | DC29: 1143.9897 | DD29: 27658 | DE29: 0 | DF29: 0 | DG29: 0 | DH29: 28801.99 | DI29: 20604755230 | DJ29: COOPERATIVA AGRARIA ANDINA DE SANTA CRUZ LTDA. | DK29: 02 Cooperativa
A30: Cooperativa Agraria Kiwicha Wayi LTDA | B30: KIWICHA | C30: KIWICHA | D30: Ancash | E30: 021201 | F30: Ancash | G30: Huaylas | H30: Caraz | M30: 1 | N30: 1 | O30: 1 | P30: 1 | Q30: PAC | R30: 2022-2023-2024 - 2025 | S30: 4 | T30: SI | U30: SI | V30: 0 | W30: 0 | X30: 0 | Y30: 0 | Z30: 0 | AA30: 0 | AB30: 0 | AC30: 0 | AD30: 0 | AE30: 0 | AF30: 12 | AG30: 14 | AH30: 26 | AI30: 12 | AJ30: 14 | AK30: 26 | AL30: 11 | AM30: 14 | AN30: 25 | AO30: 11 | AP30: 14 | AQ30: 25 | AR30: 25 | AS30: 0 | AT30: 0 | AU30: 0 | AV30: 0 | AW30: 23 | AX30: 6 | AY30: 37 | AZ30: 3 | BA30: 25 | BB30: 3 | BC30: 29 | BD30: 2 | BE30: 0 | BF30: 0 | BG30: 0 | BH30: 0 | BI30: #REF! | BJ30: #REF! | BK30: 0 | BL30: 0 | BM30: 0 | BN30: #REF! | BO30: #REF! | BP30: 0 | BQ30: 0 | BR30: 0 | BS30: #REF! | BU30: 88340 | BV30: 0 | BW30: 88340 | BX30: #REF! | BY30: #REF! | BZ30: 132750.28 | CA30: 0 | CB30: 132750.28 | CC30: #REF! | CD30: -88340 | CE30: 197902 | CF30: 0 | CG30: 197902 | CH30: #REF! | CI30: -132750.28 | CJ30: #REF! | CK30: 102372.15 | CL30: 0 | CM30: 102372.15 | CN30: #REF! | CO30: -197902 | CP30: 0 | CQ30: 59729 | CR30: 0 | CS30: 73021.284 | CT30: 0 | CU30: 0 | CV30: 132750.28 | CW30: 0 | CX30: 197902 | CY30: 0 | CZ30: 0 | DA30: 0 | DB30: 197902 | DC30: 0 | DD30: 77932.1 | DE30: 24440.055 | DF30: 0 | DG30: 0 | DH30: 102372.15 | DI30: 20600558715 | DJ30: COOPERATIVA AGRARIA KIWICHA WAYI LTDA | DK30: 02 Cooperativa
A31: Asociacion Productores Agropecuarios Santa Rosa de Kiman Ayllu | B31: PALTA | C31: PALTA | D31: Ancash | E31: 021210 | F31: Ancash | G31: Huaylas | H31: Yuracmarca | M31: 1 | N31: 1 | O31: 1 | P31: 1 | Q31: PAC | R31: 2022-2023-2024 - 2025 | S31: 4 | T31: SI | U31: SI | V31: 0 | W31: 0 | X31: 0 | Y31: 0 | Z31: 0 | AA31: 0 | AB31: 0 | AC31: 0 | AD31: 0 | AE31: 0 | AF31: 13 | AG31: 7 | AH31: 20 | AI31: 13 | AJ31: 7 | AK31: 20 | AL31: 11 | AM31: 7 | AN31: 18 | AO31: 11 | AP31: 5 | AQ31: 16 | AR31: 16 | AS31: 0 | AT31: 0 | AU31: 0 | AV31: 0 | AW31: 19 | AX31: 5 | AY31: 44 | AZ31: 3 | BA31: 32 | BB31: 4 | BC31: 35 | BD31: 0 | BE31: 0 | BF31: 0 | BG31: 0 | BH31: 0 | BI31: #REF! | BJ31: #REF! | BK31: 0 | BL31: 0 | BM31: 0 | BN31: #REF! | BO31: #REF! | BP31: 0 | BQ31: 0 | BR31: 0 | BS31: #REF! | BU31: 180390 | BV31: 0 | BW31: 180390 | BX31: #REF! | BY31: #REF! | BZ31: 208400 | CA31: 0 | CB31: 208400 | CC31: #REF! | CD31: -180390 | CE31: 241803.66 | CF31: 0 | CG31: 241803.66 | CH31: #REF! | CI31: -208400 | CJ31: #REF! | CK31: 189229.51 | CL31: 0 | CM31: 189229.51 | CN31: #REF! | CO31: -241803.66 | CP31: 0 | CQ31: 208400 | CR31: 0 | CS31: 0 | CT31: 0 | CU31: 0 | CV31: 208400 | CW31: 0 | CX31: 241803.66 | CY31: 0 | CZ31: 0 | DA31: 0 | DB31: 241803.66 | DC31: 0 | DD31: 152584.41 | DE31: 0 | DF31: 0 | DG31: 36645.095 | DH31: 189229.51 | DI31: 20533718176 | DJ31: ASOCIACION PRODUCTORES AGROPECUARIOS SANTA ROSA DE KIMAN AYLLU | DK31: 01 Asociación
A32: Cooperativa Agraria Coyapapi | B32: PALTA | C32: PALTA | D32: Ancash | E32: 020110 | F32: Ancash | G32: Huaraz | H32: Pariacoto | M32: 1 | N32: 1 | O32: 1 | Q32: PAC | R32: 2022-2023-2024 | S32: 3 | T32: SI | U32: SI | V32: 0 | W32: 0 | X32: 0 | Y32: 0 | Z32: 0 | AA32: 0 | AB32: 0 | AC32: 0 | AD32: 0 | AE32: 0 | AF32: 132 | AG32: 19 | AH32: 151 | AI32: 132 | AJ32: 19 | AK32: 151 | AL32: 135 | AM32: 14 | AN32: 149 | AO32: 0 | AP32: 0 | AQ32: 0 | AR32: 149 | AS32: 0 | AT32: 0 | AU32: 0 | AV32: 0 | AW32: 17 | AX32: 5 | AY32: 37 | AZ32: 1 | BA32: 27 | BB32: 3 | BC32: 0 | BD32: 0 | BE32: 0 | BF32: 0 | BG32: 0 | BH32: 0 | BI32: #REF! | BJ32: #REF! | BK32: 0 | BL32: 0 | BM32: 0 | BN32: #REF! | BO32: #REF! | BP32: 0 | BQ32: 0 | BR32: 0 | BS32: #REF! | BU32: 363932.5 | BV32: 0 | BW32: 363932.5 | BX32: #REF! | BY32: #REF! | BZ32: 664665.6 | CA32: 0 | CB32: 664665.6 | CC32: #REF! | CD32: -363932.5 | CE32: 1376040 | CF32: 0 | CG32: 1376040 | CH32: #REF! | CI32: -664665.6 | CJ32: #REF! | CK32: 0 | CL32: 0 | CM32: 0 | CN32: #REF! | CO32: -1376040 | CP32: 0 | CQ32: 664665.6 | CR32: 0 | CS32: 0 | CT32: 0 | CU32: 0 | CV32: 664665.6 | CW32: 0 | CX32: 1376040 | CY32: 0 | CZ32: 0 | DA32: 0 | DB32: 1376040 | DC32: 0 | DD32: 0 | DE32: 0 | DF32: 0 | DG32: 0 | DH32: 0 | DI32: 20604218358 | DJ32: COOPERATIVA AGRARIA COYAPAPI | DK32: 02 Cooperativa
A33: Asociación de Fruticultores del Valle Pampas- Afruvap | B33: PALTA | C33: PALTA | D33: Apurimac | E33: 030601 | F33: Apurimac | G33: Chincheros | H33: Chincheros | J33: 1 | K33: 1 | Q33: PAC | R33: 2019-2020 | S33: 2 | T33: SI | U33: SI | V33: 0 | W33: 15 | X33: 12 | Y33: 27 | Z33: 20 | AA33: 4 | AB33: 24 | AC33: 0 | AD33: 0 | AE33: 0 | AF33: 0 | AG33: 0 | AH33: 0 | AI33: 0 | AJ33: 0 | AK33: 0 | AL33: 0 | AM33: 0 | AN33: 0 | AO33: 0 | AP33: 0 | AQ33: 0 | AR33: 24 | AS33: 0 | AT33: 2 | AU33: 0 | AV33: 0 | AW33: 0 | AX33: 0 | AY33: 0 | AZ33: 0 | BA33: 0 | BB33: 0 | BC33: 0 | BD33: 0 | BE33: 0 | BF33: 0 | BG33: 0 | BH33: 0 | BI33: #REF! | BJ33: #REF! | BK33: 324995 | BL33: 0 | BM33: 324995 | BN33: #REF! | BO33: #REF! | BP33: 0 | BQ33: 0 | BR33: 0 | BS33: #REF! | BU33: 0 | BV33: 0 | BW33: 0 | BX33: #REF! | BY33: #REF! | BZ33: 0 | CA33: 0 | CB33: 0 | CC33: #REF! | CD33: 0 | CE33: 0 | CF33: 0 | CG33: 0 | CH33: #REF! | CI33: 0 | CJ33: #REF! | CK33: 0 | CL33: 0 | CM33: 0 | CN33: #REF! | CO33: 0 | CP33: 0 | CQ33: 0 | CR33: 0 | CS33: 0 | CT33: 0 | CU33: 0 | CV33: 0 | CW33: 0 | CX33: 0 | CY33: 0 | CZ33: 0 | DA33: 0 | DB33: 0 | DC33: 0 | DD33: 0 | DE33: 0 | DF33: 0 | DG33: 0 | DH33: 0 | DI33: 20527890285 | DJ33: ASOCIACION DE FRUTICULTORES DEL VALLE PAMPAS- AFRUVAP | DK33: 01 Asociación
A34: Asociación de Productores Agropecuarios Organicos Valle Pampas - Apaovap | B34: PALTA | C34: PALTA | D34: Apurimac | E34: 030604 | F34: Apurimac | G34: Chincheros | H34: Huaccana | I34: 1 | J34: 1 | K34: 1 | Q34: PAC | R34: 2018-2019-2020 | S34: 3 | T34: SI | U34: SI | V34: 37 | W34: 13 | X34: 15 | Y34: 28 | Z34: 11 | AA34: 8 | AB34: 19 | AC34: 0 | AD34: 0 | AE34: 0 | AF34: 0 | AG34: 0 | AH34: 0 | AI34: 0 | AJ34: 0 | AK34: 0 | AL34: 0 | AM34: 0 | AN34: 0 | AO34: 0 | AP34: 0 | AQ34: 0 | AR34: 19 | AS34: 0 | AT34: 2 | AU34: 0 | AV34: 0 | AW34: 0 | AX34: 0 | AY34: 0 | AZ34: 0 | BA34: 0 | BB34: 0 | BC34: 0 | BD34: 0 | BE34: 0 | BF34: 1974706.2 | BG34: 0 | BH34: 1974706.2 | BI34: #REF! | BJ34: #REF! | BK34: 58325 | BL34: 0 | BM34: 58325 | BN34: #REF! | BO34: #REF! | BP34: 0 | BQ34: 0 | BR34: 0 | BS34: #REF! | BU34: 0 | BV34: 0 | BW34: 0 | BX34: #REF! | BY34: #REF! | BZ34: 0 | CA34: 0 | CB34: 0 | CC34: #REF! | CD34: 0 | CE34: 0 | CF34: 0 | CG34: 0 | CH34: #REF! | CI34: 0 | CJ34: #REF! | CK34: 0 | CL34: 0 | CM34: 0 | CN34: #REF! | CO34: 0 | CP34: 0 | CQ34: 0 | CR34: 0 | CS34: 0 | CT34: 0 | CU34: 0 | CV34: 0 | CW34: 0 | CX34: 0 | CY34: 0 | CZ34: 0 | DA34: 0 | DB34: 0 | DC34: 0 | DD34: 0 | DE34: 0 | DF34: 0 | DG34: 0 | DH34: 0 | DI34: 20490594265 | DJ34: ASOCIACION DE PRODUCTORES AGROPECUARIOS ORGANICOS VALLE PAMPAS - APAOVAP | DK34: 01 Asociación
A35: Cooperativa Agroindustrial Machupicchu LTDA | B35: QUINUA Y OTROS GRANOS | C35: QUINUA | D35: Apurimac | E35: 030213 | F35: Apurimac | G35: Andahuaylas | H35: San Jeronimo | I35: 1 | J35: 1 | K35: 1 | L35: 1 | N35: 1 | P35: 1 | Q35: PAC | R35: 2018-2019-2020-2021-2023 - 2025 | S35: 6 | T35: SI | U35: SI | V35: 463 | W35: 217 | X35: 44 | Y35: 261 | Z35: 210 | AA35: 43 | AB35: 253 | AC35: 190 | AD35: 50 | AE35: 240 | AF35: 0 | AG35: 0 | AH35: 0 | AI35: 120 | AJ35: 80 | AK35: 200 | AL35: 0 | AM35: 0 | AN35: 0 | AO35: 92 | AP35: 15 | AQ35: 107 | AR35: 107 | AS35: 0 | AT35: 7 | AU35: 22 | AV35: 4 | AW35: 0 | AX35: 0 | AY35: 25 | AZ35: 7 | BA35: 0 | BB35: 0 | BC35: 24 | BD35: 0 | BE35: 2120163.2 | BF35: 2632717.2 | BG35: 0 | BH35: 2632717.2 | BI35: #REF! | BJ35: #REF! | BK35: 1413126.6 | BL35: 951293.2 | BM35: 2364419.8 | BN35: #REF! | BO35: #REF! | BP35: 671996.57 | BQ35: 364049.58 | BR35: 1036046.2 | BS35: #REF! | BU35: 0 | BV35: 0 | BW35: 0 | BX35: #REF! | BY35: #REF! | BZ35: 2082623.3 | CA35: 0 | CB35: 2082623.3 | CC35: #REF! | CD35: 0 | CE35: 0 | CF35: 0 | CG35: 0 | CH35: #REF! | CI35: -2082623.3 | CJ35: #REF! | CK35: 108583.6 | CL35: 0 | CM35: 108583.6 | CN35: #REF! | CO35: 0 | CP35: 0 | CQ35: 0 | CR35: 0 | CS35: 2082623.3 | CT35: 0 | CU35: 0 | CV35: 2082623.3 | CW35: 0 | CX35: 0 | CY35: 0 | CZ35: 0 | DA35: 0 | DB35: 0 | DC35: 0 | DD35: 0 | DE35: 108583.6 | DF35: 0 | DG35: 0 | DH35: 108583.6 | DI35: 20490810146 | DJ35: COOPERATIVA AGRARIA MACHUPICCHU LTDA - CAGMA LTDA | DK35: 02 Cooperativa
A36: Cooperativa Agroindustrial Tierra Andina LTDA | B36: QUINUA Y OTROS GRANOS | C36: QUINUA | D36: Apurimac | E36: 030201 | F36: Apurimac | G36: Andahuaylas | H36: Andahuaylas | I36: 1 | J36: 1 | K36: 1 | L36: 1 | M36: 1 | N36: 1 | Q36: PAC | R36: 2018-2019-2020-2021-2022-2023 | S36: 6 | T36: SI | U36: SI | V36: 168 | W36: 93 | X36: 42 | Y36: 135 | Z36: 82 | AA36: 41 | AB36: 123 | AC36: 103 | AD36: 47 | AE36: 150 | AF36: 103 | AG36: 47 | AH36: 150 | AI36: 103 | AJ36: 47 | AK36: 150 | AL36: 0 | AM36: 0 | AN36: 0 | AO36: 0 | AP36: 0 | AQ36: 0 | AR36: 150 | AS36: 0 | AT36: 6 | AU36: 59 | AV36: 4 | AW36: 24 | AX36: 3 | AY36: 5 | AZ36: 0 | BA36: 0 | BB36: 0 | BC36: 0 | BD36: 0 | BE36: 0 | BF36: 471229 | BG36: 0 | BH36: 471229 | BI36: #REF! | BJ36: #REF! | BK36: 1076214.4 | BL36: 0 | BM36: 1076214.4 | BN36: #REF! | BO36: #REF! | BP36: 748371.58 | BQ36: 0 | BR36: 748371.58 | BS36: #REF! | BU36: 0 | BV36: 0 | BW36: 0 | BX36: #REF! | BY36: #REF! | BZ36: 200004 | CA36: 0 | CB36: 200004 | CC36: #REF! | CD36: 0 | CE36: 0 | CF36: 0 | CG36: 0 | CH36: #REF! | CI36: -200004 | CJ36: #REF! | CK36: 0 | CL36: 0 | CM36: 0 | CN36: #REF! | CO36: 0 | CP36: 0 | CQ36: 200004 | CR36: 0 | CS36: 0 | CT36: 0 | CU36: 0 | CV36: 200004 | CW36: 0 | CX36: 0 | CY36: 0 | CZ36: 0 | DA36: 0 | DB36: 0 | DC36: 0 | DD36: 0 | DE36: 0 | DF36: 0 | DG36: 0 | DH36: 0 | DI36: 20600998847 | DJ36: COOPERATIVA AGROINDUSTRIAL TIERRA ANDINA APURIMAC LTDA - CATAA LTDA | DK36: 02 Cooperativa
A37: Asociación de Mujeres Productoras de Tallarines de Casa Santo Domingo | B37: QUINUA Y OTROS GRANOS | C37: QUINUA | D37: Apurimac | E37: 030101 | F37: Apurimac | G37: Abancay | H37: Abancay | J37: 1 | K37: 1 | L37: 1 | Q37: PAC | R37: 2019-2020-2021 | S37: 3 | T37: SI | U37: SI | V37: 0 | W37: 4 | X37: 6 | Y37: 10 | Z37: 8 | AA37: 17 | AB37: 25 | AC37: 8 | AD37: 17 | AE37: 25 | AF37: 0 | AG37: 0 | AH37: 0 | AI37: 0 | AJ37: 0 | AK37: 0 | AL37: 0 | AM37: 0 | AN37: 0 | AO37: 0 | AP37: 0 | AQ37: 0 | AR37: 25 | AS37: 0 | AT37: 0 | AU37: 3 | AV37: 0 | AW37: 0 | AX37: 0 | AY37: 0 | AZ37: 0 | BA37: 0 | BB37: 0 | BC37: 0 | BD37: 0 | BE37: 0 | BF37: 48276 | BG37: 0 | BH37: 48276 | BI37: #REF! | BJ37: #REF! | BK37: 37127 | BL37: 0 | BM37: 37127 | BN37: #REF! | BO37: #REF! | BP37: 50168 | BQ37: 0 | BR37: 50168 | BS37: #REF! | BU37: 0 | BV37: 0 | BW37: 0 | BX37: #REF! | BY37: #REF! | BZ37: 0 | CA37: 0 | CB37: 0 | CC37: #REF! | CD37: 0 | CE37: 0 | CF37: 0 | CG37: 0 | CH37: #REF! | CI37: 0 | CJ37: #REF! | CK37: 0 | CL37: 0 | CM37: 0 | CN37: #REF! | CO37: 0 | CP37: 0 | CQ37: 0 | CR37: 0 | CS37: 0 | CT37: 0 | CU37: 0 | CV37: 0 | CW37: 0 | CX37: 0 | CY37: 0 | CZ37: 0 | DA37: 0 | DB37: 0 | DC37: 0 | DD37: 0 | DE37: 0 | DF37: 0 | DG37: 0 | DH37: 0 | DI37: 20490195301 | DJ37: ASOCIACION DE MUJERES PRODUCTORAS SANTO DOMINGO TALLARIN DE CASA | DK37: 01 Asociación
A38: Asociación de Productores Tambo Inca | B38: FIBRA DE ALPACA | C38: FIBRA DE ALPACA | D38: Apurimac | E38: 030406 | F38: Apurimac | G38: Aymaraes | H38: Cotaruse | I38: 1 | J38: 1 | Q38: PAC | R38: 2018-2019 | S38: 2 | T38: SI | U38: NO | V38: 46 | W38: 15 | X38: 2 | Y38: 17 | Z38: 0 | AA38: 0 | AB38: 0 | AC38: 0 | AD38: 0 | AE38: 0 | AF38: 0 | AG38: 0 | AH38: 0 | AI38: 0 | AJ38: 0 | AK38: 0 | AL38: 0 | AM38: 0 | AN38: 0 | AO38: 0 | AP38: 0 | AQ38: 0 | AR38: 17 | AS38: 0 | AT38: 0 | AU38: 0 | AV38: 0 | AW38: 0 | AX38: 0 | AY38: 0 | AZ38: 0 | BA38: 0 | BB38: 0 | BC38: 0 | BD38: 0 | BE38: 0 | BF38: 59829.9 | BG38: 0 | BH38: 59829.9 | BI38: #REF! | BJ38: #REF! | BK38: 0 | BL38: 0 | BM38: 0 | BN38: #REF! | BO38: #REF! | BP38: 0 | BQ38: 0 | BR38: 0 | BS38: #REF! | BU38: 0 | BV38: 0 | BW38: 0 | BX38: #REF! | BY38: #REF! | BZ38: 0 | CA38: 0 | CB38: 0 | CC38: #REF! | CD38: 0 | CE38: 0 | CF38: 0 | CG38: 0 | CH38: #REF! | CI38: 0 | CJ38: #REF! | CK38: 0 | CL38: 0 | CM38: 0 | CN38: #REF! | CO38: 0 | CP38: 0 | CQ38: 0 | CR38: 0 | CS38: 0 | CT38: 0 | CU38: 0 | CV38: 0 | CW38: 0 | CX38: 0 | CY38: 0 | CZ38: 0 | DA38: 0 | DB38: 0 | DC38: 0 | DD38: 0 | DE38: 0 | DF38: 0 | DG38: 0 | DH38: 0 | DI38: 20491172135 | DJ38: ASOCIACION DE PRODUCTORES DE ALPACAS TAMBOINCA | DK38: 01 Asociación
A39: Cooperativa Agraria de Servicios Múltiples Tesoro Chanka de Kishuara - Coopagros - Kishuara | B39: PAPA | C39: PAPA | D39: Apurimac | E39: 030207 | F39: Apurimac | G39: Andahuaylas | H39: Kishuara | I39: 1 | J39: 1 | K39: 1 | L39: 1 | Q39: PAC | R39: 2018-2019-2020-2021 | S39: 4 | T39: SI | U39: SI | V39: 40 | W39: 46 | X39: 6 | Y39: 52 | Z39: 24 | AA39: 5 | AB39: 29 | AC39: 24 | AD39: 5 | AE39: 29 | AF39: 0 | AG39: 0 | AH39: 0 | AI39: 0 | AJ39: 0 | AK39: 0 | AL39: 0 | AM39: 0 | AN39: 0 | AO39: 0 | AP39: 0 | AQ39: 0 | AR39: 29 | AS39: 0 | AT39: 2 | AU39: 45 | AV39: 6 | AW39: 0 | AX39: 0 | AY39: 0 | AZ39: 0 | BA39: 0 | BB39: 0 | BC39: 0 | BD39: 0 | BE39: 25160 | BF39: 540383.69 | BG39: 0 | BH39: 540383.69 | BI39: #REF! | BJ39: #REF! | BK39: 236000 | BL39: 0 | BM39: 236000 | BN39: #REF! | BO39: #REF! | BP39: 300149 | BQ39: 0 | BR39: 300149 | BS39: #REF! | BU39: 0 | BV39: 0 | BW39: 0 | BX39: #REF! | BY39: #REF! | BZ39: 0 | CA39: 0 | CB39: 0 | CC39: #REF! | CD39: 0 | CE39: 0 | CF39: 0 | CG39: 0 | CH39: #REF! | CI39: 0 | CJ39: #REF! | CK39: 0 | CL39: 0 | CM39: 0 | CN39: #REF! | CO39: 0 | CP39: 0 | CQ39: 0 | CR39: 0 | CS39: 0 | CT39: 0 | CU39: 0 | CV39: 0 | CW39: 0 | CX39: 0 | CY39: 0 | CZ39: 0 | DA39: 0 | DB39: 0 | DC39: 0 | DD39: 0 | DE39: 0 | DF39: 0 | DG39: 0 | DH39: 0 | DI39: 20491204436 | DJ39: COOPERATIVA AGRARIA DE SERVICIOS MULTIPLES TESORO CHANKA DE KISHUARA - COOPAGROS - KISHUARA | DK39: 02 Cooperativa
A40: Cooperativa Agraria Cafetalera Valle de Incahuasi | B40: CAFÉ | C40: CAFÉ | D40: Apurimac | E40: 030201 | F40: Apurimac | G40: Andahuaylas | H40: Andahuaylas | I40: 1 | J40: 1 | K40: 1 | L40: 1 | M40: 1 | N40: 1 | Q40: PAC | R40: 2018-2019-2020-2021-2022-2023 | S40: 6 | T40: SI | U40: SI | V40: 473 | W40: 374 | X40: 82 | Y40: 456 | Z40: 405 | AA40: 80 | AB40: 485 | AC40: 386 | AD40: 86 | AE40: 472 | AF40: 401 | AG40: 92 | AH40: 493 | AI40: 401 | AJ40: 92 | AK40: 493 | AL40: 0 | AM40: 0 | AN40: 0 | AO40: 0 | AP40: 0 | AQ40: 0 | AR40: 493 | AS40: 0 | AT40: 4 | AU40: 72 | AV40: 6 | AW40: 57 | AX40: 8 | AY40: 7 | AZ40: 18 | BA40: 0 | BB40: 0 | BC40: 0 | BD40: 0 | BE40: 0 | BF40: 22490.34 | BG40: 3082078.1 | BH40: 3104568.5 | BI40: #REF! | BJ40: #REF! | BK40: 0 | BL40: 8063872.3 | BM40: 8063872.3 | BN40: #REF! | BO40: #REF! | BP40: 0 | BQ40: 9080188.9 | BR40: 9080188.9 | BS40: #REF! | BU40: 1723946.9 | BV40: 12670661 | BW40: 14394608 | BX40: #REF! | BY40: #REF! | BZ40: 227111.23 | CA40: 7340280 | CB40: 7567391.3 | CC40: #REF! | CD40: -14394608 | CE40: 0 | CF40: 0 | CG40: 0 | CH40: #REF! | CI40: -7567391.3 | CJ40: #REF! | CK40: 0 | CL40: 0 | CM40: 0 | CN40: #REF! | CO40: 0 | CP40: 0 | CQ40: 0 | CR40: 0 | CS40: 7567391.3 | CT40: 0 | CU40: 0 | CV40: 7567391.3 | CW40: 0 | CX40: 0 | CY40: 0 | CZ40: 0 | DA40: 0 | DB40: 0 | DC40: 0 | DD40: 0 | DE40: 0 | DF40: 0 | DG40: 0 | DH40: 0 | DI40: 20527565376 | DJ40: COOPERATIVA AGRARIA CAFETALERA VALLE DE INCAHUASI | DK40: 02 Cooperativa
...

Sheet base 7
A1: Unnamed: 0 | B1: Unnamed: 1 | C1: Unnamed: 2 | D1: Unnamed: 3 | E1: Unnamed: 4 | F1: Unnamed: 5 | G1: Unnamed: 6 | H1: Unnamed: 7 | I1: Unnamed: 8 | J1: Unnamed: 9 | K1: Unnamed: 10 | L1: Unnamed: 11 | M1: Unnamed: 12 | N1: Unnamed: 13 | O1: Unnamed: 14 | P1: Unnamed: 15 | Q1: Unnamed: 16 | R1: Unnamed: 17 | S1: Unnamed: 18 | T1: Unnamed: 19 | U1: Unnamed: 20 | V1: Unnamed: 21 | W1: Unnamed: 22 | X1: VENTAS POR TIPO DE COMPROMABNTE año 2025 -12.01.26) | Y1: Unnamed: 24 | Z1: Unnamed: 25 | AA1: Unnamed: 26 | AB1: Unnamed: 27 | AC1: Unnamed: 28 | AD1: Unnamed: 29 | AE1: Unnamed: 30
O2: 2025 (Ciierre de Agosto 2025) | S2: 2025 (Cierre de 12.01.26)
A3: Nombre de la Organización | B3: PRODUCTO DOM | C3: PRODUCTO 1 | D3: SEDE | E3: Ubigeo | F3: DEPARTAMENTO | G3: Provincia | H3: Distrito | I3: TIPO DE CERTIFICADO | J3: 2025 | K3: SERVICIO | L3: AÑOS DE INTERVENCION | M3: AÑOS DE INTERVENCIÓN DESDE 2018 AL 2024 | N3: INTERVENCIÓN 2019 al 2025 | O3: BENF MASC 2025 | P3: BENF FEM 2025 | Q3: TOTAL BENF 2025 | R3: TOTAL VENTAS 2018 AL 2025 | S3: V. EJEC NACIONALES 2025 | T3: V. EJEC EXPORTACION 2025 | U3: VENTAS TOTALES 2025 | V3: INCREMENTOS VENTAS EN 2025 | W3: DIFERENCIA VENTAS 2025-2024 | X3: Boleta de Venta 2025 | Y3: Declaración Jurada 2025 | Z3: Factura 2025 | AA3: Guía de Remisión 2025 | AB3: Liquidación de Compra 2025 | AC3: Total general 2025 | AD3: RUC | AE3: Tipo de Organización* (Asociación/Cooperativa/CCNN, Comunidad Campesina y otros.)
A4: Cooperativa Agraria de Usuarios de Pequeños Productores del PERU | B4: MANGO | C4: MANGO | D4: Ancash | E4: 020801 | F4: Ancash | G4: Casma | H4: Casma | I4: FAIR TRADE | J4: 1 | K4: PAC | L4: 2025 | M4: 1 | N4: SI | O4: 15 | P4: 9 | Q4: 24 | X4: 0 | Y4: 399056.4 | Z4: 866144.87 | AA4: 0 | AB4: 0 | AC4: 1265201.3 | AD4: 20601575184 | AE4: Cooperativa
A5: Cooperativa Agraria Agrofrutos Organicos | B5: MANGO | C5: MANGO | D5: Lambayeque | E5: 140307 | F5: Lambayeque | G5: Lambayeque | H5: Motupe | I5: ORGANICO | J5: 1 | K5: PAC | L5: 2025 | M5: 1 | O5: 62 | P5: 10 | Q5: 72 | R5: #REF! | S5: 22435.002 | T5: 0 | U5: 22435.002 | V5: #REF! | X5: 0 | Y5: 0 | Z5: 22435.002 | AA5: 0 | AB5: 0 | AC5: 22435.002 | AD5: 20613899287 | AE5: Cooperativa
A6: Cooperativa Agraria de Usuarios Aspraosra LTDA | B6: BANANO | C6: BANANO | D6: Piura | F6: Piura | G6: Morropon | H6: Buenos Aires | I6: ORGANICO/GLOBAL GAP | J6: 1 | K6: PAC | L6: 2025 | M6: 1 | O6: 22 | P6: 14 | Q6: 36 | R6: #REF! | S6: 0 | T6: 781855.2 | U6: 781855.2 | V6: #REF! | X6: 0 | Y6: 0 | Z6: 781855.2 | AA6: 0 | AB6: 0 | AC6: 781855.2 | AD6: 20526179367 | AE6: Cooperativa
A7: Asociacion de Agricultores Innovadores de Ancash, Ediflor | B7: PALTA | C7: PALTA | D7: Ancash | F7: Ancash | G7: Santa | H7: Chimbote | I7: GLOBAL GAP | J7: 1 | K7: PAC | L7: 2025 | O7: 4 | P7: 7 | Q7: 11 | R7: #REF! | S7: 120000 | T7: 0 | U7: 120000 | V7: #REF! | X7: 0 | Y7: 120000 | Z7: 0 | AA7: 0 | AB7: 0 | AC7: 120000 | AD7: 20611531088 | AE7: Asociacion
A8: Asociación de Productores Agropecuarios Chaskas de Huancallama-Apachahua | B8: PALTA | C8: PALTA | D8: Huancavelica | E8: 090409 | F8: Huancavelica | G8: Castrovirreyna | H8: Mollepampa | I8: GLOBAL GAP | J8: 1 | K8: PAC | L8: 2025 | M8: 1 | O8: 20 | P8: 4 | Q8: 24 | R8: #REF! | S8: 0 | T8: 0 | U8: 0 | V8: #REF! | X8: 0 | Y8: 0 | Z8: 0 | AA8: 0 | AB8: 0 | AC8: 0 | AD8: 20607063576 | AE8: Asociación
A9: Asociacion de Agricultores de Paltos en Huamampali - Alto Laran | B9: PALTA | C9: PALTA | D9: Ica | F9: Ica | G9: Chincha | H9: Huamanpali | I9: GLOBAL GAP | J9: 1 | K9: PAC | L9: 2025 | M9: 1 | O9: 19 | P9: 2 | Q9: 21 | R9: 0 | S9: 0 | T9: 0 | U9: 0 | V9: 0 | W9: 0 | X9: 0 | Y9: 0 | Z9: 0 | AA9: 0 | AB9: 0 | AC9: 0 | AD9: 20605371869 | AE9: Asociación

Sheet base consolidad MIDAGRI
