Workbook

Sheet INSTRUCCIONES
A1: PLANTILLA ÍNDICE PVE — PACTO VERDE EUROPEO
A2: Clasificación de preparación y vulnerabilidad de cooperativas café y cacao ante el EUDR / Pacto Verde Europeo
A4: PROPÓSITO
A7: CÓMO FUNCIONA
A10: FLUJO DE USO
A11: Paso 1 | B11: Revisar PONDERADORES — los pesos son editables en celdas amarillas
A12: Paso 2 | B12: Ir a MATRIZ_174 — verificar/actualizar FOB, país destino, certificaciones
A13: Paso 3 | B13: Para cada organización con FOB UE > 0, completar PREGUNTAS_PROXY usando llamada telefónica o visita de 30 min
A14: Paso 4 | B14: Revisar SCORECARDS — el semáforo se actualiza automáticamente
A15: Paso 5 | B15: Usar RADAR_BRECHAS para comparación por departamento
A17: SEMÁFORO
A18: 🔴 Crítico (0–33) | B18: La cooperativa no puede generar la declaración EUDR. Riesgo de rechazo en frontera UE desde dic 2026.
A19: 🟡 Vulnerable (34–66) | B19: Tiene infraestructura parcial pero incompleta. Necesita inversión en geolocalización y proceso.
A20: 🟢 Preparado (67–100) | B20: Cumple los requisitos mínimos. Requiere monitoreo de actualización.
A22: NOTAS IMPORTANTES

Sheet ISCAM_Score
A1: ISCAM — ISA-Completo = 0.70×ISA-EUDR + 0.30×ISA-PV | IP × IV → RE | Café y Cacao Perú — 174 organizaciones
A2: ISA-Completo = 0.70×ISA-EUDR + 0.30×ISA-PV | ISA-EUDR = 0.875×Núcleo(D1–D7, geom.) + 0.125×Extendido(D8–D9, arit.) | ISA-PV = Promedio(D12:D15) | IP = Promedio(IP1..IP5) | IV = Promedio(IV1..IV5) | RE = IV×(1−IP/100) | Corte 2×2: 50
A3: RUC | B3: Razón Social | C3: Depto | D3: FOB UE USD | E3: D1 — Clasific. Regulatoria | F3: D2 — Trazabilidad (SCORECARDS H) | G3: D3 — Legalidad (OSCE/Neon) | H3: D4 — Deforestación Cero | I3: D5 — Diligencia Debida | J3: D6 — Capacidad Digital | K3: D7 — Presión Comprador | L3: D8 — Gobernanza | M3: D9 — Riesgo Financiero | N3: D10 — Certificac. | O3: D11 — Género e Inclusión | P3: IP1 Trazabilidad D2 | Q3: IP2 √(D3×D4) | R3: IP3 (D5+D6+D8)/3 | S3: IP4 (D6+D2)/2 | T3: IP5 (D7+D9+Cert)/3 | U3: IV1 Presión EU ISA-PV×50 | V3: IV2 D1 (base=50) | W3: IV3 ha>0? → 65:35 | X3: IV4 Cert=0? → 70:30 | Y3: IV5 Tipo Asoc → 65:40 | Z3: IP Preparación | AA3: IV Vulnerabilidad | AB3: RE Exclusión | AC3: Tipología 2×2 ISCAM | AD3: Banderas Duras | AE3: D12 Huella Carbono | AF3: D13 Reporte Sostenib. | AG3: D14 Economía Circular | AH3: D15 Fitosanitario | AI3: ISA-PV Promedio D12:D15 | AJ3: P_Global Promedio P1:P14 | AK3: ISA-EUDR Geom.D1–D7 + Arit.D8–D9 | AL3: ISA-Completo 0.70×EUDR +0.30×PV
A4: 20118578415 | B4: CENT.DE COOP.AGR. CAF.VALLES SANDIA LTDA | C4: PUNO | D4: 2553623.3 | E4: 0 | F4: =IFERROR(SCORECARDS!H3,"") -> 0 | G4: =IFERROR(MATRIZ_174!U3,0) -> 1 | H4: 0 | I4: =IFERROR(SCORECARDS!I3,"") -> 0 | J4: =IFERROR(SCORECARDS!J3,"") -> 0 | K4: 0 | L4: 0 | M4: 0 | N4: 0 | O4: 0 | P4: =IFERROR(F4,0) -> 0 | Q4: =IFERROR(SQRT(G4*H4),0) -> 0 | R4: =IFERROR((I4+J4+L4)/3,0) -> 0 | S4: =IFERROR((J4+F4)/2,0) -> 0 | T4: =IFERROR((K4+M4+MATRIZ_174!O3)/3,0) -> 0 | U4: =IFERROR(MATRIZ_174!AP3*50,0) -> 6.25 | V4: =IFERROR(IF(E4=0,50,E4),0) -> 50 | W4: =IF(MATRIZ_174!R3>0,65,35) -> 35 | X4: =IF(MATRIZ_174!O3=0,70,30) -> 70 | Y4: =IF(OR(MATRIZ_174!P3="ASOCIACION",MATRIZ_174!P3="PENDIENTE"),65,40) -> 65 | Z4: =IFERROR(ROUND(AVERAGE(P4,Q4,R4,S4,T4),1),0) -> 0 | AA4: =IFERROR(ROUND(AVERAGE(U4,V4,W4,X4,Y4),1),0) -> 45.3 | AB4: =IFERROR(ROUND(AA4*(1-Z4/100),1),0) -> 45.3 | AC4: =IF(AND(Z4>=50,AA4<50),"🟢 Resilientes",IF(AND(Z4>=50,AA4>=50),"🟠 Expuestas Adaptables",IF(AND(Z4<50,AA4<50),"⬜ Riesgo Latente","🔴 Riesgo Crítico"))) -> ⬜ Riesgo Latente | AD4: =IF(G4=0,"🚫 Inh. vigente OSCE","") | AE4: =IFERROR(MATRIZ_174!W3,0) -> 1 | AF4: =IFERROR(MATRIZ_174!X3,0) -> 0 | AG4: =IFERROR(MATRIZ_174!Y3,0) -> 0 | AH4: =IFERROR(MATRIZ_174!Z3,0) -> 0 | AI4: =IFERROR(MATRIZ_174!AP3,"N/A") -> 0.125 | AJ4: =IFERROR(MATRIZ_174!AO3,"N/A") -> 0 | AK4: =IFERROR(ROUND(POWER((E4*F4*G4*H4*I4*J4*K4),1/7)*0.875+((L4+M4)/2)*0.125,1),"N/A") -> 0 | AL4: =IFERROR(IF(AK4="N/A","N/A",ROUND(0.7*AK4+0.3*AI4,1)),"N/A") -> 0
A5: 20129156083 | B5: COOP AGRARIA CAFET VALLE RIO APURIMAC | C5: AYACUCHO | D5: 0 | E5: 0 | F5: =IFERROR(SCORECARDS!H4,"") -> 0 | G5: =IFERROR(MATRIZ_174!U4,0) -> 0 | H5: 0 | I5: =IFERROR(SCORECARDS!I4,"") -> 0 | J5: =IFERROR(SCORECARDS!J4,"") -> 0 | K5: 0 | L5: 0 | M5: 0 | N5: 0 | O5: 0 | P5: =IFERROR(F5,0) -> 0 | Q5: =IFERROR(SQRT(G5*H5),0) -> 0 | R5: =IFERROR((I5+J5+L5)/3,0) -> 0 | S5: =IFERROR((J5+F5)/2,0) -> 0 | T5: =IFERROR((K5+M5+MATRIZ_174!O4)/3,0) -> 0 | U5: =IFERROR(MATRIZ_174!AP4*50,0) -> 0 | V5: =IFERROR(IF(E5=0,50,E5),0) -> 50 | W5: =IF(MATRIZ_174!R4>0,65,35) -> 35 | X5: =IF(MATRIZ_174!O4=0,70,30) -> 70 | Y5: =IF(OR(MATRIZ_174!P4="ASOCIACION",MATRIZ_174!P4="PENDIENTE"),65,40) -> 65 | Z5: =IFERROR(ROUND(AVERAGE(P5,Q5,R5,S5,T5),1),0) -> 0 | AA5: =IFERROR(ROUND(AVERAGE(U5,V5,W5,X5,Y5),1),0) -> 44 | AB5: =IFERROR(ROUND(AA5*(1-Z5/100),1),0) -> 44 | AC5: =IF(AND(Z5>=50,AA5<50),"🟢 Resilientes",IF(AND(Z5>=50,AA5>=50),"🟠 Expuestas Adaptables",IF(AND(Z5<50,AA5<50),"⬜ Riesgo Latente","🔴 Riesgo Crítico"))) -> ⬜ Riesgo Latente | AD5: =IF(G5=0,"🚫 Inh. vigente OSCE","") -> 🚫 Inh. vigente OSCE | AE5: =IFERROR(MATRIZ_174!W4,0) -> 0 | AF5: =IFERROR(MATRIZ_174!X4,0) -> 0 | AG5: =IFERROR(MATRIZ_174!Y4,0) -> 0 | AH5: =IFERROR(MATRIZ_174!Z4,0) -> 0 | AI5: =IFERROR(MATRIZ_174!AP4,"N/A") -> 0 | AJ5: =IFERROR(MATRIZ_174!AO4,"N/A") -> 0 | AK5: =IFERROR(ROUND(POWER((E5*F5*G5*H5*I5*J5*K5),1/7)*0.875+((L5+M5)/2)*0.125,1),"N/A") -> 0 | AL5: =IFERROR(IF(AK5="N/A","N/A",ROUND(0.7*AK5+0.3*AI5,1)),"N/A") -> 0
A6: 20129529530 | B6: COOP AGRARIA CAFETALERA SATIPO LTDA | C6: JUNIN | D6: 4801984.1 | E6: 0 | F6: =IFERROR(SCORECARDS!H5,"") -> 0 | G6: =IFERROR(MATRIZ_174!U5,0) -> 1 | H6: 0 | I6: =IFERROR(SCORECARDS!I5,"") -> 0 | J6: =IFERROR(SCORECARDS!J5,"") -> 0 | K6: 0 | L6: 0 | M6: 0 | N6: 0 | O6: 0 | P6: =IFERROR(F6,0) -> 0 | Q6: =IFERROR(SQRT(G6*H6),0) -> 0 | R6: =IFERROR((I6+J6+L6)/3,0) -> 0 | S6: =IFERROR((J6+F6)/2,0) -> 0 | T6: =IFERROR((K6+M6+MATRIZ_174!O5)/3,0) -> 0 | U6: =IFERROR(MATRIZ_174!AP5*50,0) -> 6.25 | V6: =IFERROR(IF(E6=0,50,E6),0) -> 50 | W6: =IF(MATRIZ_174!R5>0,65,35) -> 35 | X6: =IF(MATRIZ_174!O5=0,70,30) -> 70 | Y6: =IF(OR(MATRIZ_174!P5="ASOCIACION",MATRIZ_174!P5="PENDIENTE"),65,40) -> 65 | Z6: =IFERROR(ROUND(AVERAGE(P6,Q6,R6,S6,T6),1),0) -> 0 | AA6: =IFERROR(ROUND(AVERAGE(U6,V6,W6,X6,Y6),1),0) -> 45.3 | AB6: =IFERROR(ROUND(AA6*(1-Z6/100),1),0) -> 45.3 | AC6: =IF(AND(Z6>=50,AA6<50),"🟢 Resilientes",IF(AND(Z6>=50,AA6>=50),"🟠 Expuestas Adaptables",IF(AND(Z6<50,AA6<50),"⬜ Riesgo Latente","🔴 Riesgo Crítico"))) -> ⬜ Riesgo Latente | AD6: =IF(G6=0,"🚫 Inh. vigente OSCE","") | AE6: =IFERROR(MATRIZ_174!W5,0) -> 1 | AF6: =IFERROR(MATRIZ_174!X5,0) -> 0 | AG6: =IFERROR(MATRIZ_174!Y5,0) -> 0 | AH6: =IFERROR(MATRIZ_174!Z5,0) -> 0 | AI6: =IFERROR(MATRIZ_174!AP5,"N/A") -> 0.125 | AJ6: =IFERROR(MATRIZ_174!AO5,"N/A") -> 0 | AK6: =IFERROR(ROUND(POWER((E6*F6*G6*H6*I6*J6*K6),1/7)*0.875+((L6+M6)/2)*0.125,1),"N/A") -> 0 | AL6: =IFERROR(IF(AK6="N/A","N/A",ROUND(0.7*AK6+0.3*AI6,1)),"N/A") -> 0
A7: 20132489824 | B7: COOPERATIVA AGRARIA CAFETALERA CHANCAMAYO LTDA. N° 008-B-VII | C7: CUSCO | D7: 0 | E7: 0 | F7: =IFERROR(SCORECARDS!H6,"") -> 0 | G7: =IFERROR(MATRIZ_174!U6,0) -> 0 | H7: 0 | I7: =IFERROR(SCORECARDS!I6,"") -> 0 | J7: =IFERROR(SCORECARDS!J6,"") -> 0 | K7: 0 | L7: 0 | M7: 0 | N7: 0 | O7: 0 | P7: =IFERROR(F7,0) -> 0 | Q7: =IFERROR(SQRT(G7*H7),0) -> 0 | R7: =IFERROR((I7+J7+L7)/3,0) -> 0 | S7: =IFERROR((J7+F7)/2,0) -> 0 | T7: =IFERROR((K7+M7+MATRIZ_174!O6)/3,0) -> 0 | U7: =IFERROR(MATRIZ_174!AP6*50,0) -> 6.25 | V7: =IFERROR(IF(E7=0,50,E7),0) -> 50 | W7: =IF(MATRIZ_174!R6>0,65,35) -> 65 | X7: =IF(MATRIZ_174!O6=0,70,30) -> 70 | Y7: =IF(OR(MATRIZ_174!P6="ASOCIACION",MATRIZ_174!P6="PENDIENTE"),65,40) -> 65 | Z7: =IFERROR(ROUND(AVERAGE(P7,Q7,R7,S7,T7),1),0) -> 0 | AA7: =IFERROR(ROUND(AVERAGE(U7,V7,W7,X7,Y7),1),0) -> 51.3 | AB7: =IFERROR(ROUND(AA7*(1-Z7/100),1),0) -> 51.3 | AC7: =IF(AND(Z7>=50,AA7<50),"🟢 Resilientes",IF(AND(Z7>=50,AA7>=50),"🟠 Expuestas Adaptables",IF(AND(Z7<50,AA7<50),"⬜ Riesgo Latente","🔴 Riesgo Crítico"))) -> 🔴 Riesgo Crítico | AD7: =IF(G7=0,"🚫 Inh. vigente OSCE","") -> 🚫 Inh. vigente OSCE | AE7: =IFERROR(MATRIZ_174!W6,0) -> 1 | AF7: =IFERROR(MATRIZ_174!X6,0) -> 0 | AG7: =IFERROR(MATRIZ_174!Y6,0) -> 0 | AH7: =IFERROR(MATRIZ_174!Z6,0) -> 0 | AI7: =IFERROR(MATRIZ_174!AP6,"N/A") -> 0.125 | AJ7: =IFERROR(MATRIZ_174!AO6,"N/A") -> 0 | AK7: =IFERROR(ROUND(POWER((E7*F7*G7*H7*I7*J7*K7),1/7)*0.875+((L7+M7)/2)*0.125,1),"N/A") -> 0 | AL7: =IFERROR(IF(AK7="N/A","N/A",ROUND(0.7*AK7+0.3*AI7,1)),"N/A") -> 0
A8: 20132505455 | B8: COOPERATIVA AGRARIA CAFETALERA AGUILAYOC LTDA. 084 | C8: CUSCO | D8: 0 | E8: 0 | F8: =IFERROR(SCORECARDS!H7,"") -> 0 | G8: =IFERROR(MATRIZ_174!U7,0) -> 0 | H8: 0 | I8: =IFERROR(SCORECARDS!I7,"") -> 0 | J8: =IFERROR(SCORECARDS!J7,"") -> 0 | K8: 0 | L8: 0 | M8: 0 | N8: 0 | O8: 0 | P8: =IFERROR(F8,0) -> 0 | Q8: =IFERROR(SQRT(G8*H8),0) -> 0 | R8: =IFERROR((I8+J8+L8)/3,0) -> 0 | S8: =IFERROR((J8+F8)/2,0) -> 0 | T8: =IFERROR((K8+M8+MATRIZ_174!O7)/3,0) -> 0 | U8: =IFERROR(MATRIZ_174!AP7*50,0) -> 6.25 | V8: =IFERROR(IF(E8=0,50,E8),0) -> 50 | W8: =IF(MATRIZ_174!R7>0,65,35) -> 65 | X8: =IF(MATRIZ_174!O7=0,70,30) -> 70 | Y8: =IF(OR(MATRIZ_174!P7="ASOCIACION",MATRIZ_174!P7="PENDIENTE"),65,40) -> 65 | Z8: =IFERROR(ROUND(AVERAGE(P8,Q8,R8,S8,T8),1),0) -> 0 | AA8: =IFERROR(ROUND(AVERAGE(U8,V8,W8,X8,Y8),1),0) -> 51.3 | AB8: =IFERROR(ROUND(AA8*(1-Z8/100),1),0) -> 51.3 | AC8: =IF(AND(Z8>=50,AA8<50),"🟢 Resilientes",IF(AND(Z8>=50,AA8>=50),"🟠 Expuestas Adaptables",IF(AND(Z8<50,AA8<50),"⬜ Riesgo Latente","🔴 Riesgo Crítico"))) -> 🔴 Riesgo Crítico | AD8: =IF(G8=0,"🚫 Inh. vigente OSCE","") -> 🚫 Inh. vigente OSCE | AE8: =IFERROR(MATRIZ_174!W7,0) -> 1 | AF8: =IFERROR(MATRIZ_174!X7,0) -> 0 | AG8: =IFERROR(MATRIZ_174!Y7,0) -> 0 | AH8: =IFERROR(MATRIZ_174!Z7,0) -> 0 | AI8: =IFERROR(MATRIZ_174!AP7,"N/A") -> 0.125 | AJ8: =IFERROR(MATRIZ_174!AO7,"N/A") -> 0 | AK8: =IFERROR(ROUND(POWER((E8*F8*G8*H8*I8*J8*K8),1/7)*0.875+((L8+M8)/2)*0.125,1),"N/A") -> 0 | AL8: =IFERROR(IF(AK8="N/A","N/A",ROUND(0.7*AK8+0.3*AI8,1)),"N/A") -> 0
A9: 20132509795 | B9: COOPERATIVA AGRARIA CAFETALERA JOSE OLAYA LTDA N° 252 | C9: CUSCO | D9: 1238541.8 | E9: 0 | F9: =IFERROR(SCORECARDS!H8,"") -> 0 | G9: =IFERROR(MATRIZ_174!U8,0) -> 1 | H9: 0 | I9: =IFERROR(SCORECARDS!I8,"") -> 0 | J9: =IFERROR(SCORECARDS!J8,"") -> 0 | K9: 0 | L9: 0 | M9: 0 | N9: 0 | O9: 0 | P9: =IFERROR(F9,0) -> 0 | Q9: =IFERROR(SQRT(G9*H9),0) -> 0 | R9: =IFERROR((I9+J9+L9)/3,0) -> 0 | S9: =IFERROR((J9+F9)/2,0) -> 0 | T9: =IFERROR((K9+M9+MATRIZ_174!O8)/3,0) -> 0 | U9: =IFERROR(MATRIZ_174!AP8*50,0) -> 6.25 | V9: =IFERROR(IF(E9=0,50,E9),0) -> 50 | W9: =IF(MATRIZ_174!R8>0,65,35) -> 35 | X9: =IF(MATRIZ_174!O8=0,70,30) -> 70 | Y9: =IF(OR(MATRIZ_174!P8="ASOCIACION",MATRIZ_174!P8="PENDIENTE"),65,40) -> 65 | Z9: =IFERROR(ROUND(AVERAGE(P9,Q9,R9,S9,T9),1),0) -> 0 | AA9: =IFERROR(ROUND(AVERAGE(U9,V9,W9,X9,Y9),1),0) -> 45.3 | AB9: =IFERROR(ROUND(AA9*(1-Z9/100),1),0) -> 45.3 | AC9: =IF(AND(Z9>=50,AA9<50),"🟢 Resilientes",IF(AND(Z9>=50,AA9>=50),"🟠 Expuestas Adaptables",IF(AND(Z9<50,AA9<50),"⬜ Riesgo Latente","🔴 Riesgo Crítico"))) -> ⬜ Riesgo Latente | AD9: =IF(G9=0,"🚫 Inh. vigente OSCE","") | AE9: =IFERROR(MATRIZ_174!W8,0) -> 1 | AF9: =IFERROR(MATRIZ_174!X8,0) -> 0 | AG9: =IFERROR(MATRIZ_174!Y8,0) -> 0 | AH9: =IFERROR(MATRIZ_174!Z8,0) -> 0 | AI9: =IFERROR(MATRIZ_174!AP8,"N/A") -> 0.125 | AJ9: =IFERROR(MATRIZ_174!AO8,"N/A") -> 0 | AK9: =IFERROR(ROUND(POWER((E9*F9*G9*H9*I9*J9*K9),1/7)*0.875+((L9+M9)/2)*0.125,1),"N/A") -> 0 | AL9: =IFERROR(IF(AK9="N/A","N/A",ROUND(0.7*AK9+0.3*AI9,1)),"N/A") -> 0
A10: 20132509876 | B10: COOPERATIVA AGRARIA CAFETALERA MARANURA LTDA. 129 | C10: CUSCO | D10: 0 | E10: 0 | F10: =IFERROR(SCORECARDS!H9,"") -> 0 | G10: =IFERROR(MATRIZ_174!U9,0) -> 0 | H10: 0 | I10: =IFERROR(SCORECARDS!I9,"") -> 0 | J10: =IFERROR(SCORECARDS!J9,"") -> 0 | K10: 0 | L10: 0 | M10: 0 | N10: 0 | O10: 0 | P10: =IFERROR(F10,0) -> 0 | Q10: =IFERROR(SQRT(G10*H10),0) -> 0 | R10: =IFERROR((I10+J10+L10)/3,0) -> 0 | S10: =IFERROR((J10+F10)/2,0) -> 0 | T10: =IFERROR((K10+M10+MATRIZ_174!O9)/3,0) -> 0 | U10: =IFERROR(MATRIZ_174!AP9*50,0) -> 0 | V10: =IFERROR(IF(E10=0,50,E10),0) -> 50 | W10: =IF(MATRIZ_174!R9>0,65,35) -> 35 | X10: =IF(MATRIZ_174!O9=0,70,30) -> 70 | Y10: =IF(OR(MATRIZ_174!P9="ASOCIACION",MATRIZ_174!P9="PENDIENTE"),65,40) -> 65 | Z10: =IFERROR(ROUND(AVERAGE(P10,Q10,R10,S10,T10),1),0) -> 0 | AA10: =IFERROR(ROUND(AVERAGE(U10,V10,W10,X10,Y10),1),0) -> 44 | AB10: =IFERROR(ROUND(AA10*(1-Z10/100),1),0) -> 44 | AC10: =IF(AND(Z10>=50,AA10<50),"🟢 Resilientes",IF(AND(Z10>=50,AA10>=50),"🟠 Expuestas Adaptables",IF(AND(Z10<50,AA10<50),"⬜ Riesgo Latente","🔴 Riesgo Crítico"))) -> ⬜ Riesgo Latente | AD10: =IF(G10=0,"🚫 Inh. vigente OSCE","") -> 🚫 Inh. vigente OSCE | AE10: =IFERROR(MATRIZ_174!W9,0) -> 0 | AF10: =IFERROR(MATRIZ_174!X9,0) -> 0 | AG10: =IFERROR(MATRIZ_174!Y9,0) -> 0 | AH10: =IFERROR(MATRIZ_174!Z9,0) -> 0 | AI10: =IFERROR(MATRIZ_174!AP9,"N/A") -> 0 | AJ10: =IFERROR(MATRIZ_174!AO9,"N/A") -> 0 | AK10: =IFERROR(ROUND(POWER((E10*F10*G10*H10*I10*J10*K10),1/7)*0.875+((L10+M10)/2)*0.125,1),"N/A") -> 0 | AL10: =IFERROR(IF(AK10="N/A","N/A",ROUND(0.7*AK10+0.3*AI10,1)),"N/A") -> 0
A11: 20132517119 | B11: COOPERATIVA AGRARIA CAFETALERA MATEO PUMACAHUA LTDA N° 185 | C11: CUSCO | D11: 0 | E11: 0 | F11: =IFERROR(SCORECARDS!H10,"") -> 0 | G11: =IFERROR(MATRIZ_174!U10,0) -> 0 | H11: 0 | I11: =IFERROR(SCORECARDS!I10,"") -> 0 | J11: =IFERROR(SCORECARDS!J10,"") -> 0 | K11: 0 | L11: 0 | M11: 0 | N11: 0 | O11: 0 | P11: =IFERROR(F11,0) -> 0 | Q11: =IFERROR(SQRT(G11*H11),0) -> 0 | R11: =IFERROR((I11+J11+L11)/3,0) -> 0 | S11: =IFERROR((J11+F11)/2,0) -> 0 | T11: =IFERROR((K11+M11+MATRIZ_174!O10)/3,0) -> 0 | U11: =IFERROR(MATRIZ_174!AP10*50,0) -> 6.25 | V11: =IFERROR(IF(E11=0,50,E11),0) -> 50 | W11: =IF(MATRIZ_174!R10>0,65,35) -> 65 | X11: =IF(MATRIZ_174!O10=0,70,30) -> 70 | Y11: =IF(OR(MATRIZ_174!P10="ASOCIACION",MATRIZ_174!P10="PENDIENTE"),65,40) -> 65 | Z11: =IFERROR(ROUND(AVERAGE(P11,Q11,R11,S11,T11),1),0) -> 0 | AA11: =IFERROR(ROUND(AVERAGE(U11,V11,W11,X11,Y11),1),0) -> 51.3 | AB11: =IFERROR(ROUND(AA11*(1-Z11/100),1),0) -> 51.3 | AC11: =IF(AND(Z11>=50,AA11<50),"🟢 Resilientes",IF(AND(Z11>=50,AA11>=50),"🟠 Expuestas Adaptables",IF(AND(Z11<50,AA11<50),"⬜ Riesgo Latente","🔴 Riesgo Crítico"))) -> 🔴 Riesgo Crítico | AD11: =IF(G11=0,"🚫 Inh. vigente OSCE","") -> 🚫 Inh. vigente OSCE | AE11: =IFERROR(MATRIZ_174!W10,0) -> 1 | AF11: =IFERROR(MATRIZ_174!X10,0) -> 0 | AG11: =IFERROR(MATRIZ_174!Y10,0) -> 0 | AH11: =IFERROR(MATRIZ_174!Z10,0) -> 0 | AI11: =IFERROR(MATRIZ_174!AP10,"N/A") -> 0.125 | AJ11: =IFERROR(MATRIZ_174!AO10,"N/A") -> 0 | AK11: =IFERROR(ROUND(POWER((E11*F11*G11*H11*I11*J11*K11),1/7)*0.875+((L11+M11)/2)*0.125,1),"N/A") -> 0 | AL11: =IFERROR(IF(AK11="N/A","N/A",ROUND(0.7*AK11+0.3*AI11,1)),"N/A") -> 0
A12: 20136201132 | B12: COOPERATIVA AGRARIA CAFETALERA ALTO URUBAMBA LTDA N° 239 | C12: CUSCO | D12: 0 | E12: 0 | F12: =IFERROR(SCORECARDS!H11,"") -> 0 | G12: =IFERROR(MATRIZ_174!U11,0) -> 0 | H12: 0 | I12: =IFERROR(SCORECARDS!I11,"") -> 0 | J12: =IFERROR(SCORECARDS!J11,"") -> 0 | K12: 0 | L12: 0 | M12: 0 | N12: 0 | O12: 0 | P12: =IFERROR(F12,0) -> 0 | Q12: =IFERROR(SQRT(G12*H12),0) -> 0 | R12: =IFERROR((I12+J12+L12)/3,0) -> 0 | S12: =IFERROR((J12+F12)/2,0) -> 0 | T12: =IFERROR((K12+M12+MATRIZ_174!O11)/3,0) -> 0 | U12: =IFERROR(MATRIZ_174!AP11*50,0) -> 0 | V12: =IFERROR(IF(E12=0,50,E12),0) -> 50 | W12: =IF(MATRIZ_174!R11>0,65,35) -> 35 | X12: =IF(MATRIZ_174!O11=0,70,30) -> 70 | Y12: =IF(OR(MATRIZ_174!P11="ASOCIACION",MATRIZ_174!P11="PENDIENTE"),65,40) -> 65 | Z12: =IFERROR(ROUND(AVERAGE(P12,Q12,R12,S12,T12),1),0) -> 0 | AA12: =IFERROR(ROUND(AVERAGE(U12,V12,W12,X12,Y12),1),0) -> 44 | AB12: =IFERROR(ROUND(AA12*(1-Z12/100),1),0) -> 44 | AC12: =IF(AND(Z12>=50,AA12<50),"🟢 Resilientes",IF(AND(Z12>=50,AA12>=50),"🟠 Expuestas Adaptables",IF(AND(Z12<50,AA12<50),"⬜ Riesgo Latente","🔴 Riesgo Crítico"))) -> ⬜ Riesgo Latente | AD12: =IF(G12=0,"🚫 Inh. vigente OSCE","") -> 🚫 Inh. vigente OSCE | AE12: =IFERROR(MATRIZ_174!W11,0) -> 0 | AF12: =IFERROR(MATRIZ_174!X11,0) -> 0 | AG12: =IFERROR(MATRIZ_174!Y11,0) -> 0 | AH12: =IFERROR(MATRIZ_174!Z11,0) -> 0 | AI12: =IFERROR(MATRIZ_174!AP11,"N/A") -> 0 | AJ12: =IFERROR(MATRIZ_174!AO11,"N/A") -> 0 | AK12: =IFERROR(ROUND(POWER((E12*F12*G12*H12*I12*J12*K12),1/7)*0.875+((L12+M12)/2)*0.125,1),"N/A") -> 0 | AL12: =IFERROR(IF(AK12="N/A","N/A",ROUND(0.7*AK12+0.3*AI12,1)),"N/A") -> 0
A13: 20136201213 | B13: CENTRAL DE COOPERATIVAS AGRARIAS CAFETALERAS COCLA LTDA. N° | C13: CUSCO | D13: 894391.27 | E13: 0 | F13: =IFERROR(SCORECARDS!H12,"") -> 0 | G13: =IFERROR(MATRIZ_174!U12,0) -> 0.75 | H13: 0 | I13: =IFERROR(SCORECARDS!I12,"") -> 0 | J13: =IFERROR(SCORECARDS!J12,"") -> 0 | K13: 0 | L13: 0 | M13: 0 | N13: 0 | O13: 0 | P13: =IFERROR(F13,0) -> 0 | Q13: =IFERROR(SQRT(G13*H13),0) -> 0 | R13: =IFERROR((I13+J13+L13)/3,0) -> 0 | S13: =IFERROR((J13+F13)/2,0) -> 0 | T13: =IFERROR((K13+M13+MATRIZ_174!O12)/3,0) -> 0 | U13: =IFERROR(MATRIZ_174!AP12*50,0) -> 6.25 | V13: =IFERROR(IF(E13=0,50,E13),0) -> 50 | W13: =IF(MATRIZ_174!R12>0,65,35) -> 65 | X13: =IF(MATRIZ_174!O12=0,70,30) -> 70 | Y13: =IF(OR(MATRIZ_174!P12="ASOCIACION",MATRIZ_174!P12="PENDIENTE"),65,40) -> 65 | Z13: =IFERROR(ROUND(AVERAGE(P13,Q13,R13,S13,T13),1),0) -> 0 | AA13: =IFERROR(ROUND(AVERAGE(U13,V13,W13,X13,Y13),1),0) -> 51.3 | AB13: =IFERROR(ROUND(AA13*(1-Z13/100),1),0) -> 51.3 | AC13: =IF(AND(Z13>=50,AA13<50),"🟢 Resilientes",IF(AND(Z13>=50,AA13>=50),"🟠 Expuestas Adaptables",IF(AND(Z13<50,AA13<50),"⬜ Riesgo Latente","🔴 Riesgo Crítico"))) -> 🔴 Riesgo Crítico | AD13: =IF(G13=0,"🚫 Inh. vigente OSCE","") | AE13: =IFERROR(MATRIZ_174!W12,0) -> 1 | AF13: =IFERROR(MATRIZ_174!X12,0) -> 0 | AG13: =IFERROR(MATRIZ_174!Y12,0) -> 0 | AH13: =IFERROR(MATRIZ_174!Z12,0) -> 0 | AI13: =IFERROR(MATRIZ_174!AP12,"N/A") -> 0.125 | AJ13: =IFERROR(MATRIZ_174!AO12,"N/A") -> 0 | AK13: =IFERROR(ROUND(POWER((E13*F13*G13*H13*I13*J13*K13),1/7)*0.875+((L13+M13)/2)*0.125,1),"N/A") -> 0 | AL13: =IFERROR(IF(AK13="N/A","N/A",ROUND(0.7*AK13+0.3*AI13,1)),"N/A") -> 0
A14: 20140292657 | B14: COOPERATIVA AGRARIA CAFETALERA CCOCHAPAMPA LTDA. | C14: CUSCO | D14: 0 | E14: 0 | F14: =IFERROR(SCORECARDS!H13,"") -> 0 | G14: =IFERROR(MATRIZ_174!U13,0) -> 0 | H14: 0 | I14: =IFERROR(SCORECARDS!I13,"") -> 0 | J14: =IFERROR(SCORECARDS!J13,"") -> 0 | K14: 0 | L14: 0 | M14: 0 | N14: 0 | O14: 0 | P14: =IFERROR(F14,0) -> 0 | Q14: =IFERROR(SQRT(G14*H14),0) -> 0 | R14: =IFERROR((I14+J14+L14)/3,0) -> 0 | S14: =IFERROR((J14+F14)/2,0) -> 0 | T14: =IFERROR((K14+M14+MATRIZ_174!O13)/3,0) -> 0 | U14: =IFERROR(MATRIZ_174!AP13*50,0) -> 6.25 | V14: =IFERROR(IF(E14=0,50,E14),0) -> 50 | W14: =IF(MATRIZ_174!R13>0,65,35) -> 65 | X14: =IF(MATRIZ_174!O13=0,70,30) -> 70 | Y14: =IF(OR(MATRIZ_174!P13="ASOCIACION",MATRIZ_174!P13="PENDIENTE"),65,40) -> 65 | Z14: =IFERROR(ROUND(AVERAGE(P14,Q14,R14,S14,T14),1),0) -> 0 | AA14: =IFERROR(ROUND(AVERAGE(U14,V14,W14,X14,Y14),1),0) -> 51.3 | AB14: =IFERROR(ROUND(AA14*(1-Z14/100),1),0) -> 51.3 | AC14: =IF(AND(Z14>=50,AA14<50),"🟢 Resilientes",IF(AND(Z14>=50,AA14>=50),"🟠 Expuestas Adaptables",IF(AND(Z14<50,AA14<50),"⬜ Riesgo Latente","🔴 Riesgo Crítico"))) -> 🔴 Riesgo Crítico | AD14: =IF(G14=0,"🚫 Inh. vigente OSCE","") -> 🚫 Inh. vigente OSCE | AE14: =IFERROR(MATRIZ_174!W13,0) -> 1 | AF14: =IFERROR(MATRIZ_174!X13,0) -> 0 | AG14: =IFERROR(MATRIZ_174!Y13,0) -> 0 | AH14: =IFERROR(MATRIZ_174!Z13,0) -> 0 | AI14: =IFERROR(MATRIZ_174!AP13,"N/A") -> 0.125 | AJ14: =IFERROR(MATRIZ_174!AO13,"N/A") -> 0 | AK14: =IFERROR(ROUND(POWER((E14*F14*G14*H14*I14*J14*K14),1/7)*0.875+((L14+M14)/2)*0.125,1),"N/A") -> 0 | AL14: =IFERROR(IF(AK14="N/A","N/A",ROUND(0.7*AK14+0.3*AI14,1)),"N/A") -> 0
A15: 20143692010 | B15: COOPERATIVA AGRARIA EL QUINACHO LTDA. N° 078 | C15: AYACUCHO | D15: 2015347.3 | E15: 0 | F15: =IFERROR(SCORECARDS!H14,"") -> 0 | G15: =IFERROR(MATRIZ_174!U14,0) -> 1 | H15: 0 | I15: =IFERROR(SCORECARDS!I14,"") -> 0 | J15: =IFERROR(SCORECARDS!J14,"") -> 0 | K15: 0 | L15: 0 | M15: 0 | N15: 0 | O15: 0 | P15: =IFERROR(F15,0) -> 0 | Q15: =IFERROR(SQRT(G15*H15),0) -> 0 | R15: =IFERROR((I15+J15+L15)/3,0) -> 0 | S15: =IFERROR((J15+F15)/2,0) -> 0 | T15: =IFERROR((K15+M15+MATRIZ_174!O14)/3,0) -> 0 | U15: =IFERROR(MATRIZ_174!AP14*50,0) -> 6.25 | V15: =IFERROR(IF(E15=0,50,E15),0) -> 50 | W15: =IF(MATRIZ_174!R14>0,65,35) -> 35 | X15: =IF(MATRIZ_174!O14=0,70,30) -> 70 | Y15: =IF(OR(MATRIZ_174!P14="ASOCIACION",MATRIZ_174!P14="PENDIENTE"),65,40) -> 65 | Z15: =IFERROR(ROUND(AVERAGE(P15,Q15,R15,S15,T15),1),0) -> 0 | AA15: =IFERROR(ROUND(AVERAGE(U15,V15,W15,X15,Y15),1),0) -> 45.3 | AB15: =IFERROR(ROUND(AA15*(1-Z15/100),1),0) -> 45.3 | AC15: =IF(AND(Z15>=50,AA15<50),"🟢 Resilientes",IF(AND(Z15>=50,AA15>=50),"🟠 Expuestas Adaptables",IF(AND(Z15<50,AA15<50),"⬜ Riesgo Latente","🔴 Riesgo Crítico"))) -> ⬜ Riesgo Latente | AD15: =IF(G15=0,"🚫 Inh. vigente OSCE","") | AE15: =IFERROR(MATRIZ_174!W14,0) -> 1 | AF15: =IFERROR(MATRIZ_174!X14,0) -> 0 | AG15: =IFERROR(MATRIZ_174!Y14,0) -> 0 | AH15: =IFERROR(MATRIZ_174!Z14,0) -> 0 | AI15: =IFERROR(MATRIZ_174!AP14,"N/A") -> 0.125 | AJ15: =IFERROR(MATRIZ_174!AO14,"N/A") -> 0 | AK15: =IFERROR(ROUND(POWER((E15*F15*G15*H15*I15*J15*K15),1/7)*0.875+((L15+M15)/2)*0.125,1),"N/A") -> 0 | AL15: =IFERROR(IF(AK15="N/A","N/A",ROUND(0.7*AK15+0.3*AI15,1)),"N/A") -> 0
... A177: 20612331821 | B177: ASOCIACIÓN DE MUJERES LAS FLORES DE LUYA | C177: AMAZONAS | D177: 0 | E177: 0 | F177: =IFERROR(SCORECARDS!H176,"") -> 0 | G177: =IFERROR(MATRIZ_174!U176,0) -> 0 | H177: 0 | I177: =IFERROR(SCORECARDS!I176,"") -> 0 | J177: =IFERROR(SCORECARDS!J176,"") -> 0 | K177: 0 | L177: 0 | M177: 0 | N177: 0 | O177: 0 | P177: =IFERROR(F177,0) -> 0 | Q177: =IFERROR(SQRT(G177*H177),0) -> 0 | R177: =IFERROR((I177+J177+L177)/3,0) -> 0 | S177: =IFERROR((J177+F177)/2,0) -> 0 | T177: =IFERROR((K177+M177+MATRIZ_174!O176)/3,0) -> 0 | U177: =IFERROR(MATRIZ_174!AP176*50,0) -> 0 | V177: =IFERROR(IF(E177=0,50,E177),0) -> 50 | W177: =IF(MATRIZ_174!R176>0,65,35) -> 35 | X177: =IF(MATRIZ_174!O176=0,70,30) -> 70 | Y177: =IF(OR(MATRIZ_174!P176="ASOCIACION",MATRIZ_174!P176="PENDIENTE"),65,40) -> 65 | Z177: =IFERROR(ROUND(AVERAGE(P177,Q177,R177,S177,T177),1),0) -> 0 | AA177: =IFERROR(ROUND(AVERAGE(U177,V177,W177,X177,Y177),1),0) -> 44 | AB177: =IFERROR(ROUND(AA177*(1-Z177/100),1),0) -> 44 | AC177: =IF(AND(Z177>=50,AA177<50),"🟢 Resilientes",IF(AND(Z177>=50,AA177>=50),"🟠 Expuestas Adaptables",IF(AND(Z177<50,AA177<50),"⬜ Riesgo Latente","🔴 Riesgo Crítico"))) -> ⬜ Riesgo Latente | AD177: =IF(G177=0,"🚫 Inh. vigente OSCE","") -> 🚫 Inh. vigente OSCE | AE177: =IFERROR(MATRIZ_174!W176,0) -> 0 | AF177: =IFERROR(MATRIZ_174!X176,0) -> 0 | AG177: =IFERROR(MATRIZ_174!Y176,0) -> 0 | AH177: =IFERROR(MATRIZ_174!Z176,0) -> 0 | AI177: =IFERROR(MATRIZ_174!AP176,"N/A") -> 0 | AJ177: =IFERROR(MATRIZ_174!AO176,"N/A") -> 0 | AK177: =IFERROR(ROUND(POWER((E177*F177*G177*H177*I177*J177*K177),1/7)*0.875+((L177+M177)/2)*0.125,1),"N/A") -> 0 | AL177: =IFERROR(IF(AK177="N/A","N/A",ROUND(0.7*AK177+0.3*AI177,1)),"N/A") -> 0
A178: PROMEDIO MUESTRAL | Z178: =IFERROR(AVERAGE(Z4:Z176),"—") -> 0.0011560694 | AA178: =IFERROR(AVERAGE(AA4:AA176),"—") -> 45.008671 | AB178: =IFERROR(AVERAGE(AB4:AB176),"—") -> 45.008671 | AC178: n = 174 organizaciones | AL178: =IFERROR(AVERAGE(AL4:AL176),"—") -> 0
A180: METODOLOGÍA ISCAM | ISA-EUDR = 0.875×(D1×D2×...×D7)^(1/7) + 0.125×(D8+D9)/2 | ISA-PV = Promedio(D12:D15) | ISA-Completo = 0.70×ISA-EUDR + 0.30×ISA-PV | IP = Promedio(IP1..IP5): IP1=D2, IP2=√(D3×D4), IP3=(D5+D6+D8)/3, IP4=(D6+D2)/2, IP5=(D7+D9+Cert)/3 | IV = Promedio(IV1..IV5): IV1=ISA-PV×50, IV2=D1(base=50), IV3=ha>0?→65:35, IV4=cert=0?→70:30, IV5=tipo Asoc?→65:40 | RE = IV×(1−IP/100) | Corte 2×2: 50 | █ GRIS=pendiente Inst.2 █ AZUL=Datos llenos █ NARANJA=IV █ ROJO=RE █ VERDE=Ambiental █ OSCURO=ISA

Sheet PONDERADORES
A1: BLOQUE DE SUPUESTOS — PONDERACIONES DEL ÍNDICE PVE
A2: LEYENDA DE COLORES
A3: 🔵 Azul | B3: Input hardcoded — valor primario, editable
A4: ⚫ Negro | B4: Fórmula calculada — no editar manualmente
A5: 🟡 Amarillo | B5: Input editable — cambiar ponderación aquí
A6: 🟢 Verde | B6: Resultado positivo (cumple)
A7: 🔴 Rojo | B7: Resultado negativo (no cumple)
A8: ⬜ Gris | B8: Dato pendiente de capturar
A10: PONDERACIONES — MODIFICAR SOLO LAS CELDAS AMARILLAS
A11: Componente | B11: Dimensión EUDR | C11: Variable | D11: Ponderación (%)
A12: EXP_UE | B12: D7 / Exposición UE | C12: % FOB exportado a UE sobre FOB total | D12: 25
A13: TRAZA | B13: D2 / Trazabilidad | C13: ¿Existe vínculo lote → parcela con coords? | D13: 20
A14: DILIG | B14: D5 / Debida diligencia | C14: ¿Existe proceso de evaluación de riesgo? | D14: 15
A15: CAPAC | B15: D6 / Capacidad digital | C15: ¿Tiene personal dedicado a datos? | D15: 10
A16: PRESION | B16: D7 / Presión comprador | C16: ¿Comprador UE exige EUDR? | D16: 15
A17: CERTIF | B17: D8 / Certificaciones | C17: Score de certificaciones vigentes (Org + Ftrade) | D17: 10
A18: PPWR | B18: D14 / Envases | C18: ¿Usa sacos reutilizables o certificados? | D18: 5
A19: TOTAL | D19: =SUM(D12:D18) -> 100
A21: ⚠ El TOTAL debe sumar 100. Si lo ajustas, el Índice PVE en SCORECARDS se recalcula automáticamente.
A23: VERSION ISCAM (2026-10-12) — Pesos mostrados para transparencia (fijos, no editables)
A24: ISA-EUDR e ISA-PV usan pesos FIJOS (87.5%/12.5% y 70%/30%). IP/IV pesan 20% cada sub-dim.
A25: SUBDIM | B25: FÓRMULA | C25: PESO
A26: ISA-EUDR | C26: 100%
A28: ISA-PactoVerde | B28: =PROMEDIO(D12:D15) -> #NAME? | C28: 100%
A30: ISA-Completo | B30: =0.7*ISA-EUDR + 0.3*ISA-PV -> #NAME? | C30: 100%
A32: IP1 | B32: =D2 -> 0 | C32: 20%
A33: IP2 | B33: =√(D3 * D4) -> #NAME? | C33: 20%
A34: IP3 | B34: =(D5 + D6 + D8) / 3 -> 0 | C34: 20%
A35: IP4 | B35: =(D6 + D2) / 2 -> 0 | C35: 20%
A36: IP5 | B36: =(D7 + D9 + Cert) / 3 -> #NAME? | C36: 20%
A37: IP (total) | B37: =PROMEDIO(IP1:IP5) -> #NAME? | C37: 100%
A39: IV1 | C39: 20%
A40: IV2 | C40: 20%
A41: IV3 | C41: 20%
A42: IV4 | C42: 20%
A43: IV5 | C43: 20%
A44: IV (total) | B44: =PROMEDIO(IV1:IV5) -> #NAME? | C44: 100%
A46: RE | C46: —
A47: Cuadrante 2×2 | B47: IP≥50 vs <50 × IV≥50 vs <50 | C47: Corte=50

Sheet MATRIZ_174
A1: MATRIZ 174 — Datos existentes de organizaciones | W1: D12 | X1: D13 | Y1: D14 | Z1: D15 | AA1: P1 | AB1: P2 | AC1: P3 | AD1: P4 | AE1: P5 | AF1: P6 | AG1: P7 | AH1: P8 | AI1: P9 | AJ1: P10 | AK1: P11 | AL1: P12 | AM1: P13 | AN1: P14 | AO1: Bloque P Score (0-1) | AP1: ISA-PactoVerde (0-1)
A2: RUC | B2: Razón Social (SUNAT) | C2: Depto | D2: Producto | E2: FOB Total USD | F2: N° DUAs | G2: Exporta | H2: Cert. Orgánica | I2: Cert. Fairtrade | J2: Estado SUNAT | K2: Avance EUDR | L2: FOB UE USD | M2: % UE/FOB | N2: HS Code principal | O2: Score Cert (0-1) | P2: Tipo org. | Q2: N° aprox. socios | R2: Hectáreas aprox. | S2: PVE Score (0-100) | T2: Clasificación | U2: D3 Score (OSCE) | V2: D3 Observación | W2: D12 — Huella Carbono 0=Sin medición 1=En curso (ha conocidas) 2=Certificado ───────────────────── NOTA: Valor actual = proxy FAO/IPCC (ha × factor IPCC/FAO por cultivo). Reemplazar tras Instrumento 2 Q40-Q44. | X2: Reporte Sostenibilidad (D13) 0=No, 1=En curso, 2=Publicado | Y2: Economía Circular (D14) 0=No, 1=En transición, 2=Avanzado | Z2: Fitosanitario/LMR (D15) 0=No verificado, 1=En monitoreo, 2=Cumple UE | AA2: P1 — Productividad (USD/ha/año) | AB2: P2 — Ingreso neto (USD/ha) | AC2: P3 — % socios con acceso crédito | AD2: P4 — Gender score (% muj. en org.) | AE2: P5 — Formalización laboral (%) | AF2: P6 — Capacitación/año/persona | AG2: P7 — Tasa retención socios (%) | AH2: P8 — Diversificación ingresos (%) | AI2: P9 — Acceso mercados premium (%) | AJ2: P10 — Inversión EUDR (USD/año) | AK2: P11 — Score trazabilidad (%) | AL2: P12 — Quejas resueltas (%) | AM2: P13 — Energía renovable (%) | AN2: P14 — Residuos gestionados (%) | AO2: P_Global — Promedio P1:P14 (0=None, 1=满分) | AP2: ISA-PactoVerde = AVG(D12:D15)/2 0=Nada, 2=Certificado
A3: 20118578415 | B3: CENT.DE COOP.AGR. CAF.VALLES SANDIA LTDA | C3: PUNO | D3: CAFÉ | E3: 5107246.6 | F3: 38 | G3: SI | H3: nan | I3: nan | J3: ACTIVO | K3: nan | L3: 2553623.3 | M3: =IF(E3>0,ROUND(L3/E3*100,1),0) -> 50 | N3: PENDIENTE | O3: =IF(H3="SI",1,0)*0.6+IF(I3="SI",1,0)*0.4 -> 0 | P3: PENDIENTE | S3: =IFERROR(SCORECARDS!C1,"—") -> 0 | T3: =IF(ISTEXT(S3),S3,IF(S3<34,"🔴 Crítico",IF(S3<67,"🟡 Vulnerable","🟢 Preparado"))) -> 🔴 Crítico | U3: 1 | V3: Sin hallazgos OSCE / OEFA | W3: 1 | X3: 0 | Y3: 0 | Z3: 0 | AA3: 0 | AB3: 0 | AC3: 0 | AD3: 0 | AE3: 0 | AF3: 0 | AG3: 0 | AH3: 0 | AI3: 0 | AJ3: 0 | AK3: 0 | AL3: 0 | AM3: 0 | AN3: 0 | AO3: =IFERROR(AVERAGE(AA3,AB3,AC3,AD3,AE3,AF3,AG3,AH3,AI3,AJ3,AK3,AL3,AM3,AN3),"N/A") -> 0 | AP3: =IFERROR(AVERAGE(W3,X3,Y3,Z3)/2,"N/A") -> 0.125
A4: 20129156083 | B4: COOP AGRARIA CAFET VALLE RIO APURIMAC | C4: AYACUCHO | D4: CACAO | E4: 0 | G4: NO | H4: nan | I4: nan | J4: ACTIVO | K4: nan | L4: 0 | M4: =IF(E4>0,ROUND(L4/E4*100,1),0) -> 0 | N4: PENDIENTE | O4: =IF(H4="SI",1,0)*0.6+IF(I4="SI",1,0)*0.4 -> 0 | P4: PENDIENTE | S4: =IFERROR(SCORECARDS!C2,"—") -> ISA-Completo (0-100) | T4: =IF(ISTEXT(S4),S4,IF(S4<34,"🔴 Crítico",IF(S4<67,"🟡 Vulnerable","🟢 Preparado"))) -> ISA-Completo (0-100) | W4: 0 | X4: 0 | Y4: 0 | Z4: 0 | AA4: 0 | AB4: 0 | AC4: 0 | AD4: 0 | AE4: 0 | AF4: 0 | AG4: 0 | AH4: 0 | AI4: 0 | AJ4: 0 | AK4: 0 | AL4: 0 | AM4: 0 | AN4: 0 | AO4: =IFERROR(AVERAGE(AA4,AB4,AC4,AD4,AE4,AF4,AG4,AH4,AI4,AJ4,AK4,AL4,AM4,AN4),"N/A") -> 0 | AP4: =IFERROR(AVERAGE(W4,X4,Y4,Z4)/2,"N/A") -> 0
A5: 20129529530 | B5: COOP AGRARIA CAFETALERA SATIPO LTDA | C5: JUNIN | D5: nan | E5: 9603968.1 | F5: 41 | G5: SI | H5: nan | I5: nan | J5: ACTIVO | K5: nan | L5: 4801984.1 | M5: =IF(E5>0,ROUND(L5/E5*100,1),0) -> 50 | N5: PENDIENTE | O5: =IF(H5="SI",1,0)*0.6+IF(I5="SI",1,0)*0.4 -> 0 | P5: PENDIENTE | S5: =IFERROR(SCORECARDS!C3,"—") -> 0 | T5: =IF(ISTEXT(S5),S5,IF(S5<34,"🔴 Crítico",IF(S5<67,"🟡 Vulnerable","🟢 Preparado"))) -> 🔴 Crítico | U5: 1 | V5: Sin hallazgos OSCE / OEFA | W5: 1 | X5: 0 | Y5: 0 | Z5: 0 | AA5: 0 | AB5: 0 | AC5: 0 | AD5: 0 | AE5: 0 | AF5: 0 | AG5: 0 | AH5: 0 | AI5: 0 | AJ5: 0 | AK5: 0 | AL5: 0 | AM5: 0 | AN5: 0 | AO5: =IFERROR(AVERAGE(AA5,AB5,AC5,AD5,AE5,AF5,AG5,AH5,AI5,AJ5,AK5,AL5,AM5,AN5),"N/A") -> 0 | AP5: =IFERROR(AVERAGE(W5,X5,Y5,Z5)/2,"N/A") -> 0.125
A6: 20132489824 | B6: COOPERATIVA AGRARIA CAFETALERA CHANCAMAYO LTDA. N° 008-B-VII | C6: CUSCO | D6: nan | G6: NO | H6: Cer | I6: Vig | J6: ACTIVO | K6: nan | L6: 0 | M6: =IF(E6>0,ROUND(L6/E6*100,1),0) -> 0 | N6: PENDIENTE | O6: =IF(H6="SI",1,0)*0.6+IF(I6="SI",1,0)*0.4 -> 0 | P6: PENDIENTE | Q6: 44 | R6: 44 | S6: =IFERROR(SCORECARDS!C4,"—") -> 0 | T6: =IF(ISTEXT(S6),S6,IF(S6<34,"🔴 Crítico",IF(S6<67,"🟡 Vulnerable","🟢 Preparado"))) -> 🔴 Crítico | W6: 1 | X6: 0 | Y6: 0 | Z6: 0 | AA6: 0 | AB6: 0 | AC6: 0 | AD6: 0 | AE6: 0 | AF6: 0 | AG6: 0 | AH6: 0 | AI6: 0 | AJ6: 0 | AK6: 0 | AL6: 0 | AM6: 0 | AN6: 0 | AO6: =IFERROR(AVERAGE(AA6,AB6,AC6,AD6,AE6,AF6,AG6,AH6,AI6,AJ6,AK6,AL6,AM6,AN6),"N/A") -> 0 | AP6: =IFERROR(AVERAGE(W6,X6,Y6,Z6)/2,"N/A") -> 0.125
A7: 20132505455 | B7: COOPERATIVA AGRARIA CAFETALERA AGUILAYOC LTDA. 084 | C7: CUSCO | D7: CAFÉ | G7: NO | H7: Cer | I7: nan | J7: ACTIVO | K7: 0.75 | L7: 0 | M7: =IF(E7>0,ROUND(L7/E7*100,1),0) -> 0 | N7: PENDIENTE | O7: =IF(H7="SI",1,0)*0.6+IF(I7="SI",1,0)*0.4 -> 0 | P7: PENDIENTE | Q7: 100 | R7: 218 | S7: =IFERROR(SCORECARDS!C5,"—") -> 0 | T7: =IF(ISTEXT(S7),S7,IF(S7<34,"🔴 Crítico",IF(S7<67,"🟡 Vulnerable","🟢 Preparado"))) -> 🔴 Crítico | W7: 1 | X7: 0 | Y7: 0 | Z7: 0 | AA7: 0 | AB7: 0 | AC7: 0 | AD7: 0 | AE7: 0 | AF7: 0 | AG7: 0 | AH7: 0 | AI7: 0 | AJ7: 0 | AK7: 0 | AL7: 0 | AM7: 0 | AN7: 0 | AO7: =IFERROR(AVERAGE(AA7,AB7,AC7,AD7,AE7,AF7,AG7,AH7,AI7,AJ7,AK7,AL7,AM7,AN7),"N/A") -> 0 | AP7: =IFERROR(AVERAGE(W7,X7,Y7,Z7)/2,"N/A") -> 0.125
A8: 20132509795 | B8: COOPERATIVA AGRARIA CAFETALERA JOSE OLAYA LTDA N° 252 | C8: CUSCO | D8: CAFÉ | E8: 2477083.5 | F8: 14 | G8: SI | H8: nan | I8: nan | J8: ACTIVO | K8: nan | L8: 1238541.8 | M8: =IF(E8>0,ROUND(L8/E8*100,1),0) -> 50 | N8: PENDIENTE | O8: =IF(H8="SI",1,0)*0.6+IF(I8="SI",1,0)*0.4 -> 0 | P8: PENDIENTE | S8: =IFERROR(SCORECARDS!C6,"—") -> 0 | T8: =IF(ISTEXT(S8),S8,IF(S8<34,"🔴 Crítico",IF(S8<67,"🟡 Vulnerable","🟢 Preparado"))) -> 🔴 Crítico | U8: 1 | V8: Sin hallazgos OSCE / OEFA | W8: 1 | X8: 0 | Y8: 0 | Z8: 0 | AA8: 0 | AB8: 0 | AC8: 0 | AD8: 0 | AE8: 0 | AF8: 0 | AG8: 0 | AH8: 0 | AI8: 0 | AJ8: 0 | AK8: 0 | AL8: 0 | AM8: 0 | AN8: 0 | AO8: =IFERROR(AVERAGE(AA8,AB8,AC8,AD8,AE8,AF8,AG8,AH8,AI8,AJ8,AK8,AL8,AM8,AN8),"N/A") -> 0 | AP8: =IFERROR(AVERAGE(W8,X8,Y8,Z8)/2,"N/A") -> 0.125
A9: 20132509876 | B9: COOPERATIVA AGRARIA CAFETALERA MARANURA LTDA. 129 | C9: CUSCO | D9: CAFÉ | E9: 1689820.3 | F9: 5 | G9: SI | H9: nan | I9: nan | J9: ACTIVO | K9: nan | L9: 0 | M9: =IF(E9>0,ROUND(L9/E9*100,1),0) -> 0 | N9: PENDIENTE | O9: =IF(H9="SI",1,0)*0.6+IF(I9="SI",1,0)*0.4 -> 0 | P9: PENDIENTE | S9: =IFERROR(SCORECARDS!C7,"—") -> 0 | T9: =IF(ISTEXT(S9),S9,IF(S9<34,"🔴 Crítico",IF(S9<67,"🟡 Vulnerable","🟢 Preparado"))) -> 🔴 Crítico | W9: 0 | X9: 0 | Y9: 0 | Z9: 0 | AA9: 0 | AB9: 0 | AC9: 0 | AD9: 0 | AE9: 0 | AF9: 0 | AG9: 0 | AH9: 0 | AI9: 0 | AJ9: 0 | AK9: 0 | AL9: 0 | AM9: 0 | AN9: 0 | AO9: =IFERROR(AVERAGE(AA9,AB9,AC9,AD9,AE9,AF9,AG9,AH9,AI9,AJ9,AK9,AL9,AM9,AN9),"N/A") -> 0 | AP9: =IFERROR(AVERAGE(W9,X9,Y9,Z9)/2,"N/A") -> 0
A10: 20132517119 | B10: COOPERATIVA AGRARIA CAFETALERA MATEO PUMACAHUA LTDA N° 185 | C10: CUSCO | D10: CAFÉ | E10: 0 | G10: NO | H10: Cer | I10: Fai | J10: ACTIVO | K10: 0.75 | L10: 0 | M10: =IF(E10>0,ROUND(L10/E10*100,1),0) -> 0 | N10: PENDIENTE | O10: =IF(H10="SI",1,0)*0.6+IF(I10="SI",1,0)*0.4 -> 0 | P10: PENDIENTE | Q10: 177 | R10: 469 | S10: =IFERROR(SCORECARDS!C8,"—") -> 0 | T10: =IF(ISTEXT(S10),S10,IF(S10<34,"🔴 Crítico",IF(S10<67,"🟡 Vulnerable","🟢 Preparado"))) -> 🔴 Crítico | W10: 1 | X10: 0 | Y10: 0 | Z10: 0 | AA10: 0 | AB10: 0 | AC10: 0 | AD10: 0 | AE10: 0 | AF10: 0 | AG10: 0 | AH10: 0 | AI10: 0 | AJ10: 0 | AK10: 0 | AL10: 0 | AM10: 0 | AN10: 0 | AO10: =IFERROR(AVERAGE(AA10,AB10,AC10,AD10,AE10,AF10,AG10,AH10,AI10,AJ10,AK10,AL10,AM10,AN10),"N/A") -> 0 | AP10: =IFERROR(AVERAGE(W10,X10,Y10,Z10)/2,"N/A") -> 0.125
A11: 20136201132 | B11: COOPERATIVA AGRARIA CAFETALERA ALTO URUBAMBA LTDA N° 239 | C11: CUSCO | D11: CAFÉ | E11: 681394.36 | F11: 6 | G11: SI | H11: nan | I11: nan | J11: ACTIVO | K11: nan | L11: 0 | M11: =IF(E11>0,ROUND(L11/E11*100,1),0) -> 0 | N11: PENDIENTE | O11: =IF(H11="SI",1,0)*0.6+IF(I11="SI",1,0)*0.4 -> 0 | P11: PENDIENTE | S11: =IFERROR(SCORECARDS!C9,"—") -> 0 | T11: =IF(ISTEXT(S11),S11,IF(S11<34,"🔴 Crítico",IF(S11<67,"🟡 Vulnerable","🟢 Preparado"))) -> 🔴 Crítico | W11: 0 | X11: 0 | Y11: 0 | Z11: 0 | AA11: 0 | AB11: 0 | AC11: 0 | AD11: 0 | AE11: 0 | AF11: 0 | AG11: 0 | AH11: 0 | AI11: 0 | AJ11: 0 | AK11: 0 | AL11: 0 | AM11: 0 | AN11: 0 | AO11: =IFERROR(AVERAGE(AA11,AB11,AC11,AD11,AE11,AF11,AG11,AH11,AI11,AJ11,AK11,AL11,AM11,AN11),"N/A") -> 0 | AP11: =IFERROR(AVERAGE(W11,X11,Y11,Z11)/2,"N/A") -> 0
A12: 20136201213 | B12: CENTRAL DE COOPERATIVAS AGRARIAS CAFETALERAS COCLA LTDA. N° | C12: CUSCO | D12: CAFÉ | E12: 4445611.6 | F12: 33 | G12: SI | H12: Cer | I12: Fai | J12: ACTIVO | K12: 0.75 | L12: 894391.27 | M12: =IF(E12>0,ROUND(L12/E12*100,1),0) -> 20.1 | N12: PENDIENTE | O12: =IF(H12="SI",1,0)*0.6+IF(I12="SI",1,0)*0.4 -> 0 | P12: PENDIENTE | Q12: 660 | R12: 1670 | S12: =IFERROR(SCORECARDS!C10,"—") -> 0 | T12: =IF(ISTEXT(S12),S12,IF(S12<34,"🔴 Crítico",IF(S12<67,"🟡 Vulnerable","🟢 Preparado"))) -> 🔴 Crítico | U12: 0.75 | V12: ⚠ 1 infracc. ambiental (OEFA) | W12: 1 | X12: 0 | Y12: 0 | Z12: 0 | AA12: 0 | AB12: 0 | AC12: 0 | AD12: 0 | AE12: 0 | AF12: 0 | AG12: 0 | AH12: 0 | AI12: 0 | AJ12: 0 | AK12: 0 | AL12: 0 | AM12: 0 | AN12: 0 | AO12: =IFERROR(AVERAGE(AA12,AB12,AC12,AD12,AE12,AF12,AG12,AH12,AI12,AJ12,AK12,AL12,AM12,AN12),"N/A") -> 0 | AP12: =IFERROR(AVERAGE(W12,X12,Y12,Z12)/2,"N/A") -> 0.125
A13: 20140292657 | B13: COOPERATIVA AGRARIA CAFETALERA CCOCHAPAMPA LTDA. | C13: CUSCO | D13: CAFÉ | E13: 0 | G13: NO | H13: Cer | I13: Fa | J13: ACTIVO | K13: 0.75 | L13: 0 | M13: =IF(E13>0,ROUND(L13/E13*100,1),0) -> 0 | N13: PENDIENTE | O13: =IF(H13="SI",1,0)*0.6+IF(I13="SI",1,0)*0.4 -> 0 | P13: PENDIENTE | Q13: 49 | R13: 136.9 | S13: =IFERROR(SCORECARDS!C11,"—") -> 0 | T13: =IF(ISTEXT(S13),S13,IF(S13<34,"🔴 Crítico",IF(S13<67,"🟡 Vulnerable","🟢 Preparado"))) -> 🔴 Crítico | W13: 1 | X13: 0 | Y13: 0 | Z13: 0 | AA13: 0 | AB13: 0 | AC13: 0 | AD13: 0 | AE13: 0 | AF13: 0 | AG13: 0 | AH13: 0 | AI13: 0 | AJ13: 0 | AK13: 0 | AL13: 0 | AM13: 0 | AN13: 0 | AO13: =IFERROR(AVERAGE(AA13,AB13,AC13,AD13,AE13,AF13,AG13,AH13,AI13,AJ13,AK13,AL13,AM13,AN13),"N/A") -> 0 | AP13: =IFERROR(AVERAGE(W13,X13,Y13,Z13)/2,"N/A") -> 0.125
A14: 20143692010 | B14: COOPERATIVA AGRARIA EL QUINACHO LTDA. N° 078 | C14: AYACUCHO | D14: CACAO | E14: 4030694.7 | F14: 14 | G14: SI | H14: nan | I14: nan | J14: ACTIVO | K14: nan | L14: 2015347.3 | M14: =IF(E14>0,ROUND(L14/E14*100,1),0) -> 50 | N14: PENDIENTE | O14: =IF(H14="SI",1,0)*0.6+IF(I14="SI",1,0)*0.4 -> 0 | P14: PENDIENTE | S14: =IFERROR(SCORECARDS!C12,"—") -> 0 | T14: =IF(ISTEXT(S14),S14,IF(S14<34,"🔴 Crítico",IF(S14<67,"🟡 Vulnerable","🟢 Preparado"))) -> 🔴 Crítico | U14: 1 | V14: Sin hallazgos OSCE / OEFA | W14: 1 | X14: 0 | Y14: 0 | Z14: 0 | AA14: 0 | AB14: 0 | AC14: 0 | AD14: 0 | AE14: 0 | AF14: 0 | AG14: 0 | AH14: 0 | AI14: 0 | AJ14: 0 | AK14: 0 | AL14: 0 | AM14: 0 | AN14: 0 | AO14: =IFERROR(AVERAGE(AA14,AB14,AC14,AD14,AE14,AF14,AG14,AH14,AI14,AJ14,AK14,AL14,AM14,AN14),"N/A") -> 0 | AP14: =IFERROR(AVERAGE(W14,X14,Y14,Z14)/2,"N/A") -> 0.125
A15: 20145484597 | B15: COOPERATIVA AGRARIA CAFETALERA SAN IGNACIO LTDA. | C15: PUNO | D15: CAFÉ | G15: NO | H15: nan | I15: nan | J15: ACTIVO | K15: nan | L15: 0 | M15: =IF(E15>0,ROUND(L15/E15*100,1),0) -> 0 | N15: PENDIENTE | O15: =IF(H15="SI",1,0)*0.6+IF(I15="SI",1,0)*0.4 -> 0 | P15: PENDIENTE | S15: =IFERROR(SCORECARDS!C13,"—") -> 0 | T15: =IF(ISTEXT(S15),S15,IF(S15<34,"🔴 Crítico",IF(S15<67,"🟡 Vulnerable","🟢 Preparado"))) -> 🔴 Crítico | W15: 0 | X15: 0 | Y15: 0 | Z15: 0 | AA15: 0 | AB15: 0 | AC15: 0 | AD15: 0 | AE15: 0 | AF15: 0 | AG15: 0 | AH15: 0 | AI15: 0 | AJ15: 0 | AK15: 0 | AL15: 0 | AM15: 0 | AN15: 0 | AO15: =IFERROR(AVERAGE(AA15,AB15,AC15,AD15,AE15,AF15,AG15,AH15,AI15,AJ15,AK15,AL15,AM15,AN15),"N/A") -> 0 | AP15: =IFERROR(AVERAGE(W15,X15,Y15,Z15)/2,"N/A") -> 0
A16: 20146696041 | B16: COOP AGRARIA CAFET JOSE GABRIEL CONDORCA | C16: PIURA | D16: CAFÉ | G16: NO | H16: nan | I16: nan | J16: ACTIVO | K16: nan | L16: 0 | M16: =IF(E16>0,ROUND(L16/E16*100,1),0) -> 0 | N16: PENDIENTE | O16: =IF(H16="SI",1,0)*0.6+IF(I16="SI",1,0)*0.4 -> 0 | P16: PENDIENTE | S16: =IFERROR(SCORECARDS!C14,"—") -> 0 | T16: =IF(ISTEXT(S16),S16,IF(S16<34,"🔴 Crítico",IF(S16<67,"🟡 Vulnerable","🟢 Preparado"))) -> 🔴 Crítico | W16: 0 | X16: 0 | Y16: 0 | Z16: 0 | AA16: 0 | AB16: 0 | AC16: 0 | AD16: 0 | AE16: 0 | AF16: 0 | AG16: 0 | AH16: 0 | AI16: 0 | AJ16: 0 | AK16: 0 | AL16: 0 | AM16: 0 | AN16: 0 | AO16: =IFERROR(AVERAGE(AA16,AB16,AC16,AD16,AE16,AF16,AG16,AH16,AI16,AJ16,AK16,AL16,AM16,AN16),"N/A") -> 0 | AP16: =IFERROR(AVERAGE(W16,X16,Y16,Z16)/2,"N/A") -> 0
A17: 20147443120 | B17: COOPERATIVA AGRARIA CAFETALERA TIRIJUAY PAVAYOC LTDA 013-B-V | C17: CUSCO | D17: nan | G17: NO | H17: Cer | I17: Vig | J17: SUSPENSION TEMPORAL | K17: nan | L17: 0 | M17: =IF(E17>0,ROUND(L17/E17*100,1),0) -> 0 | N17: PENDIENTE | O17: =IF(H17="SI",1,0)*0.6+IF(I17="SI",1,0)*0.4 -> 0 | P17: PENDIENTE | Q17: 74 | R17: 150 | S17: =IFERROR(SCORECARDS!C15,"—") -> 0 | T17: =IF(ISTEXT(S17),S17,IF(S17<34,"🔴 Crítico",IF(S17<67,"🟡 Vulnerable","🟢 Preparado"))) -> 🔴 Crítico | W17: 1 | X17: 0 | Y17: 0 | Z17: 0 | AA17: 0 | AB17: 0 | AC17: 0 | AD17: 0 | AE17: 0 | AF17: 0 | AG17: 0 | AH17: 0 | AI17: 0 | AJ17: 0 | AK17: 0 | AL17: 0 | AM17: 0 | AN17: 0 | AO17: =IFERROR(AVERAGE(AA17,AB17,AC17,AD17,AE17,AF17,AG17,AH17,AI17,AJ17,AK17,AL17,AM17,AN17),"N/A") -> 0 | AP17: =IFERROR(AVERAGE(W17,X17,Y17,Z17)/2,"N/A") -> 0.125
A18: 20166786861 | B18: COMITE CENTRAL DE PRODUCTORES AGROPECUARIOS DE SAN ALEJANDRO | C18: UCAYALI | D18: CACAO | G18: NO | H18: nan | I18: nan | J18: ACTIVO | K18: nan | L18: 0 | M18: =IF(E18>0,ROUND(L18/E18*100,1),0) -> 0 | N18: PENDIENTE | O18: =IF(H18="SI",1,0)*0.6+IF(I18="SI",1,0)*0.4 -> 0 | P18: PENDIENTE | S18: =IFERROR(SCORECARDS!C16,"—") -> 0 | T18: =IF(ISTEXT(S18),S18,IF(S18<34,"🔴 Crítico",IF(S18<67,"🟡 Vulnerable","🟢 Preparado"))) -> 🔴 Crítico | W18: 0 | X18: 0 | Y18: 0 | Z18: 0 | AA18: 0 | AB18: 0 | AC18: 0 | AD18: 0 | AE18: 0 | AF18: 0 | AG18: 0 | AH18: 0 | AI18: 0 | AJ18: 0 | AK18: 0 | AL18: 0 | AM18: 0 | AN18: 0 | AO18: =IFERROR(AVERAGE(AA18,AB18,AC18,AD18,AE18,AF18,AG18,AH18,AI18,AJ18,AK18,AL18,AM18,AN18),"N/A") -> 0 | AP18: =IFERROR(AVERAGE(W18,X18,Y18,Z18)/2,"N/A") -> 0
A19: 20170142773 | B19: COOPERATIVA AGRARIA CAFETALERA BAGUA GRANDE LIMITADA | C19: AMAZONAS | D19: CAFÉ | E19: 9070756.9 | F19: 41 | G19: SI | H19: nan | I19: nan | J19: ACTIVO | K19: nan | L19: 4535378.4 | M19: =IF(E19>0,ROUND(L19/E19*100,1),0) -> 50 | N19: PENDIENTE | O19: =IF(H19="SI",1,0)*0.6+IF(I19="SI",1,0)*0.4 -> 0 | P19: PENDIENTE | S19: =IFERROR(SCORECARDS!C17,"—") -> 0 | T19: =IF(ISTEXT(S19),S19,IF(S19<34,"🔴 Crítico",IF(S19<67,"🟡 Vulnerable","🟢 Preparado"))) -> 🔴 Crítico | U19: 1 | V19: Sin hallazgos OSCE / OEFA | W19: 1 | X19: 0 | Y19: 0 | Z19: 0 | AA19: 0 | AB19: 0 | AC19: 0 | AD19: 0 | AE19: 0 | AF19: 0 | AG19: 0 | AH19: 0 | AI19: 0 | AJ19: 0 | AK19: 0 | AL19: 0 | AM19: 0 | AN19: 0 | AO19: =IFERROR(AVERAGE(AA19,AB19,AC19,AD19,AE19,AF19,AG19,AH19,AI19,AJ19,AK19,AL19,AM19,AN19),"N/A") -> 0 | AP19: =IFERROR(AVERAGE(W19,X19,Y19,Z19)/2,"N/A") -> 0.125
A20: 20200880448 | B20: COOPERATIVA AGRARIA CAFETALERA JORGE CHAVEZ LTDA | C20: CUSCO | D20: nan | G20: NO | H20: Cer | I20: Vig | J20: ACTIVO | K20: nan | L20: 0 | M20: =IF(E20>0,ROUND(L20/E20*100,1),0) -> 0 | N20: PENDIENTE | O20: =IF(H20="SI",1,0)*0.6+IF(I20="SI",1,0)*0.4 -> 0 | P20: PENDIENTE | Q20: 36 | R20: 38 | S20: =IFERROR(SCORECARDS!C18,"—") -> 0 | T20: =IF(ISTEXT(S20),S20,IF(S20<34,"🔴 Crítico",IF(S20<67,"🟡 Vulnerable","🟢 Preparado"))) -> 🔴 Crítico | W20: 1 | X20: 0 | Y20: 0 | Z20: 0 | AA20: 0 | AB20: 0 | AC20: 0 | AD20: 0 | AE20: 0 | AF20: 0 | AG20: 0 | AH20: 0 | AI20: 0 | AJ20: 0 | AK20: 0 | AL20: 0 | AM20: 0 | AN20: 0 | AO20: =IFERROR(AVERAGE(AA20,AB20,AC20,AD20,AE20,AF20,AG20,AH20,AI20,AJ20,AK20,AL20,AM20,AN20),"N/A") -> 0 | AP20: =IFERROR(AVERAGE(W20,X20,Y20,Z20)/2,"N/A") -> 0.125
A21: 20352417018 | B21: COOPERATIVA AGRARIA DE CACAOTEROS TECNIFICADOS DE PADRE ABAD | C21: UCAYALI | D21: CACAO | E21: 0 | G21: NO | H21: nan | I21: nan | J21: SUSPENSION TEMPORAL | K21: nan | L21: 0 | M21: =IF(E21>0,ROUND(L21/E21*100,1),0) -> 0 | N21: PENDIENTE | O21: =IF(H21="SI",1,0)*0.6+IF(I21="SI",1,0)*0.4 -> 0 | P21: PENDIENTE | S21: =IFERROR(SCORECARDS!C19,"—") -> 0 | T21: =IF(ISTEXT(S21),S21,IF(S21<34,"🔴 Crítico",IF(S21<67,"🟡 Vulnerable","🟢 Preparado"))) -> 🔴 Crítico | W21: 0 | X21: 0 | Y21: 0 | Z21: 0 | AA21: 0 | AB21: 0 | AC21: 0 | AD21: 0 | AE21: 0 | AF21: 0 | AG21: 0 | AH21: 0 | AI21: 0 | AJ21: 0 | AK21: 0 | AL21: 0 | AM21: 0 | AN21: 0 | AO21: =IFERROR(AVERAGE(AA21,AB21,AC21,AD21,AE21,AF21,AG21,AH21,AI21,AJ21,AK21,AL21,AM21,AN21),"N/A") -> 0 | AP21: =IFERROR(AVERAGE(W21,X21,Y21,Z21)/2,"N/A") -> 0
A22: 20352423921 | B22: COOPERATIVA AGRARIA CAFETALERA DIVISORIA LTDA | C22: HUANUCO | D22: CAFÉ | E22: 0 | G22: NO | H22: nan | I22: nan | J22: ACTIVO | K22: nan | L22: 0 | M22: =IF(E22>0,ROUND(L22/E22*100,1),0) -> 0 | N22: PENDIENTE | O22: =IF(H22="SI",1,0)*0.6+IF(I22="SI",1,0)*0.4 -> 0 | P22: PENDIENTE | S22: =IFERROR(SCORECARDS!C20,"—") -> 0 | T22: =IF(ISTEXT(S22),S22,IF(S22<34,"🔴 Crítico",IF(S22<67,"🟡 Vulnerable","🟢 Preparado"))) -> 🔴 Crítico | W22: 0 | X22: 0 | Y22: 0 | Z22: 0 | AA22: 0 | AB22: 0 | AC22: 0 | AD22: 0 | AE22: 0 | AF22: 0 | AG22: 0 | AH22: 0 | AI22: 0 | AJ22: 0 | AK22: 0 | AL22: 0 | AM22: 0 | AN22: 0 | AO22: =IFERROR(AVERAGE(AA22,AB22,AC22,AD22,AE22,AF22,AG22,AH22,AI22,AJ22,AK22,AL22,AM22,AN22),"N/A") -> 0 | AP22: =IFERROR(AVERAGE(W22,X22,Y22,Z22)/2,"N/A") -> 0
A23: 20393152207 | B23: COOPERATIVA AGRO INDUSTRIAL APCTVASH | C23: UCAYALI | D23: CACAO | G23: NO | H23: nan | I23: nan | J23: ACTIVO | K23: nan | L23: 0 | M23: =IF(E23>0,ROUND(L23/E23*100,1),0) -> 0 | N23: PENDIENTE | O23: =IF(H23="SI",1,0)*0.6+IF(I23="SI",1,0)*0.4 -> 0 | P23: PENDIENTE | S23: =IFERROR(SCORECARDS!C21,"—") -> 0 | T23: =IF(ISTEXT(S23),S23,IF(S23<34,"🔴 Crítico",IF(S23<67,"🟡 Vulnerable","🟢 Preparado"))) -> 🔴 Crítico | W23: 0 | X23: 0 | Y23: 0 | Z23: 0 | AA23: 0 | AB23: 0 | AC23: 0 | AD23: 0 | AE23: 0 | AF23: 0 | AG23: 0 | AH23: 0 | AI23: 0 | AJ23: 0 | AK23: 0 | AL23: 0 | AM23: 0 | AN23: 0 | AO23: =IFERROR(AVERAGE(AA23,AB23,AC23,AD23,AE23,AF23,AG23,AH23,AI23,AJ23,AK23,AL23,AM23,AN23),"N/A") -> 0 | AP23: =IFERROR(AVERAGE(W23,X23,Y23,Z23)/2,"N/A") -> 0
A24: 20393593670 | B24: COMITE CENTRAL CON DESARROLLO AL FUTURO DE CURIMANA | C24: UCAYALI | D24: CACAO | E24: 0 | G24: NO | H24: nan | I24: nan | J24: BAJA DE OFICIO | K24: nan | L24: 0 | M24: =IF(E24>0,ROUND(L24/E24*100,1),0) -> 0 | N24: PENDIENTE | O24: =IF(H24="SI",1,0)*0.6+IF(I24="SI",1,0)*0.4 -> 0 | P24: PENDIENTE | S24: =IFERROR(SCORECARDS!C22,"—") -> 0 | T24: =IF(ISTEXT(S24),S24,IF(S24<34,"🔴 Crítico",IF(S24<67,"🟡 Vulnerable","🟢 Preparado"))) -> 🔴 Crítico | W24: 0 | X24: 0 | Y24: 0 | Z24: 0 | AA24: 0 | AB24: 0 | AC24: 0 | AD24: 0 | AE24: 0 | AF24: 0 | AG24: 0 | AH24: 0 | AI24: 0 | AJ24: 0 | AK24: 0 | AL24: 0 | AM24: 0 | AN24: 0 | AO24: =IFERROR(AVERAGE(AA24,AB24,AC24,AD24,AE24,AF24,AG24,AH24,AI24,AJ24,AK24,AL24,AM24,AN24),"N/A") -> 0 | AP24: =IFERROR(AVERAGE(W24,X24,Y24,Z24)/2,"N/A") -> 0
A25: 20393692228 | B25: COOPERATIVA AGRARIA CACAOTERA SAN ALEJANDRO LTDA | C25: UCAYALI | D25: CACAO | E25: 0 | G25: NO | H25: nan | I25: nan | J25: ACTIVO | K25: nan | L25: 0 | M25: =IF(E25>0,ROUND(L25/E25*100,1),0) -> 0 | N25: PENDIENTE | O25: =IF(H25="SI",1,0)*0.6+IF(I25="SI",1,0)*0.4 -> 0 | P25: PENDIENTE | S25: =IFERROR(SCORECARDS!C23,"—") -> 0 | T25: =IF(ISTEXT(S25),S25,IF(S25<34,"🔴 Crítico",IF(S25<67,"🟡 Vulnerable","🟢 Preparado"))) -> 🔴 Crítico | W25: 0 | X25: 0 | Y25: 0 | Z25: 0 | AA25: 0 | AB25: 0 | AC25: 0 | AD25: 0 | AE25: 0 | AF25: 0 | AG25: 0 | AH25: 0 | AI25: 0 | AJ25: 0 | AK25: 0 | AL25: 0 | AM25: 0 | AN25: 0 | AO25: =IFERROR(AVERAGE(AA25,AB25,AC25,AD25,AE25,AF25,AG25,AH25,AI25,AJ25,AK25,AL25,AM25,AN25),"N/A") -> 0 | AP25: =IFERROR(AVERAGE(W25,X25,Y25,Z25)/2,"N/A") -> 0
A26: 20393786044 | B26: COOPERATIVA AGRARIA CAFETALERA COORDILLERA AZUL DE UCAYALI L | C26: UCAYALI | D26: CAFÉ | G26: NO | H26: nan | I26: nan | J26: ACTIVO | K26: nan | L26: 0 | M26: =IF(E26>0,ROUND(L26/E26*100,1),0) -> 0 | N26: PENDIENTE | O26: =IF(H26="SI",1,0)*0.6+IF(I26="SI",1,0)*0.4 -> 0 | P26: PENDIENTE | S26: =IFERROR(SCORECARDS!C24,"—") -> 0 | T26: =IF(ISTEXT(S26),S26,IF(S26<34,"🔴 Crítico",IF(S26<67,"🟡 Vulnerable","🟢 Preparado"))) -> 🔴 Crítico | W26: 0 | X26: 0 | Y26: 0 | Z26: 0 | AA26: 0 | AB26: 0 | AC26: 0 | AD26: 0 | AE26: 0 | AF26: 0 | AG26: 0 | AH26: 0 | AI26: 0 | AJ26: 0 | AK26: 0 | AL26: 0 | AM26: 0 | AN26: 0 | AO26: =IFERROR(AVERAGE(AA26,AB26,AC26,AD26,AE26,AF26,AG26,AH26,AI26,AJ26,AK26,AL26,AM26,AN26),"N/A") -> 0 | AP26: =IFERROR(AVERAGE(W26,X26,Y26,Z26)/2,"N/A") -> 0
A27: 20393816211 | B27: COOPERATIVA AGRARIA SAN JUAN BAUTISTA | C27: UCAYALI | D27: CACAO | E27: 0 | G27: NO | H27: nan | I27: nan | J27: ACTIVO | K27: nan | L27: 0 | M27: =IF(E27>0,ROUND(L27/E27*100,1),0) -> 0 | N27: PENDIENTE | O27: =IF(H27="SI",1,0)*0.6+IF(I27="SI",1,0)*0.4 -> 0 | P27: PENDIENTE | S27: =IFERROR(SCORECARDS!C25,"—") -> 0 | T27: =IF(ISTEXT(S27),S27,IF(S27<34,"🔴 Crítico",IF(S27<67,"🟡 Vulnerable","🟢 Preparado"))) -> 🔴 Crítico | W27: 0 | X27: 0 | Y27: 0 | Z27: 0 | AA27: 0 | AB27: 0 | AC27: 0 | AD27: 0 | AE27: 0 | AF27: 0 | AG27: 0 | AH27: 0 | AI27: 0 | AJ27: 0 | AK27: 0 | AL27: 0 | AM27: 0 | AN27: 0 | AO27: =IFERROR(AVERAGE(AA27,AB27,AC27,AD27,AE27,AF27,AG27,AH27,AI27,AJ27,AK27,AL27,AM27,AN27),"N/A") -> 0 | AP27: =IFERROR(AVERAGE(W27,X27,Y27,Z27)/2,"N/A") -> 0
A28: 20393882868 | B28: COOPERATIVA AGRARIA ASCAH | C28: UCAYALI | D28: CACAO | G28: NO | H28: nan | I28: nan | J28: ACTIVO | K28: nan | L28: 0 | M28: =IF(E28>0,ROUND(L28/E28*100,1),0) -> 0 | N28: PENDIENTE | O28: =IF(H28="SI",1,0)*0.6+IF(I28="SI",1,0)*0.4 -> 0 | P28: PENDIENTE | S28: =IFERROR(SCORECARDS!C26,"—") -> 0 | T28: =IF(ISTEXT(S28),S28,IF(S28<34,"🔴 Crítico",IF(S28<67,"🟡 Vulnerable","🟢 Preparado"))) -> 🔴 Crítico | W28: 0 | X28: 0 | Y28: 0 | Z28: 0 | AA28: 0 | AB28: 0 | AC28: 0 | AD28: 0 | AE28: 0 | AF28: 0 | AG28: 0 | AH28: 0 | AI28: 0 | AJ28: 0 | AK28: 0 | AL28: 0 | AM28: 0 | AN28: 0 | AO28: =IFERROR(AVERAGE(AA28,AB28,AC28,AD28,AE28,AF28,AG28,AH28,AI28,AJ28,AK28,AL28,AM28,AN28),"N/A") -> 0 | AP28: =IFERROR(AVERAGE(W28,X28,Y28,Z28)/2,"N/A") -> 0
A29: 20393972000 | B29: ASOCIACION DE MUJERES EMPRENDEDORAS FLOR DE BOQUERON | C29: UCAYALI | D29: CACAO | G29: NO | H29: nan | I29: nan | J29: ACTIVO | K29: nan | L29: 0 | M29: =IF(E29>0,ROUND(L29/E29*100,1),0) -> 0 | N29: PENDIENTE | O29: =IF(H29="SI",1,0)*0.6+IF(I29="SI",1,0)*0.4 -> 0 | P29: PENDIENTE | S29: =IFERROR(SCORECARDS!C27,"—") -> 0 | T29: =IF(ISTEXT(S29),S29,IF(S29<34,"🔴 Crítico",IF(S29<67,"🟡 Vulnerable","🟢 Preparado"))) -> 🔴 Crítico | W29: 0 | X29: 0 | Y29: 0 | Z29: 0 | AA29: 0 | AB29: 0 | AC29: 0 | AD29: 0 | AE29: 0 | AF29: 0 | AG29: 0 | AH29: 0 | AI29: 0 | AJ29: 0 | AK29: 0 | AL29: 0 | AM29: 0 | AN29: 0 | AO29: =IFERROR(AVERAGE(AA29,AB29,AC29,AD29,AE29,AF29,AG29,AH29,AI29,AJ29,AK29,AL29,AM29,AN29),"N/A") -> 0 | AP29: =IFERROR(AVERAGE(W29,X29,Y29,Z29)/2,"N/A") -> 0
A30: 20447888701 | B30: COOPERATIVA AGRARIA INDUSTRIAL SAN GABAN LTDA. | C30: PUNO | D30: CACAO | G30: NO | H30: nan | I30: nan | J30: ACTIVO | K30: nan | L30: 0 | M30: =IF(E30>0,ROUND(L30/E30*100,1),0) -> 0 | N30: PENDIENTE | O30: =IF(H30="SI",1,0)*0.6+IF(I30="SI",1,0)*0.4 -> 0 | P30: PENDIENTE | S30: =IFERROR(SCORECARDS!C28,"—") -> 0 | T30: =IF(ISTEXT(S30),S30,IF(S30<34,"🔴 Crítico",IF(S30<67,"🟡 Vulnerable","🟢 Preparado"))) -> 🔴 Crítico | W30: 0 | X30: 0 | Y30: 0 | Z30: 0 | AA30: 0 | AB30: 0 | AC30: 0 | AD30: 0 | AE30: 0 | AF30: 0 | AG30: 0 | AH30: 0 | AI30: 0 | AJ30: 0 | AK30: 0 | AL30: 0 | AM30: 0 | AN30: 0 | AO30: =IFERROR(AVERAGE(AA30,AB30,AC30,AD30,AE30,AF30,AG30,AH30,AI30,AJ30,AK30,AL30,AM30,AN30),"N/A") -> 0 | AP30: =IFERROR(AVERAGE(W30,X30,Y30,Z30)/2,"N/A") -> 0
A31: 20450189201 | B31: COOPERATIVA DE SERVICIOS MULTIPLES FRUTOS DE SELVA | C31: SAN MARTIN | D31: CAFÉ | E31: 0 | G31: NO | H31: nan | I31: nan | J31: ACTIVO | K31: nan | L31: 0 | M31: =IF(E31>0,ROUND(L31/E31*100,1),0) -> 0 | N31: PENDIENTE | O31: =IF(H31="SI",1,0)*0.6+IF(I31="SI",1,0)*0.4 -> 0 | P31: PENDIENTE | S31: =IFERROR(SCORECARDS!C29,"—") -> 0 | T31: =IF(ISTEXT(S31),S31,IF(S31<34,"🔴 Crítico",IF(S31<67,"🟡 Vulnerable","🟢 Preparado"))) -> 🔴 Crítico | W31: 0 | X31: 0 | Y31: 0 | Z31: 0 | AA31: 0 | AB31: 0 | AC31: 0 | AD31: 0 | AE31: 0 | AF31: 0 | AG31: 0 | AH31: 0 | AI31: 0 | AJ31: 0 | AK31: 0 | AL31: 0 | AM31: 0 | AN31: 0 | AO31: =IFERROR(AVERAGE(AA31,AB31,AC31,AD31,AE31,AF31,AG31,AH31,AI31,AJ31,AK31,AL31,AM31,AN31),"N/A") -> 0 | AP31: =IFERROR(AVERAGE(W31,X31,Y31,Z31)/2,"N/A") -> 0
A32: 20450207544 | B32: COOPERATIVA AGRARIA UCHIZA LTDA | C32: SAN MARTIN | D32: CACAO | E32: 0 | G32: NO | H32: nan | I32: nan | J32: ACTIVO | K32: nan | L32: 0 | M32: =IF(E32>0,ROUND(L32/E32*100,1),0) -> 0 | N32: PENDIENTE | O32: =IF(H32="SI",1,0)*0.6+IF(I32="SI",1,0)*0.4 -> 0 | P32: PENDIENTE | S32: =IFERROR(SCORECARDS!C30,"—") -> 0 | T32: =IF(ISTEXT(S32),S32,IF(S32<34,"🔴 Crítico",IF(S32<67,"🟡 Vulnerable","🟢 Preparado"))) -> 🔴 Crítico | W32: 0 | X32: 0 | Y32: 0 | Z32: 0 | AA32: 0 | AB32: 0 | AC32: 0 | AD32: 0 | AE32: 0 | AF32: 0 | AG32: 0 | AH32: 0 | AI32: 0 | AJ32: 0 | AK32: 0 | AL32: 0 | AM32: 0 | AN32: 0 | AO32: =IFERROR(AVERAGE(AA32,AB32,AC32,AD32,AE32,AF32,AG32,AH32,AI32,AJ32,AK32,AL32,AM32,AN32),"N/A") -> 0 | AP32: =IFERROR(AVERAGE(W32,X32,Y32,Z32)/2,"N/A") -> 0
A33: 20450242021 | B33: COOPERATIVA DE SERVICIOS MULTIPLES CAPEMA | C33: SAN MARTIN | D33: CAFÉ | E33: 0 | G33: NO | H33: nan | I33: nan | J33: ACTIVO | K33: nan | L33: 0 | M33: =IF(E33>0,ROUND(L33/E33*100,1),0) -> 0 | N33: PENDIENTE | O33: =IF(H33="SI",1,0)*0.6+IF(I33="SI",1,0)*0.4 -> 0 | P33: PENDIENTE | S33: =IFERROR(SCORECARDS!C31,"—") -> 0 | T33: =IF(ISTEXT(S33),S33,IF(S33<34,"🔴 Crítico",IF(S33<67,"🟡 Vulnerable","🟢 Preparado"))) -> 🔴 Crítico | W33: 0 | X33: 0 | Y33: 0 | Z33: 0 | AA33: 0 | AB33: 0 | AC33: 0 | AD33: 0 | AE33: 0 | AF33: 0 | AG33: 0 | AH33: 0 | AI33: 0 | AJ33: 0 | AK33: 0 | AL33: 0 | AM33: 0 | AN33: 0 | AO33: =IFERROR(AVERAGE(AA33,AB33,AC33,AD33,AE33,AF33,AG33,AH33,AI33,AJ33,AK33,AL33,AM33,AN33),"N/A") -> 0 | AP33: =IFERROR(AVERAGE(W33,X33,Y33,Z33)/2,"N/A") -> 0
A34: 20450319423 | B34: COOPERATIVA AGRARIA DE SERVICIOS MULTIPLES CAFE DONCEL | C34: SAN MARTIN | D34: CAFÉ | G34: NO | H34: nan | I34: nan | J34: ACTIVO | K34: nan | L34: 0 | M34: =IF(E34>0,ROUND(L34/E34*100,1),0) -> 0 | N34: PENDIENTE | O34: =IF(H34="SI",1,0)*0.6+IF(I34="SI",1,0)*0.4 -> 0 | P34: PENDIENTE | S34: =IFERROR(SCORECARDS!C32,"—") -> 0 | T34: =IF(ISTEXT(S34),S34,IF(S34<34,"🔴 Crítico",IF(S34<67,"🟡 Vulnerable","🟢 Preparado"))) -> 🔴 Crítico | W34: 0 | X34: 0 | Y34: 0 | Z34: 0 | AA34: 0 | AB34: 0 | AC34: 0 | AD34: 0 | AE34: 0 | AF34: 0 | AG34: 0 | AH34: 0 | AI34: 0 | AJ34: 0 | AK34: 0 | AL34: 0 | AM34: 0 | AN34: 0 | AO34: =IFERROR(AVERAGE(AA34,AB34,AC34,AD34,AE34,AF34,AG34,AH34,AI34,AJ34,AK34,AL34,AM34,AN34),"N/A") -> 0 | AP34: =IFERROR(AVERAGE(W34,X34,Y34,Z34)/2,"N/A") -> 0
A35: 20452774705 | B35: COOPERATIVA AGRARIA CACAO VRAE | C35: CUSCO | D35: CACAO | E35: 1931452.7 | F35: 7 | G35: SI | H35: nan | I35: nan | J35: ACTIVO | K35: nan | L35: 965726.35 | M35: =IF(E35>0,ROUND(L35/E35*100,1),0) -> 50 | N35: PENDIENTE | O35: =IF(H35="SI",1,0)*0.6+IF(I35="SI",1,0)*0.4 -> 0 | P35: PENDIENTE | S35: =IFERROR(SCORECARDS!C33,"—") -> 0 | T35: =IF(ISTEXT(S35),S35,IF(S35<34,"🔴 Crítico",IF(S35<67,"🟡 Vulnerable","🟢 Preparado"))) -> 🔴 Crítico | U35: 1 | V35: Sin hallazgos OSCE / OEFA | W35: 1 | X35: 0 | Y35: 0 | Z35: 0 | AA35: 0 | AB35: 0 | AC35: 0 | AD35: 0 | AE35: 0 | AF35: 0 | AG35: 0 | AH35: 0 | AI35: 0 | AJ35: 0 | AK35: 0 | AL35: 0 | AM35: 0 | AN35: 0 | AO35: =IFERROR(AVERAGE(AA35,AB35,AC35,AD35,AE35,AF35,AG35,AH35,AI35,AJ35,AK35,AL35,AM35,AN35),"N/A") -> 0 | AP35: =IFERROR(AVERAGE(W35,X35,Y35,Z35)/2,"N/A") -> 0.125
A36: 20479595276 | B36: COOPERATIVA AGRARIA CAFETALERA CASIL LTDA. | C36: CAJAMARCA | D36: CAFÉ | E36: 4538578.9 | F36: 24 | G36: SI | H36: SI | I36: SI | J36: ACTIVO | K36: nan | L36: 965167.45 | M36: =IF(E36>0,ROUND(L36/E36*100,1),0) -> 21.3 | N36: PENDIENTE | O36: =IF(H36="SI",1,0)*0.6+IF(I36="SI",1,0)*0.4 -> 1 | P36: PENDIENTE | Q36: 178 | R36: 437 | S36: =IFERROR(SCORECARDS!C34,"—") -> 0 | T36: =IF(ISTEXT(S36),S36,IF(S36<34,"🔴 Crítico",IF(S36<67,"🟡 Vulnerable","🟢 Preparado"))) -> 🔴 Crítico | U36: 1 | V36: Sin hallazgos OSCE / OEFA | W36: 1 | X36: 0 | Y36: 0 | Z36: 0 | AA36: 0 | AB36: 0 | AC36: 0 | AD36: 0 | AE36: 0 | AF36: 0 | AG36: 0 | AH36: 0 | AI36: 0 | AJ36: 0 | AK36: 0 | AL36: 0 | AM36: 0 | AN36: 0 | AO36: =IFERROR(AVERAGE(AA36,AB36,AC36,AD36,AE36,AF36,AG36,AH36,AI36,AJ36,AK36,AL36,AM36,AN36),"N/A") -> 0 | AP36: =IFERROR(AVERAGE(W36,X36,Y36,Z36)/2,"N/A") -> 0.125
A37: 20479622699 | B37: COOPERATIVA AGRARIA JUAN MARCO EL PALTO | C37: AMAZONAS | D37: CAFÉ | E37: 0 | G37: NO | H37: nan | I37: nan | J37: ACTIVO | K37: nan | L37: 0 | M37: =IF(E37>0,ROUND(L37/E37*100,1),0) -> 0 | N37: PENDIENTE | O37: =IF(H37="SI",1,0)*0.6+IF(I37="SI",1,0)*0.4 -> 0 | P37: PENDIENTE | S37: =IFERROR(SCORECARDS!C35,"—") -> 0 | T37: =IF(ISTEXT(S37),S37,IF(S37<34,"🔴 Crítico",IF(S37<67,"🟡 Vulnerable","🟢 Preparado"))) -> 🔴 Crítico | W37: 0 | X37: 0 | Y37: 0 | Z37: 0 | AA37: 0 | AB37: 0 | AC37: 0 | AD37: 0 | AE37: 0 | AF37: 0 | AG37: 0 | AH37: 0 | AI37: 0 | AJ37: 0 | AK37: 0 | AL37: 0 | AM37: 0 | AN37: 0 | AO37: =IFERROR(AVERAGE(AA37,AB37,AC37,AD37,AE37,AF37,AG37,AH37,AI37,AJ37,AK37,AL37,AM37,AN37),"N/A") -> 0 | AP37: =IFERROR(AVERAGE(W37,X37,Y37,Z37)/2,"N/A") -> 0
A38: 20479856258 | B38: ASOCIACION DE PRODUCTORES AGROPECUARIOS LUIS SOLIBARRIA | C38: AMAZONAS | D38: nan | G38: NO | H38: nan | I38: nan | J38: BAJA DE OFICIO | K38: nan | L38: 0 | M38: =IF(E38>0,ROUND(L38/E38*100,1),0) -> 0 | N38: PENDIENTE | O38: =IF(H38="SI",1,0)*0.6+IF(I38="SI",1,0)*0.4 -> 0 | P38: PENDIENTE | S38: =IFERROR(SCORECARDS!C36,"—") -> 0 | T38: =IF(ISTEXT(S38),S38,IF(S38<34,"🔴 Crítico",IF(S38<67,"🟡 Vulnerable","🟢 Preparado"))) -> 🔴 Crítico | W38: 0 | X38: 0 | Y38: 0 | Z38: 0 | AA38: 0 | AB38: 0 | AC38: 0 | AD38: 0 | AE38: 0 | AF38: 0 | AG38: 0 | AH38: 0 | AI38: 0 | AJ38: 0 | AK38: 0 | AL38: 0 | AM38: 0 | AN38: 0 | AO38: =IFERROR(AVERAGE(AA38,AB38,AC38,AD38,AE38,AF38,AG38,AH38,AI38,AJ38,AK38,AL38,AM38,AN38),"N/A") -> 0 | AP38: =IFERROR(AVERAGE(W38,X38,Y38,Z38)/2,"N/A") -> 0
A39: 20479917141 | B39: COOPERATIVA AGRARIA CENTRAL DE PRODUCTORES DE AMAZONAS | C39: AMAZONAS | D39: CACAO | E39: 1175215.3 | F39: 7 | G39: SI | H39: nan | I39: nan | J39: ACTIVO | K39: nan | L39: 587607.64 | M39: =IF(E39>0,ROUND(L39/E39*100,1),0) -> 50 | N39: PENDIENTE | O39: =IF(H39="SI",1,0)*0.6+IF(I39="SI",1,0)*0.4 -> 0 | P39: PENDIENTE | S39: =IFERROR(SCORECARDS!C37,"—") -> 0 | T39: =IF(ISTEXT(S39),S39,IF(S39<34,"🔴 Crítico",IF(S39<67,"🟡 Vulnerable","🟢 Preparado"))) -> 🔴 Crítico | U39: 1 | V39: Sin hallazgos OSCE / OEFA | W39: 1 | X39: 0 | Y39: 0 | Z39: 0 | AA39: 0 | AB39: 0 | AC39: 0 | AD39: 0 | AE39: 0 | AF39: 0 | AG39: 0 | AH39: 0 | AI39: 0 | AJ39: 0 | AK39: 0 | AL39: 0 | AM39: 0 | AN39: 0 | AO39: =IFERROR(AVERAGE(AA39,AB39,AC39,AD39,AE39,AF39,AG39,AH39,AI39,AJ39,AK39,AL39,AM39,AN39),"N/A") -> 0 | AP39: =IFERROR(AVERAGE(W39,X39,Y39,Z39)/2,"N/A") -> 0.125
A40: 20480458550 | B40: COOPERATIVA AGRARIA APROCAM | C40: AMAZONAS | D40: CACAO | E40: 1684430 | F40: 14 | G40: SI | H40: nan | I40: nan | J40: ACTIVO | K40: nan | L40: 842214.99 | M40: =IF(E40>0,ROUND(L40/E40*100,1),0) -> 50 | N40: PENDIENTE | O40: =IF(H40="SI",1,0)*0.6+IF(I40="SI",1,0)*0.4 -> 0 | P40: PENDIENTE | S40: =IFERROR(SCORECARDS!C38,"—") -> 0 | T40: =IF(ISTEXT(S40),S40,IF(S40<34,"🔴 Crítico",IF(S40<67,"🟡 Vulnerable","🟢 Preparado"))) -> 🔴 Crítico | U40: 1 | V40: Sin hallazgos OSCE / OEFA | W40: 1 | X40: 0 | Y40: 0 | Z40: 0 | AA40: 0 | AB40: 0 | AC40: 0 | AD40: 0 | AE40: 0 | AF40: 0 | AG40: 0 | AH40: 0 | AI40: 0 | AJ40: 0 | AK40: 0 | AL40: 0 | AM40: 0 | AN40: 0 | AO40: =IFERROR(AVERAGE(AA40,AB40,AC40,AD40,AE40,AF40,AG40,AH40,AI40,AJ40,AK40,AL40,AM40,AN40),"N/A") -> 0 | AP40: =IFERROR(AVERAGE(W40,X40,Y40,Z40)/2,"N/A") -> 0.125
...

Sheet PREGUNTAS_PROXY
A1: PREGUNTAS PROXY — Verificación rápida por dimensión EUDR
A2: Dim. | B2: # | C2: Pregunta | D2: Respuesta | E2: Score (0-1) | F2: Variable | G2: Fuente | H2: Obs.
A3: DIMENSIÓN D1 — Clasificación regulatoria
A4: D1 | B4: 1 | C4: ¿Cuál es el rol principal de la organización? | F4: tipo_rol | G4: Entrevista directiva / SUNAT
A5: D1 | B5: 2 | C5: ¿La organización está inscrita en el RNCA (Registro Nacional de Cooperativas Agrarias)? | F5: rnca | G5: SUNAT / MIDAGRI RNCA
A6: D1 | B6: 3 | C6: ¿Exporta directamente bajo su propio RUC (no a través de un agente)? | F6: exporta_directo | G6: ADUANET / DUAs
A7: DIMENSIÓN D2 — Trazabilidad y geolocalización
A8: D2 | B8: 1 | C8: ¿Existe al menos un registro donde cada lote exportado esté vinculado a la parcela de origen? | F8: lote_parcela | G8: Entrevista + revisión documentos
A9: D2 | B9: 2 | C9: ¿Se registran las coordenadas geográficas de las parcelas de los socios? | F9: coords | G9: Entrevista + evidencia
A10: D2 | B10: 3 | C10: ¿Con qué frecuencia se actualizan las coordenadas de parcelas? | F10: frec_coords | G10: Entrevista
A11: D2 | B11: 4 | C11: ¿Se usa balance de masas (mezcla de lotes sin segregación física)? | F11: bal_masas | G11: Entrevista — ROJO si dice Sí | H11: ⚠ Bal. de masas prohibido bajo EUDR
A12: D2 | B12: 5 | C12: ¿Los proveedores externos (no socios) representan volumen significativo? | F12: pct_ext | G12: Entrevista
