Workbook

Sheet INSTRUCCIONES
A1: PLANTILLA ÍNDICE PVE — PACTO VERDE EUROPEO
A2: Clasificación de preparación y vulnerabilidad de cooperativas café y cacao ante el EUDR / Pacto Verde Europeo
A4: PROPÓSITO
A7: CÓMO FUNCIONA
A10: FLUJO DE USO
A11: Paso 1 | B11: Revisar PONDERADORES — los pesos son editables en celdas amarillas
A12: Paso 2 | B12: Ir a MATRIZ_174 — verificar/actualizar FOB, país destino, certificaciones
A13: Paso 3 | B13: Para cada organización con FOB UE > 0, completar PREGUNTAS_PROXY usando llamada telefónica o visita de 30 min
A14: Paso 4 | B14: Revisar SCORECARDS — el semáforo se actualiza automáticamente
A15: Paso 5 | B15: Usar RADAR_BRECHAS para comparación por departamento
A17: SEMÁFORO
A18: 🔴 Crítico (0–33) | B18: La cooperativa no puede generar la declaración EUDR. Riesgo de rechazo en frontera UE desde dic 2026.
A19: 🟡 Vulnerable (34–66) | B19: Tiene infraestructura parcial pero incompleta. Necesita inversión en geolocalización y proceso.
A20: 🟢 Preparado (67–100) | B20: Cumple los requisitos mínimos. Requiere monitoreo de actualización.
A22: NOTAS IMPORTANTES

Sheet INSTRUMENTO_2_PREGUNTAS
A1: INSTRUMENTO 2 (v0.4, 119 preguntas) — Correspondencia pregunta → destino en esta plantilla
A2: Sección | B2: ID | C2: Bloque / Dimensión | D2: Pregunta | E2: Tipo de campo | F2: Opciones | G2: Destino en esta plantilla | H2: Nota
A3: Sección 0 — Metadata de campo | B3: M1 | C3: Bloque 0 — Ficha de identificación | D3: Fecha | E3: — | F3: — | G3: Google Sheet de respuestas, col. D (`fecha_aplicacion`)
A4: Sección 0 — Metadata de campo | B4: M2 | C4: Bloque 0 — Ficha de identificación | D4: Respuesta corta | E4: — | F4: — | G4: Google Sheet de respuestas, col. E (`encuestador`)
A5: Sección 0 — Metadata de campo | B5: M3 | C5: Bloque 0 — Ficha de identificación | D5: Lista desplegable | E5: Google Form directo / Piggyback GIZ / Piggyback SAFE / Piggyback MIDAGRI / Evento gremial / Otro | F5: — | G5: Google Sheet de respuestas, col. F (`canal_aplicacion`)
A6: Sección 1 — Bloque 0: Ficha de identificación | B6: B0.1 | C6: Bloque 0 — Ficha de identificación | D6: Nombre de la cooperativa / razón social | E6: Respuesta corta | F6: — | G6: `MATRIZ_174!B` (Razón Social)
A7: Sección 1 — Bloque 0: Ficha de identificación | B7: B0.2 | C7: Bloque 0 — Ficha de identificación | D7: RUC | E7: Respuesta corta (validación: regex 11 dígitos si el Form lo permite) | F7: — | G7: `MATRIZ_174!A` · `ISCAM_Score!A` · `SCORECARDS!A` — clave de join
A8: Sección 1 — Bloque 0: Ficha de identificación | B8: B0.3 | C8: Bloque 0 — Ficha de identificación | D8: Producto(s) exportado(s) (café, cacao, madera, otro — indique código SA si lo conoce) | E8: Párrafo | F8: — | G8: `MATRIZ_174!D` (Producto)
A9: Sección 1 — Bloque 0: Ficha de identificación | B9: B0.4 | C9: Bloque 0 — Ficha de identificación | D9: N.º de socios productores y hectáreas totales asociadas (indique ambos: "N.º socios: ___ / Hectáreas: ___") | E9: Párrafo | F9: — | G9: `MATRIZ_174!Q` (N.° socios) + `R` (Ha)
A10: Sección 1 — Bloque 0: Ficha de identificación | B10: B0.5 | C10: Bloque 0 — Ficha de identificación | D10: ¿Exporta directamente a la Unión Europea o a través de un tercero? | E10: Opción múltiple | F10: Directamente / A través de un tercero | G10: `MATRIZ_174!G` (Exporta SI/NO)
A11: Sección 1 — Bloque 0: Ficha de identificación | B11: B0.6 | C11: Bloque 0 — Ficha de identificación | D11: Si respondió "a través de un tercero": ¿quién es el comprador que sí exporta a la UE? (deje en blanco si no aplica) | E11: Respuesta corta (opcional) | F11: — | G11: Sin destino en la plantilla — registro de auditoría
A12: Sección 1 — Bloque 0: Ficha de identificación | B12: B0.7 | C12: Bloque 0 — Ficha de identificación | D12: Volumen anual aproximado destinado a la UE, como % del total exportado | E12: Respuesta corta (validación numérica 0-100) | F12: — | G12: `MATRIZ_174!M` (% UE/FOB) — validación cruzada
A13: Sección 1 — Bloque 0: Ficha de identificación | B13: B0.8 | C13: Bloque 0 — Ficha de identificación | D13: Destino(s) de sus exportaciones, marcando primero el principal — incluya destinos fuera de la UE | E13: Casillas de verificación | F13: Alemania / Bélgica / Países Bajos / Francia / Italia / España / Suecia / Dinamarca / Estados Unidos / Japón / China / Otro (especificar) | G13: Proxy `destino_principal` (D7); validación vs. DUAs | H13: v0.4 — modificada
A14: Sección 1 — Bloque 0: Ficha de identificación | B14: B0.9 | C14: Bloque 0 — Ficha de identificación | D14: Certificaciones voluntarias vigentes | E14: Casillas de verificación | F14: Rainforest Alliance / Fairtrade / Orgánico / UTZ / Otra / Ninguna | G14: `MATRIZ_174!H`/`I` → `O` (Score Cert)
A15: Sección 1 — Bloque 0: Ficha de identificación | B15: B0.10 | C15: Bloque 0 — Ficha de identificación | D15: ¿Las parcelas de los socios están concentradas en un solo distrito, repartidas en varios distritos de una misma provincia, o dispersas en varias provincias/regiones? | E15: Opción múltiple | F15: Un solo distrito / Varios distritos, misma provincia / Varias provincias o regiones | G15: Insumo IV3 — `ISCAM_Score!W`
A16: Sección 1 — Bloque 0: Ficha de identificación | B16: B0.11 | C16: Bloque 0 — Ficha de identificación | D16: Distancia aproximada entre las parcelas más alejadas de los socios y el centro de acopio o planta de procesamiento más cercano | E16: Opción múltiple | F16: Menos de 5 km / Entre 5 y 20 km / Entre 20 y 50 km / Más de 50 km / No se ha medido | G16: Insumo IV3 — `ISCAM_Score!W`
A17: Sección 1 — Bloque 0: Ficha de identificación | B17: B0.12 | C17: Bloque 0 — Ficha de identificación | D17: % de mujeres en la directiva/consejo directivo | E17: Respuesta corta (validación numérica 0-100) | F17: — | G17: Insumo IV5 — `ISCAM_Score!Y`
A18: Sección 1 — Bloque 0: Ficha de identificación | B18: B0.13 | C18: Bloque 0 — Ficha de identificación | D18: ¿Qué porcentaje aproximado de los socios productores opera en zonas clasificadas como de riesgo alto o muy alto de deforestación según el Mapa de Deforestación del MINAM o Global Forest Watch? | E18: Opción múltiple | F18: Menos del 10% / Entre 10% y 30% / Entre 30% y 60% / Más del 60% / No se ha evaluado | G18: Insumo IV3/IP3 — `ISCAM_Score!W`/`R`
A19: Sección 1 — Bloque 0: Ficha de identificación | B19: B0.14 | C19: Bloque 0 — Ficha de identificación | D19: ¿La cooperativa tiene capacidad técnica de verificación directa en campo —personal o prestataire con formación agronómica— para supervisar las prácticas de los socios en sus parcelas de forma periódica? | E19: Opción múltiple | F19: No tiene capacidad de verificación / Parcial, cubre menos de la mitad de los socios / Parcial, cubre más de la mitad / Sí, capacidad suficiente para visitas periódicas a todos los socios | G19: Insumo IV3/IP3 — `ISCAM_Score!W`/`R`
A20: Sección 1 — Bloque 0: Ficha de identificación | B20: B0.15 | C20: Bloque 0 — Ficha de identificación | D20: Tipo de organización | E20: Opción múltiple | F20: Asociación / Cooperativa agraria / Cooperativa de servicios / Central o federación de cooperativas / Empresa / Otro (especificar) | G20: `MATRIZ_174!P` (Tipo org.) | H20: v0.4 — nueva
A21: Sección 1 — Bloque 0: Ficha de identificación | B21: B0.16 | C21: Bloque 0 — Ficha de identificación | D21: Departamento (y provincia) donde está registrada la sede de la organización | E21: Respuesta corta | F21: — | G21: `MATRIZ_174!C` (Depto) — validación SUNAT | H21: v0.4 — nueva
A22: Sección 1 — Bloque 0: Ficha de identificación | B22: B0.17 | C22: Bloque 0 — Ficha de identificación | D22: ¿La organización está inscrita en el RNCA (Registro Nacional de Cooperativas Agrarias)? | E22: Opción múltiple | F22: Sí / En trámite / No / No aplica (no es cooperativa agraria) | G22: Insumo IV2 — `ISCAM_Score!V`; proxy `rnca` | H22: v0.4 — nueva
A23: Sección 2 — Bloque P: Variables de Performance | B23: P1 | C23: Bloque P — Performance comercial | D23: Volumen exportado a la Unión Europea en el último año (especifique unidad —kg o toneladas— y producto si exporta ambos) | E23: Párrafo | F23: — | G23: Insumo IV1 — `ISCAM_Score!U`
A24: Sección 2 — Bloque P: Variables de Performance | B24: P1b | C24: Bloque P — Performance comercial | D24: Volumen TOTAL exportado a todos los destinos (UE y no UE) en el último año, mismo producto y misma unidad que la pregunta anterior | E24: Párrafo | F24: — | G24: Insumo IV1 — `ISCAM_Score!U`
A25: Sección 2 — Bloque P: Variables de Performance | B25: P2 | C25: Bloque P — Performance comercial | D25: Volumen exportado a la Unión Europea hace 3 años, mismo producto (kg o toneladas) | E25: Párrafo | F25: — | G25: No puntúa (retrospectivo)
A26: Sección 2 — Bloque P: Variables de Performance | B26: P3 | C26: Bloque P — Performance comercial | D26: Ingreso total generado por ventas de exportación a la UE en el último año (especifique moneda: S/ o USD) | E26: Párrafo | F26: — | G26: Insumo IV1 — `ISCAM_Score!U`; deriva PVE P2
A27: Sección 2 — Bloque P: Variables de Performance | B27: P4 | C27: Bloque P — Performance comercial | D27: N.º de compradores/clientes europeos activos actualmente | E27: Respuesta corta (numérica) | F27: — | G27: Insumo IV1 — `ISCAM_Score!U`
A28: Sección 2 — Bloque P: Variables de Performance | B28: P5 | C28: Bloque P — Performance comercial | D28: N.º de compradores/clientes europeos activos hace 3 años | E28: Respuesta corta (numérica) | F28: — | G28: No puntúa (retrospectivo)
A29: Sección 2 — Bloque P: Variables de Performance | B29: P6 | C29: Bloque P — Performance comercial | D29: Precio promedio pagado al socio productor por kg/quintal en el último año (especifique S/ o USD) | E29: Respuesta corta | F29: — | G29: Derivada `var_precio_socio`
A30: Sección 2 — Bloque P: Variables de Performance | B30: P7 | C30: Bloque P — Performance comercial | D30: Precio promedio pagado al socio productor por kg/quintal hace 3 años | E30: Respuesta corta | F30: — | G30: Derivada `var_precio_socio`
A31: Sección 2 — Bloque P: Variables de Performance | B31: P8 | C31: Bloque P — Performance comercial | D31: ¿Ha tenido algún lote rechazado u observado por un comprador europeo por motivos de trazabilidad/deforestación en los últimos 2 años? | E31: Opción múltiple | F31: Sí / No / No sabe | G31: Proxy `reg_rechazos` (D5)
A32: Sección 2 — Bloque P: Variables de Performance | B32: P9 | C32: Bloque P — Performance comercial | D32: Si la respuesta anterior fue "Sí": N.º aproximado de lotes rechazados u observados (deje en blanco si no aplica) | E32: Respuesta corta (opcional) | F32: — | G32: Detalle de P8 — no puntúa
A33: Sección 2 — Bloque P: Variables de Performance | B33: P10 | C33: Bloque P — Performance comercial | D33: ¿Ha perdido algún contrato o comprador europeo en los últimos 2 años por motivos de cumplimiento (EUDR u otro requisito de sostenibilidad del comprador)? | E33: Opción múltiple | F33: Sí / No / No sabe | G33: Proxy presión PV del comprador (D7)
A34: Sección 2 — Bloque P: Variables de Performance | B34: P11 | C34: Bloque P — Performance comercial | D34: % del volumen total exportado en el último año que cuenta con trazabilidad completa verificada hasta la parcela de origen (0-100%) | E34: Respuesta corta (validación numérica 0-100) | F34: — | G34: `MATRIZ_174!AK` (P11 — Score trazabilidad)
... A41: Sección 3 — D1: Clasificación regulatoria | B41: D1.4 | C41: D1 — Clasificación regulatoria | D41: ¿Cumple los umbrales de microempresa/pequeña empresa (Directiva 2013/34/UE)? | E41: Opción múltiple | F41: Sí / No / No sabe | G41: `ISCAM_Score!E` (D1)
A42: Sección 3 — D1: Clasificación regulatoria | B42: D1.3a | C42: D1 — Clasificación regulatoria | D42: *(Rama: solo si D1.3 = "Sí con certeza" o "Idea aproximada")* ¿Cuál es el rol que le corresponde a la organización? | E42: Opción múltiple | F42: Operador / Operador posterior / Comerciante / Micro o pequeño operador primario / No sabe | G42: `ISCAM_Score!E` (D1) | H42: v0.4 — nueva
A43: Sección 4 — D2: Trazabilidad y geolocalización | B43: D2.5 | C43: D2 — Trazabilidad y geolocalización | D43: ¿Existe registro de geolocalización (GPS/polígono) por parcela de socio? | E43: Escala lineal 0-4 | F43: 0 = No existe/No sabe … 4 = Implementado y verificado/auditado | G43: `ISCAM_Score!F` vía `SCORECARDS!H` (D2)
A44: Sección 4 — D2: Trazabilidad y geolocalización | B44: D2.6 | C44: D2 — Trazabilidad y geolocalización | D44: % de socios con parcela geolocalizada | E44: Respuesta corta (validación numérica 0-100) | F44: — | G44: `ISCAM_Score!F` vía `SCORECARDS!H` (D2)
A45: Sección 4 — D2: Trazabilidad y geolocalización | B45: D2.7 | C45: D2 — Trazabilidad y geolocalización | D45: ¿El sistema vincula un lote exportado con la(s) parcela(s) específica(s)? | E45: Escala lineal 0-4 | F45: Misma leyenda que D2.5 | G45: `ISCAM_Score!F` vía `SCORECARDS!H` (D2)
A46: Sección 4 — D2: Trazabilidad y geolocalización | B46: D2.8 | C46: D2 — Trazabilidad y geolocalización | D46: ¿Quién levantó la información de geolocalización? | E46: Opción múltiple | F46: Técnico propio / Consultor / Proyecto de cooperación / Socio por su cuenta / No se ha levantado | G46: `ISCAM_Score!F` vía `SCORECARDS!H` (D2)
...

Sheet ISCAM_Score
A1: ISCAM — ISA-Completo = 0.70×ISA-EUDR + 0.30×ISA-PV | IP × IV → RE | Café y Cacao Perú — 174 organizaciones
A2: ISA-Completo = 0.70×ISA-EUDR + 0.30×ISA-PV | ISA-EUDR = 0.875×Núcleo(D1–D7, geom.) + 0.125×Extendido(D8–D9, arit.) | ISA-PV = Promedio(D12:D15) | IP = Promedio(IP1..IP5) | IV = Promedio(IV1..IV5) | RE = IV×(1−IP/100) | Corte 2×2: 50
A3: RUC | B3: Razón Social | C3: Depto | D3: FOB UE USD | E3: D1 — Clasific. Regulatoria | F3: D2 — Trazabilidad (SCORECARDS H) | G3: D3 — Legalidad (OSCE/Neon) | H3: D4 — Deforestación Cero | I3: D5 — Diligencia Debida | J3: D6 — Capacidad Digital | K3: D7 — Presión Comprador | L3: D8 — Gobernanza | M3: D9 — Riesgo Financiero | N3: D10 — Certificac. | O3: D11 — Ecosistema (inventario, no promedia) | P3: IP1 Trazabilidad D2 | Q3: IP2 √(D3×D4) | R3: IP3 (D5+D6+D8)/3 | S3: IP4 (D6+D2)/2 | T3: IP5 (D7+D9+Cert)/3 | U3: IV1 Exposición UE (% FOB UE) | V3: IV2 D1 (base=50) | W3: IV3 Parcela ha/socio (sin dato→65) | X3: IV4 Cert=0? → 70:30 | Y3: IV5 Tipo Asoc → 65:40 | Z3: IP Preparación | AA3: IV Vulnerabilidad | AB3: RE Exclusión | AC3: Tipología 2×2 ISCAM | AD3: Banderas Duras | AE3: D12 Huella Carbono | AF3: D13 Reporte Sostenib. | AG3: D14 Economía Circular | AH3: D15 Fitosanitario | AI3: ISA-PV Promedio D12:D15 | AJ3: P_Global Promedio P1:P14 | AK3: ISA-EUDR Geom.D1–D7 + Arit.D8–D9 | AL3: ISA-Completo 0.70×EUDR +0.30×PV
A4: 20118578415 | B4: CENT.DE COOP.AGR. CAF.VALLES SANDIA LTDA | C4: PUNO | D4: 2553623.3 | E4: 0 | F4: =IFERROR(SCORECARDS!H3,"") | G4: =IFERROR(MATRIZ_174!U3,0) | H4: 0 | I4: =IFERROR(SCORECARDS!I3,"") | J4: =IFERROR(SCORECARDS!J3,"") | K4: 0 | L4: 0 | M4: 0 | N4: 0 | O4: 0 | P4: =IFERROR(F4,0) | Q4: =IFERROR(SQRT(G4*H4),0) | R4: =IFERROR((I4+J4+L4)/3,0) | S4: =IFERROR((J4+F4)/2,0) | T4: =IFERROR((K4+M4+MATRIZ_174!O3)/3,0) | U4: =IFERROR(MIN(100,ROUND(MATRIZ_174!M3,1)),0) | V4: =IFERROR(IF(E4=0,50,E4),0) | W4: =IFERROR(IF(MATRIZ_174!R3=0,65,IF(MATRIZ_174!R3/MATRIZ_174!Q3>=2,35,IF(MATRIZ_174!R3/MATRIZ_174!Q3>=0.5,50,65))),65) | X4: =IF(MATRIZ_174!O3=0,70,30) | Y4: =IF(OR(MATRIZ_174!P3="ASOCIACION",MATRIZ_174!P3="PENDIENTE"),65,40) | Z4: =IFERROR(ROUND(AVERAGE(P4,Q4,R4,S4,T4),1),0) | AA4: =IFERROR(ROUND(AVERAGE(U4,V4,W4,X4,Y4),1),0) | AB4: =IFERROR(ROUND(AA4*(1-Z4/100),1),0) | AC4: =IF(AND(Z4>=50,AA4<50),"🟢 Resilientes",IF(AND(Z4>=50,AA4>=50),"🟠 Expuestas Adaptables",IF(AND(Z4<50,AA4<50),"⬜ Riesgo Latente","🔴 Riesgo Crítico"))) | AD4: =IF(G4=0,"🚫 Inh. vigente OSCE","") | AE4: =IFERROR(MATRIZ_174!W3,0) | AF4: =IFERROR(MATRIZ_174!X3,0) | AG4: =IFERROR(MATRIZ_174!Y3,0) | AH4: =IFERROR(MATRIZ_174!Z3,0) | AI4: =IFERROR(MATRIZ_174!AP3,"N/A") | AJ4: =IFERROR(MATRIZ_174!AO3,"N/A") | AK4: =IFERROR(ROUND(POWER((E4*F4*G4*H4*I4*J4*K4),1/7)*0.875+((L4+M4)/2)*0.125,1),"N/A") | AL4: =IFERROR(IF(OR(AK4="N/A",AI4="N/A"),"N/A",ROUND(0.7*AK4+0.3*AI4*100,1)),"N/A")
A5: 20129156083 | B5: COOP AGRARIA CAFET VALLE RIO APURIMAC | C5: AYACUCHO | D5: 0 | E5: 0 | F5: =IFERROR(SCORECARDS!H4,"") | G5: =IFERROR(MATRIZ_174!U4,0) | H5: 0 | I5: =IFERROR(SCORECARDS!I4,"") | J5: =IFERROR(SCORECARDS!J4,"") | K5: 0 | L5: 0 | M5: 0 | N5: 0 | O5: 0 | P5: =IFERROR(F5,0) | Q5: =IFERROR(SQRT(G5*H5),0) | R5: =IFERROR((I5+J5+L5)/3,0) | S5: =IFERROR((J5+F5)/2,0) | T5: =IFERROR((K5+M5+MATRIZ_174!O4)/3,0) | U5: =IFERROR(MIN(100,ROUND(MATRIZ_174!M4,1)),0) | V5: =IFERROR(IF(E5=0,50,E5),0) | W5: =IFERROR(IF(MATRIZ_174!R4=0,65,IF(MATRIZ_174!R4/MATRIZ_174!Q4>=2,35,IF(MATRIZ_174!R4/MATRIZ_174!Q4>=0.5,50,65))),65) | X5: =IF(MATRIZ_174!O4=0,70,30) | Y5: =IF(OR(MATRIZ_174!P4="ASOCIACION",MATRIZ_174!P4="PENDIENTE"),65,40) | Z5: =IFERROR(ROUND(AVERAGE(P5,Q5,R5,S5,T5),1),0) | AA5: =IFERROR(ROUND(AVERAGE(U5,V5,W5,X5,Y5),1),0) | AB5: =IFERROR(ROUND(AA5*(1-Z5/100),1),0) | AC5: =IF(AND(Z5>=50,AA5<50),"🟢 Resilientes",IF(AND(Z5>=50,AA5>=50),"🟠 Expuestas Adaptables",IF(AND(Z5<50,AA5<50),"⬜ Riesgo Latente","🔴 Riesgo Crítico"))) | AD5: =IF(G5=0,"🚫 Inh. vigente OSCE","") | AE5: =IFERROR(MATRIZ_174!W4,0) | AF5: =IFERROR(MATRIZ_174!X4,0) | AG5: =IFERROR(MATRIZ_174!Y4,0) | AH5: =IFERROR(MATRIZ_174!Z4,0) | AI5: =IFERROR(MATRIZ_174!AP4,"N/A") | AJ5: =IFERROR(MATRIZ_174!AO4,"N/A") | AK5: =IFERROR(ROUND(POWER((E5*F5*G5*H5*I5*J5*K5),1/7)*0.875+((L5+M5)/2)*0.125,1),"N/A") | AL5: =IFERROR(IF(OR(AK5="N/A",AI5="N/A"),"N/A",ROUND(0.7*AK5+0.3*AI5*100,1)),"N/A")
A6: 20129529530 | B6: COOP AGRARIA CAFETALERA SATIPO LTDA | C6: JUNIN | D6: 4801984.1 | E6: 0 | F6: =IFERROR(SCORECARDS!H5,"") | G6: =IFERROR(MATRIZ_174!U5,0) | H6: 0 | I6: =IFERROR(SCORECARDS!I5,"") | J6: =IFERROR(SCORECARDS!J5,"") | K6: 0 | L6: 0 | M6: 0 | N6: 0 | O6: 0 | P6: =IFERROR(F6,0) | Q6: =IFERROR(SQRT(G6*H6),0) | R6: =IFERROR((I6+J6+L6)/3,0) | S6: =IFERROR((J6+F6)/2,0) | T6: =IFERROR((K6+M6+MATRIZ_174!O5)/3,0) | U6: =IFERROR(MIN(100,ROUND(MATRIZ_174!M5,1)),0) | V6: =IFERROR(IF(E6=0,50,E6),0) | W6: =IFERROR(IF(MATRIZ_174!R5=0,65,IF(MATRIZ_174!R5/MATRIZ_174!Q5>=2,35,IF(MATRIZ_174!R5/MATRIZ_174!Q5>=0.5,50,65))),65) | X6: =IF(MATRIZ_174!O5=0,70,30) | Y6: =IF(OR(MATRIZ_174!P5="ASOCIACION",MATRIZ_174!P5="PENDIENTE"),65,40) | Z6: =IFERROR(ROUND(AVERAGE(P6,Q6,R6,S6,T6),1),0) | AA6: =IFERROR(ROUND(AVERAGE(U6,V6,W6,X6,Y6),1),0) | AB6: =IFERROR(ROUND(AA6*(1-Z6/100),1),0) | AC6: =IF(AND(Z6>=50,AA6<50),"🟢 Resilientes",IF(AND(Z6>=50,AA6>=50),"🟠 Expuestas Adaptables",IF(AND(Z6<50,AA6<50),"⬜ Riesgo Latente","🔴 Riesgo Crítico"))) | AD6: =IF(G6=0,"🚫 Inh. vigente OSCE","") | AE6: =IFERROR(MATRIZ_174!W5,0) | AF6: =IFERROR(MATRIZ_174!X5,0) | AG6: =IFERROR(MATRIZ_174!Y5,0) | AH6: =IFERROR(MATRIZ_174!Z5,0) | AI6: =IFERROR(MATRIZ_174!AP5,"N/A") | AJ6: =IFERROR(MATRIZ_174!AO5,"N/A") | AK6: =IFERROR(ROUND(POWER((E6*F6*G6*H6*I6*J6*K6),1/7)*0.875+((L6+M6)/2)*0.125,1),"N/A") | AL6: =IFERROR(IF(OR(AK6="N/A",AI6="N/A"),"N/A",ROUND(0.7*AK6+0.3*AI6*100,1)),"N/A")
A7: 20132489824 | B7: COOPERATIVA AGRARIA CAFETALERA CHANCAMAYO LTDA. N° 008-B-VII | C7: CUSCO | D7: 0 | E7: 0 | F7: =IFERROR(SCORECARDS!H6,"") | G7: =IFERROR(MATRIZ_174!U6,0) | H7: 0 | I7: =IFERROR(SCORECARDS!I6,"") | J7: =IFERROR(SCORECARDS!J6,"") | K7: 0 | L7: 0 | M7: 0 | N7: 0 | O7: 0 | P7: =IFERROR(F7,0) | Q7: =IFERROR(SQRT(G7*H7),0) | R7: =IFERROR((I7+J7+L7)/3,0) | S7: =IFERROR((J7+F7)/2,0) | T7: =IFERROR((K7+M7+MATRIZ_174!O6)/3,0) | U7: =IFERROR(MIN(100,ROUND(MATRIZ_174!M6,1)),0) | V7: =IFERROR(IF(E7=0,50,E7),0) | W7: =IFERROR(IF(MATRIZ_174!R6=0,65,IF(MATRIZ_174!R6/MATRIZ_174!Q6>=2,35,IF(MATRIZ_174!R6/MATRIZ_174!Q6>=0.5,50,65))),65) | X7: =IF(MATRIZ_174!O6=0,70,30) | Y7: =IF(OR(MATRIZ_174!P6="ASOCIACION",MATRIZ_174!P6="PENDIENTE"),65,40) | Z7: =IFERROR(ROUND(AVERAGE(P7,Q7,R7,S7,T7),1),0) | AA7: =IFERROR(ROUND(AVERAGE(U7,V7,W7,X7,Y7),1),0) | AB7: =IFERROR(ROUND(AA7*(1-Z7/100),1),0) | AC7: =IF(AND(Z7>=50,AA7<50),"🟢 Resilientes",IF(AND(Z7>=50,AA7>=50),"🟠 Expuestas Adaptables",IF(AND(Z7<50,AA7<50),"⬜ Riesgo Latente","🔴 Riesgo Crítico"))) | AD7: =IF(G7=0,"🚫 Inh. vigente OSCE","") | AE7: =IFERROR(MATRIZ_174!W6,0) | AF7: =IFERROR(MATRIZ_174!X6,0) | AG7: =IFERROR(MATRIZ_174!Y6,0) | AH7: =IFERROR(MATRIZ_174!Z6,0) | AI7: =IFERROR(MATRIZ_174!AP6,"N/A") | AJ7: =IFERROR(MATRIZ_174!AO6,"N/A") | AK7: =IFERROR(ROUND(POWER((E7*F7*G7*H7*I7*J7*K7),1/7)*0.875+((L7+M7)/2)*0.125,1),"N/A") | AL7: =IFERROR(IF(OR(AK7="N/A",AI7="N/A"),"N/A",ROUND(0.7*AK7+0.3*AI7*100,1)),"N/A")
A8: 20132505455 | B8: COOPERATIVA AGRARIA CAFETALERA AGUILAYOC LTDA. 084 | C8: CUSCO | D8: 0 | E8: 0 | F8: =IFERROR(SCORECARDS!H7,"") | G8: =IFERROR(MATRIZ_174!U7,0) | H8: 0 | I8: =IFERROR(SCORECARDS!I7,"") | J8: =IFERROR(SCORECARDS!J7,"") | K8: 0 | L8: 0 | M8: 0 | N8: 0 | O8: 0 | P8: =IFERROR(F8,0) | Q8: =IFERROR(SQRT(G8*H8),0) | R8: =IFERROR((I8+J8+L8)/3,0) | S8: =IFERROR((J8+F8)/2,0) | T8: =IFERROR((K8+M8+MATRIZ_174!O7)/3,0) | U8: =IFERROR(MIN(100,ROUND(MATRIZ_174!M7,1)),0) | V8: =IFERROR(IF(E8=0,50,E8),0) | W8: =IFERROR(IF(MATRIZ_174!R7=0,65,IF(MATRIZ_174!R7/MATRIZ_174!Q7>=2,35,IF(MATRIZ_174!R7/MATRIZ_174!Q7>=0.5,50,65))),65) | X8: =IF(MATRIZ_174!O7=0,70,30) | Y8: =IF(OR(MATRIZ_174!P7="ASOCIACION",MATRIZ_174!P7="PENDIENTE"),65,40) | Z8: =IFERROR(ROUND(AVERAGE(P8,Q8,R8,S8,T8),1),0) | AA8: =IFERROR(ROUND(AVERAGE(U8,V8,W8,X8,Y8),1),0) | AB8: =IFERROR(ROUND(AA8*(1-Z8/100),1),0) | AC8: =IF(AND(Z8>=50,AA8<50),"🟢 Resilientes",IF(AND(Z8>=50,AA8>=50),"🟠 Expuestas Adaptables",IF(AND(Z8<50,AA8<50),"⬜ Riesgo Latente","🔴 Riesgo Crítico"))) | AD8: =IF(G8=0,"🚫 Inh. vigente OSCE","") | AE8: =IFERROR(MATRIZ_174!W7,0) | AF8: =IFERROR(MATRIZ_174!X7,0) | AG8: =IFERROR(MATRIZ_174!Y7,0) | AH8: =IFERROR(MATRIZ_174!Z7,0) | AI8: =IFERROR(MATRIZ_174!AP7,"N/A") | AJ8: =IFERROR(MATRIZ_174!AO7,"N/A") | AK8: =IFERROR(ROUND(POWER((E8*F8*G8*H8*I8*J8*K8),1/7)*0.875+((L8+M8)/2)*0.125,1),"N/A") | AL8: =IFERROR(IF(OR(AK8="N/A",AI8="N/A"),"N/A",ROUND(0.7*AK8+0.3*AI8*100,1)),"N/A")
A9: 20132509795 | B9: COOPERATIVA AGRARIA CAFETALERA JOSE OLAYA LTDA N° 252 | C9: CUSCO | D9: 1238541.8 | E9: 0 | F9: =IFERROR(SCORECARDS!H8,"") | G9: =IFERROR(MATRIZ_174!U8,0) | H9: 0 | I9: =IFERROR(SCORECARDS!I8,"") | J9: =IFERROR(SCORECARDS!J8,"") | K9: 0 | L9: 0 | M9: 0 | N9: 0 | O9: 0 | P9: =IFERROR(F9,0) | Q9: =IFERROR(SQRT(G9*H9),0) | R9: =IFERROR((I9+J9+L9)/3,0) | S9: =IFERROR((J9+F9)/2,0) | T9: =IFERROR((K9+M9+MATRIZ_174!O8)/3,0) | U9: =IFERROR(MIN(100,ROUND(MATRIZ_174!M8,1)),0) | V9: =IFERROR(IF(E9=0,50,E9),0) | W9: =IFERROR(IF(MATRIZ_174!R8=0,65,IF(MATRIZ_174!R8/MATRIZ_174!Q8>=2,35,IF(MATRIZ_174!R8/MATRIZ_174!Q8>=0.5,50,65))),65) | X9: =IF(MATRIZ_174!O8=0,70,30) | Y9: =IF(OR(MATRIZ_174!P8="ASOCIACION",MATRIZ_174!P8="PENDIENTE"),65,40) | Z9: =IFERROR(ROUND(AVERAGE(P9,Q9,R9,S9,T9),1),0) | AA9: =IFERROR(ROUND(AVERAGE(U9,V9,W9,X9,Y9),1),0) | AB9: =IFERROR(ROUND(AA9*(1-Z9/100),1),0) | AC9: =IF(AND(Z9>=50,AA9<50),"🟢 Resilientes",IF(AND(Z9>=50,AA9>=50),"🟠 Expuestas Adaptables",IF(AND(Z9<50,AA9<50),"⬜ Riesgo Latente","🔴 Riesgo Crítico"))) | AD9: =IF(G9=0,"🚫 Inh. vigente OSCE","") | AE9: =IFERROR(MATRIZ_174!W8,0) | AF9: =IFERROR(MATRIZ_174!X8,0) | AG9: =IFERROR(MATRIZ_174!Y8,0) | AH9: =IFERROR(MATRIZ_174!Z8,0) | AI9: =IFERROR(MATRIZ_174!AP8,"N/A") | AJ9: =IFERROR(MATRIZ_174!AO8,"N/A") | AK9: =IFERROR(ROUND(POWER((E9*F9*G9*H9*I9*J9*K9),1/7)*0.875+((L9+M9)/2)*0.125,1),"N/A") | AL9: =IFERROR(IF(OR(AK9="N/A",AI9="N/A"),"N/A",ROUND(0.7*AK9+0.3*AI9*100,1)),"N/A")
A10: 20132509876 | B10: COOPERATIVA AGRARIA CAFETALERA MARANURA LTDA. 129 | C10: CUSCO | D10: 0 | E10: 0 | F10: =IFERROR(SCORECARDS!H9,"") | G10: =IFERROR(MATRIZ_174!U9,0) | H10: 0 | I10: =IFERROR(SCORECARDS!I9,"") | J10: =IFERROR(SCORECARDS!J9,"") | K10: 0 | L10: 0 | M10: 0 | N10: 0 | O10: 0 | P10: =IFERROR(F10,0) | Q10: =IFERROR(SQRT(G10*H10),0) | R10: =IFERROR((I10+J10+L10)/3,0) | S10: =IFERROR((J10+F10)/2,0) | T10: =IFERROR((K10+M10+MATRIZ_174!O9)/3,0) | U10: =IFERROR(MIN(100,ROUND(MATRIZ_174!M9,1)),0) | V10: =IFERROR(IF(E10=0,50,E10),0) | W10: =IFERROR(IF(MATRIZ_174!R9=0,65,IF(MATRIZ_174!R9/MATRIZ_174!Q9>=2,35,IF(MATRIZ_174!R9/MATRIZ_174!Q9>=0.5,50,65))),65) | X10: =IF(MATRIZ_174!O9=0,70,30) | Y10: =IF(OR(MATRIZ_174!P9="ASOCIACION",MATRIZ_174!P9="PENDIENTE"),65,40) | Z10: =IFERROR(ROUND(AVERAGE(P10,Q10,R10,S10,T10),1),0) | AA10: =IFERROR(ROUND(AVERAGE(U10,V10,W10,X10,Y10),1),0) | AB10: =IFERROR(ROUND(AA10*(1-Z10/100),1),0) | AC10: =IF(AND(Z10>=50,AA10<50),"🟢 Resilientes",IF(AND(Z10>=50,AA10>=50),"🟠 Expuestas Adaptables",IF(AND(Z10<50,AA10<50),"⬜ Riesgo Latente","🔴 Riesgo Crítico"))) | AD10: =IF(G10=0,"🚫 Inh. vigente OSCE","") | AE10: =IFERROR(MATRIZ_174!W9,0) | AF10: =IFERROR(MATRIZ_174!X9,0) | AG10: =IFERROR(MATRIZ_174!Y9,0) | AH10: =IFERROR(MATRIZ_174!Z9,0) | AI10: =IFERROR(MATRIZ_174!AP9,"N/A") | AJ10: =IFERROR(MATRIZ_174!AO9,"N/A") | AK10: =IFERROR(ROUND(POWER((E10*F10*G10*H10*I10*J10*K10),1/7)*0.875+((L10+M10)/2)*0.125,1),"N/A") | AL10: =IFERROR(IF(OR(AK10="N/A",AI10="N/A"),"N/A",ROUND(0.7*AK10+0.3*AI10*100,1)),"N/A")
A11: 20132517119 | B11: COOPERATIVA AGRARIA CAFETALERA MATEO PUMACAHUA LTDA N° 185 | C11: CUSCO | D11: 0 | E11: 0 | F11: =IFERROR(SCORECARDS!H10,"") | G11: =IFERROR(MATRIZ_174!U10,0) | H11: 0 | I11: =IFERROR(SCORECARDS!I10,"") | J11: =IFERROR(SCORECARDS!J10,"") | K11: 0 | L11: 0 | M11: 0 | N11: 0 | O11: 0 | P11: =IFERROR(F11,0) | Q11: =IFERROR(SQRT(G11*H11),0) | R11: =IFERROR((I11+J11+L11)/3,0) | S11: =IFERROR((J11+F11)/2,0) | T11: =IFERROR((K11+M11+MATRIZ_174!O10)/3,0) | U11: =IFERROR(MIN(100,ROUND(MATRIZ_174!M10,1)),0) | V11: =IFERROR(IF(E11=0,50,E11),0) | W11: =IFERROR(IF(MATRIZ_174!R10=0,65,IF(MATRIZ_174!R10/MATRIZ_174!Q10>=2,35,IF(MATRIZ_174!R10/MATRIZ_174!Q10>=0.5,50,65))),65) | X11: =IF(MATRIZ_174!O10=0,70,30) | Y11: =IF(OR(MATRIZ_174!P10="ASOCIACION",MATRIZ_174!P10="PENDIENTE"),65,40) | Z11: =IFERROR(ROUND(AVERAGE(P11,Q11,R11,S11,T11),1),0) | AA11: =IFERROR(ROUND(AVERAGE(U11,V11,W11,X11,Y11),1),0) | AB11: =IFERROR(ROUND(AA11*(1-Z11/100),1),0) | AC11: =IF(AND(Z11>=50,AA11<50),"🟢 Resilientes",IF(AND(Z11>=50,AA11>=50),"🟠 Expuestas Adaptables",IF(AND(Z11<50,AA11<50),"⬜ Riesgo Latente","🔴 Riesgo Crítico"))) | AD11: =IF(G11=0,"🚫 Inh. vigente OSCE","") | AE11: =IFERROR(MATRIZ_174!W10,0) | AF11: =IFERROR(MATRIZ_174!X10,0) | AG11: =IFERROR(MATRIZ_174!Y10,0) | AH11: =IFERROR(MATRIZ_174!Z10,0) | AI11: =IFERROR(MATRIZ_174!AP10,"N/A") | AJ11: =IFERROR(MATRIZ_174!AO10,"N/A") | AK11: =IFERROR(ROUND(POWER((E11*F11*G11*H11*I11*J11*K11),1/7)*0.875+((L11+M11)/2)*0.125,1),"N/A") | AL11: =IFERROR(IF(OR(AK11="N/A",AI11="N/A"),"N/A",ROUND(0.7*AK11+0.3*AI11*100,1)),"N/A")
A12: 20136201132 | B12: COOPERATIVA AGRARIA CAFETALERA ALTO URUBAMBA LTDA N° 239 | C12: CUSCO | D12: 0 | E12: 0 | F12: =IFERROR(SCORECARDS!H11,"") | G12: =IFERROR(MATRIZ_174!U11,0) | H12: 0 | I12: =IFERROR(SCORECARDS!I11,"") | J12: =IFERROR(SCORECARDS!J11,"") | K12: 0 | L12: 0 | M12: 0 | N12: 0 | O12: 0 | P12: =IFERROR(F12,0) | Q12: =IFERROR(SQRT(G12*H12),0) | R12: =IFERROR((I12+J12+L12)/3,0) | S12: =IFERROR((J12+F12)/2,0) | T12: =IFERROR((K12+M12+MATRIZ_174!O11)/3,0) | U12: =IFERROR(MIN(100,ROUND(MATRIZ_174!M11,1)),0) | V12: =IFERROR(IF(E12=0,50,E12),0) | W12: =IFERROR(IF(MATRIZ_174!R11=0,65,IF(MATRIZ_174!R11/MATRIZ_174!Q11>=2,35,IF(MATRIZ_174!R11/MATRIZ_174!Q11>=0.5,50,65))),65) | X12: =IF(MATRIZ_174!O11=0,70,30) | Y12: =IF(OR(MATRIZ_174!P11="ASOCIACION",MATRIZ_174!P11="PENDIENTE"),65,40) | Z12: =IFERROR(ROUND(AVERAGE(P12,Q12,R12,S12,T12),1),0) | AA12: =IFERROR(ROUND(AVERAGE(U12,V12,W12,X12,Y12),1),0) | AB12: =IFERROR(ROUND(AA12*(1-Z12/100),1),0) | AC12: =IF(AND(Z12>=50,AA12<50),"🟢 Resilientes",IF(AND(Z12>=50,AA12>=50),"🟠 Expuestas Adaptables",IF(AND(Z12<50,AA12<50),"⬜ Riesgo Latente","🔴 Riesgo Crítico"))) | AD12: =IF(G12=0,"🚫 Inh. vigente OSCE","") | AE12: =IFERROR(MATRIZ_174!W11,0) | AF12: =IFERROR(MATRIZ_174!X11,0) | AG12: =IFERROR(MATRIZ_174!Y11,0) | AH12: =IFERROR(MATRIZ_174!Z11,0) | AI12: =IFERROR(MATRIZ_174!AP11,"N/A") | AJ12: =IFERROR(MATRIZ_174!AO11,"N/A") | AK12: =IFERROR(ROUND(POWER((E12*F12*G12*H12*I12*J12*K12),1/7)*0.875+((L12+M12)/2)*0.125,1),"N/A") | AL12: =IFERROR(IF(OR(AK12="N/A",AI12="N/A"),"N/A",ROUND(0.7*AK12+0.3*AI12*100,1)),"N/A")
A13: 20136201213 | B13: CENTRAL DE COOPERATIVAS AGRARIAS CAFETALERAS COCLA LTDA. N° | C13: CUSCO | D13: 894391.27 | E13: 0 | F13: =IFERROR(SCORECARDS!H12,"") | G13: =IFERROR(MATRIZ_174!U12,0) | H13: 0 | I13: =IFERROR(SCORECARDS!I12,"") | J13: =IFERROR(SCORECARDS!J12,"") | K13: 0 | L13: 0 | M13: 0 | N13: 0 | O13: 0 | P13: =IFERROR(F13,0) | Q13: =IFERROR(SQRT(G13*H13),0) | R13: =IFERROR((I13+J13+L13)/3,0) | S13: =IFERROR((J13+F13)/2,0) | T13: =IFERROR((K13+M13+MATRIZ_174!O12)/3,0) | U13: =IFERROR(MIN(100,ROUND(MATRIZ_174!M12,1)),0) | V13: =IFERROR(IF(E13=0,50,E13),0) | W13: =IFERROR(IF(MATRIZ_174!R12=0,65,IF(MATRIZ_174!R12/MATRIZ_174!Q12>=2,35,IF(MATRIZ_174!R12/MATRIZ_174!Q12>=0.5,50,65))),65) | X13: =IF(MATRIZ_174!O12=0,70,30) | Y13: =IF(OR(MATRIZ_174!P12="ASOCIACION",MATRIZ_174!P12="PENDIENTE"),65,40) | Z13: =IFERROR(ROUND(AVERAGE(P13,Q13,R13,S13,T13),1),0) | AA13: =IFERROR(ROUND(AVERAGE(U13,V13,W13,X13,Y13),1),0) | AB13: =IFERROR(ROUND(AA13*(1-Z13/100),1),0) | AC13: =IF(AND(Z13>=50,AA13<50),"🟢 Resilientes",IF(AND(Z13>=50,AA13>=50),"🟠 Expuestas Adaptables",IF(AND(Z13<50,AA13<50),"⬜ Riesgo Latente","🔴 Riesgo Crítico"))) | AD13: =IF(G13=0,"🚫 Inh. vigente OSCE","") | AE13: =IFERROR(MATRIZ_174!W12,0) | AF13: =IFERROR(MATRIZ_174!X12,0) | AG13: =IFERROR(MATRIZ_174!Y12,0) | AH13: =IFERROR(MATRIZ_174!Z12,0) | AI13: =IFERROR(MATRIZ_174!AP12,"N/A") | AJ13: =IFERROR(MATRIZ_174!AO12,"N/A") | AK13: =IFERROR(ROUND(POWER((E13*F13*G13*H13*I13*J13*K13),1/7)*0.875+((L13+M13)/2)*0.125,1),"N/A") | AL13: =IFERROR(IF(OR(AK13="N/A",AI13="N/A"),"N/A",ROUND(0.7*AK13+0.3*AI13*100,1)),"N/A")
A14: 20140292657 | B14: COOPERATIVA AGRARIA CAFETALERA CCOCHAPAMPA LTDA. | C14: CUSCO | D14: 0 | E14: 0 | F14: =IFERROR(SCORECARDS!H13,"") | G14: =IFERROR(MATRIZ_174!U13,0) | H14: 0 | I14: =IFERROR(SCORECARDS!I13,"") | J14: =IFERROR(SCORECARDS!J13,"") | K14: 0 | L14: 0 | M14: 0 | N14: 0 | O14: 0 | P14: =IFERROR(F14,0) | Q14: =IFERROR(SQRT(G14*H14),0) | R14: =IFERROR((I14+J14+L14)/3,0) | S14: =IFERROR((J14+F14)/2,0) | T14: =IFERROR((K14+M14+MATRIZ_174!O13)/3,0) | U14: =IFERROR(MIN(100,ROUND(MATRIZ_174!M13,1)),0) | V14: =IFERROR(IF(E14=0,50,E14),0) | W14: =IFERROR(IF(MATRIZ_174!R13=0,65,IF(MATRIZ_174!R13/MATRIZ_174!Q13>=2,35,IF(MATRIZ_174!R13/MATRIZ_174!Q13>=0.5,50,65))),65) | X14: =IF(MATRIZ_174!O13=0,70,30) | Y14: =IF(OR(MATRIZ_174!P13="ASOCIACION",MATRIZ_174!P13="PENDIENTE"),65,40) | Z14: =IFERROR(ROUND(AVERAGE(P14,Q14,R14,S14,T14),1),0) | AA14: =IFERROR(ROUND(AVERAGE(U14,V14,W14,X14,Y14),1),0) | AB14: =IFERROR(ROUND(AA14*(1-Z14/100),1),0) | AC14: =IF(AND(Z14>=50,AA14<50),"🟢 Resilientes",IF(AND(Z14>=50,AA14>=50),"🟠 Expuestas Adaptables",IF(AND(Z14<50,AA14<50),"⬜ Riesgo Latente","🔴 Riesgo Crítico"))) | AD14: =IF(G14=0,"🚫 Inh. vigente OSCE","") | AE14: =IFERROR(MATRIZ_174!W13,0) | AF14: =IFERROR(MATRIZ_174!X13,0) | AG14: =IFERROR(MATRIZ_174!Y13,0) | AH14: =IFERROR(MATRIZ_174!Z13,0) | AI14: =IFERROR(MATRIZ_174!AP13,"N/A") | AJ14: =IFERROR(MATRIZ_174!AO13,"N/A") | AK14: =IFERROR(ROUND(POWER((E14*F14*G14*H14*I14*J14*K14),1/7)*0.875+((L14+M14)/2)*0.125,1),"N/A") | AL14: =IFERROR(IF(OR(AK14="N/A",AI14="N/A"),"N/A",ROUND(0.7*AK14+0.3*AI14*100,1)),"N/A")
A15: 20143692010 | B15: COOPERATIVA AGRARIA EL QUINACHO LTDA. N° 078 | C15: AYACUCHO | D15: 2015347.3 | E15: 0 | F15: =IFERROR(SCORECARDS!H14,"") | G15: =IFERROR(MATRIZ_174!U14,0) | H15: 0 | I15: =IFERROR(SCORECARDS!I14,"") | J15: =IFERROR(SCORECARDS!J14,"") | K15: 0 | L15: 0 | M15: 0 | N15: 0 | O15: 0 | P15: =IFERROR(F15,0) | Q15: =IFERROR(SQRT(G15*H15),0) | R15: =IFERROR((I15+J15+L15)/3,0) | S15: =IFERROR((J15+F15)/2,0) | T15: =IFERROR((K15+M15+MATRIZ_174!O14)/3,0) | U15: =IFERROR(MIN(100,ROUND(MATRIZ_174!M14,1)),0) | V15: =IFERROR(IF(E15=0,50,E15),0) | W15: =IFERROR(IF(MATRIZ_174!R14=0,65,IF(MATRIZ_174!R14/MATRIZ_174!Q14>=2,35,IF(MATRIZ_174!R14/MATRIZ_174!Q14>=0.5,50,65))),65) | X15: =IF(MATRIZ_174!O14=0,70,30) | Y15: =IF(OR(MATRIZ_174!P14="ASOCIACION",MATRIZ_174!P14="PENDIENTE"),65,40) | Z15: =IFERROR(ROUND(AVERAGE(P15,Q15,R15,S15,T15),1),0) | AA15: =IFERROR(ROUND(AVERAGE(U15,V15,W15,X15,Y15),1),0) | AB15: =IFERROR(ROUND(AA15*(1-Z15/100),1),0) | AC15: =IF(AND(Z15>=50,AA15<50),"🟢 Resilientes",IF(AND(Z15>=50,AA15>=50),"🟠 Expuestas Adaptables",IF(AND(Z15<50,AA15<50),"⬜ Riesgo Latente","🔴 Riesgo Crítico"))) | AD15: =IF(G15=0,"🚫 Inh. vigente OSCE","") | AE15: =IFERROR(MATRIZ_174!W14,0) | AF15: =IFERROR(MATRIZ_174!X14,0) | AG15: =IFERROR(MATRIZ_174!Y14,0) | AH15: =IFERROR(MATRIZ_174!Z14,0) | AI15: =IFERROR(MATRIZ_174!AP14,"N/A") | AJ15: =IFERROR(MATRIZ_174!AO14,"N/A") | AK15: =IFERROR(ROUND(POWER((E15*F15*G15*H15*I15*J15*K15),1/7)*0.875+((L15+M15)/2)*0.125,1),"N/A") | AL15: =IFERROR(IF(OR(AK15="N/A",AI15="N/A"),"N/A",ROUND(0.7*AK15+0.3*AI15*100,1)),"N/A")
... A177: 20612331821 | B177: ASOCIACIÓN DE MUJERES LAS FLORES DE LUYA | C177: AMAZONAS | D177: 0 | E177: 0 | F177: =IFERROR(SCORECARDS!H176,"") | G177: =IFERROR(MATRIZ_174!U176,0) | H177: 0 | I177: =IFERROR(SCORECARDS!I176,"") | J177: =IFERROR(SCORECARDS!J176,"") | K177: 0 | L177: 0 | M177: 0 | N177: 0 | O177: 0 | P177: =IFERROR(F177,0) | Q177: =IFERROR(SQRT(G177*H177),0) | R177: =IFERROR((I177+J177+L177)/3,0) | S177: =IFERROR((J177+F177)/2,0) | T177: =IFERROR((K177+M177+MATRIZ_174!O176)/3,0) | U177: =IFERROR(MIN(100,ROUND(MATRIZ_174!M176,1)),0) | V177: =IFERROR(IF(E177=0,50,E177),0) | W177: =IFERROR(IF(MATRIZ_174!R176=0,65,IF(MATRIZ_174!R176/MATRIZ_174!Q176>=2,35,IF(MATRIZ_174!R176/MATRIZ_174!Q176>=0.5,50,65))),65) | X177: =IF(MATRIZ_174!O176=0,70,30) | Y177: =IF(OR(MATRIZ_174!P176="ASOCIACION",MATRIZ_174!P176="PENDIENTE"),65,40) | Z177: =IFERROR(ROUND(AVERAGE(P177,Q177,R177,S177,T177),1),0) | AA177: =IFERROR(ROUND(AVERAGE(U177,V177,W177,X177,Y177),1),0) | AB177: =IFERROR(ROUND(AA177*(1-Z177/100),1),0) | AC177: =IF(AND(Z177>=50,AA177<50),"🟢 Resilientes",IF(AND(Z177>=50,AA177>=50),"🟠 Expuestas Adaptables",IF(AND(Z177<50,AA177<50),"⬜ Riesgo Latente","🔴 Riesgo Crítico"))) | AD177: =IF(G177=0,"🚫 Inh. vigente OSCE","") | AE177: =IFERROR(MATRIZ_174!W176,0) | AF177: =IFERROR(MATRIZ_174!X176,0) | AG177: =IFERROR(MATRIZ_174!Y176,0) | AH177: =IFERROR(MATRIZ_174!Z176,0) | AI177: =IFERROR(MATRIZ_174!AP176,"N/A") | AJ177: =IFERROR(MATRIZ_174!AO176,"N/A") | AK177: =IFERROR(ROUND(POWER((E177*F177*G177*H177*I177*J177*K177),1/7)*0.875+((L177+M177)/2)*0.125,1),"N/A") | AL177: =IFERROR(IF(OR(AK177="N/A",AI177="N/A"),"N/A",ROUND(0.7*AK177+0.3*AI177*100,1)),"N/A")
A178: PROMEDIO MUESTRAL | Z178: =IFERROR(AVERAGE(Z4:Z177),"—") | AA178: =IFERROR(AVERAGE(AA4:AA177),"—") | AB178: =IFERROR(AVERAGE(AB4:AB177),"—") | AC178: n = 174 organizaciones | AL178: =IFERROR(AVERAGE(AL4:AL177),"—")
A180: METODOLOGÍA ISCAM | ISA-EUDR = 0.875×(D1×D2×...×D7)^(1/7) + 0.125×(D8+D9)/2 | ISA-PV = Promedio(D12:D15) | ISA-Completo = 0.70×ISA-EUDR + 0.30×ISA-PV | IP = Promedio(IP1..IP5): IP1=D2, IP2=√(D3×D4), IP3=(D5+D6+D8)/3, IP4=(D6+D2)/2, IP5=(D7+D9+Cert)/3 | IV = Promedio(IV1..IV5): IV1=ISA-PV×50, IV2=D1(base=50), IV3=ha>0?→65:35, IV4=cert=0?→70:30, IV5=tipo Asoc?→65:40 | RE = IV×(1−IP/100) | Corte 2×2: 50 | █ GRIS=pendiente Inst.2 █ AZUL=Datos llenos █ NARANJA=IV █ ROJO=RE █ VERDE=Ambiental █ OSCURO=ISA

Sheet PONDERADORES
A1: BLOQUE DE SUPUESTOS — PONDERACIONES DEL ÍNDICE PVE
A2: LEYENDA DE COLORES
A3: 🔵 Azul | B3: Input hardcoded — valor primario, editable
A4: ⚫ Negro | B4: Fórmula calculada — no editar manualmente
A5: 🟡 Amarillo | B5: Input editable — cambiar ponderación aquí
A6: 🟢 Verde | B6: Resultado positivo (cumple)
A7: 🔴 Rojo | B7: Resultado negativo (no cumple)
A8: ⬜ Gris | B8: Dato pendiente de capturar
A10: PONDERACIONES — MODIFICAR SOLO LAS CELDAS AMARILLAS
A11: Componente | B11: Dimensión EUDR | C11: Variable | D11: Ponderación (%)
A12: EXP_UE | B12: D7 / Exposición UE | C12: % FOB exportado a UE sobre FOB total | D12: 25
A13: TRAZA | B13: D2 / Trazabilidad | C13: ¿Existe vínculo lote → parcela con coords? | D13: 20
A14: DILIG | B14: D5 / Debida diligencia | C14: ¿Existe proceso de evaluación de riesgo? | D14: 15
A15: CAPAC | B15: D6 / Capacidad digital | C15: ¿Tiene personal dedicado a datos? | D15: 10
A16: PRESION | B16: D7 / Presión comprador | C16: ¿Comprador UE exige EUDR? | D16: 15
A17: CERTIF | B17: D8 / Certificaciones (variable Cert — NO confundir con D8 Gobernanza de ISCAM_Score) | C17: Score de certificaciones vigentes (Org + Ftrade) | D17: 10
A18: PPWR | B18: D14 / Envases PPWR — NO confundir con D14 Economía Circular de ISCAM_Score | C18: ¿Usa sacos reutilizables o certificados? | D18: 5
A19: TOTAL | D19: =SUM(D12:D18)
A21: ⚠ El TOTAL debe sumar 100. Si lo ajustas, el Índice PVE en SCORECARDS se recalcula automáticamente.
A23: VERSION ISCAM (2026-10-12) — Pesos mostrados para transparencia (fijos, no editables)
A24: ISA-EUDR e ISA-PV usan pesos FIJOS (87.5%/12.5% y 70%/30%). IP/IV pesan 20% cada sub-dim.
A25: SUBDIM | B25: FÓRMULA | C25: PESO
A26: ISA-EUDR | B26: Geom(D1:D7)^(1/7)×0.875 + ((D8+D9)/2)×0.125 — ver ISCAM_Score!AK | C26: 100%
A28: ISA-PactoVerde | B28: AVG(D12:D15) — ver ISCAM_Score!AI y MATRIZ_174!AP | C28: 100%
A30: ISA-Completo | B30: 0.70×ISA-EUDR + 0.30×ISA-PV — ver ISCAM_Score!AL | C30: 100%
A32: IP1 | B32: =D2 — ver ISCAM_Score!P | C32: 20%
A33: IP2 | B33: SQRT(D3 × D4) — ver ISCAM_Score!Q | C33: 20%
A34: IP3 | B34: (D5 + D6 + D8) / 3 — ver ISCAM_Score!R | C34: 20%
A35: IP4 | B35: (D6 + D2) / 2 — ver ISCAM_Score!S | C35: 20%
A36: IP5 | B36: (D7 + D9 + Cert) / 3 — ver ISCAM_Score!T | C36: 20%
A37: IP (total) | B37: AVG(IP1:IP5) — ver ISCAM_Score!Z | C37: 100%
A39: IV1 | B39: Exposición UE = % FOB UE (MATRIZ_174!M) — ver ISCAM_Score!U | C39: 20%
A40: IV2 | B40: D1 (base 50 si D1=0) — ver ISCAM_Score!V | C40: 20%
A41: IV3 | B41: Tamaño de parcela ha/socio (Q/R); sin dato → 65 — ver ISCAM_Score!W | C41: 20%
A42: IV4 | B42: Certificación: Cert=0 → 70 / Cert>0 → 30 — ver ISCAM_Score!X | C42: 20%
A43: IV5 | B43: Tipo de organización (PENDIENTE/Asociación → 65) — ver ISCAM_Score!Y | C43: 20%
A44: IV (total) | B44: AVG(IV1:IV5) — ver ISCAM_Score!AA | C44: 100%
A46: RE | C46: —
A47: Cuadrante 2×2 | B47: IP≥50 vs <50 × IV≥50 vs <50 | C47: Corte=50
A48: NOTAS 2026-10-14: | B48: IV1–IV5 son proxies documentados mientras se ingesta el Instrumento 2; sus definiciones de diseño usan B0.7/P1/P1b/P4/D7.26a (IV1), B0.4/B0.10/B0.11/B0.13/B0.14 (IV3) y B0.12 + D3.14i (IV4/IV5).
...

Sheet MATRIZ_174
A1: MATRIZ 174 — Datos existentes de organizaciones | W1: D12 | X1: D13 | Y1: D14 | Z1: D15 | AA1: P1 | AB1: P2 | AC1: P3 | AD1: P4 | AE1: P5 | AF1: P6 | AG1: P7 | AH1: P8 | AI1: P9 | AJ1: P10 | AK1: P11 | AL1: P12 | AM1: P13 | AN1: P14 | AO1: Bloque P Score (0-1) | AP1: ISA-PactoVerde (0-1)
A2: RUC | B2: Razón Social (SUNAT) | C2: Depto | D2: Producto | E2: FOB Total USD | F2: N° DUAs | G2: Exporta | H2: Cert. Orgánica | I2: Cert. Fairtrade | J2: Estado SUNAT | K2: Avance EUDR | L2: FOB UE USD | M2: % UE/FOB | N2: HS Code principal | O2: Score Cert (0-1) | P2: Tipo org. | Q2: N° aprox. socios | R2: Hectáreas aprox. | S2: PVE Score (0-100) | T2: Clasificación | U2: D3 Score (OSCE) | V2: D3 Observación | W2: D12 — Huella Carbono 0=Sin medición 1=En curso (ha conocidas) 2=Certificado ───────────────────── NOTA: Valor actual = proxy FAO/IPCC (ha × factor IPCC/FAO por cultivo). Reemplazar tras Instrumento 2 Q40-Q44. | X2: Reporte Sostenibilidad (D13) 0=No, 1=En curso, 2=Publicado | Y2: Economía Circular (D14) 0=No, 1=En transición, 2=Avanzado | Z2: Fitosanitario/LMR (D15) 0=No verificado, 1=En monitoreo, 2=Cumple UE | AA2: P1 — Productividad (USD/ha/año) | AB2: P2 — Ingreso neto (USD/ha) | AC2: P3 — % socios con acceso crédito | AD2: P4 — Gender score (% muj. en org.) | AE2: P5 — Formalización laboral (%) | AF2: P6 — Capacitación/año/persona | AG2: P7 — Tasa retención socios (%) | AH2: P8 — Diversificación ingresos (%) | AI2: P9 — Acceso mercados premium (%) | AJ2: P10 — Inversión EUDR (USD/año) | AK2: P11 — Score trazabilidad (%) | AL2: P12 — Quejas resueltas (%) | AM2: P13 — Energía renovable (%) | AN2: P14 — Residuos gestionados (%) | AO2: P_Global — Promedio P1:P14 (0=None, 1=满分) | AP2: ISA-PactoVerde = AVG(D12:D15)/2 0=Nada, 2=Certificado
A3: 20118578415 | B3: CENT.DE COOP.AGR. CAF.VALLES SANDIA LTDA | C3: PUNO | D3: CAFÉ | E3: 5107246.6 | F3: 38 | G3: SI | H3: nan | I3: nan | J3: ACTIVO | K3: nan | L3: 2553623.3 | M3: =IF(E3>0,ROUND(L3/E3*100,1),0) | N3: PENDIENTE | O3: =IF(H3="SI",1,0)*0.6+IF(I3="SI",1,0)*0.4 | P3: PENDIENTE | S3: =IFERROR(SCORECARDS!C3,"") | T3: =IF(NOT(ISNUMBER(S3)),"—",IF(S3<34,"🔴 Crítico",IF(S3<67,"🟡 Vulnerable","🟢 Preparado"))) | U3: 1 | V3: Sin hallazgos OSCE / OEFA | W3: 1 | X3: 0 | Y3: 0 | Z3: 0 | AA3: 0 | AB3: 0 | AC3: 0 | AD3: 0 | AE3: 0 | AF3: 0 | AG3: 0 | AH3: 0 | AI3: 0 | AJ3: 0 | AK3: 0 | AL3: 0 | AM3: 0 | AN3: 0 | AO3: =IFERROR(AVERAGE(AA3,AB3,AC3,AD3,AE3,AF3,AG3,AH3,AI3,AJ3,AK3,AL3,AM3,AN3),"N/A") | AP3: =IFERROR(AVERAGE(W3,X3,Y3,Z3)/2,"N/A")
A4: 20129156083 | B4: COOP AGRARIA CAFET VALLE RIO APURIMAC | C4: AYACUCHO | D4: CACAO | E4: 0 | G4: NO | H4: nan | I4: nan | J4: ACTIVO | K4: nan | L4: 0 | M4: =IF(E4>0,ROUND(L4/E4*100,1),0) | N4: PENDIENTE | O4: =IF(H4="SI",1,0)*0.6+IF(I4="SI",1,0)*0.4 | P4: PENDIENTE | S4: =IFERROR(SCORECARDS!C4,"") | T4: =IF(NOT(ISNUMBER(S4)),"—",IF(S4<34,"🔴 Crítico",IF(S4<67,"🟡 Vulnerable","🟢 Preparado"))) | W4: 0 | X4: 0 | Y4: 0 | Z4: 0 | AA4: 0 | AB4: 0 | AC4: 0 | AD4: 0 | AE4: 0 | AF4: 0 | AG4: 0 | AH4: 0 | AI4: 0 | AJ4: 0 | AK4: 0 | AL4: 0 | AM4: 0 | AN4: 0 | AO4: =IFERROR(AVERAGE(AA4,AB4,AC4,AD4,AE4,AF4,AG4,AH4,AI4,AJ4,AK4,AL4,AM4,AN4),"N/A") | AP4: =IFERROR(AVERAGE(W4,X4,Y4,Z4)/2,"N/A")
A5: 20129529530 | B5: COOP AGRARIA CAFETALERA SATIPO LTDA | C5: JUNIN | E5: 9603968.1 | F5: 41 | G5: SI | H5: nan | I5: nan | J5: ACTIVO | K5: nan | L5: 4801984.1 | M5: =IF(E5>0,ROUND(L5/E5*100,1),0) | N5: PENDIENTE | O5: =IF(H5="SI",1,0)*0.6+IF(I5="SI",1,0)*0.4 | P5: PENDIENTE | S5: =IFERROR(SCORECARDS!C5,"") | T5: =IF(NOT(ISNUMBER(S5)),"—",IF(S5<34,"🔴 Crítico",IF(S5<67,"🟡 Vulnerable","🟢 Preparado"))) | U5: 1 | V5: Sin hallazgos OSCE / OEFA | W5: 1 | X5: 0 | Y5: 0 | Z5: 0 | AA5: 0 | AB5: 0 | AC5: 0 | AD5: 0 | AE5: 0 | AF5: 0 | AG5: 0 | AH5: 0 | AI5: 0 | AJ5: 0 | AK5: 0 | AL5: 0 | AM5: 0 | AN5: 0 | AO5: =IFERROR(AVERAGE(AA5,AB5,AC5,AD5,AE5,AF5,AG5,AH5,AI5,AJ5,AK5,AL5,AM5,AN5),"N/A") | AP5: =IFERROR(AVERAGE(W5,X5,Y5,Z5)/2,"N/A")
A6: 20132489824 | B6: COOPERATIVA AGRARIA CAFETALERA CHANCAMAYO LTDA. N° 008-B-VII | C6: CUSCO | G6: NO | H6: Cer | I6: Vig | J6: ACTIVO | K6: nan | L6: 0 | M6: =IF(E6>0,ROUND(L6/E6*100,1),0) | N6: PENDIENTE | O6: =IF(H6="SI",1,0)*0.6+IF(I6="SI",1,0)*0.4 | P6: PENDIENTE | Q6: 44 | R6: 44 | S6: =IFERROR(SCORECARDS!C6,"") | T6: =IF(NOT(ISNUMBER(S6)),"—",IF(S6<34,"🔴 Crítico",IF(S6<67,"🟡 Vulnerable","🟢 Preparado"))) | W6: 1 | X6: 0 | Y6: 0 | Z6: 0 | AA6: 0 | AB6: 0 | AC6: 0 | AD6: 0 | AE6: 0 | AF6: 0 | AG6: 0 | AH6: 0 | AI6: 0 | AJ6: 0 | AK6: 0 | AL6: 0 | AM6: 0 | AN6: 0 | AO6: =IFERROR(AVERAGE(AA6,AB6,AC6,AD6,AE6,AF6,AG6,AH6,AI6,AJ6,AK6,AL6,AM6,AN6),"N/A") | AP6: =IFERROR(AVERAGE(W6,X6,Y6,Z6)/2,"N/A")
A7: 20132505455 | B7: COOPERATIVA AGRARIA CAFETALERA AGUILAYOC LTDA. 084 | C7: CUSCO | D7: CAFÉ | G7: NO | H7: Cer | I7: nan | J7: ACTIVO | K7: 0.75 | L7: 0 | M7: =IF(E7>0,ROUND(L7/E7*100,1),0) | N7: PENDIENTE | O7: =IF(H7="SI",1,0)*0.6+IF(I7="SI",1,0)*0.4 | P7: PENDIENTE | Q7: 100 | R7: 218 | S7: =IFERROR(SCORECARDS!C7,"") | T7: =IF(NOT(ISNUMBER(S7)),"—",IF(S7<34,"🔴 Crítico",IF(S7<67,"🟡 Vulnerable","🟢 Preparado"))) | W7: 1 | X7: 0 | Y7: 0 | Z7: 0 | AA7: 0 | AB7: 0 | AC7: 0 | AD7: 0 | AE7: 0 | AF7: 0 | AG7: 0 | AH7: 0 | AI7: 0 | AJ7: 0 | AK7: 0 | AL7: 0 | AM7: 0 | AN7: 0 | AO7: =IFERROR(AVERAGE(AA7,AB7,AC7,AD7,AE7,AF7,AG7,AH7,AI7,AJ7,AK7,AL7,AM7,AN7),"N/A") | AP7: =IFERROR(AVERAGE(W7,X7,Y7,Z7)/2,"N/A")
A8: 20132509795 | B8: COOPERATIVA AGRARIA CAFETALERA JOSE OLAYA LTDA N° 252 | C8: CUSCO | D8: CAFÉ | E8: 2477083.5 | F8: 14 | G8: SI | H8: nan | I8: nan | J8: ACTIVO | K8: nan | L8: 1238541.8 | M8: =IF(E8>0,ROUND(L8/E8*100,1),0) | N8: PENDIENTE | O8: =IF(H8="SI",1,0)*0.6+IF(I8="SI",1,0)*0.4 | P8: PENDIENTE | S8: =IFERROR(SCORECARDS!C8,"") | T8: =IF(NOT(ISNUMBER(S8)),"—",IF(S8<34,"🔴 Crítico",IF(S8<67,"🟡 Vulnerable","🟢 Preparado"))) | U8: 1 | V8: Sin hallazgos OSCE / OEFA | W8: 1 | X8: 0 | Y8: 0 | Z8: 0 | AA8: 0 | AB8: 0 | AC8: 0 | AD8: 0 | AE8: 0 | AF8: 0 | AG8: 0 | AH8: 0 | AI8: 0 | AJ8: 0 | AK8: 0 | AL8: 0 | AM8: 0 | AN8: 0 | AO8: =IFERROR(AVERAGE(AA8,AB8,AC8,AD8,AE8,AF8,AG8,AH8,AI8,AJ8,AK8,AL8,AM8,AN8),"N/A") | AP8: =IFERROR(AVERAGE(W8,X8,Y8,Z8)/2,"N/A")
A9: 20132509876 | B9: COOPERATIVA AGRARIA CAFETALERA MARANURA LTDA. 129 | C9: CUSCO | D9: CAFÉ | E9: 1689820.3 | F9: 5 | G9: SI | H9: nan | I9: nan | J9: ACTIVO | K9: nan | L9: 0 | M9: =IF(E9>0,ROUND(L9/E9*100,1),0) | N9: PENDIENTE | O9: =IF(H9="SI",1,0)*0.6+IF(I9="SI",1,0)*0.4 | P9: PENDIENTE | S9: =IFERROR(SCORECARDS!C9,"") | T9: =IF(NOT(ISNUMBER(S9)),"—",IF(S9<34,"🔴 Crítico",IF(S9<67,"🟡 Vulnerable","🟢 Preparado"))) | W9: 0 | X9: 0 | Y9: 0 | Z9: 0 | AA9: 0 | AB9: 0 | AC9: 0 | AD9: 0 | AE9: 0 | AF9: 0 | AG9: 0 | AH9: 0 | AI9: 0 | AJ9: 0 | AK9: 0 | AL9: 0 | AM9: 0 | AN9: 0 | AO9: =IFERROR(AVERAGE(AA9,AB9,AC9,AD9,AE9,AF9,AG9,AH9,AI9,AJ9,AK9,AL9,AM9,AN9),"N/A") | AP9: =IFERROR(AVERAGE(W9,X9,Y9,Z9)/2,"N/A")
A10: 20132517119 | B10: COOPERATIVA AGRARIA CAFETALERA MATEO PUMACAHUA LTDA N° 185 | C10: CUSCO | D10: CAFÉ | E10: 0 | G10: NO | H10: Cer | I10: Fai | J10: ACTIVO | K10: 0.75 | L10: 0 | M10: =IF(E10>0,ROUND(L10/E10*100,1),0) | N10: PENDIENTE | O10: =IF(H10="SI",1,0)*0.6+IF(I10="SI",1,0)*0.4 | P10: PENDIENTE | Q10: 177 | R10: 469 | S10: =IFERROR(SCORECARDS!C10,"") | T10: =IF(NOT(ISNUMBER(S10)),"—",IF(S10<34,"🔴 Crítico",IF(S10<67,"🟡 Vulnerable","🟢 Preparado"))) | W10: 1 | X10: 0 | Y10: 0 | Z10: 0 | AA10: 0 | AB10: 0 | AC10: 0 | AD10: 0 | AE10: 0 | AF10: 0 | AG10: 0 | AH10: 0 | AI10: 0 | AJ10: 0 | AK10: 0 | AL10: 0 | AM10: 0 | AN10: 0 | AO10: =IFERROR(AVERAGE(AA10,AB10,AC10,AD10,AE10,AF10,AG10,AH10,AI10,AJ10,AK10,AL10,AM10,AN10),"N/A") | AP10: =IFERROR(AVERAGE(W10,X10,Y10,Z10)/2,"N/A")
A11: 20136201132 | B11: COOPERATIVA AGRARIA CAFETALERA ALTO URUBAMBA LTDA N° 239 | C11: CUSCO | D11: CAFÉ | E11: 681394.36 | F11: 6 | G11: SI | H11: nan | I11: nan | J11: ACTIVO | K11: nan | L11: 0 | M11: =IF(E11>0,ROUND(L11/E11*100,1),0) | N11: PENDIENTE | O11: =IF(H11="SI",1,0)*0.6+IF(I11="SI",1,0)*0.4 | P11: PENDIENTE | S11: =IFERROR(SCORECARDS!C11,"") | T11: =IF(NOT(ISNUMBER(S11)),"—",IF(S11<34,"🔴 Crítico",IF(S11<67,"🟡 Vulnerable","🟢 Preparado"))) | W11: 0 | X11: 0 | Y11: 0 | Z11: 0 | AA11: 0 | AB11: 0 | AC11: 0 | AD11: 0 | AE11: 0 | AF11: 0 | AG11: 0 | AH11: 0 | AI11: 0 | AJ11: 0 | AK11: 0 | AL11: 0 | AM11: 0 | AN11: 0 | AO11: =IFERROR(AVERAGE(AA11,AB11,AC11,AD11,AE11,AF11,AG11,AH11,AI11,AJ11,AK11,AL11,AM11,AN11),"N/A") | AP11: =IFERROR(AVERAGE(W11,X11,Y11,Z11)/2,"N/A")
A12: 20136201213 | B12: CENTRAL DE COOPERATIVAS AGRARIAS CAFETALERAS COCLA LTDA. N° | C12: CUSCO | D12: CAFÉ | E12: 4445611.6 | F12: 33 | G12: SI | H12: Cer | I12: Fai | J12: ACTIVO | K12: 0.75 | L12: 894391.27 | M12: =IF(E12>0,ROUND(L12/E12*100,1),0) | N12: PENDIENTE | O12: =IF(H12="SI",1,0)*0.6+IF(I12="SI",1,0)*0.4 | P12: PENDIENTE | Q12: 660 | R12: 1670 | S12: =IFERROR(SCORECARDS!C12,"") | T12: =IF(NOT(ISNUMBER(S12)),"—",IF(S12<34,"🔴 Crítico",IF(S12<67,"🟡 Vulnerable","🟢 Preparado"))) | U12: 0.75 | V12: ⚠ 1 infracc. ambiental (OEFA) | W12: 1 | X12: 0 | Y12: 0 | Z12: 0 | AA12: 0 | AB12: 0 | AC12: 0 | AD12: 0 | AE12: 0 | AF12: 0 | AG12: 0 | AH12: 0 | AI12: 0 | AJ12: 0 | AK12: 0 | AL12: 0 | AM12: 0 | AN12: 0 | AO12: =IFERROR(AVERAGE(AA12,AB12,AC12,AD12,AE12,AF12,AG12,AH12,AI12,AJ12,AK12,AL12,AM12,AN12),"N/A") | AP12: =IFERROR(AVERAGE(W12,X12,Y12,Z12)/2,"N/A")
A13: 20140292657 | B13: COOPERATIVA AGRARIA CAFETALERA CCOCHAPAMPA LTDA. | C13: CUSCO | D13: CAFÉ | E13: 0 | G13: NO | H13: Cer | I13: Fa | J13: ACTIVO | K13: 0.75 | L13: 0 | M13: =IF(E13>0,ROUND(L13/E13*100,1),0) | N13: PENDIENTE | O13: =IF(H13="SI",1,0)*0.6+IF(I13="SI",1,0)*0.4 | P13: PENDIENTE | Q13: 49 | R13: 136.9 | S13: =IFERROR(SCORECARDS!C13,"") | T13: =IF(NOT(ISNUMBER(S13)),"—",IF(S13<34,"🔴 Crítico",IF(S13<67,"🟡 Vulnerable","🟢 Preparado"))) | W13: 1 | X13: 0 | Y13: 0 | Z13: 0 | AA13: 0 | AB13: 0 | AC13: 0 | AD13: 0 | AE13: 0 | AF13: 0 | AG13: 0 | AH13: 0 | AI13: 0 | AJ13: 0 | AK13: 0 | AL13: 0 | AM13: 0 | AN13: 0 | AO13: =IFERROR(AVERAGE(AA13,AB13,AC13,AD13,AE13,AF13,AG13,AH13,AI13,AJ13,AK13,AL13,AM13,AN13),"N/A") | AP13: =IFERROR(AVERAGE(W13,X13,Y13,Z13)/2,"N/A")
A14: 20143692010 | B14: COOPERATIVA AGRARIA EL QUINACHO LTDA. N° 078 | C14: AYACUCHO | D14: CACAO | E14: 4030694.7 | F14: 14 | G14: SI | H14: nan | I14: nan | J14: ACTIVO | K14: nan | L14: 2015347.3 | M14: =IF(E14>0,ROUND(L14/E14*100,1),0) | N14: PENDIENTE | O14: =IF(H14="SI",1,0)*0.6+IF(I14="SI",1,0)*0.4 | P14: PENDIENTE | S14: =IFERROR(SCORECARDS!C14,"") | T14: =IF(NOT(ISNUMBER(S14)),"—",IF(S14<34,"🔴 Crítico",IF(S14<67,"🟡 Vulnerable","🟢 Preparado"))) | U14: 1 | V14: Sin hallazgos OSCE / OEFA | W14: 1 | X14: 0 | Y14: 0 | Z14: 0 | AA14: 0 | AB14: 0 | AC14: 0 | AD14: 0 | AE14: 0 | AF14: 0 | AG14: 0 | AH14: 0 | AI14: 0 | AJ14: 0 | AK14: 0 | AL14: 0 | AM14: 0 | AN14: 0 | AO14: =IFERROR(AVERAGE(AA14,AB14,AC14,AD14,AE14,AF14,AG14,AH14,AI14,AJ14,AK14,AL14,AM14,AN14),"N/A") | AP14: =IFERROR(AVERAGE(W14,X14,Y14,Z14)/2,"N/A")
A15: 20145484597 | B15: COOPERATIVA AGRARIA CAFETALERA SAN IGNACIO LTDA. | C15: PUNO | D15: CAFÉ | G15: NO | H15: nan | I15: nan | J15: ACTIVO | K15: nan | L15: 0 | M15: =IF(E15>0,ROUND(L15/E15*100,1),0) | N15: PENDIENTE | O15: =IF(H15="SI",1,0)*0.6+IF(I15="SI",1,0)*0.4 | P15: PENDIENTE | S15: =IFERROR(SCORECARDS!C15,"") | T15: =IF(NOT(ISNUMBER(S15)),"—",IF(S15<34,"🔴 Crítico",IF(S15<67,"🟡 Vulnerable","🟢 Preparado"))) | W15: 0 | X15: 0 | Y15: 0 | Z15: 0 | AA15: 0 | AB15: 0 | AC15: 0 | AD15: 0 | AE15: 0 | AF15: 0 | AG15: 0 | AH15: 0 | AI15: 0 | AJ15: 0 | AK15: 0 | AL15: 0 | AM15: 0 | AN15: 0 | AO15: =IFERROR(AVERAGE(AA15,AB15,AC15,AD15,AE15,AF15,AG15,AH15,AI15,AJ15,AK15,AL15,AM15,AN15),"N/A") | AP15: =IFERROR(AVERAGE(W15,X15,Y15,Z15)/2,"N/A")
A16: 20146696041 | B16: COOP AGRARIA CAFET JOSE GABRIEL CONDORCA | C16: PIURA | D16: CAFÉ | G16: NO | H16: nan | I16: nan | J16: ACTIVO | K16: nan | L16: 0 | M16: =IF(E16>0,ROUND(L16/E16*100,1),0) | N16: PENDIENTE | O16: =IF(H16="SI",1,0)*0.6+IF(I16="SI",1,0)*0.4 | P16: PENDIENTE | S16: =IFERROR(SCORECARDS!C16,"") | T16: =IF(NOT(ISNUMBER(S16)),"—",IF(S16<34,"🔴 Crítico",IF(S16<67,"🟡 Vulnerable","🟢 Preparado"))) | W16: 0 | X16: 0 | Y16: 0 | Z16: 0 | AA16: 0 | AB16: 0 | AC16: 0 | AD16: 0 | AE16: 0 | AF16: 0 | AG16: 0 | AH16: 0 | AI16: 0 | AJ16: 0 | AK16: 0 | AL16: 0 | AM16: 0 | AN16: 0 | AO16: =IFERROR(AVERAGE(AA16,AB16,AC16,AD16,AE16,AF16,AG16,AH16,AI16,AJ16,AK16,AL16,AM16,AN16),"N/A") | AP16: =IFERROR(AVERAGE(W16,X16,Y16,Z16)/2,"N/A")
A17: 20147443120 | B17: COOPERATIVA AGRARIA CAFETALERA TIRIJUAY PAVAYOC LTDA 013-B-V | C17: CUSCO | G17: NO | H17: Cer | I17: Vig | J17: SUSPENSION TEMPORAL | K17: nan | L17: 0 | M17: =IF(E17>0,ROUND(L17/E17*100,1),0) | N17: PENDIENTE | O17: =IF(H17="SI",1,0)*0.6+IF(I17="SI",1,0)*0.4 | P17: PENDIENTE | Q17: 74 | R17: 150 | S17: =IFERROR(SCORECARDS!C17,"") | T17: =IF(NOT(ISNUMBER(S17)),"—",IF(S17<34,"🔴 Crítico",IF(S17<67,"🟡 Vulnerable","🟢 Preparado"))) | W17: 1 | X17: 0 | Y17: 0 | Z17: 0 | AA17: 0 | AB17: 0 | AC17: 0 | AD17: 0 | AE17: 0 | AF17: 0 | AG17: 0 | AH17: 0 | AI17: 0 | AJ17: 0 | AK17: 0 | AL17: 0 | AM17: 0 | AN17: 0 | AO17: =IFERROR(AVERAGE(AA17,AB17,AC17,AD17,AE17,AF17,AG17,AH17,AI17,AJ17,AK17,AL17,AM17,AN17),"N/A") | AP17: =IFERROR(AVERAGE(W17,X17,Y17,Z17)/2,"N/A")
A18: 20166786861 | B18: COMITE CENTRAL DE PRODUCTORES AGROPECUARIOS DE SAN ALEJANDRO | C18: UCAYALI | D18: CACAO | G18: NO | H18: nan | I18: nan | J18: ACTIVO | K18: nan | L18: 0 | M18: =IF(E18>0,ROUND(L18/E18*100,1),0) | N18: PENDIENTE | O18: =IF(H18="SI",1,0)*0.6+IF(I18="SI",1,0)*0.4 | P18: PENDIENTE | S18: =IFERROR(SCORECARDS!C18,"") | T18: =IF(NOT(ISNUMBER(S18)),"—",IF(S18<34,"🔴 Crítico",IF(S18<67,"🟡 Vulnerable","🟢 Preparado"))) | W18: 0 | X18: 0 | Y18: 0 | Z18: 0 | AA18: 0 | AB18: 0 | AC18: 0 | AD18: 0 | AE18: 0 | AF18: 0 | AG18: 0 | AH18: 0 | AI18: 0 | AJ18: 0 | AK18: 0 | AL18: 0 | AM18: 0 | AN18: 0 | AO18: =IFERROR(AVERAGE(AA18,AB18,AC18,AD18,AE18,AF18,AG18,AH18,AI18,AJ18,AK18,AL18,AM18,AN18),"N/A") | AP18: =IFERROR(AVERAGE(W18,X18,Y18,Z18)/2,"N/A")
A19: 20170142773 | B19: COOPERATIVA AGRARIA CAFETALERA BAGUA GRANDE LIMITADA | C19: AMAZONAS | D19: CAFÉ | E19: 9070756.9 | F19: 41 | G19: SI | H19: nan | I19: nan | J19: ACTIVO | K19: nan | L19: 4535378.4 | M19: =IF(E19>0,ROUND(L19/E19*100,1),0) | N19: PENDIENTE | O19: =IF(H19="SI",1,0)*0.6+IF(I19="SI",1,0)*0.4 | P19: PENDIENTE | S19: =IFERROR(SCORECARDS!C19,"") | T19: =IF(NOT(ISNUMBER(S19)),"—",IF(S19<34,"🔴 Crítico",IF(S19<67,"🟡 Vulnerable","🟢 Preparado"))) | U19: 1 | V19: Sin hallazgos OSCE / OEFA | W19: 1 | X19: 0 | Y19: 0 | Z19: 0 | AA19: 0 | AB19: 0 | AC19: 0 | AD19: 0 | AE19: 0 | AF19: 0 | AG19: 0 | AH19: 0 | AI19: 0 | AJ19: 0 | AK19: 0 | AL19: 0 | AM19: 0 | AN19: 0 | AO19: =IFERROR(AVERAGE(AA19,AB19,AC19,AD19,AE19,AF19,AG19,AH19,AI19,AJ19,AK19,AL19,AM19,AN19),"N/A") | AP19: =IFERROR(AVERAGE(W19,X19,Y19,Z19)/2,"N/A")
A20: 20200880448 | B20: COOPERATIVA AGRARIA CAFETALERA JORGE CHAVEZ LTDA | C20: CUSCO | G20: NO | H20: Cer | I20: Vig | J20: ACTIVO | K20: nan | L20: 0 | M20: =IF(E20>0,ROUND(L20/E20*100,1),0) | N20: PENDIENTE | O20: =IF(H20="SI",1,0)*0.6+IF(I20="SI",1,0)*0.4 | P20: PENDIENTE | Q20: 36 | R20: 38 | S20: =IFERROR(SCORECARDS!C20,"") | T20: =IF(NOT(ISNUMBER(S20)),"—",IF(S20<34,"🔴 Crítico",IF(S20<67,"🟡 Vulnerable","🟢 Preparado"))) | W20: 1 | X20: 0 | Y20: 0 | Z20: 0 | AA20: 0 | AB20: 0 | AC20: 0 | AD20: 0 | AE20: 0 | AF20: 0 | AG20: 0 | AH20: 0 | AI20: 0 | AJ20: 0 | AK20: 0 | AL20: 0 | AM20: 0 | AN20: 0 | AO20: =IFERROR(AVERAGE(AA20,AB20,AC20,AD20,AE20,AF20,AG20,AH20,AI20,AJ20,AK20,AL20,AM20,AN20),"N/A") | AP20: =IFERROR(AVERAGE(W20,X20,Y20,Z20)/2,"N/A")
A21: 20352417018 | B21: COOPERATIVA AGRARIA DE CACAOTEROS TECNIFICADOS DE PADRE ABAD | C21: UCAYALI | D21: CACAO | E21: 0 | G21: NO | H21: nan | I21: nan | J21: SUSPENSION TEMPORAL | K21: nan | L21: 0 | M21: =IF(E21>0,ROUND(L21/E21*100,1),0) | N21: PENDIENTE | O21: =IF(H21="SI",1,0)*0.6+IF(I21="SI",1,0)*0.4 | P21: PENDIENTE | S21: =IFERROR(SCORECARDS!C21,"") | T21: =IF(NOT(ISNUMBER(S21)),"—",IF(S21<34,"🔴 Crítico",IF(S21<67,"🟡 Vulnerable","🟢 Preparado"))) | W21: 0 | X21: 0 | Y21: 0 | Z21: 0 | AA21: 0 | AB21: 0 | AC21: 0 | AD21: 0 | AE21: 0 | AF21: 0 | AG21: 0 | AH21: 0 | AI21: 0 | AJ21: 0 | AK21: 0 | AL21: 0 | AM21: 0 | AN21: 0 | AO21: =IFERROR(AVERAGE(AA21,AB21,AC21,AD21,AE21,AF21,AG21,AH21,AI21,AJ21,AK21,AL21,AM21,AN21),"N/A") | AP21: =IFERROR(AVERAGE(W21,X21,Y21,Z21)/2,"N/A")
A22: 20352423921 | B22: COOPERATIVA AGRARIA CAFETALERA DIVISORIA LTDA | C22: HUANUCO | D22: CAFÉ | E22: 0 | G22: NO | H22: nan | I22: nan | J22: ACTIVO | K22: nan | L22: 0 | M22: =IF(E22>0,ROUND(L22/E22*100,1),0) | N22: PENDIENTE | O22: =IF(H22="SI",1,0)*0.6+IF(I22="SI",1,0)*0.4 | P22: PENDIENTE | S22: =IFERROR(SCORECARDS!C22,"") | T22: =IF(NOT(ISNUMBER(S22)),"—",IF(S22<34,"🔴 Crítico",IF(S22<67,"🟡 Vulnerable","🟢 Preparado"))) | W22: 0 | X22: 0 | Y22: 0 | Z22: 0 | AA22: 0 | AB22: 0 | AC22: 0 | AD22: 0 | AE22: 0 | AF22: 0 | AG22: 0 | AH22: 0 | AI22: 0 | AJ22: 0 | AK22: 0 | AL22: 0 | AM22: 0 | AN22: 0 | AO22: =IFERROR(AVERAGE(AA22,AB22,AC22,AD22,AE22,AF22,AG22,AH22,AI22,AJ22,AK22,AL22,AM22,AN22),"N/A") | AP22: =IFERROR(AVERAGE(W22,X22,Y22,Z22)/2,"N/A")
A23: 20393152207 | B23: COOPERATIVA AGRO INDUSTRIAL APCTVASH | C23: UCAYALI | D23: CACAO | G23: NO | H23: nan | I23: nan | J23: ACTIVO | K23: nan | L23: 0 | M23: =IF(E23>0,ROUND(L23/E23*100,1),0) | N23: PENDIENTE | O23: =IF(H23="SI",1,0)*0.6+IF(I23="SI",1,0)*0.4 | P23: PENDIENTE | S23: =IFERROR(SCORECARDS!C23,"") | T23: =IF(NOT(ISNUMBER(S23)),"—",IF(S23<34,"🔴 Crítico",IF(S23<67,"🟡 Vulnerable","🟢 Preparado"))) | W23: 0 | X23: 0 | Y23: 0 | Z23: 0 | AA23: 0 | AB23: 0 | AC23: 0 | AD23: 0 | AE23: 0 | AF23: 0 | AG23: 0 | AH23: 0 | AI23: 0 | AJ23: 0 | AK23: 0 | AL23: 0 | AM23: 0 | AN23: 0 | AO23: =IFERROR(AVERAGE(AA23,AB23,AC23,AD23,AE23,AF23,AG23,AH23,AI23,AJ23,AK23,AL23,AM23,AN23),"N/A") | AP23: =IFERROR(AVERAGE(W23,X23,Y23,Z23)/2,"N/A")
A24: 20393593670 | B24: COMITE CENTRAL CON DESARROLLO AL FUTURO DE CURIMANA | C24: UCAYALI | D24: CACAO | E24: 0 | G24: NO | H24: nan | I24: nan | J24: BAJA DE OFICIO | K24: nan | L24: 0 | M24: =IF(E24>0,ROUND(L24/E24*100,1),0) | N24: PENDIENTE | O24: =IF(H24="SI",1,0)*0.6+IF(I24="SI",1,0)*0.4 | P24: PENDIENTE | S24: =IFERROR(SCORECARDS!C24,"") | T24: =IF(NOT(ISNUMBER(S24)),"—",IF(S24<34,"🔴 Crítico",IF(S24<67,"🟡 Vulnerable","🟢 Preparado"))) | W24: 0 | X24: 0 | Y24: 0 | Z24: 0 | AA24: 0 | AB24: 0 | AC24: 0 | AD24: 0 | AE24: 0 | AF24: 0 | AG24: 0 | AH24: 0 | AI24: 0 | AJ24: 0 | AK24: 0 | AL24: 0 | AM24: 0 | AN24: 0 | AO24: =IFERROR(AVERAGE(AA24,AB24,AC24,AD24,AE24,AF24,AG24,AH24,AI24,AJ24,AK24,AL24,AM24,AN24),"N/A") | AP24: =IFERROR(AVERAGE(W24,X24,Y24,Z24)/2,"N/A")
A25: 20393692228 | B25: COOPERATIVA AGRARIA CACAOTERA SAN ALEJANDRO LTDA | C25: UCAYALI | D25: CACAO | E25: 0 | G25: NO | H25: nan | I25: nan | J25: ACTIVO | K25: nan | L25: 0 | M25: =IF(E25>0,ROUND(L25/E25*100,1),0) | N25: PENDIENTE | O25: =IF(H25="SI",1,0)*0.6+IF(I25="SI",1,0)*0.4 | P25: PENDIENTE | S25: =IFERROR(SCORECARDS!C25,"") | T25: =IF(NOT(ISNUMBER(S25)),"—",IF(S25<34,"🔴 Crítico",IF(S25<67,"🟡 Vulnerable","🟢 Preparado"))) | W25: 0 | X25: 0 | Y25: 0 | Z25: 0 | AA25: 0 | AB25: 0 | AC25: 0 | AD25: 0 | AE25: 0 | AF25: 0 | AG25: 0 | AH25: 0 | AI25: 0 | AJ25: 0 | AK25: 0 | AL25: 0 | AM25: 0 | AN25: 0 | AO25: =IFERROR(AVERAGE(AA25,AB25,AC25,AD25,AE25,AF25,AG25,AH25,AI25,AJ25,AK25,AL25,AM25,AN25),"N/A") | AP25: =IFERROR(AVERAGE(W25,X25,Y25,Z25)/2,"N/A")
A26: 20393786044 | B26: COOPERATIVA AGRARIA CAFETALERA COORDILLERA AZUL DE UCAYALI L | C26: UCAYALI | D26: CAFÉ | G26: NO | H26: nan | I26: nan | J26: ACTIVO | K26: nan | L26: 0 | M26: =IF(E26>0,ROUND(L26/E26*100,1),0) | N26: PENDIENTE | O26: =IF(H26="SI",1,0)*0.6+IF(I26="SI",1,0)*0.4 | P26: PENDIENTE | S26: =IFERROR(SCORECARDS!C26,"") | T26: =IF(NOT(ISNUMBER(S26)),"—",IF(S26<34,"🔴 Crítico",IF(S26<67,"🟡 Vulnerable","🟢 Preparado"))) | W26: 0 | X26: 0 | Y26: 0 | Z26: 0 | AA26: 0 | AB26: 0 | AC26: 0 | AD26: 0 | AE26: 0 | AF26: 0 | AG26: 0 | AH26: 0 | AI26: 0 | AJ26: 0 | AK26: 0 | AL26: 0 | AM26: 0 | AN26: 0 | AO26: =IFERROR(AVERAGE(AA26,AB26,AC26,AD26,AE26,AF26,AG26,AH26,AI26,AJ26,AK26,AL26,AM26,AN26),"N/A") | AP26: =IFERROR(AVERAGE(W26,X26,Y26,Z26)/2,"N/A")
A27: 20393816211 | B27: COOPERATIVA AGRARIA SAN JUAN BAUTISTA | C27: UCAYALI | D27: CACAO | E27: 0 | G27: NO | H27: nan | I27: nan | J27: ACTIVO | K27: nan | L27: 0 | M27: =IF(E27>0,ROUND(L27/E27*100,1),0) | N27: PENDIENTE | O27: =IF(H27="SI",1,0)*0.6+IF(I27="SI",1,0)*0.4 | P27: PENDIENTE | S27: =IFERROR(SCORECARDS!C27,"") | T27: =IF(NOT(ISNUMBER(S27)),"—",IF(S27<34,"🔴 Crítico",IF(S27<67,"🟡 Vulnerable","🟢 Preparado"))) | W27: 0 | X27: 0 | Y27: 0 | Z27: 0 | AA27: 0 | AB27: 0 | AC27: 0 | AD27: 0 | AE27: 0 | AF27: 0 | AG27: 0 | AH27: 0 | AI27: 0 | AJ27: 0 | AK27: 0 | AL27: 0 | AM27: 0 | AN27: 0 | AO27: =IFERROR(AVERAGE(AA27,AB27,AC27,AD27,AE27,AF27,AG27,AH27,AI27,AJ27,AK27,AL27,AM27,AN27),"N/A") | AP27: =IFERROR(AVERAGE(W27,X27,Y27,Z27)/2,"N/A")
