Workbook

Sheet Leeme
A2: Actualizacion 2026-09-16 | B2: Se agrego '% de mujeres en la directiva' (Datos_Crudos, ultima columna) como insumo nuevo de IV5 (Riesgo social y comercial), tras revisar la evaluacion de preparacion EUDR de Vietnam (Team Europe Initiative, 2025), que trata la representacion/inclusion como criterio transversal de riesgo de exclusion. Es variable de contexto - NO entra al puntaje D1-D9 ni a IP, solo a IV5, invertida (baja representacion = mayor contribucion al riesgo).

Sheet Datos_Crudos
A1: Organizacion | B1: RUC | C1: D1_1 | D1: D1_2 | E1: D1_3 | F1: D1_4 | G1: D2_5 | H1: D2_6_pct | I1: D2_7 | J1: D2_8 | K1: D2_9 | L1: D2_10_flag | M1: D3_11_pct | N1: D3_12 | O1: D3_13 | P1: D3_14_flag | Q1: D3_14a | R1: D3_14b | S1: D3_14c | T1: D4_15 | U1: D4_16 | V1: D4_17 | W1: D5_18 | X1: D5_19 | Y1: D5_20 | Z1: D5_21 | AA1: D6_22 | AB1: D6_23 | AC1: D6_24 | AD1: D6_25 | AE1: D7_26 | AF1: D7_27 | AG1: D7_28_urgencia | AH1: D8_29 | AI1: D8_30_pct | AJ1: D8_31 | AK1: D8_32 | AL1: D9_33 | AM1: D9_34 | AN1: D9_35 | AO1: D10_36_texto | AP1: D10_37_texto | AQ1: D11_conteo_0a7 | AR1: Cert_conteo_0a4 | AS1: Dispersion_geo | AT1: Distancia_acopio | AU1: N_socios | AV1: Hectareas_totales | AW1: P1_vol_UE | AX1: P1b_vol_total | AY1: P4_n_compradores | AZ1: MujeresDirectiva_pct
A2: Coop. Ejemplo Norte | B2: 20100000000 | C2: 1 | D2: 0 | E2: 4 | F2: 4 | G2: 4 | H2: 28 | I2: 3 | J2: 0 | K2: 0 | L2: 0 | M2: 91 | N2: 4 | O2: 4 | P2: 0 | Q2: 0 | R2: 1 | S2: 1 | T2: 4 | U2: 1 | V2: 4 | W2: 0 | X2: 0 | Y2: 0 | Z2: 0 | AA2: 2 | AB2: 3 | AC2: 1 | AD2: 1 | AE2: 2 | AF2: 2 | AG2: 2 | AH2: 0 | AI2: 20 | AJ2: 2 | AK2: 3 | AL2: 0 | AM2: 4 | AN2: 2 | AO2: No, sabe que son distintas | AP2: No | AQ2: 7 | AR2: 4 | AS2: 0 | AT2: 2 | AU2: 272 | AV2: 646 | AW2: 31700 | AX2: 138416 | AY2: 6 | AZ2: 28
A3: Coop. Ejemplo Sur | B3: 20100111111 | C3: 3 | D3: 3 | E3: 2 | G3: 1 | H3: 62 | I3: 1 | J3: 1 | K3: 3 | L3: 3 | M3: 17 | N3: 4 | O3: 1 | P3: 4 | Q3: 3 | R3: 3 | S3: 1 | T3: 1 | U3: 1 | W3: 1 | X3: 0 | Y3: 4 | Z3: 4 | AE3: 3 | AF3: 3 | AG3: 0 | AH3: 1 | AI3: 47 | AJ3: 4 | AK3: 0 | AL3: 4 | AM3: 2 | AN3: 0 | AO3: Si, en parte | AP3: No | AQ3: 2 | AR3: 2 | AS3: 4 | AT3: 0 | AU3: 89 | AV3: 773 | AW3: 198758 | AX3: 273415 | AY3: 4 | AZ3: 33
A4: Asoc. Ejemplo Centro | B4: 20100222222 | C4: 1 | D4: 2 | E4: 3 | F4: 1 | G4: 1 | H4: 91 | I4: 1 | J4: 0 | K4: 2 | L4: 0 | M4: 69 | N4: 2 | O4: 2 | P4: 4 | Q4: 4 | R4: 1 | S4: 1 | T4: 3 | U4: 1 | V4: 3 | W4: 0 | X4: 2 | Y4: 1 | Z4: 2 | AA4: 2 | AB4: 2 | AC4: 0 | AD4: 1 | AE4: 3 | AF4: 4 | AG4: 3 | AH4: 2 | AI4: 78 | AJ4: 0 | AK4: 1 | AL4: 1 | AM4: 2 | AN4: 3 | AO4: No tiene certificacion | AP4: No | AQ4: 1 | AR4: 1 | AS4: 1 | AU4: 268 | AV4: 737 | AW4: 46311 | AX4: 193455 | AY4: 5 | AZ4: 51
A5: Coop. Ejemplo VRAEM | B5: 20100333333 | C5: 2 | D5: 4 | E5: 0 | F5: 0 | G5: 1 | H5: 47 | I5: 1 | K5: 4 | L5: 4 | M5: 38 | N5: 1 | O5: 2 | P5: 4 | Q5: 4 | R5: 4 | S5: 1 | T5: 0 | U5: 1 | V5: 1 | W5: 3 | X5: 0 | Y5: 2 | Z5: 4 | AA5: 0 | AB5: 0 | AC5: 2 | AD5: 0 | AE5: 4 | AG5: 0 | AH5: 4 | AI5: 93 | AJ5: 1 | AK5: 3 | AL5: 3 | AM5: 1 | AN5: 2 | AO5: Si, en parte | AP5: No | AQ5: 2 | AR5: 3 | AS5: 3 | AT5: 1 | AU5: 249 | AV5: 121 | AW5: 140505 | AX5: 275574 | AY5: 1 | AZ5: 28
A6: Coop. Ejemplo Amazonas | B6: 20100444444 | C6: 2 | D6: 1 | E6: 1 | F6: 0 | G6: 3 | H6: 24 | I6: 1 | J6: 3 | K6: 3 | L6: 1 | M6: 40 | N6: 2 | P6: 3 | Q6: 3 | R6: 4 | S6: 0 | T6: 1 | U6: 0 | V6: 2 | W6: 1 | X6: 1 | Y6: 2 | Z6: 4 | AA6: 4 | AB6: 2 | AC6: 0 | AD6: 1 | AE6: 0 | AF6: 0 | AG6: 2 | AH6: 1 | AI6: 16 | AJ6: 3 | AL6: 3 | AM6: 2 | AN6: 0 | AO6: Si, en parte | AP6: Si | AQ6: 2 | AR6: 2 | AS6: 1 | AT6: 2 | AU6: 135 | AV6: 304 | AW6: 110016 | AX6: 154242 | AY6: 2 | AZ6: 30
A7: Asoc. Ejemplo Cusco | B7: 20100555555 | C7: 2 | D7: 0 | E7: 4 | F7: 4 | G7: 3 | H7: 19 | I7: 3 | J7: 4 | K7: 3 | L7: 2 | M7: 68 | N7: 2 | O7: 1 | P7: 2 | Q7: 1 | S7: 2 | T7: 0 | U7: 3 | V7: 2 | W7: 2 | X7: 1 | Y7: 3 | AA7: 2 | AB7: 4 | AC7: 0 | AD7: 2 | AE7: 1 | AG7: 3 | AH7: 1 | AI7: 31 | AJ7: 0 | AK7: 0 | AL7: 4 | AM7: 0 | AN7: 1 | AO7: Si, totalmente | AP7: Si | AQ7: 6 | AR7: 2 | AS7: 3 | AT7: 4 | AU7: 104 | AV7: 97 | AW7: 170352 | AX7: 266315 | AY7: 5 | AZ7: 34
A8: Coop. Ejemplo San Martin | B8: 20100666666 | C8: 4 | D8: 4 | E8: 4 | F8: 0 | G8: 4 | H8: 78 | I8: 1 | J8: 0 | K8: 2 | L8: 3 | M8: 81 | N8: 0 | O8: 1 | P8: 0 | Q8: 0 | R8: 4 | S8: 0 | T8: 0 | U8: 3 | V8: 0 | W8: 1 | X8: 1 | Y8: 3 | Z8: 3 | AA8: 2 | AB8: 4 | AC8: 1 | AD8: 1 | AE8: 2 | AF8: 1 | AH8: 2 | AI8: 93 | AJ8: 1 | AK8: 2 | AL8: 2 | AM8: 3 | AN8: 4 | AO8: Si, en parte | AP8: No | AQ8: 1 | AR8: 3 | AT8: 4 | AU8: 260 | AV8: 895 | AW8: 89633 | AX8: 105452 | AY8: 2 | AZ8: 14
A9: Coop. Ejemplo Junin | B9: 20100777777 | C9: 4 | D9: 2 | E9: 4 | F9: 0 | G9: 1 | H9: 52 | I9: 3 | L9: 3 | M9: 44 | N9: 3 | O9: 2 | P9: 2 | R9: 3 | S9: 1 | T9: 2 | U9: 0 | V9: 4 | W9: 3 | X9: 0 | Y9: 0 | Z9: 2 | AA9: 1 | AB9: 2 | AC9: 2 | AD9: 2 | AE9: 3 | AF9: 3 | AG9: 4 | AH9: 0 | AI9: 14 | AJ9: 3 | AK9: 1 | AL9: 2 | AM9: 4 | AN9: 3 | AO9: No tiene certificacion | AP9: No | AQ9: 4 | AR9: 2 | AS9: 2 | AT9: 1 | AU9: 184 | AV9: 466 | AW9: 140398 | AX9: 169661 | AY9: 1 | AZ9: 31

Sheet Items_Normalizados
A1: Organizacion | B1: RUC | C1: D1_1 | D1: D1_2 | E1: D1_3 | F1: D1_4 | G1: D2_5 | H1: D2_6 | I1: D2_7 | J1: D2_8 | K1: D2_9 | L1: D2_10 | M1: D3_11 | N1: D3_12 | O1: D3_13 | P1: D3_14 | Q1: D3_14a | R1: D3_14b | S1: D3_14c | T1: D4_15 | U1: D4_16 | V1: D4_17 | W1: D5_18 | X1: D5_19 | Y1: D5_20 | Z1: D5_21 | AA1: D6_22 | AB1: D6_23 | AC1: D6_24 | AD1: D6_25 | AE1: D7_26 | AF1: D7_27 | AG1: D7_28_urgencia | AH1: D8_29 | AI1: D8_30 | AJ1: D8_31 | AK1: D8_32 | AL1: D9_33 | AM1: D9_34 | AN1: D9_35 | AO1: D10_36 | AP1: D10_37 | AQ1: D11_conteo_0a7 | AR1: Cert_conteo_0a4 | AS1: Dispersion_geo | AT1: Distancia_acopio | AU1: N_socios | AV1: Hectareas_totales | AW1: P1_vol_UE | AX1: P1b_vol_total | AY1: P4_n_compradores | AZ1: MujeresDirectiva
C2: =IF(Datos_Crudos!C2="","",Datos_Crudos!C2*25) | D2: =IF(Datos_Crudos!D2="","",Datos_Crudos!D2*25) | E2: =IF(Datos_Crudos!E2="","",Datos_Crudos!E2*25) | F2: =IF(Datos_Crudos!F2="","",Datos_Crudos!F2*25) | G2: =IF(Datos_Crudos!G2="","",Datos_Crudos!G2*25) | H2: =Datos_Crudos!H2 | I2: =IF(Datos_Crudos!I2="","",Datos_Crudos!I2*25) | J2: =IF(Datos_Crudos!J2="","",Datos_Crudos!J2*25) | K2: =IF(Datos_Crudos!K2="","",Datos_Crudos!K2*25) | L2: =IF(Datos_Crudos!L2="","",Datos_Crudos!L2*25) | M2: =Datos_Crudos!M2 | N2: =IF(Datos_Crudos!N2="","",Datos_Crudos!N2*25) | O2: =IF(Datos_Crudos!O2="","",Datos_Crudos!O2*25) | P2: =IF(Datos_Crudos!P2="","",Datos_Crudos!P2*25) | Q2: =IF(Datos_Crudos!Q2="","",Datos_Crudos!Q2*25) | R2: =IF(Datos_Crudos!R2="","",Datos_Crudos!R2*25) | S2: =IF(Datos_Crudos!S2="","",Datos_Crudos!S2*25) | T2: =IF(Datos_Crudos!T2="","",Datos_Crudos!T2*25) | U2: =IF(Datos_Crudos!U2="","",Datos_Crudos!U2*25) | ... AH2: =IF(Datos_Crudos!AH2="","",Datos_Crudos!AH2*25) | AI2: =Datos_Crudos!AI2 | AJ2: =IF(Datos_Crudos!AJ2="","",Datos_Crudos!AJ2*25) | AK2: =IF(Datos_Crudos!AK2="","",Datos_Crudos!AK2*25) | AL2: =IF(Datos_Crudos!AL2="","",Datos_Crudos!AL2*25) | AM2: =IF(Datos_Crudos!AM2="","",Datos_Crudos!AM2*25) | AN2: =IF(Datos_Crudos!AN2="","",Datos_Crudos!AN2*25) | AS2: =IF(Datos_Crudos!AS2="","",Datos_Crudos!AS2*25) | AT2: =IF(Datos_Crudos!AT2="","",Datos_Crudos!AT2*25) | AZ2: =Datos_Crudos!AZ2
C3: =IF(Datos_Crudos!C3="","",Datos_Crudos!C3*25) | D3: =IF(Datos_Crudos!D3="","",Datos_Crudos!D3*25) | E3: =IF(Datos_Crudos!E3="","",Datos_Crudos!E3*25) | F3: =IF(Datos_Crudos!F3="","",Datos_Crudos!F3*25) | G3: =IF(Datos_Crudos!G3="","",Datos_Crudos!G3*25) | H3: =Datos_Crudos!H3 | I3: =IF(Datos_Crudos!I3="","",Datos_Crudos!I3*25) | J3: =IF(Datos_Crudos!J3="","",Datos_Crudos!J3*25) | K3: =IF(Datos_Crudos!K3="","",Datos_Crudos!K3*25) | L3: =IF(Datos_Crudos!L3="","",Datos_Crudos!L3*25) | M3: =Datos_Crudos!M3 | N3: =IF(Datos_Crudos!N3="","",Datos_Crudos!N3*25) | O3: =IF(Datos_Crudos!O3="","",Datos_Crudos!O3*25) | P3: =IF(Datos_Crudos!P3="","",Datos_Crudos!P3*25) | Q3: =IF(Datos_Crudos!Q3="","",Datos_Crudos!Q3*25) | R3: =IF(Datos_Crudos!R3="","",Datos_Crudos!R3*25) | S3: =IF(Datos_Crudos!S3="","",Datos_Crudos!S3*25) | T3: =IF(Datos_Crudos!T3="","",Datos_Crudos!T3*25) | U3: =IF(Datos_Crudos!U3="","",Datos_Crudos!U3*25) | ... AH3: =IF(Datos_Crudos!AH3="","",Datos_Crudos!AH3*25) | AI3: =Datos_Crudos!AI3 | AJ3: =IF(Datos_Crudos!AJ3="","",Datos_Crudos!AJ3*25) | AK3: =IF(Datos_Crudos!AK3="","",Datos_Crudos!AK3*25) | AL3: =IF(Datos_Crudos!AL3="","",Datos_Crudos!AL3*25) | AM3: =IF(Datos_Crudos!AM3="","",Datos_Crudos!AM3*25) | AN3: =IF(Datos_Crudos!AN3="","",Datos_Crudos!AN3*25) | AS3: =IF(Datos_Crudos!AS3="","",Datos_Crudos!AS3*25) | AT3: =IF(Datos_Crudos!AT3="","",Datos_Crudos!AT3*25) | AZ3: =Datos_Crudos!AZ3
C4: =IF(Datos_Crudos!C4="","",Datos_Crudos!C4*25) | D4: =IF(Datos_Crudos!D4="","",Datos_Crudos!D4*25) | E4: =IF(Datos_Crudos!E4="","",Datos_Crudos!E4*25) | F4: =IF(Datos_Crudos!F4="","",Datos_Crudos!F4*25) | G4: =IF(Datos_Crudos!G4="","",Datos_Crudos!G4*25) | H4: =Datos_Crudos!H4 | I4: =IF(Datos_Crudos!I4="","",Datos_Crudos!I4*25) | J4: =IF(Datos_Crudos!J4="","",Datos_Crudos!J4*25) | K4: =IF(Datos_Crudos!K4="","",Datos_Crudos!K4*25) | L4: =IF(Datos_Crudos!L4="","",Datos_Crudos!L4*25) | M4: =Datos_Crudos!M4 | N4: =IF(Datos_Crudos!N4="","",Datos_Crudos!N4*25) | O4: =IF(Datos_Crudos!O4="","",Datos_Crudos!O4*25) | P4: =IF(Datos_Crudos!P4="","",Datos_Crudos!P4*25) | Q4: =IF(Datos_Crudos!Q4="","",Datos_Crudos!Q4*25) | R4: =IF(Datos_Crudos!R4="","",Datos_Crudos!R4*25) | S4: =IF(Datos_Crudos!S4="","",Datos_Crudos!S4*25) | T4: =IF(Datos_Crudos!T4="","",Datos_Crudos!T4*25) | U4: =IF(Datos_Crudos!U4="","",Datos_Crudos!U4*25) | ... AH4: =IF(Datos_Crudos!AH4="","",Datos_Crudos!AH4*25) | AI4: =Datos_Crudos!AI4 | AJ4: =IF(Datos_Crudos!AJ4="","",Datos_Crudos!AJ4*25) | AK4: =IF(Datos_Crudos!AK4="","",Datos_Crudos!AK4*25) | AL4: =IF(Datos_Crudos!AL4="","",Datos_Crudos!AL4*25) | AM4: =IF(Datos_Crudos!AM4="","",Datos_Crudos!AM4*25) | AN4: =IF(Datos_Crudos!AN4="","",Datos_Crudos!AN4*25) | AS4: =IF(Datos_Crudos!AS4="","",Datos_Crudos!AS4*25) | AT4: =IF(Datos_Crudos!AT4="","",Datos_Crudos!AT4*25) | AZ4: =Datos_Crudos!AZ4
C5: =IF(Datos_Crudos!C5="","",Datos_Crudos!C5*25) | D5: =IF(Datos_Crudos!D5="","",Datos_Crudos!D5*25) | E5: =IF(Datos_Crudos!E5="","",Datos_Crudos!E5*25) | F5: =IF(Datos_Crudos!F5="","",Datos_Crudos!F5*25) | G5: =IF(Datos_Crudos!G5="","",Datos_Crudos!G5*25) | H5: =Datos_Crudos!H5 | I5: =IF(Datos_Crudos!I5="","",Datos_Crudos!I5*25) | J5: =IF(Datos_Crudos!J5="","",Datos_Crudos!J5*25) | K5: =IF(Datos_Crudos!K5="","",Datos_Crudos!K5*25) | L5: =IF(Datos_Crudos!L5="","",Datos_Crudos!L5*25) | M5: =Datos_Crudos!M5 | N5: =IF(Datos_Crudos!N5="","",Datos_Crudos!N5*25) | O5: =IF(Datos_Crudos!O5="","",Datos_Crudos!O5*25) | P5: =IF(Datos_Crudos!P5="","",Datos_Crudos!P5*25) | Q5: =IF(Datos_Crudos!Q5="","",Datos_Crudos!Q5*25) | R5: =IF(Datos_Crudos!R5="","",Datos_Crudos!R5*25) | S5: =IF(Datos_Crudos!S5="","",Datos_Crudos!S5*25) | T5: =IF(Datos_Crudos!T5="","",Datos_Crudos!T5*25) | U5: =IF(Datos_Crudos!U5="","",Datos_Crudos!U5*25) | ... AH5: =IF(Datos_Crudos!AH5="","",Datos_Crudos!AH5*25) | AI5: =Datos_Crudos!AI5 | AJ5: =IF(Datos_Crudos!AJ5="","",Datos_Crudos!AJ5*25) | AK5: =IF(Datos_Crudos!AK5="","",Datos_Crudos!AK5*25) | AL5: =IF(Datos_Crudos!AL5="","",Datos_Crudos!AL5*25) | AM5: =IF(Datos_Crudos!AM5="","",Datos_Crudos!AM5*25) | AN5: =IF(Datos_Crudos!AN5="","",Datos_Crudos!AN5*25) | AS5: =IF(Datos_Crudos!AS5="","",Datos_Crudos!AS5*25) | AT5: =IF(Datos_Crudos!AT5="","",Datos_Crudos!AT5*25) | AZ5: =Datos_Crudos!AZ5
C6: =IF(Datos_Crudos!C6="","",Datos_Crudos!C6*25) | D6: =IF(Datos_Crudos!D6="","",Datos_Crudos!D6*25) | E6: =IF(Datos_Crudos!E6="","",Datos_Crudos!E6*25) | F6: =IF(Datos_Crudos!F6="","",Datos_Crudos!F6*25) | G6: =IF(Datos_Crudos!G6="","",Datos_Crudos!G6*25) | H6: =Datos_Crudos!H6 | I6: =IF(Datos_Crudos!I6="","",Datos_Crudos!I6*25) | J6: =IF(Datos_Crudos!J6="","",Datos_Crudos!J6*25) | K6: =IF(Datos_Crudos!K6="","",Datos_Crudos!K6*25) | L6: =IF(Datos_Crudos!L6="","",Datos_Crudos!L6*25) | M6: =Datos_Crudos!M6 | N6: =IF(Datos_Crudos!N6="","",Datos_Crudos!N6*25) | O6: =IF(Datos_Crudos!O6="","",Datos_Crudos!O6*25) | P6: =IF(Datos_Crudos!P6="","",Datos_Crudos!P6*25) | Q6: =IF(Datos_Crudos!Q6="","",Datos_Crudos!Q6*25) | R6: =IF(Datos_Crudos!R6="","",Datos_Crudos!R6*25) | S6: =IF(Datos_Crudos!S6="","",Datos_Crudos!S6*25) | T6: =IF(Datos_Crudos!T6="","",Datos_Crudos!T6*25) | U6: =IF(Datos_Crudos!U6="","",Datos_Crudos!U6*25) | ... AH6: =IF(Datos_Crudos!AH6="","",Datos_Crudos!AH6*25) | AI6: =Datos_Crudos!AI6 | AJ6: =IF(Datos_Crudos!AJ6="","",Datos_Crudos!AJ6*25) | AK6: =IF(Datos_Crudos!AK6="","",Datos_Crudos!AK6*25) | AL6: =IF(Datos_Crudos!AL6="","",Datos_Crudos!AL6*25) | AM6: =IF(Datos_Crudos!AM6="","",Datos_Crudos!AM6*25) | AN6: =IF(Datos_Crudos!AN6="","",Datos_Crudos!AN6*25) | AS6: =IF(Datos_Crudos!AS6="","",Datos_Crudos!AS6*25) | AT6: =IF(Datos_Crudos!AT6="","",Datos_Crudos!AT6*25) | AZ6: =Datos_Crudos!AZ6
C7: =IF(Datos_Crudos!C7="","",Datos_Crudos!C7*25) | D7: =IF(Datos_Crudos!D7="","",Datos_Crudos!D7*25) | E7: =IF(Datos_Crudos!E7="","",Datos_Crudos!E7*25) | F7: =IF(Datos_Crudos!F7="","",Datos_Crudos!F7*25) | G7: =IF(Datos_Crudos!G7="","",Datos_Crudos!G7*25) | H7: =Datos_Crudos!H7 | I7: =IF(Datos_Crudos!I7="","",Datos_Crudos!I7*25) | J7: =IF(Datos_Crudos!J7="","",Datos_Crudos!J7*25) | K7: =IF(Datos_Crudos!K7="","",Datos_Crudos!K7*25) | L7: =IF(Datos_Crudos!L7="","",Datos_Crudos!L7*25) | M7: =Datos_Crudos!M7 | N7: =IF(Datos_Crudos!N7="","",Datos_Crudos!N7*25) | O7: =IF(Datos_Crudos!O7="","",Datos_Crudos!O7*25) | P7: =IF(Datos_Crudos!P7="","",Datos_Crudos!P7*25) | Q7: =IF(Datos_Crudos!Q7="","",Datos_Crudos!Q7*25) | R7: =IF(Datos_Crudos!R7="","",Datos_Crudos!R7*25) | S7: =IF(Datos_Crudos!S7="","",Datos_Crudos!S7*25) | T7: =IF(Datos_Crudos!T7="","",Datos_Crudos!T7*25) | U7: =IF(Datos_Crudos!U7="","",Datos_Crudos!U7*25) | ... AH7: =IF(Datos_Crudos!AH7="","",Datos_Crudos!AH7*25) | AI7: =Datos_Crudos!AI7 | AJ7: =IF(Datos_Crudos!AJ7="","",Datos_Crudos!AJ7*25) | AK7: =IF(Datos_Crudos!AK7="","",Datos_Crudos!AK7*25) | AL7: =IF(Datos_Crudos!AL7="","",Datos_Crudos!AL7*25) | AM7: =IF(Datos_Crudos!AM7="","",Datos_Crudos!AM7*25) | AN7: =IF(Datos_Crudos!AN7="","",Datos_Crudos!AN7*25) | AS7: =IF(Datos_Crudos!AS7="","",Datos_Crudos!AS7*25) | AT7: =IF(Datos_Crudos!AT7="","",Datos_Crudos!AT7*25) | AZ7: =Datos_Crudos!AZ7
C8: =IF(Datos_Crudos!C8="","",Datos_Crudos!C8*25) | D8: =IF(Datos_Crudos!D8="","",Datos_Crudos!D8*25) | E8: =IF(Datos_Crudos!E8="","",Datos_Crudos!E8*25) | F8: =IF(Datos_Crudos!F8="","",Datos_Crudos!F8*25) | G8: =IF(Datos_Crudos!G8="","",Datos_Crudos!G8*25) | H8: =Datos_Crudos!H8 | I8: =IF(Datos_Crudos!I8="","",Datos_Crudos!I8*25) | J8: =IF(Datos_Crudos!J8="","",Datos_Crudos!J8*25) | K8: =IF(Datos_Crudos!K8="","",Datos_Crudos!K8*25) | L8: =IF(Datos_Crudos!L8="","",Datos_Crudos!L8*25) | M8: =Datos_Crudos!M8 | N8: =IF(Datos_Crudos!N8="","",Datos_Crudos!N8*25) | O8: =IF(Datos_Crudos!O8="","",Datos_Crudos!O8*25) | P8: =IF(Datos_Crudos!P8="","",Datos_Crudos!P8*25) | Q8: =IF(Datos_Crudos!Q8="","",Datos_Crudos!Q8*25) | R8: =IF(Datos_Crudos!R8="","",Datos_Crudos!R8*25) | S8: =IF(Datos_Crudos!S8="","",Datos_Crudos!S8*25) | T8: =IF(Datos_Crudos!T8="","",Datos_Crudos!T8*25) | U8: =IF(Datos_Crudos!U8="","",Datos_Crudos!U8*25) | ... AH8: =IF(Datos_Crudos!AH8="","",Datos_Crudos!AH8*25) | AI8: =Datos_Crudos!AI8 | AJ8: =IF(Datos_Crudos!AJ8="","",Datos_Crudos!AJ8*25) | AK8: =IF(Datos_Crudos!AK8="","",Datos_Crudos!AK8*25) | AL8: =IF(Datos_Crudos!AL8="","",Datos_Crudos!AL8*25) | AM8: =IF(Datos_Crudos!AM8="","",Datos_Crudos!AM8*25) | AN8: =IF(Datos_Crudos!AN8="","",Datos_Crudos!AN8*25) | AS8: =IF(Datos_Crudos!AS8="","",Datos_Crudos!AS8*25) | AT8: =IF(Datos_Crudos!AT8="","",Datos_Crudos!AT8*25) | AZ8: =Datos_Crudos!AZ8
C9: =IF(Datos_Crudos!C9="","",Datos_Crudos!C9*25) | D9: =IF(Datos_Crudos!D9="","",Datos_Crudos!D9*25) | E9: =IF(Datos_Crudos!E9="","",Datos_Crudos!E9*25) | F9: =IF(Datos_Crudos!F9="","",Datos_Crudos!F9*25) | G9: =IF(Datos_Crudos!G9="","",Datos_Crudos!G9*25) | H9: =Datos_Crudos!H9 | I9: =IF(Datos_Crudos!I9="","",Datos_Crudos!I9*25) | J9: =IF(Datos_Crudos!J9="","",Datos_Crudos!J9*25) | K9: =IF(Datos_Crudos!K9="","",Datos_Crudos!K9*25) | L9: =IF(Datos_Crudos!L9="","",Datos_Crudos!L9*25) | M9: =Datos_Crudos!M9 | N9: =IF(Datos_Crudos!N9="","",Datos_Crudos!N9*25) | O9: =IF(Datos_Crudos!O9="","",Datos_Crudos!O9*25) | P9: =IF(Datos_Crudos!P9="","",Datos_Crudos!P9*25) | Q9: =IF(Datos_Crudos!Q9="","",Datos_Crudos!Q9*25) | R9: =IF(Datos_Crudos!R9="","",Datos_Crudos!R9*25) | S9: =IF(Datos_Crudos!S9="","",Datos_Crudos!S9*25) | T9: =IF(Datos_Crudos!T9="","",Datos_Crudos!T9*25) | U9: =IF(Datos_Crudos!U9="","",Datos_Crudos!U9*25) | ... AH9: =IF(Datos_Crudos!AH9="","",Datos_Crudos!AH9*25) | AI9: =Datos_Crudos!AI9 | AJ9: =IF(Datos_Crudos!AJ9="","",Datos_Crudos!AJ9*25) | AK9: =IF(Datos_Crudos!AK9="","",Datos_Crudos!AK9*25) | AL9: =IF(Datos_Crudos!AL9="","",Datos_Crudos!AL9*25) | AM9: =IF(Datos_Crudos!AM9="","",Datos_Crudos!AM9*25) | AN9: =IF(Datos_Crudos!AN9="","",Datos_Crudos!AN9*25) | AS9: =IF(Datos_Crudos!AS9="","",Datos_Crudos!AS9*25) | AT9: =IF(Datos_Crudos!AT9="","",Datos_Crudos!AT9*25) | AZ9: =Datos_Crudos!AZ9

Sheet Dimensiones
A1: Organizacion | B1: D1_pct | C1: D2_pct | D1: D2_9_pct | E1: D2_10_raw | F1: D2_10_flag | G1: D3_pct | H1: D3_14_pct | I1: D4_pct | J1: D5_pct | K1: D6_pct | L1: D6_sistemas_pct | M1: D6_23_pct | N1: D6_24_pct | O1: D7_pct | P1: D7_28_urgencia | Q1: D8_pct | R1: D8_31_32_pct | S1: D9_pct | T1: D11_pct | U1: Cert_recod | V1: Dispersion_pct | W1: Distancia_pct | X1: TamanoParcela_ratio | Y1: TamanoParcela_norm | Z1: PctUE | AA1: ConcentracionCompradores | AB1: D10_36_raw | AC1: Alerta_D10 | AD1: D10_37_raw | AE1: MujeresDirectiva_pct
A2: =Datos_Crudos!A2 | B2: =IFERROR(AVERAGE(Items_Normalizados!C2,Items_Normalizados!D2,Items_Normalizados!E2,Items_Normalizados!F2),"") | C2: =IFERROR(AVERAGE(Items_Normalizados!G2,Items_Normalizados!H2,Items_Normalizados!I2,Items_Normalizados!J2,Items_Normalizados!K2),"") | D2: =Items_Normalizados!K2 | E2: =Datos_Crudos!L2 | F2: =IF(Datos_Crudos!L2="","(sin dato)",IF(Datos_Crudos!L2<=1,"ALERTA: mezcla sin control","OK")) | G2: =IFERROR(AVERAGE(Items_Normalizados!M2,Items_Normalizados!N2,Items_Normalizados!O2,Items_Normalizados!Q2,Items_Normalizados!R2,Items_Normalizados!S2),"") | H2: =Items_Normalizados!P2 | I2: =IFERROR(AVERAGE(Items_Normalizados!T2,Items_Normalizados!U2,Items_Normalizados!V2),"") | J2: =IFERROR(AVERAGE(Items_Normalizados!W2,Items_Normalizados!X2,Items_Normalizados!Y2,Items_Normalizados!Z2),"") | K2: =IFERROR(AVERAGE(Items_Normalizados!AA2,Items_Normalizados!AB2,Items_Normalizados!AC2,Items_Normalizados!AD2),"") | L2: =IFERROR(AVERAGE(Items_Normalizados!AA2,Items_Normalizados!AD2),"") | M2: =Items_Normalizados!AB2 | N2: =Items_Normalizados!AC2 | O2: =IFERROR(AVERAGE(Items_Normalizados!AE2,Items_Normalizados!AF2),"") | P2: =Items_Normalizados!AG2 | Q2: =IFERROR(AVERAGE(Items_Normalizados!AH2,Items_Normalizados!AI2,Items_Normalizados!AJ2,Items_Normalizados!AK2),"") | R2: =IFERROR(AVERAGE(Items_Normalizados!AJ2,Items_Normalizados!AK2),"") | S2: =IFERROR(AVERAGE(Items_Normalizados!AL2,Items_Normalizados!AM2,Items_Normalizados!AN2),"") | T2: =IFERROR(Datos_Crudos!AQ2/7*100,"") | U2: =IF(Datos_Crudos!AR2>=3,100,IF(Datos_Crudos!AR2=2,66,IF(Datos_Crudos!AR2=1,33,0))) | V2: =Items_Normalizados!AS2 | W2: =Items_Normalizados!AT2 | X2: =IFERROR(Datos_Crudos!AV2/Datos_Crudos!AU2,"") | Y2: =IFERROR((X2-MIN($X$2:$X$9))/(MAX($X$2:$X$9)-MIN($X$2:$X$9))*100,50) | Z2: =IFERROR(Datos_Crudos!AW2/Datos_Crudos!AX2*100,"") | AA2: =IFERROR(MIN(100,100/Datos_Crudos!AY2),100) | AB2: =Datos_Crudos!AO2 | AC2: =IF(AB2="Si, totalmente","ALERTA: falsa seguridad","OK") | AD2: =Datos_Crudos!AP2 | AE2: =Items_Normalizados!AZ2
A3: =Datos_Crudos!A3 | B3: =IFERROR(AVERAGE(Items_Normalizados!C3,Items_Normalizados!D3,Items_Normalizados!E3,Items_Normalizados!F3),"") | C3: =IFERROR(AVERAGE(Items_Normalizados!G3,Items_Normalizados!H3,Items_Normalizados!I3,Items_Normalizados!J3,Items_Normalizados!K3),"") | D3: =Items_Normalizados!K3 | E3: =Datos_Crudos!L3 | F3: =IF(Datos_Crudos!L3="","(sin dato)",IF(Datos_Crudos!L3<=1,"ALERTA: mezcla sin control","OK")) | G3: =IFERROR(AVERAGE(Items_Normalizados!M3,Items_Normalizados!N3,Items_Normalizados!O3,Items_Normalizados!Q3,Items_Normalizados!R3,Items_Normalizados!S3),"") | H3: =Items_Normalizados!P3 | I3: =IFERROR(AVERAGE(Items_Normalizados!T3,Items_Normalizados!U3,Items_Normalizados!V3),"") | J3: =IFERROR(AVERAGE(Items_Normalizados!W3,Items_Normalizados!X3,Items_Normalizados!Y3,Items_Normalizados!Z3),"") | K3: =IFERROR(AVERAGE(Items_Normalizados!AA3,Items_Normalizados!AB3,Items_Normalizados!AC3,Items_Normalizados!AD3),"") | L3: =IFERROR(AVERAGE(Items_Normalizados!AA3,Items_Normalizados!AD3),"") | M3: =Items_Normalizados!AB3 | N3: =Items_Normalizados!AC3 | O3: =IFERROR(AVERAGE(Items_Normalizados!AE3,Items_Normalizados!AF3),"") | P3: =Items_Normalizados!AG3 | Q3: =IFERROR(AVERAGE(Items_Normalizados!AH3,Items_Normalizados!AI3,Items_Normalizados!AJ3,Items_Normalizados!AK3),"") | R3: =IFERROR(AVERAGE(Items_Normalizados!AJ3,Items_Normalizados!AK3),"") | S3: =IFERROR(AVERAGE(Items_Normalizados!AL3,Items_Normalizados!AM3,Items_Normalizados!AN3),"") | T3: =IFERROR(Datos_Crudos!AQ3/7*100,"") | U3: =IF(Datos_Crudos!AR3>=3,100,IF(Datos_Crudos!AR3=2,66,IF(Datos_Crudos!AR3=1,33,0))) | V3: =Items_Normalizados!AS3 | W3: =Items_Normalizados!AT3 | X3: =IFERROR(Datos_Crudos!AV3/Datos_Crudos!AU3,"") | Y3: =IFERROR((X3-MIN($X$2:$X$9))/(MAX($X$2:$X$9)-MIN($X$2:$X$9))*100,50) | Z3: =IFERROR(Datos_Crudos!AW3/Datos_Crudos!AX3*100,"") | AA3: =IFERROR(MIN(100,100/Datos_Crudos!AY3),100) | AB3: =Datos_Crudos!AO3 | AC3: =IF(AB3="Si, totalmente","ALERTA: falsa seguridad","OK") | AD3: =Datos_Crudos!AP3 | AE3: =Items_Normalizados!AZ3
A4: =Datos_Crudos!A4 | B4: =IFERROR(AVERAGE(Items_Normalizados!C4,Items_Normalizados!D4,Items_Normalizados!E4,Items_Normalizados!F4),"") | C4: =IFERROR(AVERAGE(Items_Normalizados!G4,Items_Normalizados!H4,Items_Normalizados!I4,Items_Normalizados!J4,Items_Normalizados!K4),"") | D4: =Items_Normalizados!K4 | E4: =Datos_Crudos!L4 | F4: =IF(Datos_Crudos!L4="","(sin dato)",IF(Datos_Crudos!L4<=1,"ALERTA: mezcla sin control","OK")) | G4: =IFERROR(AVERAGE(Items_Normalizados!M4,Items_Normalizados!N4,Items_Normalizados!O4,Items_Normalizados!Q4,Items_Normalizados!R4,Items_Normalizados!S4),"") | H4: =Items_Normalizados!P4 | I4: =IFERROR(AVERAGE(Items_Normalizados!T4,Items_Normalizados!U4,Items_Normalizados!V4),"") | J4: =IFERROR(AVERAGE(Items_Normalizados!W4,Items_Normalizados!X4,Items_Normalizados!Y4,Items_Normalizados!Z4),"") | K4: =IFERROR(AVERAGE(Items_Normalizados!AA4,Items_Normalizados!AB4,Items_Normalizados!AC4,Items_Normalizados!AD4),"") | L4: =IFERROR(AVERAGE(Items_Normalizados!AA4,Items_Normalizados!AD4),"") | M4: =Items_Normalizados!AB4 | N4: =Items_Normalizados!AC4 | O4: =IFERROR(AVERAGE(Items_Normalizados!AE4,Items_Normalizados!AF4),"") | P4: =Items_Normalizados!AG4 | Q4: =IFERROR(AVERAGE(Items_Normalizados!AH4,Items_Normalizados!AI4,Items_Normalizados!AJ4,Items_Normalizados!AK4),"") | R4: =IFERROR(AVERAGE(Items_Normalizados!AJ4,Items_Normalizados!AK4),"") | S4: =IFERROR(AVERAGE(Items_Normalizados!AL4,Items_Normalizados!AM4,Items_Normalizados!AN4),"") | T4: =IFERROR(Datos_Crudos!AQ4/7*100,"") | U4: =IF(Datos_Crudos!AR4>=3,100,IF(Datos_Crudos!AR4=2,66,IF(Datos_Crudos!AR4=1,33,0))) | V4: =Items_Normalizados!AS4 | W4: =Items_Normalizados!AT4 | X4: =IFERROR(Datos_Crudos!AV4/Datos_Crudos!AU4,"") | Y4: =IFERROR((X4-MIN($X$2:$X$9))/(MAX($X$2:$X$9)-MIN($X$2:$X$9))*100,50) | Z4: =IFERROR(Datos_Crudos!AW4/Datos_Crudos!AX4*100,"") | AA4: =IFERROR(MIN(100,100/Datos_Crudos!AY4),100) | AB4: =Datos_Crudos!AO4 | AC4: =IF(AB4="Si, totalmente","ALERTA: falsa seguridad","OK") | AD4: =Datos_Crudos!AP4 | AE4: =Items_Normalizados!AZ4
A5: =Datos_Crudos!A5 | B5: =IFERROR(AVERAGE(Items_Normalizados!C5,Items_Normalizados!D5,Items_Normalizados!E5,Items_Normalizados!F5),"") | C5: =IFERROR(AVERAGE(Items_Normalizados!G5,Items_Normalizados!H5,Items_Normalizados!I5,Items_Normalizados!J5,Items_Normalizados!K5),"") | D5: =Items_Normalizados!K5 | E5: =Datos_Crudos!L5 | F5: =IF(Datos_Crudos!L5="","(sin dato)",IF(Datos_Crudos!L5<=1,"ALERTA: mezcla sin control","OK")) | G5: =IFERROR(AVERAGE(Items_Normalizados!M5,Items_Normalizados!N5,Items_Normalizados!O5,Items_Normalizados!Q5,Items_Normalizados!R5,Items_Normalizados!S5),"") | H5: =Items_Normalizados!P5 | I5: =IFERROR(AVERAGE(Items_Normalizados!T5,Items_Normalizados!U5,Items_Normalizados!V5),"") | J5: =IFERROR(AVERAGE(Items_Normalizados!W5,Items_Normalizados!X5,Items_Normalizados!Y5,Items_Normalizados!Z5),"") | K5: =IFERROR(AVERAGE(Items_Normalizados!AA5,Items_Normalizados!AB5,Items_Normalizados!AC5,Items_Normalizados!AD5),"") | L5: =IFERROR(AVERAGE(Items_Normalizados!AA5,Items_Normalizados!AD5),"") | M5: =Items_Normalizados!AB5 | N5: =Items_Normalizados!AC5 | O5: =IFERROR(AVERAGE(Items_Normalizados!AE5,Items_Normalizados!AF5),"") | P5: =Items_Normalizados!AG5 | Q5: =IFERROR(AVERAGE(Items_Normalizados!AH5,Items_Normalizados!AI5,Items_Normalizados!AJ5,Items_Normalizados!AK5),"") | R5: =IFERROR(AVERAGE(Items_Normalizados!AJ5,Items_Normalizados!AK5),"") | S5: =IFERROR(AVERAGE(Items_Normalizados!AL5,Items_Normalizados!AM5,Items_Normalizados!AN5),"") | T5: =IFERROR(Datos_Crudos!AQ5/7*100,"") | U5: =IF(Datos_Crudos!AR5>=3,100,IF(Datos_Crudos!AR5=2,66,IF(Datos_Crudos!AR5=1,33,0))) | V5: =Items_Normalizados!AS5 | W5: =Items_Normalizados!AT5 | X5: =IFERROR(Datos_Crudos!AV5/Datos_Crudos!AU5,"") | Y5: =IFERROR((X5-MIN($X$2:$X$9))/(MAX($X$2:$X$9)-MIN($X$2:$X$9))*100,50) | Z5: =IFERROR(Datos_Crudos!AW5/Datos_Crudos!AX5*100,"") | AA5: =IFERROR(MIN(100,100/Datos_Crudos!AY5),100) | AB5: =Datos_Crudos!AO5 | AC5: =IF(AB5="Si, totalmente","ALERTA: falsa seguridad","OK") | AD5: =Datos_Crudos!AP5 | AE5: =Items_Normalizados!AZ5
A6: =Datos_Crudos!A6 | B6: =IFERROR(AVERAGE(Items_Normalizados!C6,Items_Normalizados!D6,Items_Normalizados!E6,Items_Normalizados!F6),"") | C6: =IFERROR(AVERAGE(Items_Normalizados!G6,Items_Normalizados!H6,Items_Normalizados!I6,Items_Normalizados!J6,Items_Normalizados!K6),"") | D6: =Items_Normalizados!K6 | E6: =Datos_Crudos!L6 | F6: =IF(Datos_Crudos!L6="","(sin dato)",IF(Datos_Crudos!L6<=1,"ALERTA: mezcla sin control","OK")) | G6: =IFERROR(AVERAGE(Items_Normalizados!M6,Items_Normalizados!N6,Items_Normalizados!O6,Items_Normalizados!Q6,Items_Normalizados!R6,Items_Normalizados!S6),"") | H6: =Items_Normalizados!P6 | I6: =IFERROR(AVERAGE(Items_Normalizados!T6,Items_Normalizados!U6,Items_Normalizados!V6),"") | J6: =IFERROR(AVERAGE(Items_Normalizados!W6,Items_Normalizados!X6,Items_Normalizados!Y6,Items_Normalizados!Z6),"") | K6: =IFERROR(AVERAGE(Items_Normalizados!AA6,Items_Normalizados!AB6,Items_Normalizados!AC6,Items_Normalizados!AD6),"") | L6: =IFERROR(AVERAGE(Items_Normalizados!AA6,Items_Normalizados!AD6),"") | M6: =Items_Normalizados!AB6 | N6: =Items_Normalizados!AC6 | O6: =IFERROR(AVERAGE(Items_Normalizados!AE6,Items_Normalizados!AF6),"") | P6: =Items_Normalizados!AG6 | Q6: =IFERROR(AVERAGE(Items_Normalizados!AH6,Items_Normalizados!AI6,Items_Normalizados!AJ6,Items_Normalizados!AK6),"") | R6: =IFERROR(AVERAGE(Items_Normalizados!AJ6,Items_Normalizados!AK6),"") | S6: =IFERROR(AVERAGE(Items_Normalizados!AL6,Items_Normalizados!AM6,Items_Normalizados!AN6),"") | T6: =IFERROR(Datos_Crudos!AQ6/7*100,"") | U6: =IF(Datos_Crudos!AR6>=3,100,IF(Datos_Crudos!AR6=2,66,IF(Datos_Crudos!AR6=1,33,0))) | V6: =Items_Normalizados!AS6 | W6: =Items_Normalizados!AT6 | X6: =IFERROR(Datos_Crudos!AV6/Datos_Crudos!AU6,"") | Y6: =IFERROR((X6-MIN($X$2:$X$9))/(MAX($X$2:$X$9)-MIN($X$2:$X$9))*100,50) | Z6: =IFERROR(Datos_Crudos!AW6/Datos_Crudos!AX6*100,"") | AA6: =IFERROR(MIN(100,100/Datos_Crudos!AY6),100) | AB6: =Datos_Crudos!AO6 | AC6: =IF(AB6="Si, totalmente","ALERTA: falsa seguridad","OK") | AD6: =Datos_Crudos!AP6 | AE6: =Items_Normalizados!AZ6
A7: =Datos_Crudos!A7 | B7: =IFERROR(AVERAGE(Items_Normalizados!C7,Items_Normalizados!D7,Items_Normalizados!E7,Items_Normalizados!F7),"") | C7: =IFERROR(AVERAGE(Items_Normalizados!G7,Items_Normalizados!H7,Items_Normalizados!I7,Items_Normalizados!J7,Items_Normalizados!K7),"") | D7: =Items_Normalizados!K7 | E7: =Datos_Crudos!L7 | F7: =IF(Datos_Crudos!L7="","(sin dato)",IF(Datos_Crudos!L7<=1,"ALERTA: mezcla sin control","OK")) | G7: =IFERROR(AVERAGE(Items_Normalizados!M7,Items_Normalizados!N7,Items_Normalizados!O7,Items_Normalizados!Q7,Items_Normalizados!R7,Items_Normalizados!S7),"") | H7: =Items_Normalizados!P7 | I7: =IFERROR(AVERAGE(Items_Normalizados!T7,Items_Normalizados!U7,Items_Normalizados!V7),"") | J7: =IFERROR(AVERAGE(Items_Normalizados!W7,Items_Normalizados!X7,Items_Normalizados!Y7,Items_Normalizados!Z7),"") | K7: =IFERROR(AVERAGE(Items_Normalizados!AA7,Items_Normalizados!AB7,Items_Normalizados!AC7,Items_Normalizados!AD7),"") | L7: =IFERROR(AVERAGE(Items_Normalizados!AA7,Items_Normalizados!AD7),"") | M7: =Items_Normalizados!AB7 | N7: =Items_Normalizados!AC7 | O7: =IFERROR(AVERAGE(Items_Normalizados!AE7,Items_Normalizados!AF7),"") | P7: =Items_Normalizados!AG7 | Q7: =IFERROR(AVERAGE(Items_Normalizados!AH7,Items_Normalizados!AI7,Items_Normalizados!AJ7,Items_Normalizados!AK7),"") | R7: =IFERROR(AVERAGE(Items_Normalizados!AJ7,Items_Normalizados!AK7),"") | S7: =IFERROR(AVERAGE(Items_Normalizados!AL7,Items_Normalizados!AM7,Items_Normalizados!AN7),"") | T7: =IFERROR(Datos_Crudos!AQ7/7*100,"") | U7: =IF(Datos_Crudos!AR7>=3,100,IF(Datos_Crudos!AR7=2,66,IF(Datos_Crudos!AR7=1,33,0))) | V7: =Items_Normalizados!AS7 | W7: =Items_Normalizados!AT7 | X7: =IFERROR(Datos_Crudos!AV7/Datos_Crudos!AU7,"") | Y7: =IFERROR((X7-MIN($X$2:$X$9))/(MAX($X$2:$X$9)-MIN($X$2:$X$9))*100,50) | Z7: =IFERROR(Datos_Crudos!AW7/Datos_Crudos!AX7*100,"") | AA7: =IFERROR(MIN(100,100/Datos_Crudos!AY7),100) | AB7: =Datos_Crudos!AO7 | AC7: =IF(AB7="Si, totalmente","ALERTA: falsa seguridad","OK") | AD7: =Datos_Crudos!AP7 | AE7: =Items_Normalizados!AZ7
A8: =Datos_Crudos!A8 | B8: =IFERROR(AVERAGE(Items_Normalizados!C8,Items_Normalizados!D8,Items_Normalizados!E8,Items_Normalizados!F8),"") | C8: =IFERROR(AVERAGE(Items_Normalizados!G8,Items_Normalizados!H8,Items_Normalizados!I8,Items_Normalizados!J8,Items_Normalizados!K8),"") | D8: =Items_Normalizados!K8 | E8: =Datos_Crudos!L8 | F8: =IF(Datos_Crudos!L8="","(sin dato)",IF(Datos_Crudos!L8<=1,"ALERTA: mezcla sin control","OK")) | G8: =IFERROR(AVERAGE(Items_Normalizados!M8,Items_Normalizados!N8,Items_Normalizados!O8,Items_Normalizados!Q8,Items_Normalizados!R8,Items_Normalizados!S8),"") | H8: =Items_Normalizados!P8 | I8: =IFERROR(AVERAGE(Items_Normalizados!T8,Items_Normalizados!U8,Items_Normalizados!V8),"") | J8: =IFERROR(AVERAGE(Items_Normalizados!W8,Items_Normalizados!X8,Items_Normalizados!Y8,Items_Normalizados!Z8),"") | K8: =IFERROR(AVERAGE(Items_Normalizados!AA8,Items_Normalizados!AB8,Items_Normalizados!AC8,Items_Normalizados!AD8),"") | L8: =IFERROR(AVERAGE(Items_Normalizados!AA8,Items_Normalizados!AD8),"") | M8: =Items_Normalizados!AB8 | N8: =Items_Normalizados!AC8 | O8: =IFERROR(AVERAGE(Items_Normalizados!AE8,Items_Normalizados!AF8),"") | P8: =Items_Normalizados!AG8 | Q8: =IFERROR(AVERAGE(Items_Normalizados!AH8,Items_Normalizados!AI8,Items_Normalizados!AJ8,Items_Normalizados!AK8),"") | R8: =IFERROR(AVERAGE(Items_Normalizados!AJ8,Items_Normalizados!AK8),"") | S8: =IFERROR(AVERAGE(Items_Normalizados!AL8,Items_Normalizados!AM8,Items_Normalizados!AN8),"") | T8: =IFERROR(Datos_Crudos!AQ8/7*100,"") | U8: =IF(Datos_Crudos!AR8>=3,100,IF(Datos_Crudos!AR8=2,66,IF(Datos_Crudos!AR8=1,33,0))) | V8: =Items_Normalizados!AS8 | W8: =Items_Normalizados!AT8 | X8: =IFERROR(Datos_Crudos!AV8/Datos_Crudos!AU8,"") | Y8: =IFERROR((X8-MIN($X$2:$X$9))/(MAX($X$2:$X$9)-MIN($X$2:$X$9))*100,50) | Z8: =IFERROR(Datos_Crudos!AW8/Datos_Crudos!AX8*100,"") | AA8: =IFERROR(MIN(100,100/Datos_Crudos!AY8),100) | AB8: =Datos_Crudos!AO8 | AC8: =IF(AB8="Si, totalmente","ALERTA: falsa seguridad","OK") | AD8: =Datos_Crudos!AP8 | AE8: =Items_Normalizados!AZ8
A9: =Datos_Crudos!A9 | B9: =IFERROR(AVERAGE(Items_Normalizados!C9,Items_Normalizados!D9,Items_Normalizados!E9,Items_Normalizados!F9),"") | C9: =IFERROR(AVERAGE(Items_Normalizados!G9,Items_Normalizados!H9,Items_Normalizados!I9,Items_Normalizados!J9,Items_Normalizados!K9),"") | D9: =Items_Normalizados!K9 | E9: =Datos_Crudos!L9 | F9: =IF(Datos_Crudos!L9="","(sin dato)",IF(Datos_Crudos!L9<=1,"ALERTA: mezcla sin control","OK")) | G9: =IFERROR(AVERAGE(Items_Normalizados!M9,Items_Normalizados!N9,Items_Normalizados!O9,Items_Normalizados!Q9,Items_Normalizados!R9,Items_Normalizados!S9),"") | H9: =Items_Normalizados!P9 | I9: =IFERROR(AVERAGE(Items_Normalizados!T9,Items_Normalizados!U9,Items_Normalizados!V9),"") | J9: =IFERROR(AVERAGE(Items_Normalizados!W9,Items_Normalizados!X9,Items_Normalizados!Y9,Items_Normalizados!Z9),"") | K9: =IFERROR(AVERAGE(Items_Normalizados!AA9,Items_Normalizados!AB9,Items_Normalizados!AC9,Items_Normalizados!AD9),"") | L9: =IFERROR(AVERAGE(Items_Normalizados!AA9,Items_Normalizados!AD9),"") | M9: =Items_Normalizados!AB9 | N9: =Items_Normalizados!AC9 | O9: =IFERROR(AVERAGE(Items_Normalizados!AE9,Items_Normalizados!AF9),"") | P9: =Items_Normalizados!AG9 | Q9: =IFERROR(AVERAGE(Items_Normalizados!AH9,Items_Normalizados!AI9,Items_Normalizados!AJ9,Items_Normalizados!AK9),"") | R9: =IFERROR(AVERAGE(Items_Normalizados!AJ9,Items_Normalizados!AK9),"") | S9: =IFERROR(AVERAGE(Items_Normalizados!AL9,Items_Normalizados!AM9,Items_Normalizados!AN9),"") | T9: =IFERROR(Datos_Crudos!AQ9/7*100,"") | U9: =IF(Datos_Crudos!AR9>=3,100,IF(Datos_Crudos!AR9=2,66,IF(Datos_Crudos!AR9=1,33,0))) | V9: =Items_Normalizados!AS9 | W9: =Items_Normalizados!AT9 | X9: =IFERROR(Datos_Crudos!AV9/Datos_Crudos!AU9,"") | Y9: =IFERROR((X9-MIN($X$2:$X$9))/(MAX($X$2:$X$9)-MIN($X$2:$X$9))*100,50) | Z9: =IFERROR(Datos_Crudos!AW9/Datos_Crudos!AX9*100,"") | AA9: =IFERROR(MIN(100,100/Datos_Crudos!AY9),100) | AB9: =Datos_Crudos!AO9 | AC9: =IF(AB9="Si, totalmente","ALERTA: falsa seguridad","OK") | AD9: =Datos_Crudos!AP9 | AE9: =Items_Normalizados!AZ9

Sheet ISA
A1: Organizacion | B1: Nucleo_D1D7 (geometrica) | C1: Extendido_D8D9 (aritmetica) | D1: N dimensiones nucleo con dato | E1: N dimensiones extendido con dato | F1: ISA final (0-100) | G1: Estado
A2: =Datos_Crudos!A2 | B2: =IF(COUNT(Dimensiones!B2,Dimensiones!C2,Dimensiones!G2,Dimensiones!I2,Dimensiones!J2,Dimensiones!K2,Dimensiones!O2)=0,"",PRODUCT(Dimensiones!B2,Dimensiones!C2,Dimensiones!G2,Dimensiones!I2,Dimensiones!J2,Dimensiones!K2,Dimensiones!O2)^(1/COUNT(Dimensiones!B2,Dimensiones!C2,Dimensiones!G2,Dimensiones!I2,Dimensiones!J2,Dimensiones!K2,Dimensiones!O2))) | C2: =IFERROR(AVERAGE(Dimensiones!Q2,Dimensiones!S2),"") | D2: =COUNT(Dimensiones!B2,Dimensiones!C2,Dimensiones!G2,Dimensiones!I2,Dimensiones!J2,Dimensiones!K2,Dimensiones!O2) | E2: =COUNT(Dimensiones!Q2,Dimensiones!S2) | F2: =IF(B2="","",IF(D2=0,B2,0.875*B2+0.125*C2)) | G2: =IF(E2>=6,"ISA numerico","Diagnostico incompleto (aproximacion, ver Leeme)")
A3: =Datos_Crudos!A3 | B3: =IF(COUNT(Dimensiones!B3,Dimensiones!C3,Dimensiones!G3,Dimensiones!I3,Dimensiones!J3,Dimensiones!K3,Dimensiones!O3)=0,"",PRODUCT(Dimensiones!B3,Dimensiones!C3,Dimensiones!G3,Dimensiones!I3,Dimensiones!J3,Dimensiones!K3,Dimensiones!O3)^(1/COUNT(Dimensiones!B3,Dimensiones!C3,Dimensiones!G3,Dimensiones!I3,Dimensiones!J3,Dimensiones!K3,Dimensiones!O3))) | C3: =IFERROR(AVERAGE(Dimensiones!Q3,Dimensiones!S3),"") | D3: =COUNT(Dimensiones!B3,Dimensiones!C3,Dimensiones!G3,Dimensiones!I3,Dimensiones!J3,Dimensiones!K3,Dimensiones!O3) | E3: =COUNT(Dimensiones!Q3,Dimensiones!S3) | F3: =IF(B3="","",IF(D3=0,B3,0.875*B3+0.125*C3)) | G3: =IF(E3>=6,"ISA numerico","Diagnostico incompleto (aproximacion, ver Leeme)")
A4: =Datos_Crudos!A4 | B4: =IF(COUNT(Dimensiones!B4,Dimensiones!C4,Dimensiones!G4,Dimensiones!I4,Dimensiones!J4,Dimensiones!K4,Dimensiones!O4)=0,"",PRODUCT(Dimensiones!B4,Dimensiones!C4,Dimensiones!G4,Dimensiones!I4,Dimensiones!J4,Dimensiones!K4,Dimensiones!O4)^(1/COUNT(Dimensiones!B4,Dimensiones!C4,Dimensiones!G4,Dimensiones!I4,Dimensiones!J4,Dimensiones!K4,Dimensiones!O4))) | C4: =IFERROR(AVERAGE(Dimensiones!Q4,Dimensiones!S4),"") | D4: =COUNT(Dimensiones!B4,Dimensiones!C4,Dimensiones!G4,Dimensiones!I4,Dimensiones!J4,Dimensiones!K4,Dimensiones!O4) | E4: =COUNT(Dimensiones!Q4,Dimensiones!S4) | F4: =IF(B4="","",IF(D4=0,B4,0.875*B4+0.125*C4)) | G4: =IF(E4>=6,"ISA numerico","Diagnostico incompleto (aproximacion, ver Leeme)")
A5: =Datos_Crudos!A5 | B5: =IF(COUNT(Dimensiones!B5,Dimensiones!C5,Dimensiones!G5,Dimensiones!I5,Dimensiones!J5,Dimensiones!K5,Dimensiones!O5)=0,"",PRODUCT(Dimensiones!B5,Dimensiones!C5,Dimensiones!G5,Dimensiones!I5,Dimensiones!J5,Dimensiones!K5,Dimensiones!O5)^(1/COUNT(Dimensiones!B5,Dimensiones!C5,Dimensiones!G5,Dimensiones!I5,Dimensiones!J5,Dimensiones!K5,Dimensiones!O5))) | C5: =IFERROR(AVERAGE(Dimensiones!Q5,Dimensiones!S5),"") | D5: =COUNT(Dimensiones!B5,Dimensiones!C5,Dimensiones!G5,Dimensiones!I5,Dimensiones!J5,Dimensiones!K5,Dimensiones!O5) | E5: =COUNT(Dimensiones!Q5,Dimensiones!S5) | F5: =IF(B5="","",IF(D5=0,B5,0.875*B5+0.125*C5)) | G5: =IF(E5>=6,"ISA numerico","Diagnostico incompleto (aproximacion, ver Leeme)")
A6: =Datos_Crudos!A6 | B6: =IF(COUNT(Dimensiones!B6,Dimensiones!C6,Dimensiones!G6,Dimensiones!I6,Dimensiones!J6,Dimensiones!K6,Dimensiones!O6)=0,"",PRODUCT(Dimensiones!B6,Dimensiones!C6,Dimensiones!G6,Dimensiones!I6,Dimensiones!J6,Dimensiones!K6,Dimensiones!O6)^(1/COUNT(Dimensiones!B6,Dimensiones!C6,Dimensiones!G6,Dimensiones!I6,Dimensiones!J6,Dimensiones!K6,Dimensiones!O6))) | C6: =IFERROR(AVERAGE(Dimensiones!Q6,Dimensiones!S6),"") | D6: =COUNT(Dimensiones!B6,Dimensiones!C6,Dimensiones!G6,Dimensiones!I6,Dimensiones!J6,Dimensiones!K6,Dimensiones!O6) | E6: =COUNT(Dimensiones!Q6,Dimensiones!S6) | F6: =IF(B6="","",IF(D6=0,B6,0.875*B6+0.125*C6)) | G6: =IF(E6>=6,"ISA numerico","Diagnostico incompleto (aproximacion, ver Leeme)")
A7: =Datos_Crudos!A7 | B7: =IF(COUNT(Dimensiones!B7,Dimensiones!C7,Dimensiones!G7,Dimensiones!I7,Dimensiones!J7,Dimensiones!K7,Dimensiones!O7)=0,"",PRODUCT(Dimensiones!B7,Dimensiones!C7,Dimensiones!G7,Dimensiones!I7,Dimensiones!J7,Dimensiones!K7,Dimensiones!O7)^(1/COUNT(Dimensiones!B7,Dimensiones!C7,Dimensiones!G7,Dimensiones!I7,Dimensiones!J7,Dimensiones!K7,Dimensiones!O7))) | C7: =IFERROR(AVERAGE(Dimensiones!Q7,Dimensiones!S7),"") | D7: =COUNT(Dimensiones!B7,Dimensiones!C7,Dimensiones!G7,Dimensiones!I7,Dimensiones!J7,Dimensiones!K7,Dimensiones!O7) | E7: =COUNT(Dimensiones!Q7,Dimensiones!S7) | F7: =IF(B7="","",IF(D7=0,B7,0.875*B7+0.125*C7)) | G7: =IF(E7>=6,"ISA numerico","Diagnostico incompleto (aproximacion, ver Leeme)")
A8: =Datos_Crudos!A8 | B8: =IF(COUNT(Dimensiones!B8,Dimensiones!C8,Dimensiones!G8,Dimensiones!I8,Dimensiones!J8,Dimensiones!K8,Dimensiones!O8)=0,"",PRODUCT(Dimensiones!B8,Dimensiones!C8,Dimensiones!G8,Dimensiones!I8,Dimensiones!J8,Dimensiones!K8,Dimensiones!O8)^(1/COUNT(Dimensiones!B8,Dimensiones!C8,Dimensiones!G8,Dimensiones!I8,Dimensiones!J8,Dimensiones!K8,Dimensiones!O8))) | C8: =IFERROR(AVERAGE(Dimensiones!Q8,Dimensiones!S8),"") | D8: =COUNT(Dimensiones!B8,Dimensiones!C8,Dimensiones!G8,Dimensiones!I8,Dimensiones!J8,Dimensiones!K8,Dimensiones!O8) | E8: =COUNT(Dimensiones!Q8,Dimensiones!S8) | F8: =IF(B8="","",IF(D8=0,B8,0.875*B8+0.125*C8)) | G8: =IF(E8>=6,"ISA numerico","Diagnostico incompleto (aproximacion, ver Leeme)")
A9: =Datos_Crudos!A9 | B9: =IF(COUNT(Dimensiones!B9,Dimensiones!C9,Dimensiones!G9,Dimensiones!I9,Dimensiones!J9,Dimensiones!K9,Dimensiones!O9)=0,"",PRODUCT(Dimensiones!B9,Dimensiones!C9,Dimensiones!G9,Dimensiones!I9,Dimensiones!J9,Dimensiones!K9,Dimensiones!O9)^(1/COUNT(Dimensiones!B9,Dimensiones!C9,Dimensiones!G9,Dimensiones!I9,Dimensiones!J9,Dimensiones!K9,Dimensiones!O9))) | C9: =IFERROR(AVERAGE(Dimensiones!Q9,Dimensiones!S9),"") | D9: =COUNT(Dimensiones!B9,Dimensiones!C9,Dimensiones!G9,Dimensiones!I9,Dimensiones!J9,Dimensiones!K9,Dimensiones!O9) | E9: =COUNT(Dimensiones!Q9,Dimensiones!S9) | F9: =IF(B9="","",IF(D9=0,B9,0.875*B9+0.125*C9)) | G9: =IF(E9>=6,"ISA numerico","Diagnostico incompleto (aproximacion, ver Leeme)")

Sheet AHP_Pesos
A2: Matriz de comparacion pareada - Indice de Preparacion (IP)
A3: Escriba SOLO en el triangulo superior (celdas claras) la razon de Saaty: 1=igual, 3=moderada, 5=fuerte, 7=muy fuerte, 9=extrema (o su reciproco 1/3,1/5... si la columna pesa mas que la fila). El triangulo inferior y la diagonal se calculan solos.
B4: 1 | C4: 2 | D4: 3 | E4: 4 | F4: 5
A5: 1. Trazabilidad y origen | B5: 1
A6: 2. Cumplimiento ambiental | B6: =IFERROR(1/C5,"") | C6: 1
A7: 3. Capacidades organizacionales | B7: =IFERROR(1/D5,"") | C7: =IFERROR(1/D6,"") | D7: 1
A8: 4. Informacion y documentacion | B8: =IFERROR(1/E5,"") | C8: =IFERROR(1/E6,"") | D8: =IFERROR(1/E7,"") | E8: 1
A9: 5. Capacidad de adaptacion y recursos | B9: =IFERROR(1/F5,"") | C9: =IFERROR(1/F6,"") | D9: =IFERROR(1/F7,"") | E9: =IFERROR(1/F8,"") | F9: 1
A10: Suma columna | B10: =SUM(B5:B9) | C10: =SUM(C5:C9) | D10: =SUM(D5:D9) | E10: =SUM(E5:E9) | F10: =SUM(F5:F9)
A11: Matriz normalizada y vector de prioridad
B12: 1 | C12: 2 | D12: 3 | E12: 4 | F12: 5 | G12: Peso (%)
B13: =IFERROR(B5/B10,"") | C13: =IFERROR(C5/C10,"") | D13: =IFERROR(D5/D10,"") | E13: =IFERROR(E5/E10,"") | F13: =IFERROR(F5/F10,"") | G13: =IFERROR(AVERAGE(B13:F13),"")
B14: =IFERROR(B6/B10,"") | C14: =IFERROR(C6/C10,"") | D14: =IFERROR(D6/D10,"") | E14: =IFERROR(E6/E10,"") | F14: =IFERROR(F6/F10,"") | G14: =IFERROR(AVERAGE(B14:F14),"")
B15: =IFERROR(B7/B10,"") | C15: =IFERROR(C7/C10,"") | D15: =IFERROR(D7/D10,"") | E15: =IFERROR(E7/E10,"") | F15: =IFERROR(F7/F10,"") | G15: =IFERROR(AVERAGE(B15:F15),"")
B16: =IFERROR(B8/B10,"") | C16: =IFERROR(C8/C10,"") | D16: =IFERROR(D8/D10,"") | E16: =IFERROR(E8/E10,"") | F16: =IFERROR(F8/F10,"") | G16: =IFERROR(AVERAGE(B16:F16),"")
B17: =IFERROR(B9/B10,"") | C17: =IFERROR(C9/C10,"") | D17: =IFERROR(D9/D10,"") | E17: =IFERROR(E9/E10,"") | F17: =IFERROR(F9/F10,"") | G17: =IFERROR(AVERAGE(B17:F17),"")
A19: Lambda max | B19: =IFERROR(AVERAGE(B20:B24),"")
A20: Fila 1: suma ponderada / peso | B20: =IFERROR((B5*G13+C5*G14+D5*G15+E5*G16+F5*G17)/G13,"")
A21: Fila 2: suma ponderada / peso | B21: =IFERROR((B6*G13+C6*G14+D6*G15+E6*G16+F6*G17)/G14,"")
A22: Fila 3: suma ponderada / peso | B22: =IFERROR((B7*G13+C7*G14+D7*G15+E7*G16+F7*G17)/G15,"")
A23: Fila 4: suma ponderada / peso | B23: =IFERROR((B8*G13+C8*G14+D8*G15+E8*G16+F8*G17)/G16,"")
A24: Fila 5: suma ponderada / peso | B24: =IFERROR((B9*G13+C9*G14+D9*G15+E9*G16+F9*G17)/G17,"")
A26: CI = (Lambda max - n) / (n-1) | B26: =IFERROR((B19-5)/(5-1),"")
A27: CR = CI / RI (RI=1.12 para n=5) | B27: =IFERROR(B26/1.12,"")
A28: =IF(B27="","(completar las 10 comparaciones para ver el CR)",IF(B27<=0.10,"CR aceptable (<=0.10, Saaty 2008)","CR alto - revisar comparaciones, hay contradicciones"))
A40: Matriz de comparacion pareada - Indice de Vulnerabilidad (IV)
A41: Escriba SOLO en el triangulo superior (celdas claras) la razon de Saaty: 1=igual, 3=moderada, 5=fuerte, 7=muy fuerte, 9=extrema (o su reciproco 1/3,1/5... si la columna pesa mas que la fila). El triangulo inferior y la diagonal se calculan solos.
B42: 1 | C42: 2 | D42: 3 | E42: 4 | F42: 5
A43: 1. Dependencia mercado europeo | B43: 1
A44: 2. Exposicion regulatoria | B44: =IFERROR(1/C43,"") | C44: 1
A45: 3. Fragilidad productiva/territorial | B45: =IFERROR(1/D43,"") | C45: =IFERROR(1/D44,"") | D45: 1
A46: 4. Brechas tecnologicas/financieras | B46: =IFERROR(1/E43,"") | C46: =IFERROR(1/E44,"") | D46: =IFERROR(1/E45,"") | E46: 1
A47: 5. Riesgo social y comercial | B47: =IFERROR(1/F43,"") | C47: =IFERROR(1/F44,"") | D47: =IFERROR(1/F45,"") | E47: =IFERROR(1/F46,"") | F47: 1
A48: Suma columna | B48: =SUM(B43:B47) | C48: =SUM(C43:C47) | D48: =SUM(D43:D47) | E48: =SUM(E43:E47) | F48: =SUM(F43:F47)
A49: Matriz normalizada y vector de prioridad
B50: 1 | C50: 2 | D50: 3 | E50: 4 | F50: 5 | G50: Peso (%)
B51: =IFERROR(B43/B48,"") | C51: =IFERROR(C43/C48,"") | D51: =IFERROR(D43/D48,"") | E51: =IFERROR(E43/E48,"") | F51: =IFERROR(F43/F48,"") | G51: =IFERROR(AVERAGE(B51:F51),"")
B52: =IFERROR(B44/B48,"") | C52: =IFERROR(C44/C48,"") | D52: =IFERROR(D44/D48,"") | E52: =IFERROR(E44/E48,"") | F52: =IFERROR(F44/F48,"") | G52: =IFERROR(AVERAGE(B52:F52),"")
B53: =IFERROR(B45/B48,"") | C53: =IFERROR(C45/C48,"") | D53: =IFERROR(D45/D48,"") | E53: =IFERROR(E45/E48,"") | F53: =IFERROR(F45/F48,"") | G53: =IFERROR(AVERAGE(B53:F53),"")
B54: =IFERROR(B46/B48,"") | C54: =IFERROR(C46/C48,"") | D54: =IFERROR(D46/D48,"") | E54: =IFERROR(E46/E48,"") | F54: =IFERROR(F46/F48,"") | G54: =IFERROR(AVERAGE(B54:F54),"")
...

Sheet IP
A1: Organizacion | B1: IP1 Trazabilidad y origen | C1: IP2 Cumplimiento ambiental (geometrica) | D1: IP3 Capacidades organizacionales | E1: IP4 Informacion y documentacion | F1: IP5 Capacidad de adaptacion y recursos | G1: IP final (0-100)
A2: =Datos_Crudos!A2 | B2: =Dimensiones!C2 | C2: =IFERROR(SQRT(Dimensiones!G2*Dimensiones!I2),"") | D2: =IFERROR(AVERAGE(Dimensiones!Q2,Dimensiones!J2,Dimensiones!L2),"") | E2: =IFERROR(AVERAGE(Dimensiones!M2,Dimensiones!D2),"") | F2: =IFERROR(AVERAGE(Dimensiones!O2,Dimensiones!S2,Dimensiones!T2,Dimensiones!U2),"") | G2: =IFERROR(B2*AHP_Pesos!B84+C2*AHP_Pesos!B85+D2*AHP_Pesos!B86+E2*AHP_Pesos!B87+F2*AHP_Pesos!B88,"")
A3: =Datos_Crudos!A3 | B3: =Dimensiones!C3 | C3: =IFERROR(SQRT(Dimensiones!G3*Dimensiones!I3),"") | D3: =IFERROR(AVERAGE(Dimensiones!Q3,Dimensiones!J3,Dimensiones!L3),"") | E3: =IFERROR(AVERAGE(Dimensiones!M3,Dimensiones!D3),"") | F3: =IFERROR(AVERAGE(Dimensiones!O3,Dimensiones!S3,Dimensiones!T3,Dimensiones!U3),"") | G3: =IFERROR(B3*AHP_Pesos!B84+C3*AHP_Pesos!B85+D3*AHP_Pesos!B86+E3*AHP_Pesos!B87+F3*AHP_Pesos!B88,"")
A4: =Datos_Crudos!A4 | B4: =Dimensiones!C4 | C4: =IFERROR(SQRT(Dimensiones!G4*Dimensiones!I4),"") | D4: =IFERROR(AVERAGE(Dimensiones!Q4,Dimensiones!J4,Dimensiones!L4),"") | E4: =IFERROR(AVERAGE(Dimensiones!M4,Dimensiones!D4),"") | F4: =IFERROR(AVERAGE(Dimensiones!O4,Dimensiones!S4,Dimensiones!T4,Dimensiones!U4),"") | G4: =IFERROR(B4*AHP_Pesos!B84+C4*AHP_Pesos!B85+D4*AHP_Pesos!B86+E4*AHP_Pesos!B87+F4*AHP_Pesos!B88,"")
A5: =Datos_Crudos!A5 | B5: =Dimensiones!C5 | C5: =IFERROR(SQRT(Dimensiones!G5*Dimensiones!I5),"") | D5: =IFERROR(AVERAGE(Dimensiones!Q5,Dimensiones!J5,Dimensiones!L5),"") | E5: =IFERROR(AVERAGE(Dimensiones!M5,Dimensiones!D5),"") | F5: =IFERROR(AVERAGE(Dimensiones!O5,Dimensiones!S5,Dimensiones!T5,Dimensiones!U5),"") | G5: =IFERROR(B5*AHP_Pesos!B84+C5*AHP_Pesos!B85+D5*AHP_Pesos!B86+E5*AHP_Pesos!B87+F5*AHP_Pesos!B88,"")
A6: =Datos_Crudos!A6 | B6: =Dimensiones!C6 | C6: =IFERROR(SQRT(Dimensiones!G6*Dimensiones!I6),"") | D6: =IFERROR(AVERAGE(Dimensiones!Q6,Dimensiones!J6,Dimensiones!L6),"") | E6: =IFERROR(AVERAGE(Dimensiones!M6,Dimensiones!D6),"") | F6: =IFERROR(AVERAGE(Dimensiones!O6,Dimensiones!S6,Dimensiones!T6,Dimensiones!U6),"") | G6: =IFERROR(B6*AHP_Pesos!B84+C6*AHP_Pesos!B85+D6*AHP_Pesos!B86+E6*AHP_Pesos!B87+F6*AHP_Pesos!B88,"")
A7: =Datos_Crudos!A7 | B7: =Dimensiones!C7 | C7: =IFERROR(SQRT(Dimensiones!G7*Dimensiones!I7),"") | D7: =IFERROR(AVERAGE(Dimensiones!Q7,Dimensiones!J7,Dimensiones!L7),"") | E7: =IFERROR(AVERAGE(Dimensiones!M7,Dimensiones!D7),"") | F7: =IFERROR(AVERAGE(Dimensiones!O7,Dimensiones!S7,Dimensiones!T7,Dimensiones!U7),"") | G7: =IFERROR(B7*AHP_Pesos!B84+C7*AHP_Pesos!B85+D7*AHP_Pesos!B86+E7*AHP_Pesos!B87+F7*AHP_Pesos!B88,"")
A8: =Datos_Crudos!A8 | B8: =Dimensiones!C8 | C8: =IFERROR(SQRT(Dimensiones!G8*Dimensiones!I8),"") | D8: =IFERROR(AVERAGE(Dimensiones!Q8,Dimensiones!J8,Dimensiones!L8),"") | E8: =IFERROR(AVERAGE(Dimensiones!M8,Dimensiones!D8),"") | F8: =IFERROR(AVERAGE(Dimensiones!O8,Dimensiones!S8,Dimensiones!T8,Dimensiones!U8),"") | G8: =IFERROR(B8*AHP_Pesos!B84+C8*AHP_Pesos!B85+D8*AHP_Pesos!B86+E8*AHP_Pesos!B87+F8*AHP_Pesos!B88,"")
A9: =Datos_Crudos!A9 | B9: =Dimensiones!C9 | C9: =IFERROR(SQRT(Dimensiones!G9*Dimensiones!I9),"") | D9: =IFERROR(AVERAGE(Dimensiones!Q9,Dimensiones!J9,Dimensiones!L9),"") | E9: =IFERROR(AVERAGE(Dimensiones!M9,Dimensiones!D9),"") | F9: =IFERROR(AVERAGE(Dimensiones!O9,Dimensiones!S9,Dimensiones!T9,Dimensiones!U9),"") | G9: =IFERROR(B9*AHP_Pesos!B84+C9*AHP_Pesos!B85+D9*AHP_Pesos!B86+E9*AHP_Pesos!B87+F9*AHP_Pesos!B88,"")

Sheet IV
A1: Organizacion | B1: IV1 Dependencia mercado europeo | C1: IV2 Exposicion regulatoria (directo, no invertido) | D1: IV3 Fragilidad productiva/territorial | E1: IV4 Brechas tecnologicas/financieras | F1: IV5 Riesgo social y comercial | G1: IV final (0-100)
A2: =Datos_Crudos!A2 | B2: =IFERROR(AVERAGE(Dimensiones!Z2,Dimensiones!AA2),"") | C2: =Dimensiones!B2 | D2: =IFERROR(AVERAGE(100-Dimensiones!H2,100-Dimensiones!V2,100-Dimensiones!W2,100-Dimensiones!Y2),"") | E2: =IFERROR(AVERAGE(100-Dimensiones!N2,100-Dimensiones!S2),"") | F2: =IFERROR(AVERAGE(100-Dimensiones!O2,100-Dimensiones!R2,100-Dimensiones!AE2),"") | G2: =IFERROR(B2*AHP_Pesos!C84+C2*AHP_Pesos!C85+D2*AHP_Pesos!C86+E2*AHP_Pesos!C87+F2*AHP_Pesos!C88,"")
A3: =Datos_Crudos!A3 | B3: =IFERROR(AVERAGE(Dimensiones!Z3,Dimensiones!AA3),"") | C3: =Dimensiones!B3 | D3: =IFERROR(AVERAGE(100-Dimensiones!H3,100-Dimensiones!V3,100-Dimensiones!W3,100-Dimensiones!Y3),"") | E3: =IFERROR(AVERAGE(100-Dimensiones!N3,100-Dimensiones!S3),"") | F3: =IFERROR(AVERAGE(100-Dimensiones!O3,100-Dimensiones!R3,100-Dimensiones!AE3),"") | G3: =IFERROR(B3*AHP_Pesos!C84+C3*AHP_Pesos!C85+D3*AHP_Pesos!C86+E3*AHP_Pesos!C87+F3*AHP_Pesos!C88,"")
A4: =Datos_Crudos!A4 | B4: =IFERROR(AVERAGE(Dimensiones!Z4,Dimensiones!AA4),"") | C4: =Dimensiones!B4 | D4: =IFERROR(AVERAGE(100-Dimensiones!H4,100-Dimensiones!V4,100-Dimensiones!W4,100-Dimensiones!Y4),"") | E4: =IFERROR(AVERAGE(100-Dimensiones!N4,100-Dimensiones!S4),"") | F4: =IFERROR(AVERAGE(100-Dimensiones!O4,100-Dimensiones!R4,100-Dimensiones!AE4),"") | G4: =IFERROR(B4*AHP_Pesos!C84+C4*AHP_Pesos!C85+D4*AHP_Pesos!C86+E4*AHP_Pesos!C87+F4*AHP_Pesos!C88,"")
A5: =Datos_Crudos!A5 | B5: =IFERROR(AVERAGE(Dimensiones!Z5,Dimensiones!AA5),"") | C5: =Dimensiones!B5 | D5: =IFERROR(AVERAGE(100-Dimensiones!H5,100-Dimensiones!V5,100-Dimensiones!W5,100-Dimensiones!Y5),"") | E5: =IFERROR(AVERAGE(100-Dimensiones!N5,100-Dimensiones!S5),"") | F5: =IFERROR(AVERAGE(100-Dimensiones!O5,100-Dimensiones!R5,100-Dimensiones!AE5),"") | G5: =IFERROR(B5*AHP_Pesos!C84+C5*AHP_Pesos!C85+D5*AHP_Pesos!C86+E5*AHP_Pesos!C87+F5*AHP_Pesos!C88,"")
A6: =Datos_Crudos!A6 | B6: =IFERROR(AVERAGE(Dimensiones!Z6,Dimensiones!AA6),"") | C6: =Dimensiones!B6 | D6: =IFERROR(AVERAGE(100-Dimensiones!H6,100-Dimensiones!V6,100-Dimensiones!W6,100-Dimensiones!Y6),"") | E6: =IFERROR(AVERAGE(100-Dimensiones!N6,100-Dimensiones!S6),"") | F6: =IFERROR(AVERAGE(100-Dimensiones!O6,100-Dimensiones!R6,100-Dimensiones!AE6),"") | G6: =IFERROR(B6*AHP_Pesos!C84+C6*AHP_Pesos!C85+D6*AHP_Pesos!C86+E6*AHP_Pesos!C87+F6*AHP_Pesos!C88,"")
A7: =Datos_Crudos!A7 | B7: =IFERROR(AVERAGE(Dimensiones!Z7,Dimensiones!AA7),"") | C7: =Dimensiones!B7 | D7: =IFERROR(AVERAGE(100-Dimensiones!H7,100-Dimensiones!V7,100-Dimensiones!W7,100-Dimensiones!Y7),"") | E7: =IFERROR(AVERAGE(100-Dimensiones!N7,100-Dimensiones!S7),"") | F7: =IFERROR(AVERAGE(100-Dimensiones!O7,100-Dimensiones!R7,100-Dimensiones!AE7),"") | G7: =IFERROR(B7*AHP_Pesos!C84+C7*AHP_Pesos!C85+D7*AHP_Pesos!C86+E7*AHP_Pesos!C87+F7*AHP_Pesos!C88,"")
A8: =Datos_Crudos!A8 | B8: =IFERROR(AVERAGE(Dimensiones!Z8,Dimensiones!AA8),"") | C8: =Dimensiones!B8 | D8: =IFERROR(AVERAGE(100-Dimensiones!H8,100-Dimensiones!V8,100-Dimensiones!W8,100-Dimensiones!Y8),"") | E8: =IFERROR(AVERAGE(100-Dimensiones!N8,100-Dimensiones!S8),"") | F8: =IFERROR(AVERAGE(100-Dimensiones!O8,100-Dimensiones!R8,100-Dimensiones!AE8),"") | G8: =IFERROR(B8*AHP_Pesos!C84+C8*AHP_Pesos!C85+D8*AHP_Pesos!C86+E8*AHP_Pesos!C87+F8*AHP_Pesos!C88,"")
A9: =Datos_Crudos!A9 | B9: =IFERROR(AVERAGE(Dimensiones!Z9,Dimensiones!AA9),"") | C9: =Dimensiones!B9 | D9: =IFERROR(AVERAGE(100-Dimensiones!H9,100-Dimensiones!V9,100-Dimensiones!W9,100-Dimensiones!Y9),"") | E9: =IFERROR(AVERAGE(100-Dimensiones!N9,100-Dimensiones!S9),"") | F9: =IFERROR(AVERAGE(100-Dimensiones!O9,100-Dimensiones!R9,100-Dimensiones!AE9),"") | G9: =IFERROR(B9*AHP_Pesos!C84+C9*AHP_Pesos!C85+D9*AHP_Pesos!C86+E9*AHP_Pesos!C87+F9*AHP_Pesos!C88,"")

Sheet RE_Tipologia
A1: Organizacion | B1: IP final | C1: IV final | D1: RE = IV*(1-IP/100) | E1: Tipologia (corte = mediana de la muestra)
A2: =Datos_Crudos!A2 | B2: =IP!G2 | C2: =IV!G2 | D2: =IFERROR(C2*(1-B2/100),"") | E2: =IF(OR(B2="",C2=""),"(sin datos)",IF(B2>=MEDIAN(IP!$G$2:$G$9),IF(C2>=MEDIAN(IV!$G$2:$G$9),"Expuestas pero adaptables","Resilientes y mejor posicionadas"),IF(C2>=MEDIAN(IV!$G$2:$G$9),"Riesgo critico de exclusion","Riesgo latente")))
A3: =Datos_Crudos!A3 | B3: =IP!G3 | C3: =IV!G3 | D3: =IFERROR(C3*(1-B3/100),"") | E3: =IF(OR(B3="",C3=""),"(sin datos)",IF(B3>=MEDIAN(IP!$G$2:$G$9),IF(C3>=MEDIAN(IV!$G$2:$G$9),"Expuestas pero adaptables","Resilientes y mejor posicionadas"),IF(C3>=MEDIAN(IV!$G$2:$G$9),"Riesgo critico de exclusion","Riesgo latente")))
A4: =Datos_Crudos!A4 | B4: =IP!G4 | C4: =IV!G4 | D4: =IFERROR(C4*(1-B4/100),"") | E4: =IF(OR(B4="",C4=""),"(sin datos)",IF(B4>=MEDIAN(IP!$G$2:$G$9),IF(C4>=MEDIAN(IV!$G$2:$G$9),"Expuestas pero adaptables","Resilientes y mejor posicionadas"),IF(C4>=MEDIAN(IV!$G$2:$G$9),"Riesgo critico de exclusion","Riesgo latente")))
A5: =Datos_Crudos!A5 | B5: =IP!G5 | C5: =IV!G5 | D5: =IFERROR(C5*(1-B5/100),"") | E5: =IF(OR(B5="",C5=""),"(sin datos)",IF(B5>=MEDIAN(IP!$G$2:$G$9),IF(C5>=MEDIAN(IV!$G$2:$G$9),"Expuestas pero adaptables","Resilientes y mejor posicionadas"),IF(C5>=MEDIAN(IV!$G$2:$G$9),"Riesgo critico de exclusion","Riesgo latente")))
A6: =Datos_Crudos!A6 | B6: =IP!G6 | C6: =IV!G6 | D6: =IFERROR(C6*(1-B6/100),"") | E6: =IF(OR(B6="",C6=""),"(sin datos)",IF(B6>=MEDIAN(IP!$G$2:$G$9),IF(C6>=MEDIAN(IV!$G$2:$G$9),"Expuestas pero adaptables","Resilientes y mejor posicionadas"),IF(C6>=MEDIAN(IV!$G$2:$G$9),"Riesgo critico de exclusion","Riesgo latente")))
A7: =Datos_Crudos!A7 | B7: =IP!G7 | C7: =IV!G7 | D7: =IFERROR(C7*(1-B7/100),"") | E7: =IF(OR(B7="",C7=""),"(sin datos)",IF(B7>=MEDIAN(IP!$G$2:$G$9),IF(C7>=MEDIAN(IV!$G$2:$G$9),"Expuestas pero adaptables","Resilientes y mejor posicionadas"),IF(C7>=MEDIAN(IV!$G$2:$G$9),"Riesgo critico de exclusion","Riesgo latente")))
A8: =Datos_Crudos!A8 | B8: =IP!G8 | C8: =IV!G8 | D8: =IFERROR(C8*(1-B8/100),"") | E8: =IF(OR(B8="",C8=""),"(sin datos)",IF(B8>=MEDIAN(IP!$G$2:$G$9),IF(C8>=MEDIAN(IV!$G$2:$G$9),"Expuestas pero adaptables","Resilientes y mejor posicionadas"),IF(C8>=MEDIAN(IV!$G$2:$G$9),"Riesgo critico de exclusion","Riesgo latente")))
A9: =Datos_Crudos!A9 | B9: =IP!G9 | C9: =IV!G9 | D9: =IFERROR(C9*(1-B9/100),"") | E9: =IF(OR(B9="",C9=""),"(sin datos)",IF(B9>=MEDIAN(IP!$G$2:$G$9),IF(C9>=MEDIAN(IV!$G$2:$G$9),"Expuestas pero adaptables","Resilientes y mejor posicionadas"),IF(C9>=MEDIAN(IV!$G$2:$G$9),"Riesgo critico de exclusion","Riesgo latente")))
A11: El punto de corte alto/bajo usa la MEDIANA de esta muestra (8 organizaciones de ejemplo) - no es un umbral oficial. Se recalcula solo cuando reemplace los datos de ejemplo por datos reales del piloto, tal como indica el Diseno del Indice de Vulnerabilidad (no fijar el corte sin datos).

Sheet Codificacion
A1: Item | B1: Pregunta (resumen) | C1: Tipo | D1: Opciones en orden (mejor -> peor) y valor asignado | E1: Uso
A2: Regla general | B2: - | C2: - | D2: Escala 0-4: se listan las opciones de Instrumento 2 en el orden en que aparecen; la PRIMERA = 4 (mejor/mas preparado), la ULTIMA = 0 (peor), distribuidas uniformemente. Las preguntas de % se escriben directo 0-100. | E2: Convencion aplicada a todos los items salvo excepcion senalada
A3: D1.1 | B3: Introduce el producto directo a la UE | C3: binaria | D3: Si=4 | No=0 | E3: ISA (nucleo) y IV2 (directo, no invertido)
A4: D1.2 | B4: Transforma el producto | C4: binaria | D4: Transforma=4 | No transforma=0 | E4: ISA y IV2
A5: D1.3 | B5: Sabe con certeza su rol | C5: 3 opciones | D5: Si con certeza=4 | Idea aproximada=2 | No sabe=0 | E5: ISA y IV2
A6: D1.4 | B6: Cumple umbrales micro/pequena empresa | C6: 3 opciones | D6: Si=4 | No=2 | No sabe=0 | E6: ISA y IV2
A7: D2.5 | B7: Registro de geolocalizacion | C7: escala 0-4 directa | D7: Ya viene en escala 0-4 del instrumento | E7: ISA (nucleo), IP1
A8: D2.6 | B8: % socios geolocalizados | C8: porcentaje | D8: Escribir directo 0-100 | E8: ISA (nucleo), IP1
A9: D2.7 | B9: Sistema vincula lote-parcela | C9: escala 0-4 directa | D9: Ya viene en escala 0-4 | E9: ISA (nucleo), IP1
A10: D2.8 | B10: Quien levanto la informacion | C10: 5 opciones | D10: Tecnico propio=4 | Consultor=3 | Proyecto cooperacion=2 | Socio por su cuenta=1 | No se ha levantado=0 | E10: IP1
A11: D2.9 | B11: Frecuencia de actualizacion | C11: 4 opciones | D11: Por cosecha=4 | Anual=2.7 | Al ingreso del socio=1.3 | Nunca=0 | E11: IP1, IP4
A12: D2.10 | B12: Mezcla de lotes sin control (BANDERA) | C12: 3 opciones - NO se promedia | D12: Segregacion completa=4 | Se mezcla con registro=2 | Se mezcla sin control=0 | E12: Bandera aparte, nunca en el promedio
... A40: % mujeres en directiva | B40: Nueva - insumo IV5 (hallazgo Vietnam EUDR readiness study 2025) | C40: porcentaje | D40: Escribir directo 0-100 (variable de contexto, NO entra a D1-D9/ISA/IP) | E40: Solo IV5 (invertido) - proxy de riesgo de exclusion por baja representacion
