Workbook

Sheet README
B1: README — Base de organizaciones agrarias por RUC (SUNAT · OECE/RNP · MIDAGRI-PPA · Exportaciones FOB)
B2: 1. CONTENIDO DEL LIBRO Y DE CADA PESTAÑA
B3: Pestaña | C3: Contenido | D3: Archivo / fuente de origen | E3: Filas de datos | F3: RUCs únicos | G3: Rango
B4: README | C4: Esta hoja: documentación del libro, metodología, tratamiento y diccionario de atributos. | D4: — | G4: —
B5: b1 | C5: Hoja preexistente del libro (no modificada). 6 organizaciones con datos de intervención 2025: producto, sede/ubigeo, certificados, beneficiarios, ventas 2018-2025 y comprobantes 2025. | D5: Fuente interna del libro (no documentada en fuentes_urls.md) | E5: =COUNTA('b1'!A2:A7) | F5: {=ROWS(_xlfn.UNIQUE(TRIM('b1'!AD2:AD7&"")))} | G5: b1!A1:AE7
B6: b2 | C6: Hoja preexistente del libro (no modificada). Histórico por organización 2018-2025: intervención, beneficiarios por sexo, asistencia técnica/talleres, ventas nacionales y de exportación, comprobantes. Fila 1 = numeración de columnas; encabezados en fila 2. | D6: Fuente interna del libro (no documentada en fuentes_urls.md) | E6: =COUNTA('b2'!A3:A680) | F6: {=ROWS(_xlfn.UNIQUE(_xlfn._xlws.FILTER(TRIM('b2'!DI3:DI680&""),TRIM('b2'!DI3:DI680&"")<>"")))} | G6: b2!A1:DK680
B7: b3 | C7: Hoja preexistente del libro (no modificada). Ficha de 25 organizaciones cafetaleras con PAC: socios, hectáreas, producción y cosecha 2026, altitud, variedades, certificaciones, calidad, avance EUDR y contactos. | D7: Fuente interna del libro (no documentada en fuentes_urls.md) | E7: =COUNTA('b3'!E2:E26) | F7: {=ROWS(_xlfn.UNIQUE(TRIM('b3'!E2:E26&"")))} | G7: b3!A1:AW26
B8: RUC_ID | C8: Lista maestra RUC + razón social, generada por fórmula (VSTACK) desde b1+b2+b3 (registro interno del programa). 596 RUCs. No incluye 20404057805 (ACOPAGRO), que sí está en rucs.txt/RUC_CONSULTAMASIVA (universo externo de consulta) pero no aparece en b1/b2/b3. | D8: Hoja preexistente del libro / rucs.txt (universo de consulta) | E8: =COUNTA(RUC_ID!A2:A597) | F8: =ROWS(_xlfn.UNIQUE(RUC_ID!A2:A597)) | G8: RUC_ID!A1:B597
B9: RUC_CONSULTAMASIVA | C9: Ficha SUNAT completa por RUC (24 campos): contribuyente, estado/condición, fechas, ubicación, dirección, comercio exterior, CIIU, regímenes. | D9: 9 archivos RM20260919*.txt — Consulta RUC múltiple SUNAT (19/09/2026) | E9: =COUNTA(RUC_CONSULTAMASIVA!A2:A598) | F9: =ROWS(_xlfn.UNIQUE(RUC_CONSULTAMASIVA!A2:A598)) | G9: RUC_CONSULTAMASIVA!A1:X598
B10: RUC_OECE | C10: Ficha de proveedor OECE por RUC: datos SUNAT resumidos + teléfono, email y código de registro RNP. | D10: ruc-oece-ficha.txt (consulta 20/09/2026) | E10: =COUNTA(RUC_OECE!A2:A598) | F10: =ROWS(_xlfn.UNIQUE(RUC_OECE!A2:A598)) | G10: RUC_OECE!A1:L598
B11: RUC_OECE_PERSONAS | C11: Órganos de administración, representantes legales y socios por RUC (DNI, nombre, cargo, fecha de ingreso). Contiene datos personales. | D11: ruc-oece-personas.txt (consulta 20/09/2026) | E11: =COUNTA(RUC_OECE_PERSONAS!A2:A816) | F11: =ROWS(_xlfn.UNIQUE(RUC_OECE_PERSONAS!A2:A816)) | G11: RUC_OECE_PERSONAS!A1:I816
B12: RNP | C12: Subconjunto de RUC_OECE: solo proveedores inscritos en el Registro Nacional de Proveedores (con código de registro). | D12: ruc-oece-ficha-inscritos-rnp.txt (consulta 20/09/2026) | E12: =COUNTA(RNP!A2:A156) | F12: =ROWS(_xlfn.UNIQUE(RNP!A2:A156)) | G12: RNP!A1:L156
B13: RUC_PPA | C13: Inscripción en el Padrón de Productores Agrarios (MIDAGRI) y nombre registrado. | D13: ruc-padron-ppa.txt (consulta 20/09/2026) | E13: =COUNTA(RUC_PPA!A2:A598) | F13: =ROWS(_xlfn.UNIQUE(RUC_PPA!A2:A598)) | G13: RUC_PPA!A1:D598
B14: RUC_FOB | C14: Detalle de exportaciones: una fila por RUC-anio-mes-aduana-agente-pais con valor FOB (USD). Ene-2025 a may-2026 (fuente original, 597 RUC) mas 2024 completo para 33 RUC que ya exportaban en 2025-2026 (fuente historica 2010-2025, ver CTL_FUENTE_CONSULTA fila 8). El resto del universo no tiene 2024. Numero de DUA y canal de control (verde/rojo/naranja) por operacion en RUC_FOB_DUA (pestana nueva, ver CTL_FUENTE_CONSULTA fila 9) -- NO es la partida arancelaria, esa sigue bloqueada por captcha. | D14: ruc-exportaciones-fob.txt (consulta 19/09/2026) mas SUNAT exportaciones 2010-2025.xlsx (archivo aportado por el usuario, cargado 17/09/2026, agregado el 23/09/2026) | E14: =COUNTA(RUC_FOB!A2:A5000) | F14: {=ROWS(_xlfn.UNIQUE(_xlfn._xlws.FILTER(RUC_FOB!A2:A5000,RUC_FOB!A2:A5000<>"")))} | G14: RUC_FOB!A1:K959
B15: RUC_FOB (2) | C15: Resumen de RUC_FOB agrupado por RUC (una fila por RUC), calculado con formulas; fila 69 = totales y fila 70 = control contra el detalle (fila 68 queda en blanco a proposito). Estas dos filas NO son RUCs: estan resaltadas en amarillo con nota en A69; cualquier suma de columna (p.ej. fob_total_usd) debe acotarse a filas 2:67, nunca a la columna completa ni a un rango que incluya 68:70, o se duplica el total. | D15: Derivada de RUC_FOB | E15: =COUNTA('RUC_FOB (2)'!A2:A67) | F15: {=ROWS(_xlfn.UNIQUE('RUC_FOB (2)'!A2:A67))} | G15: RUC_FOB (2)'!A1:M70
B18: 2. METODOLOGÍA DE ACCESO A LOS DATASETS
B19: Universo: rucs.txt (597 RUCs únicos; fuentes_urls.md indica 598). Cada fuente se consultó RUC por RUC sobre ese universo y el resultado se exportó a .txt (campo fecha_consulta en cada fila). Las URLs son las documentadas en fuentes_urls.md como fuentes oficiales para reconstruir o ampliar cada dato.
B20: Dataset (pestaña) | C20: Institución / sistema | D20: Forma de acceso | E20: Fecha de consulta | F20: Fuentes oficiales / endpoints para reconstruir o ampliar | G20: Limitaciones
B21: rucs.txt (RUC_ID) | C21: Input interno | D21: Lista entregada: define el universo de cooperativas y asociaciones agrarias a cruzar | E21: — | F21: No es un dataset público; es la base de partida | G21: Solo contiene el número de RUC
B22: RM20260919*.txt (RUC_CONSULTAMASIVA) | C22: SUNAT — Consulta RUC | D22: Consulta múltiple de RUC en SUNAT, en lotes de hasta 100 RUCs; descarga en .txt separado por '|' (9 archivos) | E22: 19/09/2026 | F22: https://e.sunat.gob.pe/ (formulario web) · APIs de terceros: https://openruc.com/api/ruc/{ruc}, https://docs.apisunat.pe/consulta/sunat-ruc, https://docs.apiperu.dev/referencia/consultar-ruc/ | G22: Formulario con CAPTCHA; no hay API oficial de descarga masiva
B23: ruc-oece-ficha.txt (RUC_OECE) | C23: OECE — ficha de proveedor | D23: GET https://eap.oece.gob.pe/ficha-proveedor-cns/1.0/ficha/{ruc}/resumen (JSON, sin captcha ni sesión — accesible por fetch directo, confirmado en vivo 20/09/2026) más GET https://eap.oece.gob.pe/perfilprov-bus/1.0/ficha/{ruc} para teléfono/email. La misma respuesta trae también la conformación societaria completa (representantes, órganos de administración, socios) con DNI — alimenta a la vez RUC_OECE_PERSONAS y RNP. Ver identidad-fiscal/api/src/ingest/oece-ficha-connector.ts (repo Rastro/appsperu). | E23: 20/09/2026 | F23: https://eap.oece.gob.pe/ficha-proveedor-cns/1.0/ficha (endpoint real usado, no documentado oficialmente por OECE) · https://www.gob.pe/oece · https://contratacionesabiertas.oece.gob.pe · APIs RUC de terceros no usadas: openruc.com, apisunat, apiperu, json.pe | G23: No es una API pública documentada por OECE; depende de que no cambien la ruta ni agreguen autenticación. Teléfono/email solo cuando el RUC figura como proveedor.
B24: ruc-oece-personas.txt (RUC_OECE_PERSONAS) | C24: OECE / RNP — directivos y representantes | D24: Misma consulta que RUC_OECE (GET .../ficha-proveedor-cns/1.0/ficha/{ruc}/resumen): la respuesta JSON trae órganos de administración, representantes y socios con DNI en el mismo payload, sin llamada aparte. | E24: 20/09/2026 | F24: https://eap.oece.gob.pe/ficha-proveedor-cns/1.0/ficha (mismo endpoint que RUC_OECE) · https://contratacionesabiertas.oece.gob.pe (OCDS, no cubre esta estructura) · https://www.gob.pe/institucion/oece/tema/transparencia-y-datos-abiertos · APIs de terceros no usadas: Croma, Apify | G24: No es una API pública documentada por OECE. Contiene datos personales (DNI): uso interno.
B25: ruc-oece-ficha-inscritos-rnp.txt (RNP) | C25: RNP — Registro Nacional de Proveedores | D25: Derivado del mismo payload de RUC_OECE (GET .../ficha-proveedor-cns/1.0/ficha/{ruc}/resumen): se filtra a los RUC cuyo codigo_registro viene no vacío. No requiere consulta aparte ni CAPTCHA — la nota anterior de CAPTCHA correspondía al portal web público del RNP, no al endpoint realmente usado. | E25: 20/09/2026 | F25: https://eap.oece.gob.pe/ficha-proveedor-cns/1.0/ficha (mismo endpoint que RUC_OECE) · portal web con CAPTCHA no usado: https://www.rnp.gob.pe/Constancia/RNP_Constancia/ConsultaRuc.asp · https://www.rnp.gob.pe/Constancia/RNP_Constancia/ConsultaRucEyC.asp | G25: No es una API pública documentada por OECE (comparte limitación con RUC_OECE).
B26: ruc-padron-ppa.txt (RUC_PPA) | C26: MIDAGRI — Padrón de Productores Agrarios | D26: GET https://gateway.midagri.gob.pe/sisppa/api/services/app/Consulta/GetNombreConsulta?codDocumento=6&Documento={ruc} (JSON, API interna ABP Framework, sin captcha ni sesión — accesible por fetch directo, confirmado en vivo 20/09/2026). codDocumento=6 = RUC, confirmado en vivo probando valores. Ver identidad-fiscal/api/src/ingest/padron-ppa-connector.ts (repo Rastro/appsperu). | E26: 20/09/2026 | F26: https://gateway.midagri.gob.pe/sisppa/api/services/app/Consulta/GetNombreConsulta (endpoint real usado, no documentado oficialmente por MIDAGRI) · https://ppa.midagri.gob.pe · ficha técnica PDF · trámite gob.pe | G26: No es una API pública documentada por MIDAGRI; depende de que no cambien la ruta del gateway ABP ni agreguen autenticación.
B27: ruc-exportaciones-fob.txt (RUC_FOB) | C27: SUNAT — Aduanas (exportaciones) | D27: GET por RUC y año contra el endpoint HTML "Consulta por Importador/Exportador" de Aduanet (no es una API pública documentada, pero no está bloqueado para fetch directo — confirmado en vivo el 19/09/2026). Filtra régimen=40 (exportación definitiva). El parámetro de año no es el año real: hay que mandar año-1992 (offset descubierto empíricamente probando valores contra resultados conocidos). Sin resultado en JSON: se parsea el HTML de respuesta. Sin bulk: una consulta por RUC-año, con pausa de ~400ms entre pedidos. Ver identidad-fiscal/api/src/ingest/exportaciones-fob-connector.ts en el repo Rastro (appsperu) para la implementación de referencia. | E27: 19/09/2026 | F27: http://www.aduanet.gob.pe/cl-ad-itconsultadwh/ieITS01Alias (endpoint real usado, no documentado oficialmente por SUNAT/Aduanas) · https://www.sunat.gob.pe/estadisticasestudios/exportaciones.html · https://www.sunat.gob.pe/estad-comExt/modelo_web/informes/anuarios/2024/cdro_33.xlsx · https://ww3.sunat.gob.pe/servlet/HRGDecExp?opcion=aduanaexp&codr=50 · http://www.aduanet.gob.pe/cl-ad-itestadispartida/resumenPPaisS01Alias · https://datosabiertos.gob.pe | G27: No es una API pública documentada — es un endpoint HTML interno de Aduanet que resultó no estar bloqueado para fetch directo (a diferencia de *.sunat.gob.pe). Depende de que Aduanet no cambie esa ruta ni bloquee el acceso; el offset de año (-1992) y el código de régimen (40) tampoco están documentados por SUNAT. Los anuarios/cuadros oficiales (URLs alternativas de arriba) solo dan totales por aduana/país, no por RUC.
B28: ruc-contratacion-estatal.txt (RUC_CONTRATACION) | C28: OECE / Open Contracting Partnership (mirror OCDS) | D28: Descarga bulk anual de OCDS republicada por Open Contracting Partnership; filtrada por los 597 RUC del universo (script oece_contrataciones_por_ruc.py) | E28: 23/09/2026 | F28: https://data.open-contracting.org/en/publication/135 (bulk anual) · https://contratacionesabiertas.oece.gob.pe (endpoint search?supplier= no filtra por proveedor) | G28: Solo 10 de 597 RUC tienen procesos/contratos; el endpoint de búsqueda de OECE no filtra por proveedor, se usó el bulk anual como vía verificada
B31: 2.1 Endpoints públicos directos e indirectos
B32: Directo = portal, servicio o archivo oficial de la entidad que produce el dato (SUNAT, OECE, RNP, MIDAGRI, PNDA). Indirecto = servicio de terceros que replica, indexa o consulta la fuente oficial (OpenRUC, APISUNAT, APIperu, json.pe, Croma, Apify). Fuente: fuentes_urls.md.
B33: Dataset (pestañas) | C33: Tipo | D33: Recurso | E33: Endpoint / URL | F33: Método y acceso | G33: Formato / notas
B34: RUC_CONSULTAMASIVA · RUC_OECE · RNP (ficha RUC) | C34: Directo | D34: SUNAT — Consulta RUC (web oficial) | E34: https://e.sunat.gob.pe/ | F34: Web · formulario con CAPTCHA · consulta individual y múltiple | G34: HTML / descarga .txt (consulta múltiple)
B35: RUC_CONSULTAMASIVA · RUC_OECE · RNP (ficha RUC) | C35: Indirecto | D35: OpenRUC — API RUC SUNAT (Latinfo) | E35: GET https://openruc.com/api/ruc/{ruc} | F35: API REST GET · sin API key · gratis | G35: JSON: razón social, estado, condición, dirección
B36: RUC_CONSULTAMASIVA · RUC_OECE · RNP (ficha RUC) | C36: Indirecto | D36: APISUNAT — Consulta RUC | E36: GET https://dev.apisunat.pe/api/v1/business/ruc/{RUC} (doc: https://docs.apisunat.pe/consulta/sunat-ruc) | F36: API REST GET · requiere API key | G36: JSON
B37: RUC_CONSULTAMASIVA · RUC_OECE · RNP (ficha RUC) | C37: Indirecto | D37: APIperu — Consultar RUC | E37: POST https://api.apiperu.dev/ruc (doc: https://docs.apiperu.dev/referencia/consultar-ruc/) | F37: API REST POST · token · plan gratuito | G37: JSON (ficha RUC completa)
B38: RUC_CONSULTAMASIVA · RUC_OECE · RNP (ficha RUC) | C38: Indirecto | D38: json.pe — Consulta RUC | E38: POST https://api.json.pe/api/ruc (doc: https://docs.json.pe/api-consulta/endpoint/ruc) | F38: API REST POST · requiere token | G38: JSON
B39: RUC_OECE · RUC_OECE_PERSONAS | C39: Directo | D39: OECE — Portal de Contrataciones Abiertas (OCDS) | E39: https://contratacionesabiertas.oece.gob.pe | F39: Descarga masiva (bulk) · sin autenticación · actualización diaria | G39: JSON / CSV / Excel (OCDS), procesos 2003–presente
B40: RUC_OECE · RUC_OECE_PERSONAS | C40: Directo | D40: OECE — Transparencia y datos abiertos | E40: https://www.gob.pe/institucion/oece/tema/transparencia-y-datos-abiertos | F40: Web · enlaces a estadísticas, BI y observatorio de precios | G40: HTML / descargas
B41: RUC_OECE · RUC_OECE_PERSONAS · RNP | C41: Directo | D41: OECE — SEACE / Registro de proveedores | E41: https://www.gob.pe/oece | F41: Web · consulta por RUC (ficha de proveedor con directivos) | G41: HTML · sin bulk
B42: RUC_OECE · RUC_OECE_PERSONAS | C42: Indirecto | D42: Croma API — OECE Contrataciones | E42: POST https://api.croma.run/pe/oece/processes-search/v1 | F42: API REST POST · búsqueda por RUC proveedor, entidad, texto, categoría, fechas | G42: JSON (dataset indexado)
B43: RUC_OECE · RUC_OECE_PERSONAS | C43: Indirecto | D43: Apify — Peru OECE Tender Scraper | E43: https://apify.com/publicmoney/peru-oece-scraper | F43: Actor/scraper sobre contratacionesabiertas.oece.gob.pe · cuenta Apify | G43: JSON / CSV / Excel
B44: RNP | C44: Directo | D44: RNP — Consulta RUC | E44: https://www.rnp.gob.pe/Constancia/RNP_Constancia/ConsultaRuc.asp | F44: Web · formulario con CAPTCHA · uno por uno | G44: HTML (verificación de inscripción)
...

Sheet DIM_ORGANIZACION
A1: ruc | B1: razon_social | C1: nombre_comercial | D1: tipo_contribuyente | E1: tipo_organizacion_programa | F1: estado_contribuyente | G1: condicion_contribuyente | H1: fecha_inscripcion_ruc | I1: fecha_inicio_actividades | J1: ubigeo | K1: departamento | L1: provincia | M1: distrito | N1: direccion_fiscal | O1: actividad_comercio_exterior | P1: ciiu_principal | Q1: ciiu_secundario_1 | R1: ciiu_secundario_2 | S1: buen_contribuyente | T1: agente_retencion | U1: telefono_principal | V1: email_principal | W1: inscrito_rnp | X1: codigo_rnp | Y1: inscrito_ppa | Z1: nombre_ppa | AA1: ventas_totales_2024 | AB1: ventas_totales_2025 | AC1: exporta | AD1: fob_total_usd | AE1: ultimo_periodo_exportacion | AF1: fob_ultimo_anio_usd | AG1: n_paises_destino | AH1: presidente_vigente | AI1: representante_legal_vigente | AJ1: gerente_general | AK1: n_directivos_vigentes | AL1: producto_dominante | AM1: anios_intervencion | AN1: servicio_programa | AO1: n_socios_varones | AP1: n_socias_mujeres | AQ1: hectareas_totales | AR1: certificacion_organica | AS1: certificacion_comercio_justo | AT1: avance_eudr | AU1: fecha_ultima_actualizacion | AV1: score_completitud | AW1: n_duas | AX1: n_duas_canal_no_verde
A2: {=_xlfn._xlws.SORT(_xlfn.UNIQUE(_xlfn._xlws.FILTER(RUC_CONSULTAMASIVA!$A$2:$A$5000,RUC_CONSULTAMASIVA!$A$2:$A$5000<>"")))} | B2: {=_xlfn.LET(_xlpm.s,_xlfn.LET(_xlpm.v,TRIM(_xlfn.XLOOKUP(_xlfn.ANCHORARRAY($A$2),RUC_CONSULTAMASIVA!$A$2:$A$5000,RUC_CONSULTAMASIVA!$B$2:$B$5000,"")&""),IF((_xlpm.v="-")+(_xlpm.v="0"),"",_xlpm.v)),_xlpm.o,_xlfn.LET(_xlpm.v,TRIM(_xlfn.XLOOKUP(_xlfn.ANCHORARRAY($A$2),RUC_OECE!$A$2:$A$5000,RUC_OECE!$B$2:$B$5000,"")&""),IF((_xlpm.v="-")+(_xlpm.v="0"),"",_xlpm.v)),IF(_xlpm.s="",_xlpm.o,_xlpm.s))} | C2: {=_xlfn.LET(_xlpm.v,TRIM(_xlfn.XLOOKUP(_xlfn.ANCHORARRAY($A$2),RUC_CONSULTAMASIVA!$A$2:$A$5000,RUC_CONSULTAMASIVA!$E$2:$E$5000,"")&""),IF((_xlpm.v="-")+(_xlpm.v="0"),"",_xlpm.v))} | D2: {=_xlfn.LET(_xlpm.s,_xlfn.LET(_xlpm.v,TRIM(_xlfn.XLOOKUP(_xlfn.ANCHORARRAY($A$2),RUC_CONSULTAMASIVA!$A$2:$A$5000,RUC_CONSULTAMASIVA!$C$2:$C$5000,"")&""),IF((_xlpm.v="-")+(_xlpm.v="0"),"",_xlpm.v)),_xlpm.o,_xlfn.LET(_xlpm.v,TRIM(_xlfn.XLOOKUP(_xlfn.ANCHORARRAY($A$2),RUC_OECE!$A$2:$A$5000,RUC_OECE!$C$2:$C$5000,"")&""),IF((_xlpm.v="-")+(_xlpm.v="0"),"",_xlpm.v)),IF(_xlpm.s="",_xlpm.o,_xlpm.s))} | E2: {=_xlfn.LET(_xlpm.v,TRIM(_xlfn.XLOOKUP(_xlfn.ANCHORARRAY($A$2),TRIM('b2'!$DI$3:$DI$2000&""),'b2'!$DK$3:$DK$2000,"")&""),IF((_xlpm.v="-")+(_xlpm.v="0"),"",_xlpm.v))} | F2: {=_xlfn.LET(_xlpm.s,_xlfn.LET(_xlpm.v,TRIM(_xlfn.XLOOKUP(_xlfn.ANCHORARRAY($A$2),RUC_CONSULTAMASIVA!$A$2:$A$5000,RUC_CONSULTAMASIVA!$G$2:$G$5000,"")&""),IF((_xlpm.v="-")+(_xlpm.v="0"),"",_xlpm.v)),_xlpm.o,_xlfn.LET(_xlpm.v,TRIM(_xlfn.XLOOKUP(_xlfn.ANCHORARRAY($A$2),RUC_OECE!$A$2:$A$5000,RUC_OECE!$D$2:$D$5000,"")&""),IF((_xlpm.v="-")+(_xlpm.v="0"),"",_xlpm.v)),IF(_xlpm.s="",_xlpm.o,_xlpm.s))} | G2: {=_xlfn.LET(_xlpm.s,_xlfn.LET(_xlpm.v,TRIM(_xlfn.XLOOKUP(_xlfn.ANCHORARRAY($A$2),RUC_CONSULTAMASIVA!$A$2:$A$5000,RUC_CONSULTAMASIVA!$F$2:$F$5000,"")&""),IF((_xlpm.v="-")+(_xlpm.v="0"),"",_xlpm.v)),_xlpm.o,_xlfn.LET(_xlpm.v,TRIM(_xlfn.XLOOKUP(_xlfn.ANCHORARRAY($A$2),RUC_OECE!$A$2:$A$5000,RUC_OECE!$E$2:$E$5000,"")&""),IF((_xlpm.v="-")+(_xlpm.v="0"),"",_xlpm.v)),IF(_xlpm.s="",_xlpm.o,_xlpm.s))} | H2: {=_xlfn.LET(_xlpm.t,_xlfn.LET(_xlpm.v,TRIM(_xlfn.XLOOKUP(_xlfn.ANCHORARRAY($A$2),RUC_CONSULTAMASIVA!$A$2:$A$5000,RUC_CONSULTAMASIVA!$H$2:$H$5000,"")&""),IF((_xlpm.v="-")+(_xlpm.v="0"),"",_xlpm.v)),IFERROR(DATE(RIGHT(_xlpm.t,4),MID(_xlpm.t,4,2),LEFT(_xlpm.t,2)),""))} | I2: {=_xlfn.LET(_xlpm.t,_xlfn.LET(_xlpm.v,TRIM(_xlfn.XLOOKUP(_xlfn.ANCHORARRAY($A$2),RUC_CONSULTAMASIVA!$A$2:$A$5000,RUC_CONSULTAMASIVA!$I$2:$I$5000,"")&""),IF((_xlpm.v="-")+(_xlpm.v="0"),"",_xlpm.v)),IFERROR(DATE(RIGHT(_xlpm.t,4),MID(_xlpm.t,4,2),LEFT(_xlpm.t,2)),""))} | J2: {=_xlfn.LET(_xlpm.v,TRIM(_xlfn.XLOOKUP(_xlfn.ANCHORARRAY($A$2),TRIM('b2'!$DI$3:$DI$2000&""),'b2'!$E$3:$E$2000,"")&""),IF((_xlpm.v="-")+(_xlpm.v="0"),"",_xlpm.v))} | K2: {=_xlfn.LET(_xlpm.s,_xlfn.LET(_xlpm.v,TRIM(_xlfn.XLOOKUP(_xlfn.ANCHORARRAY($A$2),RUC_CONSULTAMASIVA!$A$2:$A$5000,RUC_CONSULTAMASIVA!$J$2:$J$5000,"")&""),IF((_xlpm.v="-")+(_xlpm.v="0"),"",_xlpm.v)),_xlpm.o,_xlfn.LET(_xlpm.v,TRIM(_xlfn.XLOOKUP(_xlfn.ANCHORARRAY($A$2),RUC_OECE!$A$2:$A$5000,RUC_OECE!$F$2:$F$5000,"")&""),IF((_xlpm.v="-")+(_xlpm.v="0"),"",_xlpm.v)),IF(_xlpm.s="",_xlpm.o,_xlpm.s))} | L2: {=_xlfn.LET(_xlpm.s,_xlfn.LET(_xlpm.v,TRIM(_xlfn.XLOOKUP(_xlfn.ANCHORARRAY($A$2),RUC_CONSULTAMASIVA!$A$2:$A$5000,RUC_CONSULTAMASIVA!$K$2:$K$5000,"")&""),IF((_xlpm.v="-")+(_xlpm.v="0"),"",_xlpm.v)),_xlpm.o,_xlfn.LET(_xlpm.v,TRIM(_xlfn.XLOOKUP(_xlfn.ANCHORARRAY($A$2),RUC_OECE!$A$2:$A$5000,RUC_OECE!$G$2:$G$5000,"")&""),IF((_xlpm.v="-")+(_xlpm.v="0"),"",_xlpm.v)),IF(_xlpm.s="",_xlpm.o,_xlpm.s))} | M2: {=_xlfn.LET(_xlpm.s,_xlfn.LET(_xlpm.v,TRIM(_xlfn.XLOOKUP(_xlfn.ANCHORARRAY($A$2),RUC_CONSULTAMASIVA!$A$2:$A$5000,RUC_CONSULTAMASIVA!$L$2:$L$5000,"")&""),IF((_xlpm.v="-")+(_xlpm.v="0"),"",_xlpm.v)),_xlpm.o,_xlfn.LET(_xlpm.v,TRIM(_xlfn.XLOOKUP(_xlfn.ANCHORARRAY($A$2),RUC_OECE!$A$2:$A$5000,RUC_OECE!$H$2:$H$5000,"")&""),IF((_xlpm.v="-")+(_xlpm.v="0"),"",_xlpm.v)),IF(_xlpm.s="",_xlpm.o,_xlpm.s))} | N2: {=_xlfn.LET(_xlpm.s,_xlfn.LET(_xlpm.v,TRIM(_xlfn.XLOOKUP(_xlfn.ANCHORARRAY($A$2),RUC_CONSULTAMASIVA!$A$2:$A$5000,RUC_CONSULTAMASIVA!$M$2:$M$5000,"")&""),IF((_xlpm.v="-")+(_xlpm.v="0"),"",_xlpm.v)),_xlpm.o,_xlfn.LET(_xlpm.v,TRIM(_xlfn.XLOOKUP(_xlfn.ANCHORARRAY($A$2),TRIM('b3'!$E$2:$E$200&""),'b3'!$Z$2:$Z$200,"")&""),IF((_xlpm.v="-")+(_xlpm.v="0"),"",_xlpm.v)),IF(_xlpm.s="",_xlpm.o,_xlpm.s))} | O2: {=_xlfn.LET(_xlpm.v,TRIM(_xlfn.XLOOKUP(_xlfn.ANCHORARRAY($A$2),RUC_CONSULTAMASIVA!$A$2:$A$5000,RUC_CONSULTAMASIVA!$P$2:$P$5000,"")&""),IF((_xlpm.v="-")+(_xlpm.v="0"),"",_xlpm.v))} | P2: {=_xlfn.LET(_xlpm.v,TRIM(_xlfn.XLOOKUP(_xlfn.ANCHORARRAY($A$2),RUC_CONSULTAMASIVA!$A$2:$A$5000,RUC_CONSULTAMASIVA!$Q$2:$Q$5000,"")&""),IF((_xlpm.v="-")+(_xlpm.v="0"),"",_xlpm.v))} | Q2: {=_xlfn.LET(_xlpm.v,TRIM(_xlfn.XLOOKUP(_xlfn.ANCHORARRAY($A$2),RUC_CONSULTAMASIVA!$A$2:$A$5000,RUC_CONSULTAMASIVA!$R$2:$R$5000,"")&""),IF((_xlpm.v="-")+(_xlpm.v="0"),"",_xlpm.v))} | R2: {=_xlfn.LET(_xlpm.v,TRIM(_xlfn.XLOOKUP(_xlfn.ANCHORARRAY($A$2),RUC_CONSULTAMASIVA!$A$2:$A$5000,RUC_CONSULTAMASIVA!$S$2:$S$5000,"")&""),IF((_xlpm.v="-")+(_xlpm.v="0"),"",_xlpm.v))} | S2: {=_xlfn.LET(_xlpm.v,TRIM(_xlfn.XLOOKUP(_xlfn.ANCHORARRAY($A$2),RUC_CONSULTAMASIVA!$A$2:$A$5000,RUC_CONSULTAMASIVA!$U$2:$U$5000,"")&""),IF((_xlpm.v="-")+(_xlpm.v="0"),"",_xlpm.v))} | T2: {=_xlfn.LET(_xlpm.v,TRIM(_xlfn.XLOOKUP(_xlfn.ANCHORARRAY($A$2),RUC_CONSULTAMASIVA!$A$2:$A$5000,RUC_CONSULTAMASIVA!$V$2:$V$5000,"")&""),IF((_xlpm.v="-")+(_xlpm.v="0"),"",_xlpm.v))} | U2: {=_xlfn.LET(_xlpm.s,_xlfn.LET(_xlpm.v,TRIM(_xlfn.XLOOKUP(_xlfn.ANCHORARRAY($A$2),RUC_OECE!$A$2:$A$5000,RUC_OECE!$I$2:$I$5000,"")&""),IF((_xlpm.v="-")+(_xlpm.v="0"),"",_xlpm.v)),_xlpm.o,_xlfn.LET(_xlpm.v,TRIM(_xlfn.XLOOKUP(_xlfn.ANCHORARRAY($A$2),TRIM('b3'!$E$2:$E$200&""),'b3'!$AB$2:$AB$200,"")&""),IF((_xlpm.v="-")+(_xlpm.v="0"),"",_xlpm.v)),IF(_xlpm.s="",_xlpm.o,_xlpm.s))} | V2: {=_xlfn.LET(_xlpm.s,_xlfn.LET(_xlpm.v,TRIM(_xlfn.XLOOKUP(_xlfn.ANCHORARRAY($A$2),RUC_OECE!$A$2:$A$5000,RUC_OECE!$J$2:$J$5000,"")&""),IF((_xlpm.v="-")+(_xlpm.v="0"),"",_xlpm.v)),_xlpm.o,_xlfn.LET(_xlpm.v,TRIM(_xlfn.XLOOKUP(_xlfn.ANCHORARRAY($A$2),TRIM('b3'!$E$2:$E$200&""),'b3'!$AA$2:$AA$200,"")&""),IF((_xlpm.v="-")+(_xlpm.v="0"),"",_xlpm.v)),IF(_xlpm.s="",_xlpm.o,_xlpm.s))} | W2: {=IF(COUNTIF(_xlfn.ANCHORARRAY(REG_RNP!A2),_xlfn.ANCHORARRAY($A$2))>0,"SI","NO")} | X2: {=_xlfn.XLOOKUP(_xlfn.ANCHORARRAY($A$2),_xlfn.ANCHORARRAY(REG_RNP!A2),_xlfn.ANCHORARRAY(REG_RNP!B2),"")} | Y2: {=_xlfn.XLOOKUP(_xlfn.ANCHORARRAY($A$2),_xlfn.ANCHORARRAY(REG_PPA!A2),_xlfn.ANCHORARRAY(REG_PPA!B2),"")} | Z2: {=_xlfn.XLOOKUP(_xlfn.ANCHORARRAY($A$2),_xlfn.ANCHORARRAY(REG_PPA!A2),_xlfn.ANCHORARRAY(REG_PPA!C2),"")} | AA2: {=SUMIFS(HECHO_PROGRAMA_ANUAL!$N$2:$N$5000,HECHO_PROGRAMA_ANUAL!$B$2:$B$5000,_xlfn.ANCHORARRAY($A$2),HECHO_PROGRAMA_ANUAL!$D$2:$D$5000,VALUE(RIGHT($AA$1,4)))} | AB2: {=SUMIFS(HECHO_PROGRAMA_ANUAL!$N$2:$N$5000,HECHO_PROGRAMA_ANUAL!$B$2:$B$5000,_xlfn.ANCHORARRAY($A$2),HECHO_PROGRAMA_ANUAL!$D$2:$D$5000,VALUE(RIGHT($AB$1,4)))} | AC2: {=IF(COUNTIF(_xlfn.ANCHORARRAY(HECHO_EXPORTACION!A2),_xlfn.ANCHORARRAY($A$2))>0,"SI","NO")} | AD2: {=IF(_xlfn.ANCHORARRAY(AC2)="SI",SUMIFS(_xlfn.ANCHORARRAY(HECHO_EXPORTACION!K2),_xlfn.ANCHORARRAY(HECHO_EXPORTACION!A2),_xlfn.ANCHORARRAY($A$2)),"")} | AE2: {=_xlfn.MAP(_xlfn.ANCHORARRAY($A$2),_xlfn.LAMBDA(_xlpm.r,_xlfn.LET(_xlpm.x,_xlfn._xlws.FILTER(_xlfn.ANCHORARRAY(HECHO_EXPORTACION!D2),_xlfn.ANCHORARRAY(HECHO_EXPORTACION!A2)=_xlpm.r,""),_xlpm.m,MAX(IFERROR(--_xlpm.x,0)),IF(_xlpm.m=0,"",LEFT(_xlpm.m,4)&"-"&RIGHT(_xlpm.m,2)))))} | AF2: {=IF(_xlfn.ANCHORARRAY(AE2)="","",SUMIFS(_xlfn.ANCHORARRAY(HECHO_EXPORTACION!K2),_xlfn.ANCHORARRAY(HECHO_EXPORTACION!A2),_xlfn.ANCHORARRAY($A$2),_xlfn.ANCHORARRAY(HECHO_EXPORTACION!B2),LEFT(_xlfn.ANCHORARRAY(AE2),4)))} | AG2: {=_xlfn.MAP(_xlfn.ANCHORARRAY($A$2),_xlfn.LAMBDA(_xlpm.r,IF(COUNTIF(_xlfn.ANCHORARRAY(HECHO_EXPORTACION!A2),_xlpm.r)=0,"",ROWS(_xlfn.UNIQUE(_xlfn._xlws.FILTER(_xlfn.ANCHORARRAY(HECHO_EXPORTACION!J2),_xlfn.ANCHORARRAY(HECHO_EXPORTACION!A2)=_xlpm.r))))))} | AH2: {=_xlfn.XLOOKUP(_xlfn.ANCHORARRAY($A$2)&"|PRESIDENTE|SI",_xlfn.ANCHORARRAY(REL_PERSONA_CARGO!A2)&"|"&UPPER(TRIM(_xlfn.ANCHORARRAY(REL_PERSONA_CARGO!F2)))&"|"&_xlfn.ANCHORARRAY(REL_PERSONA_CARGO!I2),_xlfn.ANCHORARRAY(REL_PERSONA_CARGO!C2),"")} | AI2: {=_xlfn.LET(_xlpm.s,_xlfn.XLOOKUP(_xlfn.ANCHORARRAY($A$2)&"|REPRESENTANTE|SI",_xlfn.ANCHORARRAY(REL_PERSONA_CARGO!A2)&"|"&_xlfn.ANCHORARRAY(REL_PERSONA_CARGO!D2)&"|"&_xlfn.ANCHORARRAY(REL_PERSONA_CARGO!I2),_xlfn.ANCHORARRAY(REL_PERSONA_CARGO!C2),""),_xlpm.o,_xlfn.LET(_xlpm.v,TRIM(_xlfn.XLOOKUP(_xlfn.ANCHORARRAY($A$2),TRIM('b3'!$E$2:$E$200&""),'b3'!$AH$2:$AH$200,"")&""),IF((_xlpm.v="-")+(_xlpm.v="0"),"",_xlpm.v)),IF(_xlpm.s="",_xlpm.o,_xlpm.s))} | AJ2: {=_xlfn.LET(_xlpm.s,_xlfn.XLOOKUP(_xlfn.ANCHORARRAY($A$2)&"|GERENTE GENERAL|SI",_xlfn.ANCHORARRAY(REL_PERSONA_CARGO!A2)&"|"&UPPER(TRIM(_xlfn.ANCHORARRAY(REL_PERSONA_CARGO!F2)))&"|"&_xlfn.ANCHORARRAY(REL_PERSONA_CARGO!I2),_xlfn.ANCHORARRAY(REL_PERSONA_CARGO!C2),""),_xlpm.o,_xlfn.LET(_xlpm.v,TRIM(_xlfn.XLOOKUP(_xlfn.ANCHORARRAY($A$2),TRIM('b3'!$E$2:$E$200&""),'b3'!$AE$2:$AE$200,"")&""),IF((_xlpm.v="-")+(_xlpm.v="0"),"",_xlpm.v)),IF(_xlpm.s="",_xlpm.o,_xlpm.s))} | AK2: {=_xlfn.LET(_xlpm.n,COUNTIFS(_xlfn.ANCHORARRAY(REL_PERSONA_CARGO!A2),_xlfn.ANCHORARRAY($A$2),_xlfn.ANCHORARRAY(REL_PERSONA_CARGO!D2),"ORGANO_ADMINISTRACION",_xlfn.ANCHORARRAY(REL_PERSONA_CARGO!I2),"SI"),IF(_xlpm.n=0,"",_xlpm.n))} | AL2: {=_xlfn.LET(_xlpm.v,TRIM(_xlfn.XLOOKUP(_xlfn.ANCHORARRAY($A$2),TRIM('b2'!$DI$3:$DI$2000&""),'b2'!$B$3:$B$2000,"")&""),IF((_xlpm.v="-")+(_xlpm.v="0"),"",_xlpm.v))} | AM2: {=_xlfn.LET(_xlpm.v,TRIM(_xlfn.XLOOKUP(_xlfn.ANCHORARRAY($A$2),TRIM('b2'!$DI$3:$DI$2000&""),'b2'!$R$3:$R$2000,"")&""),IF((_xlpm.v="-")+(_xlpm.v="0"),"",_xlpm.v))} | AN2: {=_xlfn.LET(_xlpm.v,TRIM(_xlfn.XLOOKUP(_xlfn.ANCHORARRAY($A$2),TRIM('b2'!$DI$3:$DI$2000&""),'b2'!$Q$3:$Q$2000,"")&""),IF((_xlpm.v="-")+(_xlpm.v="0"),"",_xlpm.v))} | AO2: {=_xlfn.LET(_xlpm.v,_xlfn.XLOOKUP(_xlfn.ANCHORARRAY($A$2),TRIM('b3'!$E$2:$E$200&""),'b3'!$M$2:$M$200,""),IF(_xlpm.v="","",_xlpm.v))} | AP2: {=_xlfn.LET(_xlpm.v,_xlfn.XLOOKUP(_xlfn.ANCHORARRAY($A$2),TRIM('b3'!$E$2:$E$200&""),'b3'!$N$2:$N$200,""),IF(_xlpm.v="","",_xlpm.v))} | AQ2: {=_xlfn.LET(_xlpm.v,_xlfn.XLOOKUP(_xlfn.ANCHORARRAY($A$2),TRIM('b3'!$E$2:$E$200&""),'b3'!$O$2:$O$200,""),IF(_xlpm.v="","",_xlpm.v))} | AR2: {=_xlfn.LET(_xlpm.v,TRIM(_xlfn.XLOOKUP(_xlfn.ANCHORARRAY($A$2),TRIM('b3'!$E$2:$E$200&""),'b3'!$U$2:$U$200,"")&""),IF((_xlpm.v="-")+(_xlpm.v="0"),"",_xlpm.v))} | AS2: {=_xlfn.LET(_xlpm.v,TRIM(_xlfn.XLOOKUP(_xlfn.ANCHORARRAY($A$2),TRIM('b3'!$E$2:$E$200&""),'b3'!$V$2:$V$200,"")&""),IF((_xlpm.v="-")+(_xlpm.v="0"),"",_xlpm.v))} | AT2: {=_xlfn.LET(_xlpm.v,TRIM(_xlfn.XLOOKUP(_xlfn.ANCHORARRAY($A$2),TRIM('b3'!$E$2:$E$200&""),'b3'!$Y$2:$Y$200,"")&""),IF((_xlpm.v="-")+(_xlpm.v="0"),"",_xlpm.v))} | AU2: {=_xlfn.LET(_xlpm.cv,_xlfn.LAMBDA(_xlpm.t,IFERROR(DATE(LEFT(_xlpm.t,4),MID(_xlpm.t,6,2),MID(_xlpm.t,9,2))+TIME(MID(_xlpm.t,12,2),MID(_xlpm.t,15,2),MID(_xlpm.t,18,2)),0)),_xlpm.o,_xlpm.cv(_xlfn.XLOOKUP(_xlfn.ANCHORARRAY($A$2),RUC_OECE!$A$2:$A$5000,RUC_OECE!$L$2:$L$5000,"")),_xlpm.p,_xlpm.cv(_xlfn.XLOOKUP(_xlfn.ANCHORARRAY($A$2),_xlfn.ANCHORARRAY(REG_PPA!A2),_xlfn.ANCHORARRAY(REG_PPA!F2),"")),_xlpm.e,_xlpm.cv(_xlfn.XLOOKUP(_xlfn.ANCHORARRAY($A$2),_xlfn.ANCHORARRAY(HECHO_EXPORTACION!A2),_xlfn.ANCHORARRAY(HECHO_EXPORTACION!P2),"")),_xlpm.m,IF(_xlpm.o>_xlpm.p,_xlpm.o,_xlpm.p),_xlpm.x,IF(_xlpm.m>_xlpm.e,_xlpm.m,_xlpm.e),IF(_xlpm.x=0,"",_xlpm.x))} | AV2: {=_xlfn.LET(_xlpm.n,ROWS(_xlfn.ANCHORARRAY($A$2)),_xlpm.b,_xlfn.TAKE(_xlfn.HSTACK($B$2:$AT$5000,$AW$2:$AX$5000),_xlpm.n),_xlfn.BYROW(_xlpm.b,_xlfn.LAMBDA(_xlpm.r,SUM(--(_xlpm.r<>""))/COLUMNS(_xlpm.r))))} | AW2: {=_xlfn.LET(_xlpm.n,COUNTIFS(RUC_FOB_DUA!$A$2:$A$5000,_xlfn.ANCHORARRAY($A$2)),IF(_xlpm.n=0,"",_xlpm.n))} | AX2: {=_xlfn.LET(_xlpm.n,COUNTIFS(RUC_FOB_DUA!$A$2:$A$5000,_xlfn.ANCHORARRAY($A$2),RUC_FOB_DUA!$I$2:$I$5000,"<>VERDE"),IF(_xlpm.n=0,"",_xlpm.n))}
A3: 20118588135 | B3: CENTRAL DE COOPERATIVAS DE SERVICIOS ESPECIALES ALPAQUERAS DE PUNO LTDA. - CECOALP | C3: CECOALP | D3: COOPERATIVAS, SAIS, CAPS | E3: 07 Otros | F3: ACTIVO | G3: HABIDO | H3: 34084 | I3: 33239 | J3: 211101 | K3: PUNO | L3: SAN ROMAN | M3: JULIACA | N3: JR. MIRAFLORES NRO. 1496 URB. SAN FRANCISCO (A UNA ACUADRA MERDO.PEDRO VILCA A.) | O3: IMPORTADOR/EXPORTADOR | P3: VTA. MAY. DE MATERIAS PRIMAS AGROPEC. | U3: 051328851 | V3: nilvaflors@gmail.com | W3: SI | X3: S0148048 | Y3: SI | Z3: CENTRAL DE COOPERATIVAS DE SERVICIOS ESPECIALES ALPAQUERAS DE PUNO LTDA. - CECOALP | AA3: 0 | AB3: 0 | AC3: NO | AH3: MAMANI OJEDA PEDRO LAUREANO | AI3: LOPEZ MULLISACA CESAR | AK3: 3 | AL3: FIBRA DE ALPACA | AM3: 2018-2019-2020-2021-2023 | AN3: PAC | AU3: 46285.072 | AV3: 0.66666667
A4: 20119208026 | B4: FONGAL TACNA | C4: FONGAL TACNA | D4: ASOCIACION | E4: 01 Asociación | F4: ACTIVO | G4: HABIDO | H4: 34088 | I4: 29468 | J4: 230101 | K4: TACNA | L4: TACNA | M4: CRL. GREG. ALBARRACIN LANCHIPA | N4: OVL. CUSCO NRO. S/N FND. LA AGRONOMICA | O4: SIN ACTIVIDAD | P4: ELAB DE OTROS PROD. ALIMENTICIOS. | Q4: SERVICIOS AGRICOLAS, GANADERAS. | U4: 052-401722 | V4: john_sarmiento_4321@hotmail.es | W4: SI | X4: B0048031 | Y4: SI | Z4: FONGAL TACNA | AA4: 0 | AB4: 0 | AC4: NO | AH4: MAMANI MAMANI VICTOR | AI4: MAMANI MAMANI VICTOR | AK4: 6 | AL4: DERIVADOS LACTEOS | AM4: 2018 | AN4: PAC | AU4: 46285.072 | AV4: 0.68888889
A5: 20129156083 | B5: COOP AGRARIA CAFET VALLE RIO APURIMAC | C5: CAC VALLE RIO APURIMAC | D5: COOPERATIVAS, SAIS, CAPS | E5: 02 Cooperativa | F5: ACTIVO | G5: HABIDO | H5: 34093 | I5: 25551 | J5: 050503 | K5: AYACUCHO | L5: LA MAR | M5: AYNA | N5: AV. 28 DE JULIO NRO. 4 (PUERTO SAN FRANCISCO) | O5: EXPORTADOR | P5: VTA. MAY. ALIMENTOS, BEBIDAS Y TABACO. | Q5: ELAB. CACAO, CHOCOLATE Y CONFIT. | U5: 066-325179 | V5: cacvra@yahoo.es | W5: SI | X5: S0128686 | Y5: SI | Z5: COOP AGRARIA CAFET VALLE RIO APURIMAC | AA5: 0 | AB5: 0 | AC5: NO | AH5: HUAMAN SANTA CRUZ BENJAMIN | AI5: ZAMALLOA BRAVO HERNAN | AK5: 7 | AL5: CACAO | AM5: 2018-2019-2020-2021-2023 | AN5: PAC | AU5: 46285.072 | AV5: 0.68888889
A6: 20129529530 | B6: COOP AGRARIA CAFETALERA SATIPO LTDA | C6: C.A.C. SATIPO LTDA. | D6: COOPERATIVAS, SAIS, CAPS | F6: ACTIVO | G6: HABIDO | H6: 34093 | I6: 34039 | K6: JUNIN | L6: SATIPO | M6: SATIPO | N6: JR. MANUEL PRADO NRO. 433 | O6: EXPORTADOR | P6: CULTIVO DE FRUTAS. | R6: ACTIVIDADES INMOBILIARIAS | T6: SI, incorporado al Régimen de Agentes de Retención de IGV (R.S.229-2024) a partir del 01/01/2025 | U6: 545030 | V6: edisondario@hotmail.com | W6: SI | X6: S0836027 | Y6: SI | Z6: COOP AGRARIA CAFETALERA SATIPO LTDA | AA6: 0 | AB6: 0 | AC6: SI | AD6: 9603968.1 | AE6: 2026-04 | AF6: 261159.86 | AG6: 4 | AH6: HUARCAYA HUINCHO AGAPITO | AI6: AYALA LOMBARDI JOSEPH OSCAR JOHNNATAN | AK6: 7 | AU6: 46285.072 | AV6: 0.68888889
A7: 20129772043 | B7: COOPERATIVA COMUNAL VICCO LTDA | C7: COOPERATIVA COMUNAL VICCO LTDA | D7: COOPERATIVAS, SAIS, CAPS | F7: ACTIVO | G7: HABIDO | H7: 34093 | I7: 26547 | K7: PASCO | L7: PASCO | M7: VICCO | N7: AV. CERRO DE PASCO NRO. 990 CERCADO (COST. CAPILLA 3 DE MAYO) | O7: SIN ACTIVIDAD | P7: CRIA DE GANADO. | Q7: TRANSPORTE DE CARGA POR CARRETERA. | W7: NO | Y7: SI | Z7: COOPERATIVA COMUNAL VICCO LTDA | AA7: 0 | AB7: 0 | AC7: NO | AU7: 46285.072 | AV7: 0.44444444
A8: 20129830426 | B8: COOPERATIVA COMUNAL HUAYLLAY LTDA 16 | D8: COOPERATIVAS, SAIS, CAPS | E8: 02 Cooperativa | F8: ACTIVO | G8: HABIDO | H8: 34093 | I8: 26342 | J8: 190104 | K8: PASCO | L8: PASCO | M8: HUAYLLAY | N8: PZA. RAMON CASTILLA NRO. 121 HUAYLLAY | O8: SIN ACTIVIDAD | P8: CRIA DE GANADO. | Q8: ELAB DE PRODUCTOS LACTEOS. | W8: SI | X8: S1069969 | Y8: SI | Z8: COOPERATIVA COMUNAL HUAYLLAY LTDA 16 | AA8: 0 | AB8: 0 | AC8: NO | AL8: FIBRA DE ALPACA | AM8: 2021-2022-2024 - 2025 | AN8: PAC | AU8: 46285.072 | AV8: 0.55555556
A9: 20129842351 | B9: COOPERATIVA COMUNAL SAN ANTONIO DE RANCAS LTDA. 289 | C9: RANCAS | D9: COOPERATIVAS, SAIS, CAPS | E9: 02 Cooperativa | F9: ACTIVO | G9: HABIDO | H9: 34093 | I9: 21124 | J9: 190109 | K9: PASCO | L9: PASCO | M9: SIMON BOLIVAR | N9: CAL. SAN MARTIN NRO. 121 SN ANTONIO RANCAS (PLAZA PRINCIPAL) | O9: SIN ACTIVIDAD | P9: CRIA DE GANADO. | Q9: TRANSPORTE DE CARGA POR CARRETERA. | R9: OTROS TIPOS DE VENTA AL POR MENOR. | W9: NO | Y9: SI | Z9: COOPERATIVA COMUNAL SAN ANTONIO DE RANCAS LTDA. 289 | AA9: 0 | AB9: 0 | AC9: NO | AL9: FIBRA DE ALPACA | AM9: 2019-2020-2021-2022 | AN9: PAC | AU9: 46285.072 | AV9: 0.57777778
A10: 20131453427 | B10: COOPERATIVA COMUNAL SAN PEDRO DE RACCO | D10: COOPERATIVAS, SAIS, CAPS | E10: 02 Cooperativa | F10: ACTIVO | G10: HABIDO | H10: 34093 | I10: 25469 | J10: 190109 | K10: PASCO | L10: PASCO | M10: SIMON BOLIVAR | N10: AV. FEDERICO ROJAS HERRERA NRO. S/N ANX. SAN PEDRO DE RACCO | O10: SIN ACTIVIDAD | P10: CRIA DE GANADO. | Q10: ALQUILER OTROS TIPOS MAQ.Y EQUI. NCP. | R10: CRIA DE ANIMALES DOMESTICOS. | S10: SI, incorporado al Régimen de Buenos Contribuyentes (Resolución N° 1930050007770) a partir del 01/02/2022 | W10: SI | X10: S2342817 | Y10: SI | Z10: COOPERATIVA COMUNAL SAN PEDRO DE RACCO | AA10: 0 | AB10: 0 | AC10: NO | AL10: FIBRA DE ALPACA | AM10: 2021-2022-2024 - 2025 | AN10: PAC | AU10: 46285.072 | AV10: 0.6
A11: 20132489824 | B11: COOPERATIVA AGRARIA CAFETALERA CHANCAMAYO LTDA. N° 008-B-VII | D11: COOPERATIVAS, SAIS, CAPS | F11: ACTIVO | G11: HABIDO | H11: 34095 | I11: 27075 | K11: CUSCO | L11: LA CONVENCION | M11: SANTA ANA | N11: AV. EDGAR DE LA TORRE NRO. 1353 (CENTRAL COCLA) | O11: SIN ACTIVIDAD | P11: TRANSPORTE DE CARGA POR CARRETERA. | Q11: SERVICIOS AGRICOLAS, GANADERAS. | R11: ACTIVIDADES INMOBILIARIAS | U11: 976 065194 | V11: walticomt@hotmail.com | W11: SI | X11: S0438053 | Y11: SI | Z11: COOPERATIVA AGRARIA CAFETALERA CHANCAMAYO LTDA. N° 008-B-VII | AA11: 0 | AB11: 0 | AC11: NO | AI11: Fredy Castillo Herrera | AJ11: Fredy Castillo Herrera | AO11: 30 | AP11: 14 | AQ11: 44 | AR11: Certificacion Organica, vigencia hasta 14/08/2026 | AS11: Vigencia organica hasta 26/03/2027 | AU11: 46285.072 | AV11: 0.66666667
A12: 20132505455 | B12: COOPERATIVA AGRARIA CAFETALERA AGUILAYOC LTDA. 084 | D12: COOPERATIVAS, SAIS, CAPS | E12: 02 Cooperativa | F12: ACTIVO | G12: HABIDO | H12: 34095 | I12: 29317 | J12: 080901 | K12: CUSCO | L12: LA CONVENCION | M12: SANTA ANA | N12: JR. OLLANTA NRO. 130 URB. SANTA ANA | O12: SIN ACTIVIDAD | P12: EXPLOTACION MIXTA. | Q12: ACTIVIDADES INMOBILIARIAS | S12: SI, incorporado al Régimen de Buenos Contribuyentes (Resolución N° 0930050010724) a partir del 01/04/2018 | U12: 084282566 | V12: cacaguilayoc@gmail.com | W12: SI | X12: S1293176 | Y12: SI | Z12: COOPERATIVA AGRARIA CAFETALERA AGUILAYOC LTDA. 084 | AA12: 168351.56 | AB12: 615259.83 | AC12: NO | AH12: mora candia walter | AI12: GIBAJA CRUZ YOLANDA | AJ12: Fernando Saldivar Perez | AK12: 5 | AL12: CAFÉ | AM12: 2024 - 2025 | AN12: PAC | AO12: 73 | AP12: 27 | AQ12: 218 | AR12: Certificacion Organica, 26 de noviembre del 2026 | AT12: 0.75 | AU12: 46285.072 | AV12: 0.82222222
A13: 20132509795 | B13: COOPERATIVA AGRARIA CAFETALERA JOSE OLAYA LTDA N° 252 | C13: CAC JOSE OLAYA LTDA 252 | D13: COOPERATIVAS, SAIS, CAPS | E13: 02 Cooperativa | F13: ACTIVO | G13: HABIDO | H13: 34095 | I13: 26401 | J13: 080901 | K13: CUSCO | L13: LA CONVENCION | M13: SANTA ANA | N13: AV. EDGAR DE LA TORRE NRO. 232 COO. QUILLABAMBA | O13: IMPORTADOR/EXPORTADOR | P13: CULTIVO DE FRUTAS. | Q13: ACTIVIDADES INMOBILIARIAS | U13: 282638 | V13: 252cacjoseolaya@gmail.com | W13: SI | X13: S0882298 | Y13: SI | Z13: COOPERATIVA AGRARIA CAFETALERA JOSE OLAYA LTDA N° 252 | AA13: 0 | AB13: 0 | AC13: SI | AD13: 2477083.5 | AE13: 2025-12 | AF13: 1039099.4 | AG13: 5 | AH13: PEZO TTUPA PERCY | AI13: HERRERA PAULLO LEONID | AK13: 7 | AL13: CAFÉ | AM13: 2018-2019-2020-2021-2022-2023 | AN13: PAC | AU13: 46285.072 | AV13: 0.77777778
A14: 20132509876 | B14: COOPERATIVA AGRARIA CAFETALERA MARANURA LTDA. 129 | D14: COOPERATIVAS, SAIS, CAPS | E14: 02 Cooperativa | F14: ACTIVO | G14: HABIDO | H14: 34095 | I14: 23713 | J14: 080904 | K14: CUSCO | L14: LA CONVENCION | M14: MARANURA | N14: NRO. SN SEC. PAMPA MARANURA (CARRTERA QBBA CUSCO KM10 EX FUNDOMARANUR) | O14: IMPORTADOR/EXPORTADOR | P14: TRANSPORTE DE CARGA POR CARRETERA. | Q14: ELAB. CACAO, CHOCOLATE Y CONFIT. | U14: 984403611 | V14: CACMARANURA@HOTMAIL.COM | W14: SI | X14: S1112758 | Y14: SI | Z14: COOPERATIVA AGRARIA CAFETALERA MARANURA LTDA. 129 | AA14: 0 | AB14: 0 | AC14: SI | AD14: 1689820.3 | AE14: 2026-01 | AF14: 610049.62 | AG14: 1 | AH14: huaman delgado silvestre | AI14: PIMENTEL CONDORI LUDGARDO | AK14: 5 | AL14: CAFÉ | AM14: 2019-2020-2021-2022-2023 | AN14: PAC | AU14: 46285.072 | AV14: 0.75555556
A15: 20132517119 | B15: COOPERATIVA AGRARIA CAFETALERA MATEO PUMACAHUA LTDA N° 185 | C15: COOP. AGRARIA CAFETALERA | D15: COOPERATIVAS, SAIS, CAPS | E15: 02 Cooperativa | F15: ACTIVO | G15: HABIDO | H15: 34095 | I15: 24066 | J15: 080901 | K15: CUSCO | L15: LA CONVENCION | M15: SANTA ANA | N15: JR. LIBERTAD NRO. 631 | O15: IMPORTADOR/EXPORTADOR | P15: ELAB. CACAO, CHOCOLATE Y CONFIT. | Q15: ACTIVIDADES INMOBILIARIAS | U15: 084281110 | V15: CAMARALACONVENCION_@hotmail.com | W15: SI | X15: S1142161 | Y15: SI | Z15: COOPERATIVA AGRARIA CAFETALERA MATEO PUMACAHUA LTDA N° 185 | AA15: 80172.952 | AB15: 274646.15 | AC15: NO | AH15: VALDEZ VALENCIA REMIGIO | AI15: JOHN ERIC MOLINA HERRERA | AJ15: Remigio Valdez Valencia | AK15: 5 | AL15: CAFÉ | AM15: 2024 - 2025 | AN15: PAC | AO15: 133 | AP15: 44 | AQ15: 469 | AR15: Certificación Orgánica, Vigencia hasta agosto 2026 | AS15: Fairtrade hasta junio 2026 | AT15: 0.75 | AU15: 46285.072 | AV15: 0.84444444
A16: 20136201132 | B16: COOPERATIVA AGRARIA CAFETALERA ALTO URUBAMBA LTDA N° 239 | C16: C.A.C. ALTO URUBAMBA | D16: COOPERATIVAS, SAIS, CAPS | E16: 02 Cooperativa | F16: ACTIVO | G16: HABIDO | H16: 34102 | I16: 24744 | J16: 080901 | K16: CUSCO | L16: LA CONVENCION | M16: SANTA ANA | N16: AV. FRANCISCA ZUBIAGA NRO. 427 QUILLABAMBA (COSTADO DE ELECTRO SUR S.A.) | O16: SIN ACTIVIDAD | P16: VTA. MAY. DE MATERIAS PRIMAS AGROPEC. | Q16: RESTAURANTES, BARES Y CANTINAS. | U16: 944257022 | V16: c.a.c.altourubamba@gmail.com | W16: SI | X16: S0143918 | Y16: SI | Z16: COOPERATIVA AGRARIA CAFETALERA ALTO URUBAMBA LTDA N° 239 | AA16: 0 | AB16: 0 | AC16: SI | AD16: 681394.36 | AE16: 2025-11 | AF16: 561223.8 | AG16: 4 | AH16: CIRILO QUISPE ILLA | AI16: FLOREZ PALOMINO JOSE | AK16: 5 | AL16: CAFÉ | AM16: 2018-2019-2020-2021-2022-2023 | AN16: PAC | AU16: 46285.072 | AV16: 0.77777778
A17: 20136201213 | B17: CENTRAL DE COOPERATIVAS AGRARIAS CAFETALERAS COCLA LTDA. N° 281 | C17: CENTRAL COCLA LTDA. 281 | D17: COOPERATIVAS, SAIS, CAPS | E17: 02 Cooperativa | F17: ACTIVO | G17: HABIDO | H17: 34102 | I17: 24314 | J17: 080901 | K17: CUSCO | L17: LA CONVENCION | M17: SANTA ANA | N17: AV. EDGAR DE LA TORRE NRO. 1353 QUILLABAMBA (LOCAL DE COCLA) | O17: EXPORTADOR | P17: VTA. MAY. DE OTROS PRODUCTOS. | Q17: ELAB DE OTROS PROD. ALIMENTICIOS. | R17: ACTIVIDADES INMOBILIARIAS | T17: NO, Excluido del Régimen de Agentes de Retención de IGV a partir del 01/02/2015 | U17: 084-281377 | V17: gerencia@cocla.pe | W17: SI | X17: S0552459 | Y17: SI | Z17: CENTRAL DE COOPERATIVAS AGRARIAS CAFETALERAS COCLA LTDA. N° 281 | AA17: 6987135.7 | AB17: 9915753.4 | AC17: SI | AD17: 4445611.6 | AE17: 2026-03 | AF17: 166105.86 | AG17: 5 | AH17: aguilar lozano guillermo | AI17: CURI LEON TANY | AJ17: Vivanco Delgado Vladimir | AK17: 5 | AL17: CAFÉ | AM17: 2024 - 2025 | AN17: PAC | AO17: 472 | AP17: 188 | AQ17: 1670 | AR17: Certificación Orgánica, vigencia hasta agosto 2026 | AS17: Fair trade hasta junio 2027 | AT17: 0.75 | AU17: 46285.072 | AV17: 0.97777778
A18: 20140181405 | B18: COOPERATIVA AGRARIA CAFETALERA LA FLORIDA | C18: COOPERATIVA LA FLORIDA | D18: COOPERATIVAS, SAIS, CAPS | F18: ACTIVO | G18: HABIDO | H18: 34129 | I18: 25849 | K18: JUNIN | L18: CHANCHAMAYO | M18: PERENE | N18: AV. CHANCHAMAYO MZA. O LOTE. 24 C.P. PUERTO YURINAKI (A UNA CDRA PARQUE PTO YURINAKI S75098560) | O18: EXPORTADOR | P18: CULTIVO DE FRUTAS. | Q18: RESTAURANTES, BARES Y CANTINAS. | T18: NO, Excluido del Régimen de Agentes de Retención de IGV a partir del 01/01/2025 | U18: 064-531190 | V18: admlaflorida@spide.com | W18: SI | X18: S0599278 | Y18: SI | Z18: COOPERATIVA AGRARIA CAFETALERA LA FLORIDA | AA18: 0 | AB18: 0 | AC18: SI | AD18: 4202982.9 | AE18: 2026-04 | AF18: 67334.78 | AG18: 7 | AI18: RIVAS PEÑA CESAR | AJ18: Edwin Villacorta Reategui | AO18: 339 | AP18: 111 | AQ18: 1605.8 | AR18: 1780867353, VIGENCIA HASTA 06 FEB 2028 | AS18: FLO ID 796, VIGENCIA HASTA 24 DIC 2028 | AT18: 0.75 | AU18: 46285.072 | AV18: 0.8
A19: 20140292657 | B19: COOPERATIVA AGRARIA CAFETALERA CCOCHAPAMPA LTDA. | C19: COOP AGRARIA CAFETALERA | D19: COOPERATIVAS, SAIS, CAPS | E19: 02 Cooperativa | F19: ACTIVO | G19: HABIDO | H19: 34129 | I19: 33909 | J19: 080901 | K19: CUSCO | L19: LA CONVENCION | M19: SANTA ANA | N19: AV. EDGAR DE LA TORRE NRO. 350 (FT I.E TUPAC AMAR LOCAL COOP. 2P CELESTE) | O19: EXPORTADOR | P19: CULTIVO DE FRUTAS. | Q19: VTA. MAY. DE OTROS PRODUCTOS. | U19: 958301167 | V19: CONTABILIDADAGREGADOSCUSCO@HOTMAIL.COM | W19: SI | X19: S1370809 | Y19: SI | Z19: COOPERATIVA AGRARIA CAFETALERA CCOCHAPAMPA LTDA. | AA19: 477922.31 | AB19: 1773460 | AC19: NO | AH19: aguilar masias gabriel | AI19: PIMENTEL CONDORI LUDGARDO | AJ19: Augusto Tirado Bejar | AK19: 7 | AL19: CAFÉ | AM19: 2024 - 2025 | AN19: PAC | AO19: 38 | AP19: 11 | AQ19: 136.9 | AR19: Certificacion Organica, , vigencia hasta agosto 2026. | AS19: FairTrade (en proceso) | AT19: 0.75 | AU19: 46285.072 | AV19: 0.84444444
A20: 20143224857 | B20: COOPERATIVA AGRARIA DE USUARIOS AMAYBAMBA PISTIPATA LTDA. N°34 | C20: COOPERATIVA AGRARIA | D20: COOPERATIVAS, SAIS, CAPS | E20: 02 Cooperativa | F20: ACTIVO | G20: HABIDO | H20: 34144 | I20: 25934 | J20: 080903 | K20: CUSCO | L20: LA CONVENCION | M20: HUAYOPATA | N20: CAR. QUILLABAMBA CUSCO NRO. KM35 | O20: SIN ACTIVIDAD | P20: CULTIVO DE FRUTAS. | W20: NO | Y20: SI | Z20: COOPERATIVA AGRARIA DE USUARIOS AMAYBAMBA PISTIPATA LTDA. N°34 | AA20: 45825.402 | AB20: 167029 | AC20: NO | AL20: TE | AM20: 2021-2022-2023-2024 - 2025 | AN20: PAC | AU20: 46285.072 | AV20: 0.53333333
A21: 20143692010 | B21: COOPERATIVA AGRARIA EL QUINACHO LTDA. N° 078 | C21: CAC. EL QUINACHO | D21: COOPERATIVAS, SAIS, CAPS | E21: 02 Cooperativa | F21: ACTIVO | G21: HABIDO | H21: 34144 | I21: 25942 | J21: 050407 | K21: AYACUCHO | L21: HUANTA | M21: SIVIA | N21: AV. QUINACHO MZA. V LOTE. 1 (COSTADO DE LA PLAZA PRINCIPAL) | O21: IMPORTADOR/EXPORTADOR | P21: ELAB. CACAO, CHOCOLATE Y CONFIT. | U21: 980444176 | V21: astogozmemarisol@gmail.com | W21: SI | X21: S0758757 | Y21: SI | Z21: COOPERATIVA AGRARIA EL QUINACHO LTDA. N° 078 | AA21: 0 | AB21: 3073770.7 | AC21: SI | AD21: 4030694.7 | AE21: 2026-05 | AF21: 109193.16 | AG21: 3 | AH21: LAPA ÑAHUINCCOPA EFRAIN | AI21: SANTIVAÑEZ SANCHEZ NENE LUIS | AK21: 3 | AL21: CACAO | AM21: 2020-2021-2022-2023 - 2025 | AN21: CALIDAD | AU21: 46285.072 | AV21: 0.75555556
A22: 20145484597 | B22: COOPERATIVA AGRARIA CAFETALERA SAN IGNACIO LTDA. | D22: COOPERATIVAS, SAIS, CAPS | E22: 02 Cooperativa | F22: ACTIVO | G22: HABIDO | H22: 34150 | I22: 33990 | J22: 211201 | K22: PUNO | L22: SANDIA | M22: SAN PEDRO DE PUTINA PUNCO | N22: JR. PROGRESO MZA. L LOTE. 15 BAR. BELLAVISTA (AL FRENTE DEL CENTRO DE SALUD) | O22: SIN ACTIVIDAD | P22: VTA. MAY. DE MATERIAS PRIMAS AGROPEC. | Q22: TRANSPORTE DE CARGA POR CARRETERA. | U22: 951401272 | W22: SI | X22: S0369016 | Y22: SI | Z22: COOPERATIVA AGRARIA CAFETALERA SAN IGNACIO LTDA. | AA22: 0 | AB22: 0 | AC22: NO | AI22: BLANCO CHIARA ADOLFO | AL22: CAFÉ | AM22: 2018-2019-2020 | AN22: PAC | AU22: 46285.072 | AV22: 0.6
A23: 20146696041 | B23: COOP AGRARIA CAFET JOSE GABRIEL CONDORCA | C23: COOP AGRA CAF JOSE GAB COND | D23: COOPERATIVAS, SAIS, CAPS | E23: 02 Cooperativa | F23: ACTIVO | G23: HABIDO | H23: 34151 | I23: 25517 | J23: 200302 | K23: PIURA | L23: HUANCABAMBA | M23: CANCHAQUE | N23: NRO. S/N INT. S/N C.P.M COYONA (A 500M DEL PUESTO DE SALUD DE COYONA) | O23: SIN ACTIVIDAD | P23: VTA. MAY. ALIMENTOS, BEBIDAS Y TABACO. | S23: SI, incorporado al Régimen de Buenos Contribuyentes (Resolución N° 0830050012681) a partir del 01/02/2022 | W23: NO | Y23: SI | Z23: COOP AGRARIA CAFET JOSE GABRIEL CONDORCA | AA23: 0 | AB23: 0 | AC23: NO | AL23: CAFÉ | AM23: 2021-2023 | AN23: PAC | AU23: 46285.072 | AV23: 0.55555556
A24: 20147443120 | B24: COOPERATIVA AGRARIA CAFETALERA TIRIJUAY PAVAYOC LTDA 013-B-VII | D24: COOPERATIVAS, SAIS, CAPS | F24: SUSPENSION TEMPORAL | G24: NO HABIDO | H24: 34151 | I24: 27668 | K24: CUSCO | L24: LA CONVENCION | M24: OCOBAMBA | N24: NRO. SN C.P. DE VERSALLES (CALLE PRINCIPAL FRENT A ESCUELA C2P AZUL) | O24: SIN ACTIVIDAD | P24: VTA. MAY. MATERIALES DE CONSTRUCCION. | Q24: SERVICIOS AGRICOLAS, GANADERAS. | U24: 974 776 817 | V24: cactirijuaypavayoc@gmail.com | W24: NO | Y24: SI | Z24: COOPERATIVA AGRARIA CAFETALERA TIRIJUAY PAVAYOC LTDA 013-B-VII | AA24: 0 | AB24: 0 | AC24: NO | AI24: Carlos Velasquez Champi | AJ24: Carlos Velasquez Champi | AO24: 44 | AP24: 30 | AQ24: 150 | AR24: Certificacion Organica, vigencia hasta 14/08/2026 | AS24: Vigencia organica hasta 26/03/2027 | AU24: 46285.072 | AV24: 0.62222222
A25: 20166786861 | B25: COMITE CENTRAL DE PRODUCTORES AGROPECUARIOS DE SAN ALEJANDRO | D25: ASOCIACION | E25: 01 Asociación | F25: ACTIVO | G25: HABIDO | H25: 34194 | I25: 33295 | J25: 250302 | K25: UCAYALI | L25: PADRE ABAD | M25: IRAZOLA | N25: JR. JR. JHON F. KENNEDY MZA. 0 LOTE. 01 C.V. JJ.VV. MIGUEL GRAU (CERCA AL PUERTO GRAU) | O25: SIN ACTIVIDAD | P25: EXPLOTACION MIXTA. | Q25: ELAB. CACAO, CHOCOLATE Y CONFIT. | W25: NO | Y25: SI | Z25: COMITE CENTRAL DE PRODUCTORES AGROPECUARIOS DE SAN ALEJANDRO | AA25: 0 | AB25: 23891.548 | AC25: NO | AL25: CACAO | AM25: 2025 | AN25: PAC | AU25: 46285.072 | AV25: 0.53333333
A26: 20170142773 | B26: COOPERATIVA AGRARIA CAFETALERA BAGUA GRANDE LIMITADA | C26: CAC.BAGUA GRANDE LTDA | D26: COOPERATIVAS, SAIS, CAPS | E26: 02 Cooperativa | F26: ACTIVO | G26: HABIDO | H26: 34202 | I26: 28840 | J26: 010701 | K26: AMAZONAS | L26: UTCUBAMBA | M26: BAGUA GRANDE | N26: JR. ISIDRO MAMANI NRO. 120 SECTOR SAN LUIS (FRENTE A LA PLAZA DE GANADO) | O26: IMPORTADOR/EXPORTADOR | P26: CULTIVO DE FRUTAS. | Q26: OTRAS ACTIVID.DE TIPO SERVICIO NCP | W26: SI | X26: S1645249 | Y26: SI | Z26: COOPERATIVA AGRARIA CAFETALERA BAGUA GRANDE LIMITADA | AA26: 9154082 | AB26: 0 | AC26: SI | AD26: 9070756.9 | AE26: 2026-05 | AF26: 402384.75 | AG26: 7 | AH26: saavedra gonzales clodomiro | AI26: TALLEDO TORRES RAUL MANUEL | AK26: 3 | AL26: CAFÉ | AM26: 2018-2019-2020-2023-2024 | AN26: PAC | AU26: 46285.072 | AV26: 0.73333333
A27: 20175089111 | B27: COOP. AG. SOCIEDAD AGRICOLA DE INTERES SOCIAL JOSE CARLOS MARIATEGUI LTDA.N°16 SUNCHUBAMBA Y ANEXOS | D27: COOPERATIVAS, SAIS, CAPS | E27: 02 Cooperativa | F27: ACTIVO | G27: HABIDO | H27: 34229 | I27: 26594 | J27: 060104 | K27: CAJAMARCA | L27: CAJAMARCA | M27: COSPAN | N27: CAL. CENTRO POBLADO SUNCHUBAMB NRO. S/N C.P. SUNCHUBAMBA | O27: EXPORTADOR | P27: EXPLOTACION MIXTA. | Q27: TRANSPORTE DE CARGA POR CARRETERA. | U27: 076607101 | V27: JCMRODRIGUEZ@GMAIL.COM | W27: SI | X27: S0170876 | Y27: SI | Z27: COOP. AG. SOCIEDAD AGRICOLA DE INTERES SOCIAL JOSE CARLOS MARIATEGUI LTDA.N°16 SUNCHUBAMBA Y ANEXOS | AA27: 17323 | AB27: 15800 | AC27: NO | AH27: sanchez gaitan esteban | AI27: ALCALDE INFANTE JORGE LUIS | AK27: 6 | AL27: DERIVADOS LACTEOS | AM27: 2023-2024 - 2025 | AN27: PAC | AU27: 46285.072 | AV27: 0.66666667
A28: 20183732031 | B28: ASOCIACION DE PRODUCTORES DE ROCOTO Y PRODUCTOS AGRICOLAS DE OXAPAMPA | D28: ASOCIACION | E28: 01 Asociación | F28: BAJA DE OFICIO | G28: HABIDO | H28: 45056 | I28: 45056 | J28: 190301 | K28: PASCO | L28: OXAPAMPA | M28: OXAPAMPA | N28: JR. MULLER NRO. S/N LA ESPERANZA (CDRA. 8 - PLANTA ROCOTERA) | O28: SIN ACTIVIDAD | P28: CULTIVO DE HORTALIZAS Y LEGUMBRES. | W28: NO | Y28: SI | Z28: ASOCIACION DE PRODUCTORES DE ROCOTO Y PRODUCTOS AGRICOLAS DE OXAPAMPA | AA28: 0 | AB28: 0 | AC28: NO | AL28: CAPSICUMS | AM28: 2019 | AN28: PAC | AU28: 46285.072 | AV28: 0.51111111
A29: 20200880448 | B29: COOPERATIVA AGRARIA CAFETALERA JORGE CHAVEZ LTDA | D29: COOPERATIVAS, SAIS, CAPS | F29: ACTIVO | G29: HABIDO | H29: 34321 | I29: 30231 | K29: CUSCO | L29: CALCA | M29: YANATILE | N29: NRO. S/N INT. S/N C.C.CUQUIPATA (CARRETERA KM.117) | O29: SIN ACTIVIDAD | P29: VTA. MAY. DE OTROS PRODUCTOS. | U29: 954 004 223 | V29: josecarloshanccotorres144@gmail.com | W29: NO | Y29: SI | Z29: COOPERATIVA AGRARIA CAFETALERA JORGE CHAVEZ LTDA | AA29: 0 | AB29: 0 | AC29: NO | AI29: Raul Castro Farfan | AO29: 29 | AP29: 7 | AQ29: 38 | AR29: Certificacion Organica, vigencia hasta 14/08/2026 | AS29: Vigencia organica hasta 26/03/2027 | AU29: 46285.072 | AV29: 0.57777778
A30: 20204028061 | B30: COOPERATIVA COMUNAL SAN PEDRO DE CAJAS | C30: COOP COMUNAL SN PEDRO DE CAJAS | D30: COOPERATIVAS, SAIS, CAPS | E30: 02 Cooperativa | F30: ACTIVO | G30: HABIDO | H30: 34341 | I30: 28351 | J30: 120708 | K30: JUNIN | L30: TARMA | M30: SAN PEDRO DE CAJAS | N30: JR. AREQUIPA Y GRAU NRO. SN (CERCA PLAZA PRINCIPAL) | O30: SIN ACTIVIDAD | P30: CRIA DE ANIMALES DOMESTICOS. | Q30: CRIA DE GANADO. | W30: NO | Y30: SI | Z30: COOPERATIVA COMUNAL SAN PEDRO DE CAJAS | AA30: 0 | AB30: 0 | AC30: NO | AL30: FIBRA DE ALPACA | AM30: 2019-2020 | AN30: PAC | AU30: 46285.072 | AV30: 0.55555556
A31: 20287980672 | B31: COMUNIDAD NATIVA TRES ISLAS | C31: CN. TRES ISCAS | D31: COMUNIDAD CAMPESINA, NATIVA | E31: 05 Comunidades Campesinas | F31: ACTIVO | G31: HABIDO | H31: 34906 | I31: 34881 | J31: 170101 | K31: MADRE DE DIOS | L31: TAMBOPATA | M31: TAMBOPATA | N31: CAR. TRES ISLAS KM. 18 COMUNIDAD TRES ISLAS (MISMO SALON COMUNAL TRES ISLAS) | O31: SIN ACTIVIDAD | P31: SILVICULTURA Y EXT. DE MADERA. | Q31: EXT. DE PIEDRA, ARENA Y ARCILLA. | W31: NO | Y31: SI | Z31: COMUNIDAD NATIVA TRES ISLAS | AA31: 74396 | AB31: 101505 | AC31: NO | AL31: AGUAJE | AM31: 2019 | AN31: PAC | AU31: 46285.072 | AV31: 0.55555556
A32: 20323699365 | B32: INVERSIONES PERUALP S.A. | C32: FLORALP | D32: SOCIEDAD ANONIMA | E32: 07 Otros | F32: ACTIVO | G32: HABIDO | H32: 35719 | I32: 35718 | J32: 190301 | K32: PASCO | L32: OXAPAMPA | M32: CHONTABAMBA | N32: CAR. PRINCIPAL KM. 2 BAR. BARRIO NUEVA FLORIDA (MARGEN DERECHA CARRETERA A CHONTABAMBA) | O32: IMPORTADOR/EXPORTADOR | P32: ELAB DE PRODUCTOS LACTEOS. | Q32: TRANSPORTE DE CARGA POR CARRETERA. | U32: 063462465 | V32: jduarte@floralpperu.com | W32: SI | X32: B0014648 | Y32: SI | Z32: INVERSIONES PERUALP S.A. | AA32: 0 | AB32: 0 | AC32: NO | AH32: MARIN FREY, HELGA SARA | AI32: MARIN FREY, JAIME ALFREDO | AJ32: JAIME ALBERTO MARIN FREY | AK32: 6 | AL32: DERIVADOS LACTEOS | AM32: 2018 | AN32: PAC | AU32: 46285.072 | AV32: 0.71111111
A33: 20326767400 | B33: ASOC.C.DE ACOPIO D.LECHE SR.D.L.MILAGROS | D33: ASOCIACION | E33: 01 Asociación | F33: ACTIVO | G33: HABIDO | H33: 35257 | I33: 35257 | J33: 040520 | K33: AREQUIPA | L33: CAYLLOMA | M33: LLUTA | N33: PARCELAMIENTO NRO. B (FRENTE A PARCELA B2-80 IRRIG. MAJES) | O33: SIN ACTIVIDAD | P33: ACTIVIDADES OTRAS ASOCIACIONES NCP. | Q33: ELAB DE PRODUCTOS LACTEOS. | R33: TRANSPORTE DE CARGA POR CARRETERA. | U33: 958996698 | V33: calmilagroscontabilidad@hotmail.com | W33: SI | X33: S2943858 | Y33: SI | Z33: ASOC.C.DE ACOPIO D.LECHE SR.D.L.MILAGROS | AA33: 394769.86 | AB33: 338125.16 | AC33: NO | AH33: OBANDO DE GUZMAN LILIA MARIA | AI33: OBANDO DE GUZMAN LILIA MARIA | AK33: 7 | AL33: DERIVADOS LACTEOS | AM33: 2022-2023-2024 - 2025 | AN33: PAC | AU33: 46285.072 | AV33: 0.68888889
A34: 20327993705 | B34: CENTRO DE ACOPIO DE LECHE LUIS PASTEUR | D34: ASOCIACION | E34: 01 Asociación | F34: ACTIVO | G34: HABIDO | H34: 35465 | I34: 35465 | J34: 040520 | K34: AREQUIPA | L34: CAYLLOMA | M34: MAJES | N34: SECCION NRO. D INT. 1 IRRIGACION MAJES (1ER. RAMAL ALTURA 908, PANAMERICANA SUR) | O34: SIN ACTIVIDAD | P34: ELAB DE PRODUCTOS LACTEOS. | Q34: TRANSPORTE DE CARGA POR CARRETERA. | W34: NO | Y34: SI | Z34: CENTRO DE ACOPIO DE LECHE LUIS PASTEUR | AA34: 0 | AB34: 246100 | AC34: NO | AL34: DERIVADOS LACTEOS | AM34: 2025 | AN34: PAC | AU34: 46285.072 | AV34: 0.53333333
A35: 20352266052 | B35: ASOCIACION DE PRODUCTORES DE PALMITO DE AGUAYTIA | D35: ASOCIACION | E35: 01 Asociación | F35: BAJA DE OFICIO | G35: NO HABIDO | H35: 40346 | I35: 40346 | J35: 250301 | K35: UCAYALI | L35: PADRE ABAD | M35: PADRE ABAD | N35: JR. GENARO PAREDES MZA. 167 LOTE. 2 JJ.VV. PAMPA YURAC | O35: SIN ACTIVIDAD | P35: CULTIVOS DE CEREALES. | W35: NO | Y35: SI | Z35: ASOCIACION DE PRODUCTORES DE PALMITO DE AGUAYTIA | AA35: 0 | AB35: 0 | AC35: NO | AL35: PALMITO | AM35: 2018-2019 | AN35: PAC | AU35: 46285.072 | AV35: 0.51111111
A36: 20352417018 | B36: COOPERATIVA AGRARIA DE CACAOTEROS TECNIFICADOS DE PADRE ABAD | C36: ACATPA | D36: COOPERATIVAS, SAIS, CAPS | E36: 02 Cooperativa | F36: SUSPENSION TEMPORAL | G36: HABIDO | H36: 39538 | I36: 39539 | J36: 250302 | K36: UCAYALI | L36: PADRE ABAD | M36: IRAZOLA | N36: MZA. Ñ LOTE. 10 SAN ALEJANDRO (JUNTA VECINAL MIGUEL GRAU) | O36: IMPORTADOR/EXPORTADOR | P36: CULTIVO DE FRUTAS. | Q36: OTROS TIPOS TRANSPORTE REG. VIA TER. | U36: 576387 | W36: SI | X36: S0374689 | Y36: SI | Z36: COOPERATIVA AGRARIA DE CACAOTEROS TECNIFICADOS DE PADRE ABAD | AA36: 0 | AB36: 0 | AC36: NO | AI36: ESPIRITU PRUDENCIO JACINTO GUILLERMO | AL36: CACAO | AM36: 2018 | AN36: PAC | AU36: 46285.072 | AV36: 0.62222222
A37: 20352423921 | B37: COOPERATIVA AGRARIA CAFETALERA DIVISORIA LTDA | D37: COOPERATIVAS, SAIS, CAPS | E37: 02 Cooperativa | F37: ACTIVO | G37: HABIDO | H37: 36964 | I37: 36964 | J37: 100605 | K37: HUANUCO | L37: LEONCIO PRADO | M37: LUYANDO | N37: CAL. CARRETERA TINGO MARIA-PU MZA. A LOTE. 23 ZONA HABILITACION URBANA (BALANZA MAPRESA) | O37: IMPORTADOR/EXPORTADOR | P37: VTA. MAY. DE MATERIAS PRIMAS AGROPEC. | Q37: ELAB DE OTROS PROD. ALIMENTICIOS. | U37: 947595969 | V37: gerencia@cacdivisoria.com | W37: SI | X37: S0596909 | Y37: SI | Z37: COOPERATIVA AGRARIA CAFETALERA DIVISORIA LTDA | AA37: 0 | AB37: 0 | AC37: NO | AH37: PARRA CABALLERO MARIO AQUILES | AI37: RODRIGUEZ CIRIACO EUGENIO MARIO | AK37: 5 | AL37: CAFÉ | AM37: 2018 | AN37: PAC | AU37: 46285.072 | AV37: 0.66666667
A38: 20365575674 | B38: COMUNIDAD CAMPESINA SAN ANTONIO DE RANCAS | D38: COMUNIDAD CAMPESINA, NATIVA | E38: 05 Comunidades Campesinas | F38: ACTIVO | G38: HABIDO | H38: 36118 | I38: 36100 | J38: 190109 | K38: PASCO | L38: PASCO | M38: SIMON BOLIVAR | N38: CAL. SUCRE NRO. 127 RANCAS (SEGUNDO PISO FRENTE A LA BODEGA CHAVEZ) | O38: SIN ACTIVIDAD | P38: EXPLOTACION MIXTA. | Q38: FAB. DE CALZADO. | W38: SI | X38: S2209855 | Y38: SI | Z38: COMUNIDAD CAMPESINA SAN ANTONIO DE RANCAS | AA38: 156032 | AB38: 291119.08 | AC38: NO | AH38: ROBLES CHAVEZ PERCY GODOFREDO | AI38: 04045388 | AK38: 2 | AL38: DERIVADOS LACTEOS | AM38: 2024 - 2025 | AN38: PAC | AU38: 46285.072 | AV38: 0.62222222
A39: 20393152207 | B39: COOPERATIVA AGRO INDUSTRIAL APCTVASH | D39: COOPERATIVAS, SAIS, CAPS | E39: 02 Cooperativa | F39: ACTIVO | G39: HABIDO | H39: 44069 | I39: 44075 | J39: 250301 | K39: UCAYALI | L39: PADRE ABAD | M39: PADRE ABAD | N39: KM. 6 P.J. CASERIO SHAMBILLO | O39: SIN ACTIVIDAD | P39: VTA. MAY. DE MATERIAS PRIMAS AGROPEC. | Q39: ELAB. CACAO, CHOCOLATE Y CONFIT. | R39: OTROS TIPOS DE VENTA POR MENOR. | U39: 061-794794 | W39: SI | X39: S0490351 | Y39: SI | Z39: COOPERATIVA AGRO INDUSTRIAL APCTVASH | AA39: 34611.17 | AB39: 0 | AC39: NO | AI39: GARCIA GUTIERREZ GERMAN | AL39: CACAO | AM39: 2024 | AN39: PAC | AU39: 46285.072 | AV39: 0.62222222
A40: 20393335620 | B40: ASOCIACIÓN DE PRODUCTORES ECOLÓGICOS DEL CASERÍO SAN CRISTÓBAL DE AGUA BLANCA | D40: ASOCIACION | E40: 01 Asociación | F40: BAJA DE OFICIO | G40: HABIDO | H40: 41066 | I40: 41066 | J40: 250102 | K40: UCAYALI | L40: CORONEL PORTILLO | M40: CAMPOVERDE | N40: JR. SAN MARTIN MZA. 57 LOTE. 5 (ENTRANDO POR EL MERCADO 250 METROS) | O40: SIN ACTIVIDAD | P40: CULTIVOS DE CEREALES. | W40: NO | Y40: SI | Z40: ASOCIACIÓN DE PRODUCTORES ECOLÓGICOS DEL CASERÍO SAN CRISTÓBAL DE AGUA BLANCA | AA40: 0 | AB40: 0 | AC40: NO | AL40: PANELA | AM40: 2018 | AN40: PAC | AU40: 46285.072 | AV40: 0.51111111
...

Sheet b1
A1: Nombre de la Organización | B1: PRODUCTO DOM | C1: PRODUCTO 1 | D1: SEDE | E1: Ubigeo | F1: DEPARTAMENTO | G1: Provincia | H1: Distrito | I1: TIPO DE CERTIFICADO | J1: 2025 | K1: SERVICIO | L1: AÑOS DE INTERVENCION | M1: AÑOS DE INTERVENCIÓN DESDE 2018 AL 2024 | N1: INTERVENCIÓN 2019 al 2025 | O1: BENF MASC 2025 | P1: BENF FEM 2025 | Q1: TOTAL BENF 2025 | R1: TOTAL VENTAS 2018 AL 2025 | S1: V. EJEC NACIONALES 2025 | T1: V. EJEC EXPORTACION 2025 | U1: VENTAS TOTALES 2025 | V1: INCREMENTOS VENTAS EN 2025 | W1: DIFERENCIA VENTAS 2025-2024 | X1: Boleta de Venta 2025 | Y1: Declaración Jurada 2025 | Z1: Factura 2025 | AA1: Guía de Remisión 2025 | AB1: Liquidación de Compra 2025 | AC1: Total general 2025 | AD1: RUC | AE1: Tipo de Organización* (Asociación/Cooperativa/CCNN, Comunidad Campesina y otros.)
A2: COOPERATIVA AGRARIA DE USUARIOS DE PEQUEÑOS PRODUCTORES DEL PERU | B2: MANGO | C2: MANGO | D2: ANCASH | E2: 020801 | F2: ANCASH | G2: CASMA | H2: CASMA | I2: FAIR TRADE | J2: 1 | K2: PAC | L2: 2025 | M2: 1 | N2: SI | O2: 15 | P2: 9 | Q2: 24 | X2: 0 | Y2: 399056.4 | Z2: 866144.87 | AA2: 0 | AB2: 0 | AC2: 1265201.3 | AD2: 20601575184 | AE2: Cooperativa
A3: COOPERATIVA AGRARIA AGROFRUTOS ORGANICOS | B3: MANGO | C3: MANGO | D3: LAMBAYEQUE | E3: 140307 | F3: LAMBAYEQUE | G3: LAMBAYEQUE | H3: MOTUPE | I3: ORGANICO | J3: 1 | K3: PAC | L3: 2025 | M3: 1 | N3: =IF(OR([1]!Tabla16[[#This Row],[2019]]=1,[1]!Tabla16[[#This Row],[2020]]=1,[1]!Tabla16[[#This Row],[2021]]=1,[1]!Tabla16[[#This Row],[2022]]=1,[1]!Tabla16[[#This Row],[2023]]=1,[1]!Tabla16[[#This Row],[2024]]=1,[1]!Tabla16[[#This Row],[2025]]=1),"SI","NO") | O3: 62 | P3: 10 | Q3: 72 | R3: #REF! | S3: 22435.002 | T3: 0 | U3: 22435.002 | V3: #REF! | W3: ='[2]DATA CONSOLIDADA 2018-2025 '!$CM5-[1]!Tabla16[[#This Row],[VENTAS TOTALES 20224]] | X3: 0 | Y3: 0 | Z3: 22435.002 | AA3: 0 | AB3: 0 | AC3: 22435.002 | AD3: 20613899287 | AE3: Cooperativa
A4: COOPERATIVA AGRARIA DE USUARIOS ASPRAOSRA LTDA | B4: BANANO | C4: BANANO | D4: PIURA | F4: PIURA | G4: MORROPON | H4: BUENOS AIRES | I4: ORGANICO/GLOBAL GAP | J4: 1 | K4: PAC | L4: 2025 | M4: 1 | N4: =IF(OR([1]!Tabla16[[#This Row],[2019]]=1,[1]!Tabla16[[#This Row],[2020]]=1,[1]!Tabla16[[#This Row],[2021]]=1,[1]!Tabla16[[#This Row],[2022]]=1,[1]!Tabla16[[#This Row],[2023]]=1,[1]!Tabla16[[#This Row],[2024]]=1,[1]!Tabla16[[#This Row],[2025]]=1),"SI","NO") | O4: 22 | P4: 14 | Q4: 36 | R4: #REF! | S4: 0 | T4: 781855.2 | U4: 781855.2 | V4: #REF! | W4: ='[2]DATA CONSOLIDADA 2018-2025 '!$CM6-[1]!Tabla16[[#This Row],[VENTAS TOTALES 20224]] | X4: 0 | Y4: 0 | Z4: 781855.2 | AA4: 0 | AB4: 0 | AC4: 781855.2 | AD4: 20526179367 | AE4: Cooperativa
