Workbook

Sheet Hoja1
A1: 2 | B1: 3 | C1: 4 | D1: 7 | E1: 8 | F1: 9 | G1: 10 | H1: 11 | I1: 12 | J1: 13 | K1: 14 | L1: 15 | M1: 16 | N1: 17 | O1: 18 | P1: 19 | R1: 20 | S1: 21 | T1: 22 | V1: 23 | W1: 24 | X1: 25 | Y1: 26 | Z1: 27 | AA1: 28 | AB1: 29 | AC1: 30 | AD1: 31 | AE1: 32 | AF1: 33 | AG1: 34 | AH1: 35 | AI1: 36 | AJ1: 37 | AK1: 38 | AL1: 39 | AM1: 40 | AN1: 41 | AO1: 42 | AP1: 43 | AQ1: 44 | AR1: 45 | AS1: 46 | AT1: 47 | AU1: 48 | AV1: 49 | AW1: 50 | AX1: 51 | AY1: 52 | AZ1: 53 | BA1: 54 | BB1: 55 | BC1: 56 | BD1: 57 | BE1: 58 | BF1: 59 | BG1: 60 | BH1: 61 | BI1: 62 | BJ1: 63 | BK1: 64 | BL1: 65 | BM1: 66 | BN1: 67 | BO1: 68 | BP1: 69 | BQ1: 70 | BR1: 71 | BS1: 72 | BT1: 73 | BU1: 74 | BV1: 75 | BW1: 76 | BX1: 77 | BY1: 78 | BZ1: 79 | CA1: 80 | CB1: 81 | CC1: 82 | CD1: 83 | CE1: 84 | CF1: 85 | CG1: 86 | CH1: 87 | CI1: 88 | CJ1: 89 | CK1: 90 | CL1: 91 | CM1: 92 | CN1: 93 | CO1: 94 | CP1: 95 | CQ1: 96 | CR1: 97 | CS1: 98 | CT1: 99 | CU1: 100 | CV1: 101 | CW1: 102 | CX1: 103 | CY1: 104 | CZ1: 105 | DA1: 106 | DB1: 107 | DI1: 122 | DJ1: 123 | DK1: 124
I2: AÑOS INTERVENCIÓN | V2: BENEFICIARIOS | BE2: VENTAS HISTORIAL | CP2: VENTAS PORTIPO DE COMPROMABNTE (OBTENIDO SISPAC 2023 DEL REPORTE MATRIZ GENERAL DE VENTAS) | CW2: VENTAS POR TIPO DE COMPROMABNTE año 2024 | DC2: VENTAS POR TIPO DE COMPROMABNTE año 2025 -12.01.26)
V3: 2018 | W3: 2019 | Z3: 2020 | AC3: 2021 | AF3: 2022 | AI3: 2023 | AL3: 2024 | AO3: 2025 (Ciierre de Agosto 2025) | AS3: 2020 | AU3: 2021 | AW3: 2022 | AY3: 2023 | BA3: 2024 | BC3: 2025 (cierre agosto 2025) | BE3: 2018 | BF3: 2019 | BK3: 2020 | BP3: 2021 | BU3: 2022 | BZ3: 2023 | CE3: 2024 | CK3: 2025 (Cierre de 12.01.26) | CP3: 2023 detallado por tipo comprobante
A4: Nombre de la Organización | B4: PRODUCTO DOM | C4: PRODUCTO 1 | D4: SEDE | E4: Ubigeo | F4: DEPARTAMENTO | G4: Provincia | H4: Distrito | I4: 2018 | J4: 2019 | K4: 2020 | L4: 2021 | M4: 2022 | N4: 2023 | O4: 2024 | P4: 2025 | Q4: SERVICIO | R4: AÑOS DE INTERVENCION | S4: AÑOS DE INTERVENCIÓN DESDE 2018 AL 2024 | T4: INTERVENCIÓN 2019 al 2025 | U4: INTERVENCIÓN 2020 al 2026 | V4: TOTAL BENF 2018 | W4: BENF MASC 2019 | X4: BENF FEM 2019 | Y4: TOTAL BENF 2019 | Z4: BENF MASC 2020 | AA4: BENF FEM 2020 | AB4: TOTAL BENF 2020 | AC4: BENF MASC 2021 | AD4: BENF FEM 2021 | AE4: TOTAL BENF 2021 | AF4: BENF MASC 2022 | AG4: BENF FEM 2022 | AH4: TOTAL BENF 2022 | AI4: BENF MASC 2023 | AJ4: BENF FEM 2023 | AK4: TOTAL BENF 2023 | AL4: BENF MASC 2024 | AM4: BENF FEM 2024 | AN4: TOTAL BENF 2024 | AO4: BENF MASC 2025 | AP4: BENF FEM 2025 | AQ4: TOTAL BENF 2025 | AR4: BENEFICIADOS ULTIMO AÑO | AS4: ASISTENCIA TÉCNICA 2020 | AT4: TALLERES 2020 | AU4: ASISTENCIA TÉCNICA 2021 | AV4: TALLERES 2021 | AW4: ASISTENCIA TÉCNICA 2022 | AX4: TALLERES 2022 | AY4: ASISTENCIA TÉCNICA 2023 | AZ4: TALLERES 2023 | BA4: ASISTENCIA TÉCNICA 2024 | BB4: TALLERES 2024 | BC4: ASISTENCIA TÉCNICA 2025 | BD4: TALLERES 2025 | BE4: VENTAS TOTALES 2018 | BF4: VENTAS NACIONALES 2019 | BG4: VENTAS INTERNACIONALES 2019 | BH4: VENTAS TOTALES 2019 | BI4: INCREMENTOS VENTAS EN 2019 | BJ4: INCREMENTOS VENTAS EN 20192 | BK4: VENTAS NACIONALES 2020 | BL4: VENTAS INTERNACIONALES 2020 | BM4: VENTAS TOTALES 2020 | BN4: INCREMENTOS VENTAS EN 2020 | BO4: DIFERENCIA VENTA 2020-2019 | BP4: VENTAS NACIONALES 2021 | BQ4: VENTAS INTERNACIONALES 2021 | BR4: VENTAS TOTALES 2021 | BS4: INCREMENTOS VENTAS EN 20201 | BT4: DIFERENCIA VENTA 2021-2020 | BU4: V. EJEC NACIONALES 2022 | BV4: V. EJEC EXPORTACION 2022 | BW4: VENTAS TOTALES 2022 | BX4: INCREMENTOS VENTAS EN 22022 | BY4: DIFERENCIA VENTAS 2022-2021 | BZ4: V. EJEC NACIONALES 2023 | CA4: V. EJEC EXPORTACION 2023 | CB4: VENTAS TOTALES 2023 | CC4: INCREMENTOS VENTAS EN 2023 | CD4: DIFERENCIA VENTAS 2023-2022 | CE4: V. EJEC NACIONALES 2024 | CF4: V. EJEC EXPORTACION 2024 | CG4: VENTAS TOTALES 20224 | CH4: INCREMENTOS VENTAS EN 2024 | CI4: DIFERENCIA VENTAS 2024-2023 | CJ4: TOTAL VENTAS 2018 AL 2025 | CK4: V. EJEC NACIONALES 2025 | CL4: V. EJEC EXPORTACION 2025 | CM4: VENTAS TOTALES 2025 | CN4: INCREMENTOS VENTAS EN 2025 | CO4: DIFERENCIA VENTAS 2025-2024 | CP4: Boleta de Venta 2023 | CQ4: Declaracion Jurada 2023 | CR4: Documento de Entrega Cooperativo (DEC) 2023 | CS4: Factura 2023 | CT4: Guia de Remision 2023 | CU4: Liquidacion de Compra 2023 | CV4: Total Ventas 2023 (De comprobantes) (*) | CW4: Boleta de Venta 2024 | CX4: Declaración Jurada 2024 | CY4: Factura 2024 | CZ4: Guía de Remisión 2024 | DA4: Liquidación de Compra 2024 | DB4: Total general 2024 | DC4: Boleta de Venta 2025 | DD4: Declaración Jurada 2025 | DE4: Factura 2025 | DF4: Guía de Remisión 2025 | DG4: Liquidación de Compra 2025 | DH4: Total general 2025 | DI4: RUC | DJ4: NOMBRE SUNAT | DK4: Tipo de Organización* (Asociación/Cooperativa/CCNN, Comunidad Campesina y otros.)
A5: COOPERATIVA AGRARIA CAFETALERA MONTAÑA AZUL LTDA. - COOPACMA | B5: CAFÉ | C5: CAFÉ | D5: AMAZONAS | E5: 010706 | F5: AMAZONAS | G5: UTCUBAMBA | H5: LONYA GRANDE | I5: 1 | J5: 1 | K5: 1 | Q5: PAC | R5: =IF(I5=1, I$4, "") & IF(J5=1, IF(I5=1, "-", "") & J$4, "") & IF(K5=1, IF(OR(J5=1, I5=1), "-", "") & K$4, "") & IF(L5=1, IF(OR(K5=1, J5=1, I5=1), "-", "") & L$4, "") & IF(M5=1, IF(OR(L5=1, K5=1, J5=1, I5=1), "-", "") & M$4, "") & IF(N5=1, IF(OR(M5=1, L5=1, K5=1, J5=1, I5=1), "-", "") & N$4, "") & IF(O5=1, IF(OR(N5=1, M5=1, L5=1, K5=1, J5=1, I5=1), "-", "") & O$4, "") & IF(P5=1, IF(I5=1, " - ", IF(J5=1, " - ", IF(K5=1, " - ", IF(L5=1, " - ", IF(M5=1, " - ", IF(N5=1, " - ", IF(O5=1, " - ", ""))))))) & P$4, "") -> 2018-2019-2020 | S5: =SUM(Hoja1!$I5:$P5) -> 3 | T5: =IF(OR(Hoja1!$J5=1,Hoja1!$K5=1,Hoja1!$L5=1,Hoja1!$M5=1,Hoja1!$N5=1,Hoja1!$O5=1,Hoja1!$P5=1),"SI","NO") -> SI | U5: =IF(OR(Hoja1!$K5=1,Hoja1!$L5=1,Hoja1!$M5=1,Hoja1!$N5=1,Hoja1!$O5=1,Hoja1!$P5=1),"SI","NO") -> SI | V5: 106 | W5: 72 | X5: 34 | Y5: 106 | Z5: 68 | AA5: 31 | AB5: 99 | AC5: 0 | AD5: 0 | AE5: 0 | AF5: 0 | AG5: 0 | AH5: 0 | AI5: 0 | AJ5: 0 | AK5: 0 | AL5: 0 | AM5: 0 | AN5: 0 | AO5: 0 | AP5: 0 | AQ5: 0 | AR5: =IF(Hoja1!$AQ5>0,Hoja1!$AQ5,IF(Hoja1!$AN5>0,Hoja1!$AN5,IF(Hoja1!$AK5>0,Hoja1!$AK5,IF(Hoja1!$AH5>0,Hoja1!$AH5,IF(Hoja1!$AE5>0,Hoja1!$AE5,IF(Hoja1!$AB5>0,Hoja1!$AB5,IF(Hoja1!$Y5>0,Hoja1!$Y5,IF(Hoja1!$V5>0,Hoja1!$V5," ---")))))))) -> 99 | AS5: 0 | AT5: 9 | AU5: 0 | AV5: 0 | AW5: 0 | AX5: 0 | AY5: 0 | AZ5: 0 | BA5: 0 | BB5: 0 | BC5: 0 | BD5: 0 | BE5: 0 | BF5: 0 | BG5: 83583.84 | BH5: 83583.84 | BI5: =IF('[1]DATA CONSOLIDADA 2018-2025 '!$BH5>'[1]DATA CONSOLIDADA 2018-2025 '!$AN5,"Incremento",IF('[1]DATA CONSOLIDADA 2018-2025 '!$AN5='[1]DATA CONSOLIDADA 2018-2025 '!$BH5,"Sin incremento",IF('[1]DATA CONSOLIDADA 2018-2025 '!$BH5<'[1]DATA CONSOLIDADA 2018-2025 '!$AN5,"Disminución"," ---"))) -> #REF! | BJ5: ='[1]DATA CONSOLIDADA 2018-2025 '!$BH5-'[1]DATA CONSOLIDADA 2018-2025 '!$BE5 -> #REF! | BK5: 3460.24 | BL5: 0 | BM5: 3460.24 | BN5: =IF('[1]DATA CONSOLIDADA 2018-2025 '!$BM5>'[1]DATA CONSOLIDADA 2018-2025 '!$BH5,"Incremento",IF('[1]DATA CONSOLIDADA 2018-2025 '!$BH5='[1]DATA CONSOLIDADA 2018-2025 '!$BM5,"Sin incremento",IF('[1]DATA CONSOLIDADA 2018-2025 '!$BM5<'[1]DATA CONSOLIDADA 2018-2025 '!$BH5,"Disminución"," ---"))) -> #REF! | BO5: ='[1]DATA CONSOLIDADA 2018-2025 '!$BM5-'[1]DATA CONSOLIDADA 2018-2025 '!$BH5 -> #REF! | BP5: 0 | BQ5: 0 | BR5: 0 | BS5: =IF('[1]DATA CONSOLIDADA 2018-2025 '!$BR5>'[1]DATA CONSOLIDADA 2018-2025 '!$BM5,"Incremento",IF('[1]DATA CONSOLIDADA 2018-2025 '!$BM5='[1]DATA CONSOLIDADA 2018-2025 '!$BR5,"Sin incremento",IF('[1]DATA CONSOLIDADA 2018-2025 '!$BR5<'[1]DATA CONSOLIDADA 2018-2025 '!$BM5,"Disminución"," ---"))) -> #REF! | BT5: ='[1]DATA CONSOLIDADA 2018-2025 '!$BR5-Hoja1!$BO5 -> #REF! | BU5: 0 | BV5: 0 | BW5: 0 | BX5: =IF('[1]DATA CONSOLIDADA 2018-2025 '!$BW5>'[1]DATA CONSOLIDADA 2018-2025 '!$BR5,"Incremento",IF('[1]DATA CONSOLIDADA 2018-2025 '!$BR5='[1]DATA CONSOLIDADA 2018-2025 '!$BW5,"Sin incremento",IF('[1]DATA CONSOLIDADA 2018-2025 '!$BW5<'[1]DATA CONSOLIDADA 2018-2025 '!$BR5,"Disminución"," ---"))) -> #REF! | BY5: ='[1]DATA CONSOLIDADA 2018-2025 '!$BW5-'[1]DATA CONSOLIDADA 2018-2025 '!$BR5 -> #REF! | BZ5: 0 | CA5: 0 | CB5: 0 | CC5: =IF('[1]DATA CONSOLIDADA 2018-2025 '!$CB5>'[1]DATA CONSOLIDADA 2018-2025 '!$BW5,"Incremento",IF('[1]DATA CONSOLIDADA 2018-2025 '!$BW5='[1]DATA CONSOLIDADA 2018-2025 '!$CB5,"Sin incremento",IF('[1]DATA CONSOLIDADA 2018-2025 '!$CB5<'[1]DATA CONSOLIDADA 2018-2025 '!$BW5,"Disminución"," ---"))) -> #REF! | CD5: ='[1]DATA CONSOLIDADA 2018-2025 '!$CB5-Hoja1!$BW5 -> #REF! | CE5: 0 | CF5: 0 | CG5: 0 | CH5: =IF('[1]DATA CONSOLIDADA 2018-2025 '!$CG5>'[1]DATA CONSOLIDADA 2018-2025 '!$CB5,"Incremento",IF('[1]DATA CONSOLIDADA 2018-2025 '!$CB5='[1]DATA CONSOLIDADA 2018-2025 '!$CG5,"Sin incremento",IF('[1]DATA CONSOLIDADA 2018-2025 '!$CG5<'[1]DATA CONSOLIDADA 2018-2025 '!$CB5,"Disminución"," ---"))) -> #REF! | CI5: ='[1]DATA CONSOLIDADA 2018-2025 '!$CG5-Hoja1!$CB5 -> #REF! | CJ5: ='[1]DATA CONSOLIDADA 2018-2025 '!$BE5+'[1]DATA CONSOLIDADA 2018-2025 '!$BH5+'[1]DATA CONSOLIDADA 2018-2025 '!$BM5+'[1]DATA CONSOLIDADA 2018-2025 '!$BR5+'[1]DATA CONSOLIDADA 2018-2025 '!$BW5+'[1]DATA CONSOLIDADA 2018-2025 '!$CB5+'[1]DATA CONSOLIDADA 2018-2025 '!$CG5 -> #REF! | CK5: 0 | CL5: 0 | CM5: 0 | CN5: =IF('[1]DATA CONSOLIDADA 2018-2025 '!$CM5>'[1]DATA CONSOLIDADA 2018-2025 '!$CG5,"Incremento",IF('[1]DATA CONSOLIDADA 2018-2025 '!$CG5='[1]DATA CONSOLIDADA 2018-2025 '!$CM5,"Sin incremento",IF('[1]DATA CONSOLIDADA 2018-2025 '!$CM5<'[1]DATA CONSOLIDADA 2018-2025 '!$CG5,"Disminución"," ---"))) -> #REF! | CO5: ='[1]DATA CONSOLIDADA 2018-2025 '!$CM5-Hoja1!$CG5 -> #REF! | CP5: 0 | CQ5: 0 | CR5: 0 | CS5: 0 | CT5: 0 | CU5: 0 | CV5: 0 | CW5: 0 | CX5: 0 | CY5: 0 | CZ5: 0 | DA5: 0 | DB5: 0 | DC5: 0 | DD5: 0 | DE5: 0 | DF5: 0 | DG5: 0 | DH5: 0 | DI5: 20600200756 | DJ5: COOPERATIVA AGRARIA CAFETALERA MONTAÑA AZUL LTDA. - COOPACMA | DK5: 02 Cooperativa
A6: ASOCIACIÓN DE PRODUCTORES DE CAFÉ ORGANICO Y CAFES ESPECIALES -APROCOYCE AMAZONAS | B6: CAFÉ | C6: CAFÉ | D6: AMAZONAS | E6: 010601 | F6: AMAZONAS | G6: RODRIGUEZ DE MENDOZA | H6: SAN NICOLAS | J6: 1 | K6: 1 | L6: 1 | M6: 1 | N6: 1 | Q6: PAC | R6: =IF(I6=1, I$4, "") & IF(J6=1, IF(I6=1, "-", "") & J$4, "") & IF(K6=1, IF(OR(J6=1, I6=1), "-", "") & K$4, "") & IF(L6=1, IF(OR(K6=1, J6=1, I6=1), "-", "") & L$4, "") & IF(M6=1, IF(OR(L6=1, K6=1, J6=1, I6=1), "-", "") & M$4, "") & IF(N6=1, IF(OR(M6=1, L6=1, K6=1, J6=1, I6=1), "-", "") & N$4, "") & IF(O6=1, IF(OR(N6=1, M6=1, L6=1, K6=1, J6=1, I6=1), "-", "") & O$4, "") & IF(P6=1, IF(I6=1, " - ", IF(J6=1, " - ", IF(K6=1, " - ", IF(L6=1, " - ", IF(M6=1, " - ", IF(N6=1, " - ", IF(O6=1, " - ", ""))))))) & P$4, "") -> 2019-2020-2021-2022-2023 | S6: =SUM(Hoja1!$I6:$P6) -> 5 | T6: =IF(OR(Hoja1!$J6=1,Hoja1!$K6=1,Hoja1!$L6=1,Hoja1!$M6=1,Hoja1!$N6=1,Hoja1!$O6=1,Hoja1!$P6=1),"SI","NO") -> SI | U6: =IF(OR(Hoja1!$K6=1,Hoja1!$L6=1,Hoja1!$M6=1,Hoja1!$N6=1,Hoja1!$O6=1,Hoja1!$P6=1),"SI","NO") -> SI | V6: 0 | W6: 50 | X6: 33 | Y6: 83 | Z6: 222 | AA6: 135 | AB6: 357 | AC6: 208 | AD6: 150 | AE6: 358 | AF6: 208 | AG6: 150 | AH6: 358 | AI6: 208 | AJ6: 150 | AK6: 358 | AL6: 0 | AM6: 0 | AN6: 0 | AO6: 0 | AP6: 0 | AQ6: 0 | AR6: =IF(Hoja1!$AQ6>0,Hoja1!$AQ6,IF(Hoja1!$AN6>0,Hoja1!$AN6,IF(Hoja1!$AK6>0,Hoja1!$AK6,IF(Hoja1!$AH6>0,Hoja1!$AH6,IF(Hoja1!$AE6>0,Hoja1!$AE6,IF(Hoja1!$AB6>0,Hoja1!$AB6,IF(Hoja1!$Y6>0,Hoja1!$Y6,IF(Hoja1!$V6>0,Hoja1!$V6," ---")))))))) -> 358 | AS6: 0 | AT6: 0 | AU6: 27 | AV6: 8 | AW6: 41 | AX6: 7 | AY6: 32 | AZ6: 6 | BA6: 0 | BB6: 0 | BC6: 0 | BD6: 0 | BE6: 0 | BF6: 4171009.2 | BG6: 0 | BH6: 4171009.2 | BI6: =IF('[1]DATA CONSOLIDADA 2018-2025 '!$BH6>'[1]DATA CONSOLIDADA 2018-2025 '!$AN6,"Incremento",IF('[1]DATA CONSOLIDADA 2018-2025 '!$AN6='[1]DATA CONSOLIDADA 2018-2025 '!$BH6,"Sin incremento",IF('[1]DATA CONSOLIDADA 2018-2025 '!$BH6<'[1]DATA CONSOLIDADA 2018-2025 '!$AN6,"Disminución"," ---"))) -> #REF! | BJ6: ='[1]DATA CONSOLIDADA 2018-2025 '!$BH6-'[1]DATA CONSOLIDADA 2018-2025 '!$BE6 -> #REF! | BK6: 741888.91 | BL6: 0 | BM6: 741888.91 | BN6: =IF('[1]DATA CONSOLIDADA 2018-2025 '!$BM6>'[1]DATA CONSOLIDADA 2018-2025 '!$BH6,"Incremento",IF('[1]DATA CONSOLIDADA 2018-2025 '!$BH6='[1]DATA CONSOLIDADA 2018-2025 '!$BM6,"Sin incremento",IF('[1]DATA CONSOLIDADA 2018-2025 '!$BM6<'[1]DATA CONSOLIDADA 2018-2025 '!$BH6,"Disminución"," ---"))) -> #REF! | BO6: ='[1]DATA CONSOLIDADA 2018-2025 '!$BM6-'[1]DATA CONSOLIDADA 2018-2025 '!$BH6 -> #REF! | BP6: 4099294.7 | BQ6: 0 | BR6: 4099294.7 | BS6: =IF('[1]DATA CONSOLIDADA 2018-2025 '!$BR6>'[1]DATA CONSOLIDADA 2018-2025 '!$BM6,"Incremento",IF('[1]DATA CONSOLIDADA 2018-2025 '!$BM6='[1]DATA CONSOLIDADA 2018-2025 '!$BR6,"Sin incremento",IF('[1]DATA CONSOLIDADA 2018-2025 '!$BR6<'[1]DATA CONSOLIDADA 2018-2025 '!$BM6,"Disminución"," ---"))) -> #REF! | BT6: ='[1]DATA CONSOLIDADA 2018-2025 '!$BR6-Hoja1!$BO6 -> #REF! | BU6: 1820885 | BV6: 0 | BW6: 1820885 | BX6: =IF('[1]DATA CONSOLIDADA 2018-2025 '!$BW6>'[1]DATA CONSOLIDADA 2018-2025 '!$BR6,"Incremento",IF('[1]DATA CONSOLIDADA 2018-2025 '!$BR6='[1]DATA CONSOLIDADA 2018-2025 '!$BW6,"Sin incremento",IF('[1]DATA CONSOLIDADA 2018-2025 '!$BW6<'[1]DATA CONSOLIDADA 2018-2025 '!$BR6,"Disminución"," ---"))) -> #REF! | BY6: ='[1]DATA CONSOLIDADA 2018-2025 '!$BW6-'[1]DATA CONSOLIDADA 2018-2025 '!$BR6 -> #REF! | BZ6: 4179472.3 | CA6: 0 | CB6: 4179472.3 | CC6: =IF('[1]DATA CONSOLIDADA 2018-2025 '!$CB6>'[1]DATA CONSOLIDADA 2018-2025 '!$BW6,"Incremento",IF('[1]DATA CONSOLIDADA 2018-2025 '!$BW6='[1]DATA CONSOLIDADA 2018-2025 '!$CB6,"Sin incremento",IF('[1]DATA CONSOLIDADA 2018-2025 '!$CB6<'[1]DATA CONSOLIDADA 2018-2025 '!$BW6,"Disminución"," ---"))) -> #REF! | CD6: ='[1]DATA CONSOLIDADA 2018-2025 '!$CB6-Hoja1!$BW6 -> #REF! | CE6: 0 | CF6: 0 | CG6: 0 | CH6: =IF('[1]DATA CONSOLIDADA 2018-2025 '!$CG6>'[1]DATA CONSOLIDADA 2018-2025 '!$CB6,"Incremento",IF('[1]DATA CONSOLIDADA 2018-2025 '!$CB6='[1]DATA CONSOLIDADA 2018-2025 '!$CG6,"Sin incremento",IF('[1]DATA CONSOLIDADA 2018-2025 '!$CG6<'[1]DATA CONSOLIDADA 2018-2025 '!$CB6,"Disminución"," ---"))) -> #REF! | CI6: ='[1]DATA CONSOLIDADA 2018-2025 '!$CG6-Hoja1!$CB6 -> #REF! | CJ6: ='[1]DATA CONSOLIDADA 2018-2025 '!$BE6+'[1]DATA CONSOLIDADA 2018-2025 '!$BH6+'[1]DATA CONSOLIDADA 2018-2025 '!$BM6+'[1]DATA CONSOLIDADA 2018-2025 '!$BR6+'[1]DATA CONSOLIDADA 2018-2025 '!$BW6+'[1]DATA CONSOLIDADA 2018-2025 '!$CB6+'[1]DATA CONSOLIDADA 2018-2025 '!$CG6 -> #REF! | CK6: 0 | CL6: 0 | CM6: 0 | CN6: =IF('[1]DATA CONSOLIDADA 2018-2025 '!$CM6>'[1]DATA CONSOLIDADA 2018-2025 '!$CG6,"Incremento",IF('[1]DATA CONSOLIDADA 2018-2025 '!$CG6='[1]DATA CONSOLIDADA 2018-2025 '!$CM6,"Sin incremento",IF('[1]DATA CONSOLIDADA 2018-2025 '!$CM6<'[1]DATA CONSOLIDADA 2018-2025 '!$CG6,"Disminución"," ---"))) -> #REF! | CO6: ='[1]DATA CONSOLIDADA 2018-2025 '!$CM6-Hoja1!$CG6 -> #REF! | CP6: 0 | CQ6: 0 | CR6: 0 | CS6: 4179472.3 | CT6: 0 | CU6: 0 | CV6: 4179472.3 | CW6: 0 | CX6: 0 | CY6: 0 | CZ6: 0 | DA6: 0 | DB6: 0 | DC6: 0 | DD6: 0 | DE6: 0 | DF6: 0 | DG6: 0 | DH6: 0 | DI6: 20539241665 | DJ6: ASOCIACION DE PRODUCTORES DE CAFES ORGANICOS Y CAFES ESPECIALES DE AMAZONAS | DK6: 01 Asociación
A7: ASOCIACIÓN DE PRODUCTORES Y EXPORTADORES DE CAFÉ RODRIGUEZ DE MENDOZA-APROEXPORT | B7: CAFÉ | C7: CAFÉ | D7: AMAZONAS | E7: 010601 | F7: AMAZONAS | G7: RODRIGUEZ DE MENDOZA | H7: SAN NICOLAS | J7: 1 | Q7: PAC | R7: =IF(I7=1, I$4, "") & IF(J7=1, IF(I7=1, "-", "") & J$4, "") & IF(K7=1, IF(OR(J7=1, I7=1), "-", "") & K$4, "") & IF(L7=1, IF(OR(K7=1, J7=1, I7=1), "-", "") & L$4, "") & IF(M7=1, IF(OR(L7=1, K7=1, J7=1, I7=1), "-", "") & M$4, "") & IF(N7=1, IF(OR(M7=1, L7=1, K7=1, J7=1, I7=1), "-", "") & N$4, "") & IF(O7=1, IF(OR(N7=1, M7=1, L7=1, K7=1, J7=1, I7=1), "-", "") & O$4, "") & IF(P7=1, IF(I7=1, " - ", IF(J7=1, " - ", IF(K7=1, " - ", IF(L7=1, " - ", IF(M7=1, " - ", IF(N7=1, " - ", IF(O7=1, " - ", ""))))))) & P$4, "") -> 2019 | S7: =SUM(Hoja1!$I7:$P7) -> 1 | T7: =IF(OR(Hoja1!$J7=1,Hoja1!$K7=1,Hoja1!$L7=1,Hoja1!$M7=1,Hoja1!$N7=1,Hoja1!$O7=1,Hoja1!$P7=1),"SI","NO") -> SI | U7: =IF(OR(Hoja1!$K7=1,Hoja1!$L7=1,Hoja1!$M7=1,Hoja1!$N7=1,Hoja1!$O7=1,Hoja1!$P7=1),"SI","NO") -> NO | V7: 0 | W7: 231 | X7: 149 | Y7: 380 | Z7: 0 | AA7: 0 | AB7: 0 | AC7: 0 | AD7: 0 | AE7: 0 | AF7: 0 | AG7: 0 | AH7: 0 | AI7: 0 | AJ7: 0 | AK7: 0 | AL7: 0 | AM7: 0 | AN7: 0 | AO7: 0 | AP7: 0 | AQ7: 0 | AR7: =IF(Hoja1!$AQ7>0,Hoja1!$AQ7,IF(Hoja1!$AN7>0,Hoja1!$AN7,IF(Hoja1!$AK7>0,Hoja1!$AK7,IF(Hoja1!$AH7>0,Hoja1!$AH7,IF(Hoja1!$AE7>0,Hoja1!$AE7,IF(Hoja1!$AB7>0,Hoja1!$AB7,IF(Hoja1!$Y7>0,Hoja1!$Y7,IF(Hoja1!$V7>0,Hoja1!$V7," ---")))))))) -> 380 | AS7: 0 | AT7: 0 | AU7: 0 | AV7: 0 | AW7: 0 | AX7: 0 | AY7: 0 | AZ7: 0 | BA7: 0 | BB7: 0 | BC7: 0 | BD7: 0 | BE7: 0 | BF7: 0 | BG7: 0 | BH7: 0 | BI7: =IF('[1]DATA CONSOLIDADA 2018-2025 '!$BH7>'[1]DATA CONSOLIDADA 2018-2025 '!$AN7,"Incremento",IF('[1]DATA CONSOLIDADA 2018-2025 '!$AN7='[1]DATA CONSOLIDADA 2018-2025 '!$BH7,"Sin incremento",IF('[1]DATA CONSOLIDADA 2018-2025 '!$BH7<'[1]DATA CONSOLIDADA 2018-2025 '!$AN7,"Disminución"," ---"))) -> #REF! | BJ7: ='[1]DATA CONSOLIDADA 2018-2025 '!$BH7-'[1]DATA CONSOLIDADA 2018-2025 '!$BE7 -> #REF! | BK7: 0 | BL7: 0 | BM7: 0 | BN7: =IF('[1]DATA CONSOLIDADA 2018-2025 '!$BM7>'[1]DATA CONSOLIDADA 2018-2025 '!$BH7,"Incremento",IF('[1]DATA CONSOLIDADA 2018-2025 '!$BH7='[1]DATA CONSOLIDADA 2018-2025 '!$BM7,"Sin incremento",IF('[1]DATA CONSOLIDADA 2018-2025 '!$BM7<'[1]DATA CONSOLIDADA 2018-2025 '!$BH7,"Disminución"," ---"))) -> #REF! | BO7: ='[1]DATA CONSOLIDADA 2018-2025 '!$BM7-'[1]DATA CONSOLIDADA 2018-2025 '!$BH7 -> #REF! | BP7: 0 | BQ7: 0 | BR7: 0 | BS7: =IF('[1]DATA CONSOLIDADA 2018-2025 '!$BR7>'[1]DATA CONSOLIDADA 2018-2025 '!$BM7,"Incremento",IF('[1]DATA CONSOLIDADA 2018-2025 '!$BM7='[1]DATA CONSOLIDADA 2018-2025 '!$BR7,"Sin incremento",IF('[1]DATA CONSOLIDADA 2018-2025 '!$BR7<'[1]DATA CONSOLIDADA 2018-2025 '!$BM7,"Disminución"," ---"))) -> #REF! | BT7: ='[1]DATA CONSOLIDADA 2018-2025 '!$BR7-Hoja1!$BO7 -> #REF! | BU7: 0 | BV7: 0 | BW7: 0 | BX7: =IF('[1]DATA CONSOLIDADA 2018-2025 '!$BW7>'[1]DATA CONSOLIDADA 2018-2025 '!$BR7,"Incremento",IF('[1]DATA CONSOLIDADA 2018-2025 '!$BR7='[1]DATA CONSOLIDADA 2018-2025 '!$BW7,"Sin incremento",IF('[1]DATA CONSOLIDADA 2018-2025 '!$BW7<'[1]DATA CONSOLIDADA 2018-2025 '!$BR7,"Disminución"," ---"))) -> #REF! | BY7: ='[1]DATA CONSOLIDADA 2018-2025 '!$BW7-'[1]DATA CONSOLIDADA 2018-2025 '!$BR7 -> #REF! | BZ7: 0 | CA7: 0 | CB7: 0 | CC7: =IF('[1]DATA CONSOLIDADA 2018-2025 '!$CB7>'[1]DATA CONSOLIDADA 2018-2025 '!$BW7,"Incremento",IF('[1]DATA CONSOLIDADA 2018-2025 '!$BW7='[1]DATA CONSOLIDADA 2018-2025 '!$CB7,"Sin incremento",IF('[1]DATA CONSOLIDADA 2018-2025 '!$CB7<'[1]DATA CONSOLIDADA 2018-2025 '!$BW7,"Disminución"," ---"))) -> #REF! | CD7: ='[1]DATA CONSOLIDADA 2018-2025 '!$CB7-Hoja1!$BW7 -> #REF! | CE7: 0 | CF7: 0 | CG7: 0 | CH7: =IF('[1]DATA CONSOLIDADA 2018-2025 '!$CG7>'[1]DATA CONSOLIDADA 2018-2025 '!$CB7,"Incremento",IF('[1]DATA CONSOLIDADA 2018-2025 '!$CB7='[1]DATA CONSOLIDADA 2018-2025 '!$CG7,"Sin incremento",IF('[1]DATA CONSOLIDADA 2018-2025 '!$CG7<'[1]DATA CONSOLIDADA 2018-2025 '!$CB7,"Disminución"," ---"))) -> #REF! | CI7: ='[1]DATA CONSOLIDADA 2018-2025 '!$CG7-Hoja1!$CB7 -> #REF! | CJ7: ='[1]DATA CONSOLIDADA 2018-2025 '!$BE7+'[1]DATA CONSOLIDADA 2018-2025 '!$BH7+'[1]DATA CONSOLIDADA 2018-2025 '!$BM7+'[1]DATA CONSOLIDADA 2018-2025 '!$BR7+'[1]DATA CONSOLIDADA 2018-2025 '!$BW7+'[1]DATA CONSOLIDADA 2018-2025 '!$CB7+'[1]DATA CONSOLIDADA 2018-2025 '!$CG7 -> #REF! | CK7: 0 | CL7: 0 | CM7: 0 | CN7: =IF('[1]DATA CONSOLIDADA 2018-2025 '!$CM7>'[1]DATA CONSOLIDADA 2018-2025 '!$CG7,"Incremento",IF('[1]DATA CONSOLIDADA 2018-2025 '!$CG7='[1]DATA CONSOLIDADA 2018-2025 '!$CM7,"Sin incremento",IF('[1]DATA CONSOLIDADA 2018-2025 '!$CM7<'[1]DATA CONSOLIDADA 2018-2025 '!$CG7,"Disminución"," ---"))) -> #REF! | CO7: ='[1]DATA CONSOLIDADA 2018-2025 '!$CM7-Hoja1!$CG7 -> #REF! | CP7: 0 | CQ7: 0 | CR7: 0 | CS7: 0 | CT7: 0 | CU7: 0 | CV7: 0 | CW7: 0 | CX7: 0 | CY7: 0 | CZ7: 0 | DA7: 0 | DB7: 0 | DC7: 0 | DD7: 0 | DE7: 0 | DF7: 0 | DG7: 0 | DH7: 0 | DI7: 20539205600 | DJ7: ASOCIACION DE PRODUCTORES Y EXPORTADORES DE CAFE RODRIGUEZ DE MENDOZA | DK7: 01 Asociación
A8: COOPERATIVA AGRARIA CAFETALERA ALTA MONTAÑA | B8: CAFÉ | C8: CAFÉ | D8: AMAZONAS | E8: 010604 | F8: AMAZONAS | G8: RODRIGUEZ DE MENDOZA | H8: HUAMBO | I8: 1 | J8: 1 | K8: 1 | L8: 1 | M8: 1 | N8: 1 | Q8: PAC | R8: =IF(I8=1, I$4, "") & IF(J8=1, IF(I8=1, "-", "") & J$4, "") & IF(K8=1, IF(OR(J8=1, I8=1), "-", "") & K$4, "") & IF(L8=1, IF(OR(K8=1, J8=1, I8=1), "-", "") & L$4, "") & IF(M8=1, IF(OR(L8=1, K8=1, J8=1, I8=1), "-", "") & M$4, "") & IF(N8=1, IF(OR(M8=1, L8=1, K8=1, J8=1, I8=1), "-", "") & N$4, "") & IF(O8=1, IF(OR(N8=1, M8=1, L8=1, K8=1, J8=1, I8=1), "-", "") & O$4, "") & IF(P8=1, IF(I8=1, " - ", IF(J8=1, " - ", IF(K8=1, " - ", IF(L8=1, " - ", IF(M8=1, " - ", IF(N8=1, " - ", IF(O8=1, " - ", ""))))))) & P$4, "") -> 2018-2019-2020-2021-2022-2023 | S8: =SUM(Hoja1!$I8:$P8) -> 6 | T8: =IF(OR(Hoja1!$J8=1,Hoja1!$K8=1,Hoja1!$L8=1,Hoja1!$M8=1,Hoja1!$N8=1,Hoja1!$O8=1,Hoja1!$P8=1),"SI","NO") -> SI | U8: =IF(OR(Hoja1!$K8=1,Hoja1!$L8=1,Hoja1!$M8=1,Hoja1!$N8=1,Hoja1!$O8=1,Hoja1!$P8=1),"SI","NO") -> SI | V8: 150 | W8: 0 | X8: 0 | Y8: 0 | Z8: 108 | AA8: 42 | AB8: 150 | AC8: 205 | AD8: 119 | AE8: 324 | AF8: 205 | AG8: 119 | AH8: 324 | AI8: 205 | AJ8: 119 | AK8: 324 | AL8: 0 | AM8: 0 | AN8: 0 | AO8: 0 | AP8: 0 | AQ8: 0 | AR8: =IF(Hoja1!$AQ8>0,Hoja1!$AQ8,IF(Hoja1!$AN8>0,Hoja1!$AN8,IF(Hoja1!$AK8>0,Hoja1!$AK8,IF(Hoja1!$AH8>0,Hoja1!$AH8,IF(Hoja1!$AE8>0,Hoja1!$AE8,IF(Hoja1!$AB8>0,Hoja1!$AB8,IF(Hoja1!$Y8>0,Hoja1!$Y8,IF(Hoja1!$V8>0,Hoja1!$V8," ---")))))))) -> 324 | AS8: 0 | AT8: 0 | AU8: 25 | AV8: 9 | AW8: 41 | AX8: 7 | AY8: 32 | AZ8: 6 | BA8: 0 | BB8: 0 | BC8: 0 | BD8: 0 | BE8: 0 | BF8: 409100 | BG8: 0 | BH8: 409100 | BI8: =IF('[1]DATA CONSOLIDADA 2018-2025 '!$BH8>'[1]DATA CONSOLIDADA 2018-2025 '!$AN8,"Incremento",IF('[1]DATA CONSOLIDADA 2018-2025 '!$AN8='[1]DATA CONSOLIDADA 2018-2025 '!$BH8,"Sin incremento",IF('[1]DATA CONSOLIDADA 2018-2025 '!$BH8<'[1]DATA CONSOLIDADA 2018-2025 '!$AN8,"Disminución"," ---"))) -> #REF! | BJ8: ='[1]DATA CONSOLIDADA 2018-2025 '!$BH8-'[1]DATA CONSOLIDADA 2018-2025 '!$BE8 -> #REF! | BK8: 325000 | BL8: 0 | BM8: 325000 | BN8: =IF('[1]DATA CONSOLIDADA 2018-2025 '!$BM8>'[1]DATA CONSOLIDADA 2018-2025 '!$BH8,"Incremento",IF('[1]DATA CONSOLIDADA 2018-2025 '!$BH8='[1]DATA CONSOLIDADA 2018-2025 '!$BM8,"Sin incremento",IF('[1]DATA CONSOLIDADA 2018-2025 '!$BM8<'[1]DATA CONSOLIDADA 2018-2025 '!$BH8,"Disminución"," ---"))) -> #REF! | BO8: ='[1]DATA CONSOLIDADA 2018-2025 '!$BM8-'[1]DATA CONSOLIDADA 2018-2025 '!$BH8 -> #REF! | BP8: 1224192.5 | BQ8: 398235.92 | BR8: 1622428.4 | BS8: =IF('[1]DATA CONSOLIDADA 2018-2025 '!$BR8>'[1]DATA CONSOLIDADA 2018-2025 '!$BM8,"Incremento",IF('[1]DATA CONSOLIDADA 2018-2025 '!$BM8='[1]DATA CONSOLIDADA 2018-2025 '!$BR8,"Sin incremento",IF('[1]DATA CONSOLIDADA 2018-2025 '!$BR8<'[1]DATA CONSOLIDADA 2018-2025 '!$BM8,"Disminución"," ---"))) -> #REF! | BT8: ='[1]DATA CONSOLIDADA 2018-2025 '!$BR8-Hoja1!$BO8 -> #REF! | BU8: 820950 | BV8: 0 | BW8: 820950 | BX8: =IF('[1]DATA CONSOLIDADA 2018-2025 '!$BW8>'[1]DATA CONSOLIDADA 2018-2025 '!$BR8,"Incremento",IF('[1]DATA CONSOLIDADA 2018-2025 '!$BR8='[1]DATA CONSOLIDADA 2018-2025 '!$BW8,"Sin incremento",IF('[1]DATA CONSOLIDADA 2018-2025 '!$BW8<'[1]DATA CONSOLIDADA 2018-2025 '!$BR8,"Disminución"," ---"))) -> #REF! | BY8: ='[1]DATA CONSOLIDADA 2018-2025 '!$BW8-'[1]DATA CONSOLIDADA 2018-2025 '!$BR8 -> #REF! | BZ8: 165821.2 | CA8: 0 | CB8: 165821.2 | CC8: =IF('[1]DATA CONSOLIDADA 2018-2025 '!$CB8>'[1]DATA CONSOLIDADA 2018-2025 '!$BW8,"Incremento",IF('[1]DATA CONSOLIDADA 2018-2025 '!$BW8='[1]DATA CONSOLIDADA 2018-2025 '!$CB8,"Sin incremento",IF('[1]DATA CONSOLIDADA 2018-2025 '!$CB8<'[1]DATA CONSOLIDADA 2018-2025 '!$BW8,"Disminución"," ---"))) -> #REF! | CD8: ='[1]DATA CONSOLIDADA 2018-2025 '!$CB8-Hoja1!$BW8 -> #REF! | CE8: 0 | CF8: 0 | CG8: 0 | CH8: =IF('[1]DATA CONSOLIDADA 2018-2025 '!$CG8>'[1]DATA CONSOLIDADA 2018-2025 '!$CB8,"Incremento",IF('[1]DATA CONSOLIDADA 2018-2025 '!$CB8='[1]DATA CONSOLIDADA 2018-2025 '!$CG8,"Sin incremento",IF('[1]DATA CONSOLIDADA 2018-2025 '!$CG8<'[1]DATA CONSOLIDADA 2018-2025 '!$CB8,"Disminución"," ---"))) -> #REF! | CI8: ='[1]DATA CONSOLIDADA 2018-2025 '!$CG8-Hoja1!$CB8 -> #REF! | CJ8: ='[1]DATA CONSOLIDADA 2018-2025 '!$BE8+'[1]DATA CONSOLIDADA 2018-2025 '!$BH8+'[1]DATA CONSOLIDADA 2018-2025 '!$BM8+'[1]DATA CONSOLIDADA 2018-2025 '!$BR8+'[1]DATA CONSOLIDADA 2018-2025 '!$BW8+'[1]DATA CONSOLIDADA 2018-2025 '!$CB8+'[1]DATA CONSOLIDADA 2018-2025 '!$CG8 -> #REF! | CK8: 0 | CL8: 0 | CM8: 0 | CN8: =IF('[1]DATA CONSOLIDADA 2018-2025 '!$CM8>'[1]DATA CONSOLIDADA 2018-2025 '!$CG8,"Incremento",IF('[1]DATA CONSOLIDADA 2018-2025 '!$CG8='[1]DATA CONSOLIDADA 2018-2025 '!$CM8,"Sin incremento",IF('[1]DATA CONSOLIDADA 2018-2025 '!$CM8<'[1]DATA CONSOLIDADA 2018-2025 '!$CG8,"Disminución"," ---"))) -> #REF! | CO8: ='[1]DATA CONSOLIDADA 2018-2025 '!$CM8-Hoja1!$CG8 -> #REF! | CP8: 9793.4 | CQ8: 0 | CR8: 0 | CS8: 156027.8 | CT8: 0 | CU8: 0 | CV8: 165821.2 | CW8: 0 | CX8: 0 | CY8: 0 | CZ8: 0 | DA8: 0 | DB8: 0 | DC8: 0 | DD8: 0 | DE8: 0 | DF8: 0 | DG8: 0 | DH8: 0 | DI8: 20603320621 | DJ8: COOPERATIVA AGRARIA CAFETALERA ALTA MONTAÑA | DK8: 02 Cooperativa
A9: ASOCIACION DE PRODUCTORES AGROPECUARIOS LA FLOR DE CAFÉ | B9: CAFÉ | C9: CAFÉ | D9: AMAZONAS | E9: 010601 | F9: AMAZONAS | G9: RODRIGUEZ DE MENDOZA | H9: SAN NICOLAS | J9: 1 | K9: 1 | L9: 1 | M9: 1 | N9: 1 | Q9: PAC | R9: =IF(I9=1, I$4, "") & IF(J9=1, IF(I9=1, "-", "") & J$4, "") & IF(K9=1, IF(OR(J9=1, I9=1), "-", "") & K$4, "") & IF(L9=1, IF(OR(K9=1, J9=1, I9=1), "-", "") & L$4, "") & IF(M9=1, IF(OR(L9=1, K9=1, J9=1, I9=1), "-", "") & M$4, "") & IF(N9=1, IF(OR(M9=1, L9=1, K9=1, J9=1, I9=1), "-", "") & N$4, "") & IF(O9=1, IF(OR(N9=1, M9=1, L9=1, K9=1, J9=1, I9=1), "-", "") & O$4, "") & IF(P9=1, IF(I9=1, " - ", IF(J9=1, " - ", IF(K9=1, " - ", IF(L9=1, " - ", IF(M9=1, " - ", IF(N9=1, " - ", IF(O9=1, " - ", ""))))))) & P$4, "") -> 2019-2020-2021-2022-2023 | S9: =SUM(Hoja1!$I9:$P9) -> 5 | T9: =IF(OR(Hoja1!$J9=1,Hoja1!$K9=1,Hoja1!$L9=1,Hoja1!$M9=1,Hoja1!$N9=1,Hoja1!$O9=1,Hoja1!$P9=1),"SI","NO") -> SI | U9: =IF(OR(Hoja1!$K9=1,Hoja1!$L9=1,Hoja1!$M9=1,Hoja1!$N9=1,Hoja1!$O9=1,Hoja1!$P9=1),"SI","NO") -> SI | V9: 0 | W9: 210 | X9: 113 | Y9: 323 | Z9: 210 | AA9: 113 | AB9: 323 | AC9: 274 | AD9: 137 | AE9: 411 | AF9: 274 | AG9: 137 | AH9: 411 | AI9: 274 | AJ9: 137 | AK9: 411 | AL9: 0 | AM9: 0 | AN9: 0 | AO9: 0 | AP9: 0 | AQ9: 0 | AR9: =IF(Hoja1!$AQ9>0,Hoja1!$AQ9,IF(Hoja1!$AN9>0,Hoja1!$AN9,IF(Hoja1!$AK9>0,Hoja1!$AK9,IF(Hoja1!$AH9>0,Hoja1!$AH9,IF(Hoja1!$AE9>0,Hoja1!$AE9,IF(Hoja1!$AB9>0,Hoja1!$AB9,IF(Hoja1!$Y9>0,Hoja1!$Y9,IF(Hoja1!$V9>0,Hoja1!$V9," ---")))))))) -> 411 | AS9: 0 | AT9: 0 | AU9: 26 | AV9: 8 | AW9: 43 | AX9: 7 | AY9: 32 | AZ9: 6 | BA9: 0 | BB9: 0 | BC9: 0 | BD9: 0 | BE9: 0 | BF9: 6041471.5 | BG9: 0 | BH9: 6041471.5 | BI9: =IF('[1]DATA CONSOLIDADA 2018-2025 '!$BH9>'[1]DATA CONSOLIDADA 2018-2025 '!$AN9,"Incremento",IF('[1]DATA CONSOLIDADA 2018-2025 '!$AN9='[1]DATA CONSOLIDADA 2018-2025 '!$BH9,"Sin incremento",IF('[1]DATA CONSOLIDADA 2018-2025 '!$BH9<'[1]DATA CONSOLIDADA 2018-2025 '!$AN9,"Disminución"," ---"))) -> #REF! | BJ9: ='[1]DATA CONSOLIDADA 2018-2025 '!$BH9-'[1]DATA CONSOLIDADA 2018-2025 '!$BE9 -> #REF! | BK9: 523737.39 | BL9: 0 | BM9: 523737.39 | BN9: =IF('[1]DATA CONSOLIDADA 2018-2025 '!$BM9>'[1]DATA CONSOLIDADA 2018-2025 '!$BH9,"Incremento",IF('[1]DATA CONSOLIDADA 2018-2025 '!$BH9='[1]DATA CONSOLIDADA 2018-2025 '!$BM9,"Sin incremento",IF('[1]DATA CONSOLIDADA 2018-2025 '!$BM9<'[1]DATA CONSOLIDADA 2018-2025 '!$BH9,"Disminución"," ---"))) -> #REF! | BO9: ='[1]DATA CONSOLIDADA 2018-2025 '!$BM9-'[1]DATA CONSOLIDADA 2018-2025 '!$BH9 -> #REF! | BP9: 3394807.7 | BQ9: 0 | BR9: 3394807.7 | BS9: =IF('[1]DATA CONSOLIDADA 2018-2025 '!$BR9>'[1]DATA CONSOLIDADA 2018-2025 '!$BM9,"Incremento",IF('[1]DATA CONSOLIDADA 2018-2025 '!$BM9='[1]DATA CONSOLIDADA 2018-2025 '!$BR9,"Sin incremento",IF('[1]DATA CONSOLIDADA 2018-2025 '!$BR9<'[1]DATA CONSOLIDADA 2018-2025 '!$BM9,"Disminución"," ---"))) -> #REF! | BT9: ='[1]DATA CONSOLIDADA 2018-2025 '!$BR9-Hoja1!$BO9 -> #REF! | BU9: 4076542 | BV9: 446118 | BW9: 4522660 | BX9: =IF('[1]DATA CONSOLIDADA 2018-2025 '!$BW9>'[1]DATA CONSOLIDADA 2018-2025 '!$BR9,"Incremento",IF('[1]DATA CONSOLIDADA 2018-2025 '!$BR9='[1]DATA CONSOLIDADA 2018-2025 '!$BW9,"Sin incremento",IF('[1]DATA CONSOLIDADA 2018-2025 '!$BW9<'[1]DATA CONSOLIDADA 2018-2025 '!$BR9,"Disminución"," ---"))) -> #REF! | BY9: ='[1]DATA CONSOLIDADA 2018-2025 '!$BW9-'[1]DATA CONSOLIDADA 2018-2025 '!$BR9 -> #REF! | BZ9: 5733612.8 | CA9: 984023.42 | CB9: 6717636.2 | CC9: =IF('[1]DATA CONSOLIDADA 2018-2025 '!$CB9>'[1]DATA CONSOLIDADA 2018-2025 '!$BW9,"Incremento",IF('[1]DATA CONSOLIDADA 2018-2025 '!$BW9='[1]DATA CONSOLIDADA 2018-2025 '!$CB9,"Sin incremento",IF('[1]DATA CONSOLIDADA 2018-2025 '!$CB9<'[1]DATA CONSOLIDADA 2018-2025 '!$BW9,"Disminución"," ---"))) -> #REF! | CD9: ='[1]DATA CONSOLIDADA 2018-2025 '!$CB9-Hoja1!$BW9 -> #REF! | CE9: 0 | CF9: 0 | CG9: 0 | CH9: =IF('[1]DATA CONSOLIDADA 2018-2025 '!$CG9>'[1]DATA CONSOLIDADA 2018-2025 '!$CB9,"Incremento",IF('[1]DATA CONSOLIDADA 2018-2025 '!$CB9='[1]DATA CONSOLIDADA 2018-2025 '!$CG9,"Sin incremento",IF('[1]DATA CONSOLIDADA 2018-2025 '!$CG9<'[1]DATA CONSOLIDADA 2018-2025 '!$CB9,"Disminución"," ---"))) -> #REF! | CI9: ='[1]DATA CONSOLIDADA 2018-2025 '!$CG9-Hoja1!$CB9 -> #REF! | CJ9: ='[1]DATA CONSOLIDADA 2018-2025 '!$BE9+'[1]DATA CONSOLIDADA 2018-2025 '!$BH9+'[1]DATA CONSOLIDADA 2018-2025 '!$BM9+'[1]DATA CONSOLIDADA 2018-2025 '!$BR9+'[1]DATA CONSOLIDADA 2018-2025 '!$BW9+'[1]DATA CONSOLIDADA 2018-2025 '!$CB9+'[1]DATA CONSOLIDADA 2018-2025 '!$CG9 -> #REF! | CK9: 0 | CL9: 0 | CM9: 0 | CN9: =IF('[1]DATA CONSOLIDADA 2018-2025 '!$CM9>'[1]DATA CONSOLIDADA 2018-2025 '!$CG9,"Incremento",IF('[1]DATA CONSOLIDADA 2018-2025 '!$CG9='[1]DATA CONSOLIDADA 2018-2025 '!$CM9,"Sin incremento",IF('[1]DATA CONSOLIDADA 2018-2025 '!$CM9<'[1]DATA CONSOLIDADA 2018-2025 '!$CG9,"Disminución"," ---"))) -> #REF! | CO9: ='[1]DATA CONSOLIDADA 2018-2025 '!$CM9-Hoja1!$CG9 -> #REF! | CP9: 0 | CQ9: 0 | CR9: 0 | CS9: 6717636.2 | CT9: 0 | CU9: 0 | CV9: 6717636.2 | CW9: 0 | CX9: 0 | CY9: 0 | CZ9: 0 | DA9: 0 | DB9: 0 | DC9: 0 | DD9: 0 | DE9: 0 | DF9: 0 | DG9: 0 | DH9: 0 | DI9: 20480762895 | DJ9: ASOCIACION DE PRODUCTORES AGROPECUARIOS LA FLOR DE CAFÉ | DK9: 01 Asociación
A10: COOPERATIVA DE SERVICIOS MULTIPLES - APROCAM | B10: CACAO | C10: CACAO | D10: AMAZONAS | E10: 010201 | F10: AMAZONAS | G10: BAGUA | H10: BAGUA | I10: 1 | J10: 1 | K10: 1 | L10: 1 | M10: 1 | N10: 1 | Q10: PAC | R10: =IF(I10=1, I$4, "") & IF(J10=1, IF(I10=1, "-", "") & J$4, "") & IF(K10=1, IF(OR(J10=1, I10=1), "-", "") & K$4, "") & IF(L10=1, IF(OR(K10=1, J10=1, I10=1), "-", "") & L$4, "") & IF(M10=1, IF(OR(L10=1, K10=1, J10=1, I10=1), "-", "") & M$4, "") & IF(N10=1, IF(OR(M10=1, L10=1, K10=1, J10=1, I10=1), "-", "") & N$4, "") & IF(O10=1, IF(OR(N10=1, M10=1, L10=1, K10=1, J10=1, I10=1), "-", "") & O$4, "") & IF(P10=1, IF(I10=1, " - ", IF(J10=1, " - ", IF(K10=1, " - ", IF(L10=1, " - ", IF(M10=1, " - ", IF(N10=1, " - ", IF(O10=1, " - ", ""))))))) & P$4, "") -> 2018-2019-2020-2021-2022-2023 | S10: =SUM(Hoja1!$I10:$P10) -> 6 | T10: =IF(OR(Hoja1!$J10=1,Hoja1!$K10=1,Hoja1!$L10=1,Hoja1!$M10=1,Hoja1!$N10=1,Hoja1!$O10=1,Hoja1!$P10=1),"SI","NO") -> SI | U10: =IF(OR(Hoja1!$K10=1,Hoja1!$L10=1,Hoja1!$M10=1,Hoja1!$N10=1,Hoja1!$O10=1,Hoja1!$P10=1),"SI","NO") -> SI | V10: 418 | W10: 353 | X10: 65 | Y10: 418 | Z10: 357 | AA10: 66 | AB10: 423 | AC10: 201 | AD10: 43 | AE10: 244 | AF10: 201 | AG10: 43 | AH10: 244 | AI10: 201 | AJ10: 43 | AK10: 244 | AL10: 0 | AM10: 0 | AN10: 0 | AO10: 0 | AP10: 0 | AQ10: 0 | AR10: =IF(Hoja1!$AQ10>0,Hoja1!$AQ10,IF(Hoja1!$AN10>0,Hoja1!$AN10,IF(Hoja1!$AK10>0,Hoja1!$AK10,IF(Hoja1!$AH10>0,Hoja1!$AH10,IF(Hoja1!$AE10>0,Hoja1!$AE10,IF(Hoja1!$AB10>0,Hoja1!$AB10,IF(Hoja1!$Y10>0,Hoja1!$Y10,IF(Hoja1!$V10>0,Hoja1!$V10," ---")))))))) -> 244 | AS10: 0 | AT10: 0 | AU10: 35 | AV10: 7 | AW10: 32 | AX10: 5 | AY10: 39 | AZ10: 7 | BA10: 0 | BB10: 0 | BC10: 0 | BD10: 0 | BE10: 279033.24 | BF10: 0 | BG10: 1026216.8 | BH10: 1026216.8 | BI10: =IF('[1]DATA CONSOLIDADA 2018-2025 '!$BH10>'[1]DATA CONSOLIDADA 2018-2025 '!$AN10,"Incremento",IF('[1]DATA CONSOLIDADA 2018-2025 '!$AN10='[1]DATA CONSOLIDADA 2018-2025 '!$BH10,"Sin incremento",IF('[1]DATA CONSOLIDADA 2018-2025 '!$BH10<'[1]DATA CONSOLIDADA 2018-2025 '!$AN10,"Disminución"," ---"))) -> #REF! | BJ10: ='[1]DATA CONSOLIDADA 2018-2025 '!$BH10-'[1]DATA CONSOLIDADA 2018-2025 '!$BE10 -> #REF! | BK10: 101917.7 | BL10: 284025.07 | BM10: 385942.77 | BN10: =IF('[1]DATA CONSOLIDADA 2018-2025 '!$BM10>'[1]DATA CONSOLIDADA 2018-2025 '!$BH10,"Incremento",IF('[1]DATA CONSOLIDADA 2018-2025 '!$BH10='[1]DATA CONSOLIDADA 2018-2025 '!$BM10,"Sin incremento",IF('[1]DATA CONSOLIDADA 2018-2025 '!$BM10<'[1]DATA CONSOLIDADA 2018-2025 '!$BH10,"Disminución"," ---"))) -> #REF! | BO10: ='[1]DATA CONSOLIDADA 2018-2025 '!$BM10-'[1]DATA CONSOLIDADA 2018-2025 '!$BH10 -> #REF! | BP10: 78859.15 | BQ10: 2033180.4 | BR10: 2112039.5 | BS10: =IF('[1]DATA CONSOLIDADA 2018-2025 '!$BR10>'[1]DATA CONSOLIDADA 2018-2025 '!$BM10,"Incremento",IF('[1]DATA CONSOLIDADA 2018-2025 '!$BM10='[1]DATA CONSOLIDADA 2018-2025 '!$BR10,"Sin incremento",IF('[1]DATA CONSOLIDADA 2018-2025 '!$BR10<'[1]DATA CONSOLIDADA 2018-2025 '!$BM10,"Disminución"," ---"))) -> #REF! | BT10: ='[1]DATA CONSOLIDADA 2018-2025 '!$BR10-Hoja1!$BO10 -> #REF! | BU10: 65644.73 | BV10: 1189543.9 | BW10: 1255188.6 | BX10: =IF('[1]DATA CONSOLIDADA 2018-2025 '!$BW10>'[1]DATA CONSOLIDADA 2018-2025 '!$BR10,"Incremento",IF('[1]DATA CONSOLIDADA 2018-2025 '!$BR10='[1]DATA CONSOLIDADA 2018-2025 '!$BW10,"Sin incremento",IF('[1]DATA CONSOLIDADA 2018-2025 '!$BW10<'[1]DATA CONSOLIDADA 2018-2025 '!$BR10,"Disminución"," ---"))) -> #REF! | BY10: ='[1]DATA CONSOLIDADA 2018-2025 '!$BW10-'[1]DATA CONSOLIDADA 2018-2025 '!$BR10 -> #REF! | BZ10: 114467.98 | CA10: 1092156.7 | CB10: 1206624.7 | CC10: =IF('[1]DATA CONSOLIDADA 2018-2025 '!$CB10>'[1]DATA CONSOLIDADA 2018-2025 '!$BW10,"Incremento",IF('[1]DATA CONSOLIDADA 2018-2025 '!$BW10='[1]DATA CONSOLIDADA 2018-2025 '!$CB10,"Sin incremento",IF('[1]DATA CONSOLIDADA 2018-2025 '!$CB10<'[1]DATA CONSOLIDADA 2018-2025 '!$BW10,"Disminución"," ---"))) -> #REF! | CD10: ='[1]DATA CONSOLIDADA 2018-2025 '!$CB10-Hoja1!$BW10 -> #REF! | CE10: 0 | CF10: 0 | CG10: 0 | CH10: =IF('[1]DATA CONSOLIDADA 2018-2025 '!$CG10>'[1]DATA CONSOLIDADA 2018-2025 '!$CB10,"Incremento",IF('[1]DATA CONSOLIDADA 2018-2025 '!$CB10='[1]DATA CONSOLIDADA 2018-2025 '!$CG10,"Sin incremento",IF('[1]DATA CONSOLIDADA 2018-2025 '!$CG10<'[1]DATA CONSOLIDADA 2018-2025 '!$CB10,"Disminución"," ---"))) -> #REF! | CI10: ='[1]DATA CONSOLIDADA 2018-2025 '!$CG10-Hoja1!$CB10 -> #REF! | CJ10: ='[1]DATA CONSOLIDADA 2018-2025 '!$BE10+'[1]DATA CONSOLIDADA 2018-2025 '!$BH10+'[1]DATA CONSOLIDADA 2018-2025 '!$BM10+'[1]DATA CONSOLIDADA 2018-2025 '!$BR10+'[1]DATA CONSOLIDADA 2018-2025 '!$BW10+'[1]DATA CONSOLIDADA 2018-2025 '!$CB10+'[1]DATA CONSOLIDADA 2018-2025 '!$CG10 -> #REF! | CK10: 0 | CL10: 0 | CM10: 0 | CN10: =IF('[1]DATA CONSOLIDADA 2018-2025 '!$CM10>'[1]DATA CONSOLIDADA 2018-2025 '!$CG10,"Incremento",IF('[1]DATA CONSOLIDADA 2018-2025 '!$CG10='[1]DATA CONSOLIDADA 2018-2025 '!$CM10,"Sin incremento",IF('[1]DATA CONSOLIDADA 2018-2025 '!$CM10<'[1]DATA CONSOLIDADA 2018-2025 '!$CG10,"Disminución"," ---"))) -> #REF! | CO10: ='[1]DATA CONSOLIDADA 2018-2025 '!$CM10-Hoja1!$CG10 -> #REF! | CP10: 34067.084 | CQ10: 0 | CR10: 0 | CS10: 1172557.6 | CT10: 0 | CU10: 0 | CV10: 1206624.7 | CW10: 0 | CX10: 0 | CY10: 0 | CZ10: 0 | DA10: 0 | DB10: 0 | DC10: 0 | DD10: 0 | DE10: 0 | DF10: 0 | DG10: 0 | DH10: 0 | DI10: 20480458550 | DJ10: COOPERATIVA AGRARIA APROCAM | DK10: 02 Cooperativa
A11: COOPERATIVA CENTRAL DE PRODUCTORES AGROPECUARIOS DE AMAZONAS - CEPROAA | B11: CACAO | C11: CACAO | D11: AMAZONAS | E11: 010702 | F11: AMAZONAS | G11: UTCUBAMBA | H11: CAJARURO | I11: 1 | J11: 1 | K11: 1 | L11: 1 | M11: 1 | N11: 1 | Q11: PAC | R11: =IF(I11=1, I$4, "") & IF(J11=1, IF(I11=1, "-", "") & J$4, "") & IF(K11=1, IF(OR(J11=1, I11=1), "-", "") & K$4, "") & IF(L11=1, IF(OR(K11=1, J11=1, I11=1), "-", "") & L$4, "") & IF(M11=1, IF(OR(L11=1, K11=1, J11=1, I11=1), "-", "") & M$4, "") & IF(N11=1, IF(OR(M11=1, L11=1, K11=1, J11=1, I11=1), "-", "") & N$4, "") & IF(O11=1, IF(OR(N11=1, M11=1, L11=1, K11=1, J11=1, I11=1), "-", "") & O$4, "") & IF(P11=1, IF(I11=1, " - ", IF(J11=1, " - ", IF(K11=1, " - ", IF(L11=1, " - ", IF(M11=1, " - ", IF(N11=1, " - ", IF(O11=1, " - ", ""))))))) & P$4, "") -> 2018-2019-2020-2021-2022-2023 | S11: =SUM(Hoja1!$I11:$P11) -> 6 | T11: =IF(OR(Hoja1!$J11=1,Hoja1!$K11=1,Hoja1!$L11=1,Hoja1!$M11=1,Hoja1!$N11=1,Hoja1!$O11=1,Hoja1!$P11=1),"SI","NO") -> SI | U11: =IF(OR(Hoja1!$K11=1,Hoja1!$L11=1,Hoja1!$M11=1,Hoja1!$N11=1,Hoja1!$O11=1,Hoja1!$P11=1),"SI","NO") -> SI | V11: 344 | W11: 272 | X11: 71 | Y11: 343 | Z11: 266 | AA11: 71 | AB11: 337 | AC11: 271 | AD11: 71 | AE11: 342 | AF11: 271 | AG11: 71 | AH11: 342 | AI11: 271 | AJ11: 71 | AK11: 342 | AL11: 0 | AM11: 0 | AN11: 0 | AO11: 0 | AP11: 0 | AQ11: 0 | AR11: =IF(Hoja1!$AQ11>0,Hoja1!$AQ11,IF(Hoja1!$AN11>0,Hoja1!$AN11,IF(Hoja1!$AK11>0,Hoja1!$AK11,IF(Hoja1!$AH11>0,Hoja1!$AH11,IF(Hoja1!$AE11>0,Hoja1!$AE11,IF(Hoja1!$AB11>0,Hoja1!$AB11,IF(Hoja1!$Y11>0,Hoja1!$Y11,IF(Hoja1!$V11>0,Hoja1!$V11," ---")))))))) -> 342 | AS11: 0 | AT11: 0 | AU11: 24 | AV11: 7 | AW11: 28 | AX11: 7 | AY11: 39 | AZ11: 6 | BA11: 0 | BB11: 0 | BC11: 0 | BD11: 0 | BE11: 0 | BF11: 0 | BG11: 1072102.3 | BH11: 1072102.3 | BI11: =IF('[1]DATA CONSOLIDADA 2018-2025 '!$BH11>'[1]DATA CONSOLIDADA 2018-2025 '!$AN11,"Incremento",IF('[1]DATA CONSOLIDADA 2018-2025 '!$AN11='[1]DATA CONSOLIDADA 2018-2025 '!$BH11,"Sin incremento",IF('[1]DATA CONSOLIDADA 2018-2025 '!$BH11<'[1]DATA CONSOLIDADA 2018-2025 '!$AN11,"Disminución"," ---"))) -> #REF! | BJ11: ='[1]DATA CONSOLIDADA 2018-2025 '!$BH11-'[1]DATA CONSOLIDADA 2018-2025 '!$BE11 -> #REF! | BK11: 454472.63 | BL11: 0 | BM11: 454472.63 | BN11: =IF('[1]DATA CONSOLIDADA 2018-2025 '!$BM11>'[1]DATA CONSOLIDADA 2018-2025 '!$BH11,"Incremento",IF('[1]DATA CONSOLIDADA 2018-2025 '!$BH11='[1]DATA CONSOLIDADA 2018-2025 '!$BM11,"Sin incremento",IF('[1]DATA CONSOLIDADA 2018-2025 '!$BM11<'[1]DATA CONSOLIDADA 2018-2025 '!$BH11,"Disminución"," ---"))) -> #REF! | BO11: ='[1]DATA CONSOLIDADA 2018-2025 '!$BM11-'[1]DATA CONSOLIDADA 2018-2025 '!$BH11 -> #REF! | BP11: 1609560.4 | BQ11: 0 | BR11: 1609560.4 | BS11: =IF('[1]DATA CONSOLIDADA 2018-2025 '!$BR11>'[1]DATA CONSOLIDADA 2018-2025 '!$BM11,"Incremento",IF('[1]DATA CONSOLIDADA 2018-2025 '!$BM11='[1]DATA CONSOLIDADA 2018-2025 '!$BR11,"Sin incremento",IF('[1]DATA CONSOLIDADA 2018-2025 '!$BR11<'[1]DATA CONSOLIDADA 2018-2025 '!$BM11,"Disminución"," ---"))) -> #REF! | BT11: ='[1]DATA CONSOLIDADA 2018-2025 '!$BR11-Hoja1!$BO11 -> #REF! | BU11: 1731876.8 | BV11: 0 | BW11: 1731876.8 | BX11: =IF('[1]DATA CONSOLIDADA 2018-2025 '!$BW11>'[1]DATA CONSOLIDADA 2018-2025 '!$BR11,"Incremento",IF('[1]DATA CONSOLIDADA 2018-2025 '!$BR11='[1]DATA CONSOLIDADA 2018-2025 '!$BW11,"Sin incremento",IF('[1]DATA CONSOLIDADA 2018-2025 '!$BW11<'[1]DATA CONSOLIDADA 2018-2025 '!$BR11,"Disminución"," ---"))) -> #REF! | BY11: ='[1]DATA CONSOLIDADA 2018-2025 '!$BW11-'[1]DATA CONSOLIDADA 2018-2025 '!$BR11 -> #REF! | BZ11: 1545263.1 | CA11: 0 | CB11: 1545263.1 | CC11: =IF('[1]DATA CONSOLIDADA 2018-2025 '!$CB11>'[1]DATA CONSOLIDADA 2018-2025 '!$BW11,"Incremento",IF('[1]DATA CONSOLIDADA 2018-2025 '!$BW11='[1]DATA CONSOLIDADA 2018-2025 '!$CB11,"Sin incremento",IF('[1]DATA CONSOLIDADA 2018-2025 '!$CB11<'[1]DATA CONSOLIDADA 2018-2025 '!$BW11,"Disminución"," ---"))) -> #REF! | CD11: ='[1]DATA CONSOLIDADA 2018-2025 '!$CB11-Hoja1!$BW11 -> #REF! | CE11: 0 | CF11: 0 | CG11: 0 | CH11: =IF('[1]DATA CONSOLIDADA 2018-2025 '!$CG11>'[1]DATA CONSOLIDADA 2018-2025 '!$CB11,"Incremento",IF('[1]DATA CONSOLIDADA 2018-2025 '!$CB11='[1]DATA CONSOLIDADA 2018-2025 '!$CG11,"Sin incremento",IF('[1]DATA CONSOLIDADA 2018-2025 '!$CG11<'[1]DATA CONSOLIDADA 2018-2025 '!$CB11,"Disminución"," ---"))) -> #REF! | CI11: ='[1]DATA CONSOLIDADA 2018-2025 '!$CG11-Hoja1!$CB11 -> #REF! | CJ11: ='[1]DATA CONSOLIDADA 2018-2025 '!$BE11+'[1]DATA CONSOLIDADA 2018-2025 '!$BH11+'[1]DATA CONSOLIDADA 2018-2025 '!$BM11+'[1]DATA CONSOLIDADA 2018-2025 '!$BR11+'[1]DATA CONSOLIDADA 2018-2025 '!$BW11+'[1]DATA CONSOLIDADA 2018-2025 '!$CB11+'[1]DATA CONSOLIDADA 2018-2025 '!$CG11 -> #REF! | CK11: 0 | CL11: 0 | CM11: 0 | CN11: =IF('[1]DATA CONSOLIDADA 2018-2025 '!$CM11>'[1]DATA CONSOLIDADA 2018-2025 '!$CG11,"Incremento",IF('[1]DATA CONSOLIDADA 2018-2025 '!$CG11='[1]DATA CONSOLIDADA 2018-2025 '!$CM11,"Sin incremento",IF('[1]DATA CONSOLIDADA 2018-2025 '!$CM11<'[1]DATA CONSOLIDADA 2018-2025 '!$CG11,"Disminución"," ---"))) -> #REF! | CO11: ='[1]DATA CONSOLIDADA 2018-2025 '!$CM11-Hoja1!$CG11 -> #REF! | CP11: 9912.9964 | CQ11: 0 | CR11: 820166.58 | CS11: 715183.52 | CT11: 0 | CU11: 0 | CV11: 1545263.1 | CW11: 0 | CX11: 0 | CY11: 0 | CZ11: 0 | DA11: 0 | DB11: 0 | DC11: 0 | DD11: 0 | DE11: 0 | DF11: 0 | DG11: 0 | DH11: 0 | DI11: 20479917141 | DJ11: COOPERATIVA AGRARIA CENTRAL DE PRODUCTORES DE AMAZONAS | DK11: 02 Cooperativa
A12: ASOCIACION DE PRODUCTORES AGROPECUARIOS LUIS SOLIBARRIA | B12: CACAO | C12: CACAO | D12: AMAZONAS | E12: 010701 | F12: AMAZONAS | G12: UTCUBAMBA | H12: BAGUA GRANDE | I12: 1 | J12: 1 | Q12: PAC | R12: =IF(I12=1, I$4, "") & IF(J12=1, IF(I12=1, "-", "") & J$4, "") & IF(K12=1, IF(OR(J12=1, I12=1), "-", "") & K$4, "") & IF(L12=1, IF(OR(K12=1, J12=1, I12=1), "-", "") & L$4, "") & IF(M12=1, IF(OR(L12=1, K12=1, J12=1, I12=1), "-", "") & M$4, "") & IF(N12=1, IF(OR(M12=1, L12=1, K12=1, J12=1, I12=1), "-", "") & N$4, "") & IF(O12=1, IF(OR(N12=1, M12=1, L12=1, K12=1, J12=1, I12=1), "-", "") & O$4, "") & IF(P12=1, IF(I12=1, " - ", IF(J12=1, " - ", IF(K12=1, " - ", IF(L12=1, " - ", IF(M12=1, " - ", IF(N12=1, " - ", IF(O12=1, " - ", ""))))))) & P$4, "") -> 2018-2019 | S12: =SUM(Hoja1!$I12:$P12) -> 2 | T12: =IF(OR(Hoja1!$J12=1,Hoja1!$K12=1,Hoja1!$L12=1,Hoja1!$M12=1,Hoja1!$N12=1,Hoja1!$O12=1,Hoja1!$P12=1),"SI","NO") -> SI | U12: =IF(OR(Hoja1!$K12=1,Hoja1!$L12=1,Hoja1!$M12=1,Hoja1!$N12=1,Hoja1!$O12=1,Hoja1!$P12=1),"SI","NO") -> NO | V12: 147 | W12: 120 | X12: 25 | Y12: 145 | Z12: 0 | AA12: 0 | AB12: 0 | AC12: 0 | AD12: 0 | AE12: 0 | AF12: 0 | AG12: 0 | AH12: 0 | AI12: 0 | AJ12: 0 | AK12: 0 | AL12: 0 | AM12: 0 | AN12: 0 | AO12: 0 | AP12: 0 | AQ12: 0 | AR12: =IF(Hoja1!$AQ12>0,Hoja1!$AQ12,IF(Hoja1!$AN12>0,Hoja1!$AN12,IF(Hoja1!$AK12>0,Hoja1!$AK12,IF(Hoja1!$AH12>0,Hoja1!$AH12,IF(Hoja1!$AE12>0,Hoja1!$AE12,IF(Hoja1!$AB12>0,Hoja1!$AB12,IF(Hoja1!$Y12>0,Hoja1!$Y12,IF(Hoja1!$V12>0,Hoja1!$V12," ---")))))))) -> 145 | AS12: 0 | AT12: 0 | AU12: 0 | AV12: 0 | AW12: 0 | AX12: 0 | AY12: 0 | AZ12: 0 | BA12: 0 | BB12: 0 | BC12: 0 | BD12: 0 | BE12: 0 | BF12: 0 | BG12: 0 | BH12: 0 | BI12: =IF('[1]DATA CONSOLIDADA 2018-2025 '!$BH12>'[1]DATA CONSOLIDADA 2018-2025 '!$AN12,"Incremento",IF('[1]DATA CONSOLIDADA 2018-2025 '!$AN12='[1]DATA CONSOLIDADA 2018-2025 '!$BH12,"Sin incremento",IF('[1]DATA CONSOLIDADA 2018-2025 '!$BH12<'[1]DATA CONSOLIDADA 2018-2025 '!$AN12,"Disminución"," ---"))) -> #REF! | BJ12: ='[1]DATA CONSOLIDADA 2018-2025 '!$BH12-'[1]DATA CONSOLIDADA 2018-2025 '!$BE12 -> #REF! | BK12: 0 | BL12: 0 | BM12: 0 | BN12: =IF('[1]DATA CONSOLIDADA 2018-2025 '!$BM12>'[1]DATA CONSOLIDADA 2018-2025 '!$BH12,"Incremento",IF('[1]DATA CONSOLIDADA 2018-2025 '!$BH12='[1]DATA CONSOLIDADA 2018-2025 '!$BM12,"Sin incremento",IF('[1]DATA CONSOLIDADA 2018-2025 '!$BM12<'[1]DATA CONSOLIDADA 2018-2025 '!$BH12,"Disminución"," ---"))) -> #REF! | BO12: ='[1]DATA CONSOLIDADA 2018-2025 '!$BM12-'[1]DATA CONSOLIDADA 2018-2025 '!$BH12 -> #REF! | BP12: 0 | BQ12: 0 | BR12: 0 | BS12: =IF('[1]DATA CONSOLIDADA 2018-2025 '!$BR12>'[1]DATA CONSOLIDADA 2018-2025 '!$BM12,"Incremento",IF('[1]DATA CONSOLIDADA 2018-2025 '!$BM12='[1]DATA CONSOLIDADA 2018-2025 '!$BR12,"Sin incremento",IF('[1]DATA CONSOLIDADA 2018-2025 '!$BR12<'[1]DATA CONSOLIDADA 2018-2025 '!$BM12,"Disminución"," ---"))) -> #REF! | BT12: ='[1]DATA CONSOLIDADA 2018-2025 '!$BR12-Hoja1!$BO12 -> #REF! | BU12: 0 | BV12: 0 | BW12: 0 | BX12: =IF('[1]DATA CONSOLIDADA 2018-2025 '!$BW12>'[1]DATA CONSOLIDADA 2018-2025 '!$BR12,"Incremento",IF('[1]DATA CONSOLIDADA 2018-2025 '!$BR12='[1]DATA CONSOLIDADA 2018-2025 '!$BW12,"Sin incremento",IF('[1]DATA CONSOLIDADA 2018-2025 '!$BW12<'[1]DATA CONSOLIDADA 2018-2025 '!$BR12,"Disminución"," ---"))) -> #REF! | BY12: ='[1]DATA CONSOLIDADA 2018-2025 '!$BW12-'[1]DATA CONSOLIDADA 2018-2025 '!$BR12 -> #REF! | BZ12: 0 | CA12: 0 | CB12: 0 | CC12: =IF('[1]DATA CONSOLIDADA 2018-2025 '!$CB12>'[1]DATA CONSOLIDADA 2018-2025 '!$BW12,"Incremento",IF('[1]DATA CONSOLIDADA 2018-2025 '!$BW12='[1]DATA CONSOLIDADA 2018-2025 '!$CB12,"Sin incremento",IF('[1]DATA CONSOLIDADA 2018-2025 '!$CB12<'[1]DATA CONSOLIDADA 2018-2025 '!$BW12,"Disminución"," ---"))) -> #REF! | CD12: ='[1]DATA CONSOLIDADA 2018-2025 '!$CB12-Hoja1!$BW12 -> #REF! | CE12: 0 | CF12: 0 | CG12: 0 | CH12: =IF('[1]DATA CONSOLIDADA 2018-2025 '!$CG12>'[1]DATA CONSOLIDADA 2018-2025 '!$CB12,"Incremento",IF('[1]DATA CONSOLIDADA 2018-2025 '!$CB12='[1]DATA CONSOLIDADA 2018-2025 '!$CG12,"Sin incremento",IF('[1]DATA CONSOLIDADA 2018-2025 '!$CG12<'[1]DATA CONSOLIDADA 2018-2025 '!$CB12,"Disminución"," ---"))) -> #REF! | CI12: ='[1]DATA CONSOLIDADA 2018-2025 '!$CG12-Hoja1!$CB12 -> #REF! | CJ12: ='[1]DATA CONSOLIDADA 2018-2025 '!$BE12+'[1]DATA CONSOLIDADA 2018-2025 '!$BH12+'[1]DATA CONSOLIDADA 2018-2025 '!$BM12+'[1]DATA CONSOLIDADA 2018-2025 '!$BR12+'[1]DATA CONSOLIDADA 2018-2025 '!$BW12+'[1]DATA CONSOLIDADA 2018-2025 '!$CB12+'[1]DATA CONSOLIDADA 2018-2025 '!$CG12 -> #REF! | CK12: 0 | CL12: 0 | CM12: 0 | CN12: =IF('[1]DATA CONSOLIDADA 2018-2025 '!$CM12>'[1]DATA CONSOLIDADA 2018-2025 '!$CG12,"Incremento",IF('[1]DATA CONSOLIDADA 2018-2025 '!$CG12='[1]DATA CONSOLIDADA 2018-2025 '!$CM12,"Sin incremento",IF('[1]DATA CONSOLIDADA 2018-2025 '!$CM12<'[1]DATA CONSOLIDADA 2018-2025 '!$CG12,"Disminución"," ---"))) -> #REF! | CO12: ='[1]DATA CONSOLIDADA 2018-2025 '!$CM12-Hoja1!$CG12 -> #REF! | CP12: 0 | CQ12: 0 | CR12: 0 | CS12: 0 | CT12: 0 | CU12: 0 | CV12: 0 | CW12: 0 | CX12: 0 | CY12: 0 | CZ12: 0 | DA12: 0 | DB12: 0 | DC12: 0 | DD12: 0 | DE12: 0 | DF12: 0 | DG12: 0 | DH12: 0 | DI12: 20479856258 | DJ12: ASOCIACION DE PRODUCTORES AGROPECUARIOS LUIS SOLIBARRIA | DK12: 01 Asociación
A13: COOPERATIVA AGRARIA CAFETALERA BAGUA GRANDE LTDA | B13: CAFÉ | C13: CAFÉ | D13: AMAZONAS | E13: 010701 | F13: AMAZONAS | G13: UTCUBAMBA | H13: BAGUA GRANDE | I13: 1 | J13: 1 | K13: 1 | N13: 1 | O13: 1 | Q13: PAC | R13: =IF(I13=1, I$4, "") & IF(J13=1, IF(I13=1, "-", "") & J$4, "") & IF(K13=1, IF(OR(J13=1, I13=1), "-", "") & K$4, "") & IF(L13=1, IF(OR(K13=1, J13=1, I13=1), "-", "") & L$4, "") & IF(M13=1, IF(OR(L13=1, K13=1, J13=1, I13=1), "-", "") & M$4, "") & IF(N13=1, IF(OR(M13=1, L13=1, K13=1, J13=1, I13=1), "-", "") & N$4, "") & IF(O13=1, IF(OR(N13=1, M13=1, L13=1, K13=1, J13=1, I13=1), "-", "") & O$4, "") & IF(P13=1, IF(I13=1, " - ", IF(J13=1, " - ", IF(K13=1, " - ", IF(L13=1, " - ", IF(M13=1, " - ", IF(N13=1, " - ", IF(O13=1, " - ", ""))))))) & P$4, "") -> 2018-2019-2020-2023-2024 | S13: =SUM(Hoja1!$I13:$P13) -> 5 | T13: =IF(OR(Hoja1!$J13=1,Hoja1!$K13=1,Hoja1!$L13=1,Hoja1!$M13=1,Hoja1!$N13=1,Hoja1!$O13=1,Hoja1!$P13=1),"SI","NO") -> SI | U13: =IF(OR(Hoja1!$K13=1,Hoja1!$L13=1,Hoja1!$M13=1,Hoja1!$N13=1,Hoja1!$O13=1,Hoja1!$P13=1),"SI","NO") -> SI | V13: 592 | W13: 498 | X13: 91 | Y13: 589 | Z13: 296 | AA13: 58 | AB13: 354 | AC13: 0 | AD13: 0 | AE13: 0 | AF13: 0 | AG13: 0 | AH13: 0 | AI13: 596 | AJ13: 94 | AK13: 690 | AL13: 263 | AM13: 46 | AN13: 309 | AO13: 0 | AP13: 0 | AQ13: 0 | AR13: =IF(Hoja1!$AQ13>0,Hoja1!$AQ13,IF(Hoja1!$AN13>0,Hoja1!$AN13,IF(Hoja1!$AK13>0,Hoja1!$AK13,IF(Hoja1!$AH13>0,Hoja1!$AH13,IF(Hoja1!$AE13>0,Hoja1!$AE13,IF(Hoja1!$AB13>0,Hoja1!$AB13,IF(Hoja1!$Y13>0,Hoja1!$Y13,IF(Hoja1!$V13>0,Hoja1!$V13," ---")))))))) -> 309 | AS13: 0 | AT13: 9 | AU13: 0 | AV13: 0 | AW13: 0 | AX13: 0 | AY13: 45 | AZ13: 6 | BA13: 30 | BB13: 5 | BC13: 0 | BD13: 0 | BE13: 448800 | BF13: 0 | BG13: 1768356.9 | BH13: 1768356.9 | BI13: =IF('[1]DATA CONSOLIDADA 2018-2025 '!$BH13>'[1]DATA CONSOLIDADA 2018-2025 '!$AN13,"Incremento",IF('[1]DATA CONSOLIDADA 2018-2025 '!$AN13='[1]DATA CONSOLIDADA 2018-2025 '!$BH13,"Sin incremento",IF('[1]DATA CONSOLIDADA 2018-2025 '!$BH13<'[1]DATA CONSOLIDADA 2018-2025 '!$AN13,"Disminución"," ---"))) -> #REF! | BJ13: ='[1]DATA CONSOLIDADA 2018-2025 '!$BH13-'[1]DATA CONSOLIDADA 2018-2025 '!$BE13 -> #REF! | BK13: 443003.7 | BL13: 1384395.9 | BM13: 1827399.6 | BN13: =IF('[1]DATA CONSOLIDADA 2018-2025 '!$BM13>'[1]DATA CONSOLIDADA 2018-2025 '!$BH13,"Incremento",IF('[1]DATA CONSOLIDADA 2018-2025 '!$BH13='[1]DATA CONSOLIDADA 2018-2025 '!$BM13,"Sin incremento",IF('[1]DATA CONSOLIDADA 2018-2025 '!$BM13<'[1]DATA CONSOLIDADA 2018-2025 '!$BH13,"Disminución"," ---"))) -> #REF! | BO13: ='[1]DATA CONSOLIDADA 2018-2025 '!$BM13-'[1]DATA CONSOLIDADA 2018-2025 '!$BH13 -> #REF! | BP13: 0 | BQ13: 0 | BR13: 0 | BS13: =IF('[1]DATA CONSOLIDADA 2018-2025 '!$BR13>'[1]DATA CONSOLIDADA 2018-2025 '!$BM13,"Incremento",IF('[1]DATA CONSOLIDADA 2018-2025 '!$BM13='[1]DATA CONSOLIDADA 2018-2025 '!$BR13,"Sin incremento",IF('[1]DATA CONSOLIDADA 2018-2025 '!$BR13<'[1]DATA CONSOLIDADA 2018-2025 '!$BM13,"Disminución"," ---"))) -> #REF! | BT13: ='[1]DATA CONSOLIDADA 2018-2025 '!$BR13-Hoja1!$BO13 -> #REF! | BU13: 0 | BV13: 0 | BW13: 0 | BX13: =IF('[1]DATA CONSOLIDADA 2018-2025 '!$BW13>'[1]DATA CONSOLIDADA 2018-2025 '!$BR13,"Incremento",IF('[1]DATA CONSOLIDADA 2018-2025 '!$BR13='[1]DATA CONSOLIDADA 2018-2025 '!$BW13,"Sin incremento",IF('[1]DATA CONSOLIDADA 2018-2025 '!$BW13<'[1]DATA CONSOLIDADA 2018-2025 '!$BR13,"Disminución"," ---"))) -> #REF! | BY13: ='[1]DATA CONSOLIDADA 2018-2025 '!$BW13-'[1]DATA CONSOLIDADA 2018-2025 '!$BR13 -> #REF! | BZ13: 0 | CA13: 5910875.3 | CB13: 5910875.3 | CC13: =IF('[1]DATA CONSOLIDADA 2018-2025 '!$CB13>'[1]DATA CONSOLIDADA 2018-2025 '!$BW13,"Incremento",IF('[1]DATA CONSOLIDADA 2018-2025 '!$BW13='[1]DATA CONSOLIDADA 2018-2025 '!$CB13,"Sin incremento",IF('[1]DATA CONSOLIDADA 2018-2025 '!$CB13<'[1]DATA CONSOLIDADA 2018-2025 '!$BW13,"Disminución"," ---"))) -> #REF! | CD13: ='[1]DATA CONSOLIDADA 2018-2025 '!$CB13-Hoja1!$BW13 -> #REF! | CE13: 264948.69 | CF13: 8889133.3 | CG13: 9154082 | CH13: =IF('[1]DATA CONSOLIDADA 2018-2025 '!$CG13>'[1]DATA CONSOLIDADA 2018-2025 '!$CB13,"Incremento",IF('[1]DATA CONSOLIDADA 2018-2025 '!$CB13='[1]DATA CONSOLIDADA 2018-2025 '!$CG13,"Sin incremento",IF('[1]DATA CONSOLIDADA 2018-2025 '!$CG13<'[1]DATA CONSOLIDADA 2018-2025 '!$CB13,"Disminución"," ---"))) -> #REF! | CI13: ='[1]DATA CONSOLIDADA 2018-2025 '!$CG13-Hoja1!$CB13 -> #REF! | CJ13: ='[1]DATA CONSOLIDADA 2018-2025 '!$BE13+'[1]DATA CONSOLIDADA 2018-2025 '!$BH13+'[1]DATA CONSOLIDADA 2018-2025 '!$BM13+'[1]DATA CONSOLIDADA 2018-2025 '!$BR13+'[1]DATA CONSOLIDADA 2018-2025 '!$BW13+'[1]DATA CONSOLIDADA 2018-2025 '!$CB13+'[1]DATA CONSOLIDADA 2018-2025 '!$CG13 -> #REF! | CK13: 0 | CL13: 0 | CM13: 0 | CN13: =IF('[1]DATA CONSOLIDADA 2018-2025 '!$CM13>'[1]DATA CONSOLIDADA 2018-2025 '!$CG13,"Incremento",IF('[1]DATA CONSOLIDADA 2018-2025 '!$CG13='[1]DATA CONSOLIDADA 2018-2025 '!$CM13,"Sin incremento",IF('[1]DATA CONSOLIDADA 2018-2025 '!$CM13<'[1]DATA CONSOLIDADA 2018-2025 '!$CG13,"Disminución"," ---"))) -> #REF! | CO13: ='[1]DATA CONSOLIDADA 2018-2025 '!$CM13-Hoja1!$CG13 -> #REF! | CP13: 0 | CQ13: 0 | CR13: 0 | CS13: 5910875.3 | CT13: 0 | CU13: 0 | CV13: 5910875.3 | CW13: 0 | CX13: 0 | CY13: 9154082 | CZ13: 0 | DA13: 0 | DB13: 9154082 | DC13: 0 | DD13: 0 | DE13: 0 | DF13: 0 | DG13: 0 | DH13: 0 | DI13: 20170142773 | DJ13: COOPERATIVA AGRARIA CAFETALERA BAGUA GRANDE LIMITADA | DK13: 02 Cooperativa
A14: ASOCIACION DE PRODUCTORES AGROPECUARIOS VALLE VERDE DE RODRIGUEZ DE MENDOZA | B14: CAFÉ | C14: CAFÉ | D14: AMAZONAS | E14: 010601 | F14: AMAZONAS | G14: RODRIGUEZ DE MENDOZA | H14: SAN NICOLAS | I14: 1 | J14: 1 | Q14: PAC | R14: =IF(I14=1, I$4, "") & IF(J14=1, IF(I14=1, "-", "") & J$4, "") & IF(K14=1, IF(OR(J14=1, I14=1), "-", "") & K$4, "") & IF(L14=1, IF(OR(K14=1, J14=1, I14=1), "-", "") & L$4, "") & IF(M14=1, IF(OR(L14=1, K14=1, J14=1, I14=1), "-", "") & M$4, "") & IF(N14=1, IF(OR(M14=1, L14=1, K14=1, J14=1, I14=1), "-", "") & N$4, "") & IF(O14=1, IF(OR(N14=1, M14=1, L14=1, K14=1, J14=1, I14=1), "-", "") & O$4, "") & IF(P14=1, IF(I14=1, " - ", IF(J14=1, " - ", IF(K14=1, " - ", IF(L14=1, " - ", IF(M14=1, " - ", IF(N14=1, " - ", IF(O14=1, " - ", ""))))))) & P$4, "") -> 2018-2019 | S14: =SUM(Hoja1!$I14:$P14) -> 2 | T14: =IF(OR(Hoja1!$J14=1,Hoja1!$K14=1,Hoja1!$L14=1,Hoja1!$M14=1,Hoja1!$N14=1,Hoja1!$O14=1,Hoja1!$P14=1),"SI","NO") -> SI | U14: =IF(OR(Hoja1!$K14=1,Hoja1!$L14=1,Hoja1!$M14=1,Hoja1!$N14=1,Hoja1!$O14=1,Hoja1!$P14=1),"SI","NO") -> NO | V14: 427 | W14: 0 | X14: 0 | Y14: 0 | Z14: 0 | AA14: 0 | AB14: 0 | AC14: 0 | AD14: 0 | AE14: 0 | AF14: 0 | AG14: 0 | AH14: 0 | AI14: 0 | AJ14: 0 | AK14: 0 | AL14: 0 | AM14: 0 | AN14: 0 | AO14: 0 | AP14: 0 | AQ14: 0 | AR14: =IF(Hoja1!$AQ14>0,Hoja1!$AQ14,IF(Hoja1!$AN14>0,Hoja1!$AN14,IF(Hoja1!$AK14>0,Hoja1!$AK14,IF(Hoja1!$AH14>0,Hoja1!$AH14,IF(Hoja1!$AE14>0,Hoja1!$AE14,IF(Hoja1!$AB14>0,Hoja1!$AB14,IF(Hoja1!$Y14>0,Hoja1!$Y14,IF(Hoja1!$V14>0,Hoja1!$V14," ---")))))))) -> 427 | AS14: 0 | AT14: 0 | AU14: 0 | AV14: 0 | AW14: 0 | AX14: 0 | AY14: 0 | AZ14: 0 | BA14: 0 | BB14: 0 | BC14: 0 | BD14: 0 | BE14: 0 | BF14: 0 | BG14: 0 | BH14: 0 | BI14: =IF('[1]DATA CONSOLIDADA 2018-2025 '!$BH14>'[1]DATA CONSOLIDADA 2018-2025 '!$AN14,"Incremento",IF('[1]DATA CONSOLIDADA 2018-2025 '!$AN14='[1]DATA CONSOLIDADA 2018-2025 '!$BH14,"Sin incremento",IF('[1]DATA CONSOLIDADA 2018-2025 '!$BH14<'[1]DATA CONSOLIDADA 2018-2025 '!$AN14,"Disminución"," ---"))) -> #REF! | BJ14: ='[1]DATA CONSOLIDADA 2018-2025 '!$BH14-'[1]DATA CONSOLIDADA 2018-2025 '!$BE14 -> #REF! | BK14: 0 | BL14: 0 | BM14: 0 | BN14: =IF('[1]DATA CONSOLIDADA 2018-2025 '!$BM14>'[1]DATA CONSOLIDADA 2018-2025 '!$BH14,"Incremento",IF('[1]DATA CONSOLIDADA 2018-2025 '!$BH14='[1]DATA CONSOLIDADA 2018-2025 '!$BM14,"Sin incremento",IF('[1]DATA CONSOLIDADA 2018-2025 '!$BM14<'[1]DATA CONSOLIDADA 2018-2025 '!$BH14,"Disminución"," ---"))) -> #REF! | BO14: ='[1]DATA CONSOLIDADA 2018-2025 '!$BM14-'[1]DATA CONSOLIDADA 2018-2025 '!$BH14 -> #REF! | BP14: 0 | BQ14: 0 | BR14: 0 | BS14: =IF('[1]DATA CONSOLIDADA 2018-2025 '!$BR14>'[1]DATA CONSOLIDADA 2018-2025 '!$BM14,"Incremento",IF('[1]DATA CONSOLIDADA 2018-2025 '!$BM14='[1]DATA CONSOLIDADA 2018-2025 '!$BR14,"Sin incremento",IF('[1]DATA CONSOLIDADA 2018-2025 '!$BR14<'[1]DATA CONSOLIDADA 2018-2025 '!$BM14,"Disminución"," ---"))) -> #REF! | BT14: ='[1]DATA CONSOLIDADA 2018-2025 '!$BR14-Hoja1!$BO14 -> #REF! | BU14: 0 | BV14: 0 | BW14: 0 | BX14: =IF('[1]DATA CONSOLIDADA 2018-2025 '!$BW14>'[1]DATA CONSOLIDADA 2018-2025 '!$BR14,"Incremento",IF('[1]DATA CONSOLIDADA 2018-2025 '!$BR14='[1]DATA CONSOLIDADA 2018-2025 '!$BW14,"Sin incremento",IF('[1]DATA CONSOLIDADA 2018-2025 '!$BW14<'[1]DATA CONSOLIDADA 2018-2025 '!$BR14,"Disminución"," ---"))) -> #REF! | BY14: ='[1]DATA CONSOLIDADA 2018-2025 '!$BW14-'[1]DATA CONSOLIDADA 2018-2025 '!$BR14 -> #REF! | BZ14: 0 | CA14: 0 | CB14: 0 | CC14: =IF('[1]DATA CONSOLIDADA 2018-2025 '!$CB14>'[1]DATA CONSOLIDADA 2018-2025 '!$BW14,"Incremento",IF('[1]DATA CONSOLIDADA 2018-2025 '!$BW14='[1]DATA CONSOLIDADA 2018-2025 '!$CB14,"Sin incremento",IF('[1]DATA CONSOLIDADA 2018-2025 '!$CB14<'[1]DATA CONSOLIDADA 2018-2025 '!$BW14,"Disminución"," ---"))) -> #REF! | CD14: ='[1]DATA CONSOLIDADA 2018-2025 '!$CB14-Hoja1!$BW14 -> #REF! | CE14: 0 | CF14: 0 | CG14: 0 | CH14: =IF('[1]DATA CONSOLIDADA 2018-2025 '!$CG14>'[1]DATA CONSOLIDADA 2018-2025 '!$CB14,"Incremento",IF('[1]DATA CONSOLIDADA 2018-2025 '!$CB14='[1]DATA CONSOLIDADA 2018-2025 '!$CG14,"Sin incremento",IF('[1]DATA CONSOLIDADA 2018-2025 '!$CG14<'[1]DATA CONSOLIDADA 2018-2025 '!$CB14,"Disminución"," ---"))) -> #REF! | CI14: ='[1]DATA CONSOLIDADA 2018-2025 '!$CG14-Hoja1!$CB14 -> #REF! | CJ14: ='[1]DATA CONSOLIDADA 2018-2025 '!$BE14+'[1]DATA CONSOLIDADA 2018-2025 '!$BH14+'[1]DATA CONSOLIDADA 2018-2025 '!$BM14+'[1]DATA CONSOLIDADA 2018-2025 '!$BR14+'[1]DATA CONSOLIDADA 2018-2025 '!$BW14+'[1]DATA CONSOLIDADA 2018-2025 '!$CB14+'[1]DATA CONSOLIDADA 2018-2025 '!$CG14 -> #REF! | CK14: 0 | CL14: 0 | CM14: 0 | CN14: =IF('[1]DATA CONSOLIDADA 2018-2025 '!$CM14>'[1]DATA CONSOLIDADA 2018-2025 '!$CG14,"Incremento",IF('[1]DATA CONSOLIDADA 2018-2025 '!$CG14='[1]DATA CONSOLIDADA 2018-2025 '!$CM14,"Sin incremento",IF('[1]DATA CONSOLIDADA 2018-2025 '!$CM14<'[1]DATA CONSOLIDADA 2018-2025 '!$CG14,"Disminución"," ---"))) -> #REF! | CO14: ='[1]DATA CONSOLIDADA 2018-2025 '!$CM14-Hoja1!$CG14 -> #REF! | CP14: 0 | CQ14: 0 | CR14: 0 | CS14: 0 | CT14: 0 | CU14: 0 | CV14: 0 | CW14: 0 | CX14: 0 | CY14: 0 | CZ14: 0 | DA14: 0 | DB14: 0 | DC14: 0 | DD14: 0 | DE14: 0 | DF14: 0 | DG14: 0 | DH14: 0 | DI14: 20600682386 | DJ14: ASOCIACION DE PRODUCTORES AGROPECUARIOS VALLE VERDE DE RODRIGUEZ DE MENDOZA | DK14: 01 Asociación
