Workbook

Sheet INSTRUCCIONES
A1: PLANTILLA ÍNDICE PVE — PACTO VERDE EUROPEO
A2: Clasificación de preparación y vulnerabilidad de cooperativas café y cacao ante el EUDR / Pacto Verde Europeo
A4: SIN DATO = «—», NUNCA 0 (regla vigente desde 2026-10-15)
A5: La falta de dato no se convierte en 0 en ningún nivel: en la base precensal el % UE/FOB, el FOB, el puntaje de certificación y los indicadores P1–P14 aparecen como «—». En el motor, ISA-EUDR e IP se reportan «—» cuando no alcanzan su umbral de dimensiones con dato. ISA-PactoVerde es la excepción declarada: sobre sus componentes con dato se computa igual, y mientras no cumpla su umbral (3 de 4 dimensiones D12–D15) el valor se muestra como PROVISIONAL, etiquetado «◐ Parcial · n/7» en MATRIZ_174 (columnas AT y T) —nunca como un color de clasificación ni como 0—.
A7: CÓMO FUNCIONA
A8: El puntaje se arma en dos pasos. Primero, el Índice de Preparación (IP) mide qué tan lista está la organización hoy: documentación, trazabilidad, legalidad, capacidad digital, acceso a mercado. Segundo, el Índice de Vulnerabilidad (IV) mide qué tan expuesta está si no se prepara a tiempo: dependencia del mercado europeo, fragmentación de tierra, informalidad, tipo de organización. Combinando ambos se calcula el Riesgo de Exclusión (RE): una organización muy preparada tiene RE bajo aunque sea estructuralmente vulnerable, porque su preparación ya compensa ese riesgo; una organización sin ninguna preparación traslada toda su vulnerabilidad directamente a riesgo de exclusión. El semáforo (🔴🟡🟢, abajo) traduce el puntaje final a una categoría fácil de comunicar.
A10: FLUJO DE USO
A11: Paso 1 | B11: Revisar PONDERADORES — los pesos son editables en celdas amarillas
A12: Paso 2 | B12: Ir a MATRIZ_174 — verificar/actualizar FOB, país destino, certificaciones
A13: Paso 3 | B13: Cargar las respuestas del Instrumento 2 en la hoja CAPTURA: una fila por cooperativa (RUC y razón social ya precargados) y una columna por pregunta, con lista desplegable en las preguntas de opción. Es la única hoja donde se escribe: NORMALIZADO calcula los 0-100 por pregunta y las dimensiones D1-D11, y el motor (ISCAM_Score), los semáforos y el radar se recalculan solos.
A14: Paso 4 | B14: Revisar SCORECARDS — el semáforo se actualiza automáticamente
A15: Paso 5 | B15: Usar RADAR_BRECHAS para comparación por departamento
A17: SEMÁFORO
A18: 🔴 Crítico (0–33) | B18: La cooperativa no puede generar la declaración EUDR. Riesgo de rechazo en frontera UE desde dic 2026.
A19: 🟡 Vulnerable (34–66) | B19: Tiene infraestructura parcial pero incompleta. Necesita inversión en geolocalización y proceso.
A20: 🟢 Preparado (67–100) | B20: Cumple los requisitos mínimos. Requiere monitoreo de actualización.
A22: NOTAS IMPORTANTES
A23: Dato faltante no es lo mismo que incumplimiento: si a una organización le falta información en alguna pregunta, el sistema la muestra como "sin dato" (gris), nunca como si cumpliera. Un puntaje bajo por falta de carga no significa que la organización no esté preparada — significa que todavía no se le aplicó el instrumento.
A24: Esta plantilla es un instrumento vivo: los pesos en PONDERADORES son editables (celda amarilla) y se ajustarán con un panel de expertos (método AHP) y con los resultados del primer piloto.
A25: El RUC es la llave que conecta todas las hojas entre sí: nunca debe quedar vacío, y no se debe reordenar esa columna una vez que se empiece a cargar información real.
A26: Cada cambio relevante a esta plantilla debe guardarse como una copia fechada (carpeta respaldos), para poder reconstruir cualquier estado anterior si algo sale mal.
A27: Cómo funciona la carga del instrumento: la hoja CODIFICACION es la tabla de codificación (cada opción de respuesta vale 0-100, o «sin dato» si la opción expresa desconocimiento o no aplicación); la hoja CAPTURA es la entrada de datos; y la hoja NORMALIZADO convierte y agrega. Si una respuesta no está en la tabla, se marca «⚠» para revisarla. Las preguntas de casillas múltiples se separan con «;». La tabla de codificación marca con «[R]» los ítems a ratificar antes del levantamiento de campo.
A29: GLOSARIO
A30: EUDR | B30: Reglamento (UE) 2023/1115: la norma europea que exige trazabilidad y legalidad para café y cacao exportado a la UE a partir de diciembre de 2026.
A31: Pacto Verde Europeo (PVE) | B31: La estrategia más amplia de la Unión Europea para una economía climáticamente neutra. El EUDR es una de sus piezas; el PVE además evalúa huella de carbono, economía circular y envases.
A32: ISA (Índice Sintético de Alineamiento) | B32: El puntaje final (ISA-Completo, 0-100) que resume la preparación y vulnerabilidad de cada organización frente al EUDR y al Pacto Verde.
A33: IP (Índice de Preparación) | B33: Qué tan lista está la organización hoy (documentación, trazabilidad, legalidad, capacidad digital, acceso a mercado).
A34: IV (Índice de Vulnerabilidad) | B34: Qué tan expuesta está la organización si no logra prepararse a tiempo (dependencia del mercado europeo, fragmentación de tierra, informalidad).
A35: RE (Riesgo de Exclusión) | B35: El riesgo real de quedar fuera del mercado europeo: combina IP e IV — la preparación (IP) modera cuánto de la vulnerabilidad (IV) se vuelve riesgo real.
A36: AHP (Proceso de Análisis Jerárquico) | B36: Método estándar para que un panel de expertos derive los pesos de un índice a partir de comparaciones por pares, en vez de asumir pesos iguales por defecto.

Sheet INSTRUMENTO_2_PREGUNTAS
A1: INSTRUMENTO 2 (v0.4, 119 preguntas) — Correspondencia pregunta → destino en esta plantilla
A2: Sección | B2: ID | C2: Bloque / Dimensión | D2: Pregunta | E2: Tipo de campo | F2: Opciones | G2: Destino en esta plantilla
A3: Sección 0 — Metadata de campo | B3: M1 | C3: Bloque 0 — Ficha de identificación | D3: Fecha | E3: — | F3: — | G3: Google Sheet de respuestas, col. D (`fecha_aplicacion`)
A4: Sección 0 — Metadata de campo | B4: M2 | C4: Bloque 0 — Ficha de identificación | D4: Respuesta corta | E4: — | F4: — | G4: Google Sheet de respuestas, col. E (`encuestador`)
A5: Sección 0 — Metadata de campo | B5: M3 | C5: Bloque 0 — Ficha de identificación | D5: Lista desplegable | E5: Google Form directo / Piggyback GIZ / Piggyback SAFE / Piggyback MIDAGRI / Evento gremial / Otro | F5: — | G5: Google Sheet de respuestas, col. F (`canal_aplicacion`)
A6: Sección 1 — Bloque 0: Ficha de identificación | B6: B0.1 | C6: Bloque 0 — Ficha de identificación | D6: Nombre de la cooperativa / razón social | E6: Respuesta corta | F6: — | G6: `MATRIZ_174!B` (Razón Social)
A7: Sección 1 — Bloque 0: Ficha de identificación | B7: B0.2 | C7: Bloque 0 — Ficha de identificación | D7: RUC | E7: Respuesta corta (validación: regex 11 dígitos si el Form lo permite) | F7: — | G7: `MATRIZ_174!A` · `ISCAM_Score!A` · `SCORECARDS!A` — clave de unión
A8: Sección 1 — Bloque 0: Ficha de identificación | B8: B0.3 | C8: Bloque 0 — Ficha de identificación | D8: Producto(s) exportado(s) (café, cacao, madera, otro — indique código SA si lo conoce) | E8: Párrafo | F8: — | G8: `MATRIZ_174!D` (Producto)
A9: Sección 1 — Bloque 0: Ficha de identificación | B9: B0.4 | C9: Bloque 0 — Ficha de identificación | D9: N.º de socios productores y hectáreas totales asociadas (indique ambos: "N.º socios: ___ / Hectáreas: ___") | E9: Párrafo | F9: — | G9: `MATRIZ_174!Q` (N.° socios) + `R` (Ha)
A10: Sección 1 — Bloque 0: Ficha de identificación | B10: B0.5 | C10: Bloque 0 — Ficha de identificación | D10: ¿Exporta directamente a la Unión Europea o a través de un tercero? | E10: Opción múltiple | F10: Directamente / A través de un tercero | G10: `MATRIZ_174!G` (Exporta SI/NO)
A11: Sección 1 — Bloque 0: Ficha de identificación | B11: B0.6 | C11: Bloque 0 — Ficha de identificación | D11: Si respondió "a través de un tercero": ¿quién es el comprador que sí exporta a la UE? (deje en blanco si no aplica) | E11: Respuesta corta (opcional) | F11: — | G11: Sin destino en la plantilla — registro de auditoría
A12: Sección 1 — Bloque 0: Ficha de identificación | B12: B0.7 | C12: Bloque 0 — Ficha de identificación | D12: Volumen anual aproximado destinado a la UE, como % del total exportado | E12: Respuesta corta (validación numérica 0-100) | F12: — | G12: `MATRIZ_174!M` (% UE/FOB) — validación cruzada
A13: Sección 1 — Bloque 0: Ficha de identificación | B13: B0.8 | C13: Bloque 0 — Ficha de identificación | D13: Destino(s) de sus exportaciones, marcando primero el principal — incluya destinos fuera de la UE | E13: Casillas de verificación | F13: Alemania / Bélgica / Países Bajos / Francia / Italia / España / Suecia / Dinamarca / Estados Unidos / Japón / China / Otro (especificar) | G13: Proxy `destino_principal` (D7); validación vs. DUAs
... A121: Sección 16 — Bloque R: Indicadores de Desempeño (columnas P1–P14 de `MATRIZ_174`) | B121: R10 | C121: Bloque R — Indicadores de Desempeño | D121: ¿Qué porcentaje de los residuos y subproductos del beneficio se gestionan con tratamiento (compostaje, reciclaje, biogás u otro)? | E121: Respuesta corta (validación numérica 0-100) | F121: — | G121: `MATRIZ_174!AN` (P14) → `AO`
A123: Notas: verde = pregunta nueva en v0.4 (30); amarillo = modificada en v0.4 (5). Columnas `MATRIZ_174`, `ISCAM_Score`, `SCORECARDS` y `PONDERADORES` son hojas de este mismo libro. Las 17 columnas D12–D15 no listadas como activas esperan la evaluación de comprensibilidad del técnico de campo (ver `DOC_TRABAJO_Instrumento2_ISCAM_v2.md` §10.2). Fuente: `Instrumentos\Texto para Google Form - Instrumento 2.md`. Las preguntas marcadas "Insumo IVx" alimentan IV1–IV5 al cargar la ronda del instrumento; hoy esas subdimensiones operan con proxies documentados (ver PONDERADORES y §1.8 del documento de metodología).

Sheet CODIFICACION
A1: CODIFICACIÓN — Instrumento 2 · opción de respuesta → puntaje 0-100. 100 = mejor alineamiento con el EUDR. «sin dato» = no se promedia. Banderas, mapeos y bloques 0/P se capturan y se reportan por separado: no entran a ningún promedio (Instrumento 2, Tabla 5 y reglas de integridad).
A2: ID | B2: Sección / Bloque | C2: Tipo de campo | D2: Opción de respuesta | E2: Puntaje (0-100) | F2: Clave (ID|Opción) | G2: Nota
A3: M1 | B3: Bloque 0 — Ficha de identificación | C3: — | D3: — | G3: no puntúa el índice (identificación, validación o derivada)
A4: M2 | B4: Bloque 0 — Ficha de identificación | C4: — | D4: — | G4: no puntúa el índice (identificación, validación o derivada)
A5: M3 | B5: Bloque 0 — Ficha de identificación | C5: Google Form directo / Piggyback GIZ / Piggyback SAFE / Piggyback MIDAGRI / Evento gremial / Otro | D5: — | G5: no puntúa el índice (identificación, validación o derivada)
A6: B0.1 | B6: Bloque 0 — Ficha de identificación | C6: Respuesta corta | D6: — | G6: no puntúa el índice (identificación, validación o derivada)
A7: B0.2 | B7: Bloque 0 — Ficha de identificación | C7: Respuesta corta (validación: regex 11 dígitos si el Form lo permite) | D7: — | G7: no puntúa el índice (identificación, validación o derivada)
A8: B0.3 | B8: Bloque 0 — Ficha de identificación | C8: Párrafo | D8: — | G8: no puntúa el índice (identificación, validación o derivada)
A9: B0.4 | B9: Bloque 0 — Ficha de identificación | C9: Párrafo | D9: — | G9: no puntúa el índice (identificación, validación o derivada)
A10: B0.5 | B10: Bloque 0 — Ficha de identificación | C10: Opción múltiple | D10: Directamente / A través de un tercero | G10: no puntúa el índice (identificación, validación o derivada)
A11: B0.6 | B11: Bloque 0 — Ficha de identificación | C11: Respuesta corta (opcional) | D11: — | G11: no puntúa el índice (identificación, validación o derivada)
A12: B0.7 | B12: Bloque 0 — Ficha de identificación | C12: Respuesta corta (validación numérica 0-100) | D12: — | G12: no puntúa el índice (identificación, validación o derivada)
A13: B0.8 | B13: Bloque 0 — Ficha de identificación | C13: Casillas de verificación | D13: (casillas múltiples, separar con «;») | G13: Bloque 0 (identificación) — no puntúa. Se captura y se reporta como variable de verificación de destinos (no entra a D7).
A14: B0.9 | B14: Bloque 0 — Ficha de identificación | C14: Casillas de verificación | D14: Rainforest Alliance / Fairtrade / Orgánico / UTZ / Otra / Ninguna | G14: no puntúa el índice (identificación, validación o derivada)
... A30: P7 | B30: Bloque P — Desempeño comercial | C30: Respuesta corta | D30: — | G30: no puntúa el índice (identificación, validación o derivada)
A31: P8 | B31: Bloque P — Desempeño comercial | C31: Opción múltiple | D31: Sí | E31: 0 | F31: P8|Sí | G31: Bloque P (desempeño) — no puntúa; variable de resultado. Se reporta por separado.
A32: P8 | B32: Bloque P — Desempeño comercial | C32: Opción múltiple | D32: No | E32: 100 | F32: P8|No | G32: Bloque P (desempeño) — no puntúa; variable de resultado. Se reporta por separado.
A33: P8 | B33: Bloque P — Desempeño comercial | C33: Opción múltiple | D33: No sabe | E33: sin dato | F33: P8|No sabe | G33: Bloque P (desempeño) — no puntúa; variable de resultado. Se reporta por separado. · «sin dato» no promedia
A34: P9 | B34: Bloque P — Desempeño comercial | C34: Respuesta corta (opcional) | D34: — | G34: no puntúa el índice (identificación, validación o derivada)
A35: P10 | B35: Bloque P — Desempeño comercial | C35: Opción múltiple | D35: Sí | E35: 0 | F35: P10|Sí | G35: Bloque P (desempeño) — no puntúa; variable de resultado. Se reporta por separado.
A36: P10 | B36: Bloque P — Desempeño comercial | C36: Opción múltiple | D36: No | E36: 100 | F36: P10|No | G36: Bloque P (desempeño) — no puntúa; variable de resultado. Se reporta por separado.
A37: P10 | B37: Bloque P — Desempeño comercial | C37: Opción múltiple | D37: No sabe | E37: sin dato | F37: P10|No sabe | G37: Bloque P (desempeño) — no puntúa; variable de resultado. Se reporta por separado. · «sin dato» no promedia
A38: P11 | B38: Bloque P — Desempeño comercial | C38: Respuesta corta (validación numérica 0-100) | D38: — | G38: no puntúa el índice (identificación, validación o derivada)
A39: P12 | B39: Bloque P — Desempeño comercial | C39: Respuesta corta (numérica) | D39: — | G39: no puntúa el índice (identificación, validación o derivada)
A40: P13 | B40: Bloque P — Desempeño comercial | C40: Opción múltiple | D40: No | E40: 0 | F40: P13|No | G40: Bloque P (desempeño) — no puntúa; variable de resultado. Se reporta por separado.
A41: P13 | B41: Bloque P — Desempeño comercial | C41: Opción múltiple | D41: Sí, de forma verbal o informal | E41: 33 | F41: P13|Sí, de forma verbal o informal | G41: Bloque P (desempeño) — no puntúa; variable de resultado. Se reporta por separado.
A42: P13 | B42: Bloque P — Desempeño comercial | C42: Opción múltiple | D42: Sí, como cuestionario de proveedor o documentación formal | E42: 67 | F42: P13|Sí, como cuestionario de proveedor o documentación formal | G42: Bloque P (desempeño) — no puntúa; variable de resultado. Se reporta por separado.
A43: P13 | B43: Bloque P — Desempeño comercial | C43: Opción múltiple | D43: Sí, como cláusula contractual o condición de pago | E43: 100 | F43: P13|Sí, como cláusula contractual o condición de pago | G43: Bloque P (desempeño) — no puntúa; variable de resultado. Se reporta por separado.
A44: P14 | B44: Bloque P — Desempeño comercial | C44: Opción múltiple | D44: No ha intentado | E44: 0 | F44: P14|No ha intentado | G44: Bloque P (desempeño) — no puntúa; variable de resultado. Se reporta por separado.
A45: P14 | B45: Bloque P — Desempeño comercial | C45: Opción múltiple | D45: Lo intentó pero no cumplió los criterios | E45: 25 | F45: P14|Lo intentó pero no cumplió los criterios | G45: Bloque P (desempeño) — no puntúa; variable de resultado. Se reporta por separado.
A46: P14 | B46: Bloque P — Desempeño comercial | C46: Opción múltiple | D46: Sí, recibió financiamiento verde | E46: 100 | F46: P14|Sí, recibió financiamiento verde | G46: Bloque P (desempeño) — no puntúa; variable de resultado. Se reporta por separado.
A47: P14 | B47: Bloque P — Desempeño comercial | C47: Opción múltiple | D47: No sabe si aplica a su caso | E47: sin dato | F47: P14|No sabe si aplica a su caso | G47: Bloque P (desempeño) — no puntúa; variable de resultado. Se reporta por separado. · «sin dato» no promedia
A48: D1.1 | B48: D1 — Clasificación regulatoria | C48: Opción múltiple | D48: Sí | E48: 100 | F48: D1.1|Sí | G48: Ratificado 2026-10-15: 100 = introduce bajo su propio nombre (operador directo); 50 = vende a través de un tercero.
A49: D1.1 | B49: D1 — Clasificación regulatoria | C49: Opción múltiple | D49: No | E49: 50 | F49: D1.1|No | G49: Ratificado 2026-10-15: 100 = introduce bajo su propio nombre (operador directo); 50 = vende a través de un tercero.
A50: D1.2 | B50: D1 — Clasificación regulatoria | C50: Opción múltiple | D50: Transforma / No transforma | G50: no puntúa el índice (identificación, validación o derivada)
A51: D1.3 | B51: D1 — Clasificación regulatoria | C51: Opción múltiple | D51: Sí con certeza | E51: 100 | F51: D1.3|Sí con certeza
A52: D1.3 | B52: D1 — Clasificación regulatoria | C52: Opción múltiple | D52: Idea aproximada | E52: 50 | F52: D1.3|Idea aproximada
A53: D1.3 | B53: D1 — Clasificación regulatoria | C53: Opción múltiple | D53: No sabe | E53: sin dato | F53: D1.3|No sabe | G53: «sin dato» no promedia
A54: D1.4 | B54: D1 — Clasificación regulatoria | C54: Opción múltiple | D54: Sí | E54: 100 | F54: D1.4|Sí | G54: Ratificado 2026-10-15: 100 = cumple los umbrales de micro/pequeña empresa (Directiva 2013/34/UE), que definen su régimen simplificado.
A55: D1.4 | B55: D1 — Clasificación regulatoria | C55: Opción múltiple | D55: No | E55: 50 | F55: D1.4|No | G55: Ratificado 2026-10-15: 100 = cumple los umbrales de micro/pequeña empresa (Directiva 2013/34/UE), que definen su régimen simplificado.
...

Sheet CAPTURA
A1: CAPTURA — Instrumento 2 (119 preguntas · 1 respuesta por cooperativa). Pegue aquí las respuestas del formulario; el motor calcula solo. Casillas múltiples: separe con «;». El enunciado completo está en INSTRUMENTO_2_PREGUNTAS.
A2: RUC (clave de unión) | B2: Razón Social | C2: M1 | D2: M2 | E2: M3 | F2: B0.1 | G2: B0.2 | H2: B0.3 | I2: B0.4 | J2: B0.5 | K2: B0.6 | L2: B0.7 | M2: B0.8 | N2: B0.9 | O2: B0.10 | P2: B0.11 | Q2: B0.12 | R2: B0.13 | S2: B0.14 | T2: B0.15 | U2: B0.16 | V2: B0.17 | W2: P1 | X2: P1b | Y2: P2 | Z2: P3 | AA2: P4 | AB2: P5 | AC2: P6 | AD2: P7 | AE2: P8 | AF2: P9 | AG2: P10 | AH2: P11 | AI2: P12 | AJ2: P13 | AK2: P14 | AL2: D1.1 | AM2: D1.2 | AN2: D1.3 | AO2: D1.4 | AP2: D1.3a | AQ2: D2.5 | AR2: D2.6 | AS2: D2.7 | AT2: D2.8 | AU2: D2.9 | AV2: D2.10 | AW2: D2.5a | AX2: D2.5b | AY2: D3.11 | AZ2: D3.12 | BA2: D3.13 | BB2: D3.14 | BC2: D3.14a | BD2: D3.14b | BE2: D3.14c | BF2: D3.14d | BG2: D3.14e | BH2: D3.14f | BI2: D3.14g | BJ2: D3.14h | BK2: D3.14i | BL2: D4.15 | BM2: D4.16 | BN2: D4.17 | BO2: D4.15a | BP2: D5.18 | BQ2: D5.18a | BR2: D5.18b | BS2: D5.19 | BT2: D5.19a | BU2: D5.20 | BV2: D5.21 | BW2: D5.21a | BX2: D5.21b | BY2: D6.22 | BZ2: D6.22a | CA2: D6.22b | CB2: D6.23 | CC2: D6.24 | CD2: D6.25 | CE2: D6.25a | CF2: D6.25b | CG2: D6.22c | CH2: D7.26 | CI2: D7.27 | CJ2: D7.28 | CK2: D7.28b | CL2: D7.28c | CM2: D7.26a | CN2: D7.26b | CO2: D8.29 | CP2: D8.30 | CQ2: D8.31 | CR2: D8.32 | CS2: D9.33 | CT2: D9.34 | CU2: D9.35 | CV2: D10.36 | CW2: D10.37 | CX2: D10.36a | CY2: D11.38 | CZ2: D11.39 | DA2: D11.39a | DB2: D12.42 | DC2: D13.45 | DD2: D14.51 | DE2: D15.58 | DF2: PP1 | DG2: PP2 | DH2: R1 | DI2: R2 | DJ2: R3 | DK2: R4 | DL2: R5 | DM2: R6 | DN2: R7 | DO2: R8 | DP2: R9 | DQ2: R10
A3: 20118578415 | B3: CENT.DE COOP.AGR. CAF.VALLES SANDIA LTDA
A4: 20129156083 | B4: COOP AGRARIA CAFET VALLE RIO APURIMAC
A5: 20129529530 | B5: COOP AGRARIA CAFETALERA SATIPO LTDA
A6: 20132489824 | B6: COOPERATIVA AGRARIA CAFETALERA CHANCAMAYO LTDA. N° 008-B-VII
A7: 20132505455 | B7: COOPERATIVA AGRARIA CAFETALERA AGUILAYOC LTDA. 084
A8: 20132509795 | B8: COOPERATIVA AGRARIA CAFETALERA JOSE OLAYA LTDA N° 252
A9: 20132509876 | B9: COOPERATIVA AGRARIA CAFETALERA MARANURA LTDA. 129
A10: 20132517119 | B10: COOPERATIVA AGRARIA CAFETALERA MATEO PUMACAHUA LTDA N° 185
A11: 20136201132 | B11: COOPERATIVA AGRARIA CAFETALERA ALTO URUBAMBA LTDA N° 239
A12: 20136201213 | B12: CENTRAL DE COOPERATIVAS AGRARIAS CAFETALERAS COCLA LTDA. N°
A13: 20140292657 | B13: COOPERATIVA AGRARIA CAFETALERA CCOCHAPAMPA LTDA.
A14: 20143692010 | B14: COOPERATIVA AGRARIA EL QUINACHO LTDA. N° 078
... A173: 20610772553 | B173: ASOCIACION DE MUJERES CAFICULTORAS DE CHINYAMA
A174: 20611316616
A175: 20611935243 | B175: COOPERATIVA AGRARIA ECOLOGICA CANIARI AMAZONICA CAECAM
A176: 20612331821 | B176: ASOCIACIÓN DE MUJERES LAS FLORES DE LUYA

Sheet NORMALIZADO
A1: NORMALIZADO — 0-100 automático (hoja de cálculo, no editar). Lee CAPTURA y aplica CODIFICACION; los vacíos se propagan como «sin dato».
A2: RUC | B2: Razón Social | C2: B0.8 | D2: P8 | E2: P10 | F2: P13 | G2: P14 | H2: D1.1 | I2: D1.3 | J2: D1.4 | K2: D1.3a | L2: D2.5 | M2: D2.6 | N2: D2.7 | O2: D2.8 | P2: D2.9 | Q2: D2.10 | R2: D2.5a | S2: D2.5b | T2: D3.11 | U2: D3.12 | V2: D3.13 | W2: D3.14 | X2: D3.14a | Y2: D3.14b | Z2: D3.14c | AA2: D3.14d | AB2: D3.14e | AC2: D3.14f | AD2: D3.14g | AE2: D3.14h | AF2: D3.14i | AG2: D4.15 | AH2: D4.16 | AI2: D4.17 | AJ2: D4.15a | AK2: D5.18 | AL2: D5.18a | AM2: D5.18b | AN2: D5.19 | AO2: D5.19a | AP2: D5.20 | AQ2: D5.21 | AR2: D5.21a | AS2: D5.21b | AT2: D6.22 | AU2: D6.22a | AV2: D6.22b | AW2: D6.23 | AX2: D6.24 | AY2: D6.25 | AZ2: D6.25a | BA2: D6.25b | BB2: D6.22c | BC2: D7.26 | BD2: D7.27 | BE2: D7.28 | BF2: D7.28b | BG2: D7.28c | BH2: D7.26a | BI2: D7.26b | BJ2: D8.29 | BK2: D8.30 | BL2: D8.31 | BM2: D8.32 | BN2: D9.33 | BO2: D9.34 | BP2: D9.35 | BQ2: D10.36 | BR2: D10.37 | BS2: D10.36a | BT2: D11.38 | BU2: D11.39a | BV2: D12.42 | BW2: D13.45 | BX2: D14.51 | BY2: D15.58 | BZ2: PP1 | CA2: PP2 | CB2: D1 | CC2: D2 | CD2: D3 | CE2: D4 | CF2: D5 | CG2: D6 | CH2: D7 | CI2: D8 | CJ2: D9 | CK2: D10 | CL2: D11
A3: =CAPTURA!A3 -> 20118578415 | B3: =CAPTURA!C3 -> 0 | C3: =IF(CAPTURA!M3="","",ROUND((ISNUMBER(SEARCH("Alemania",CAPTURA!M3))+ISNUMBER(SEARCH("Bélgica",CAPTURA!M3))+ISNUMBER(SEARCH("Países Bajos",CAPTURA!M3))+ISNUMBER(SEARCH("Francia",CAPTURA!M3))+ISNUMBER(SEARCH("Italia",CAPTURA!M3))+ISNUMBER(SEARCH("España",CAPTURA!M3))+ISNUMBER(SEARCH("Suecia",CAPTURA!M3))+ISNUMBER(SEARCH("Dinamarca",CAPTURA!M3)))/((LEN(CAPTURA!M3)-LEN(SUBSTITUTE(CAPTURA!M3,";","")))+1)*100,1)) | D3: =IF(CAPTURA!AE3="","",IFERROR(IF(INDEX(CODIFICACION!$E$2:$E$500,MATCH("P8|"&CAPTURA!AE3,CODIFICACION!$F$2:$F$500,0))="sin dato","",INDEX(CODIFICACION!$E$2:$E$500,MATCH("P8|"&CAPTURA!AE3,CODIFICACION!$F$2:$F$500,0))),"⚠")) | E3: =IF(CAPTURA!AG3="","",IFERROR(IF(INDEX(CODIFICACION!$E$2:$E$500,MATCH("P10|"&CAPTURA!AG3,CODIFICACION!$F$2:$F$500,0))="sin dato","",INDEX(CODIFICACION!$E$2:$E$500,MATCH("P10|"&CAPTURA!AG3,CODIFICACION!$F$2:$F$500,0))),"⚠")) | F3: =IF(CAPTURA!AJ3="","",IFERROR(IF(INDEX(CODIFICACION!$E$2:$E$500,MATCH("P13|"&CAPTURA!AJ3,CODIFICACION!$F$2:$F$500,0))="sin dato","",INDEX(CODIFICACION!$E$2:$E$500,MATCH("P13|"&CAPTURA!AJ3,CODIFICACION!$F$2:$F$500,0))),"⚠")) | G3: =IF(CAPTURA!AK3="","",IFERROR(IF(INDEX(CODIFICACION!$E$2:$E$500,MATCH("P14|"&CAPTURA!AK3,CODIFICACION!$F$2:$F$500,0))="sin dato","",INDEX(CODIFICACION!$E$2:$E$500,MATCH("P14|"&CAPTURA!AK3,CODIFICACION!$F$2:$F$500,0))),"⚠")) | H3: =IF(CAPTURA!AL3="","",IFERROR(IF(INDEX(CODIFICACION!$E$2:$E$500,MATCH("D1.1|"&CAPTURA!AL3,CODIFICACION!$F$2:$F$500,0))="sin dato","",INDEX(CODIFICACION!$E$2:$E$500,MATCH("D1.1|"&CAPTURA!AL3,CODIFICACION!$F$2:$F$500,0))),"⚠")) | I3: =IF(CAPTURA!AN3="","",IFERROR(IF(INDEX(CODIFICACION!$E$2:$E$500,MATCH("D1.3|"&CAPTURA!AN3,CODIFICACION!$F$2:$F$500,0))="sin dato","",INDEX(CODIFICACION!$E$2:$E$500,MATCH("D1.3|"&CAPTURA!AN3,CODIFICACION!$F$2:$F$500,0))),"⚠")) | J3: =IF(CAPTURA!AO3="","",IFERROR(IF(INDEX(CODIFICACION!$E$2:$E$500,MATCH("D1.4|"&CAPTURA!AO3,CODIFICACION!$F$2:$F$500,0))="sin dato","",INDEX(CODIFICACION!$E$2:$E$500,MATCH("D1.4|"&CAPTURA!AO3,CODIFICACION!$F$2:$F$500,0))),"⚠")) | K3: =IF(CAPTURA!AP3="","",IFERROR(IF(INDEX(CODIFICACION!$E$2:$E$500,MATCH("D1.3a|"&CAPTURA!AP3,CODIFICACION!$F$2:$F$500,0))="sin dato","",INDEX(CODIFICACION!$E$2:$E$500,MATCH("D1.3a|"&CAPTURA!AP3,CODIFICACION!$F$2:$F$500,0))),"⚠")) | L3: =IF(CAPTURA!AQ3="","",IF(AND(ISNUMBER(CAPTURA!AQ3),CAPTURA!AQ3>=0,CAPTURA!AQ3<=4),CAPTURA!AQ3*25,"⚠")) | M3: =IF(CAPTURA!AR3="","",IF(ISNUMBER(CAPTURA!AR3),MAX(0,MIN(100,CAPTURA!AR3)),"⚠")) | N3: =IF(CAPTURA!AS3="","",IF(AND(ISNUMBER(CAPTURA!AS3),CAPTURA!AS3>=0,CAPTURA!AS3<=4),CAPTURA!AS3*25,"⚠")) | O3: =IF(CAPTURA!AT3="","",IFERROR(IF(INDEX(CODIFICACION!$E$2:$E$500,MATCH("D2.8|"&CAPTURA!AT3,CODIFICACION!$F$2:$F$500,0))="sin dato","",INDEX(CODIFICACION!$E$2:$E$500,MATCH("D2.8|"&CAPTURA!AT3,CODIFICACION!$F$2:$F$500,0))),"⚠")) | P3: =IF(CAPTURA!AU3="","",IFERROR(IF(INDEX(CODIFICACION!$E$2:$E$500,MATCH("D2.9|"&CAPTURA!AU3,CODIFICACION!$F$2:$F$500,0))="sin dato","",INDEX(CODIFICACION!$E$2:$E$500,MATCH("D2.9|"&CAPTURA!AU3,CODIFICACION!$F$2:$F$500,0))),"⚠")) | Q3: =IF(CAPTURA!AV3="","",IFERROR(IF(INDEX(CODIFICACION!$E$2:$E$500,MATCH("D2.10|"&CAPTURA!AV3,CODIFICACION!$F$2:$F$500,0))="sin dato","",INDEX(CODIFICACION!$E$2:$E$500,MATCH("D2.10|"&CAPTURA!AV3,CODIFICACION!$F$2:$F$500,0))),"⚠")) | R3: =IF(CAPTURA!AW3="","",IFERROR(IF(INDEX(CODIFICACION!$E$2:$E$500,MATCH("D2.5a|"&CAPTURA!AW3,CODIFICACION!$F$2:$F$500,0))="sin dato","",INDEX(CODIFICACION!$E$2:$E$500,MATCH("D2.5a|"&CAPTURA!AW3,CODIFICACION!$F$2:$F$500,0))),"⚠")) | S3: =IF(CAPTURA!AX3="","",IFERROR(IF(INDEX(CODIFICACION!$E$2:$E$500,MATCH("D2.5b|"&CAPTURA!AX3,CODIFICACION!$F$2:$F$500,0))="sin dato","",INDEX(CODIFICACION!$E$2:$E$500,MATCH("D2.5b|"&CAPTURA!AX3,CODIFICACION!$F$2:$F$500,0))),"⚠")) | T3: =IF(CAPTURA!AY3="","",IF(ISNUMBER(CAPTURA!AY3),MAX(0,MIN(100,CAPTURA!AY3)),"⚠")) | U3: =IF(CAPTURA!AZ3="","",IFERROR(IF(INDEX(CODIFICACION!$E$2:$E$500,MATCH("D3.12|"&CAPTURA!AZ3,CODIFICACION!$F$2:$F$500,0))="sin dato","",INDEX(CODIFICACION!$E$2:$E$500,MATCH("D3.12|"&CAPTURA!AZ3,CODIFICACION!$F$2:$F$500,0))),"⚠")) | V3: =IF(CAPTURA!BA3="","",IF(AND(ISNUMBER(CAPTURA!BA3),CAPTURA!BA3>=0,CAPTURA!BA3<=4),CAPTURA!BA3*25,"⚠")) | W3: =IF(CAPTURA!BB3="","",IFERROR(IF(INDEX(CODIFICACION!$E$2:$E$500,MATCH("D3.14|"&CAPTURA!BB3,CODIFICACION!$F$2:$F$500,0))="sin dato","",INDEX(CODIFICACION!$E$2:$E$500,MATCH("D3.14|"&CAPTURA!BB3,CODIFICACION!$F$2:$F$500,0))),"⚠")) | X3: =IF(CAPTURA!BC3="","",IFERROR(IF(INDEX(CODIFICACION!$E$2:$E$500,MATCH("D3.14a|"&CAPTURA!BC3,CODIFICACION!$F$2:$F$500,0))="sin dato","",INDEX(CODIFICACION!$E$2:$E$500,MATCH("D3.14a|"&CAPTURA!BC3,CODIFICACION!$F$2:$F$500,0))),"⚠")) | Y3: =IF(CAPTURA!BD3="","",IFERROR(IF(INDEX(CODIFICACION!$E$2:$E$500,MATCH("D3.14b|"&CAPTURA!BD3,CODIFICACION!$F$2:$F$500,0))="sin dato","",INDEX(CODIFICACION!$E$2:$E$500,MATCH("D3.14b|"&CAPTURA!BD3,CODIFICACION!$F$2:$F$500,0))),"⚠")) | Z3: =IF(CAPTURA!BE3="","",IFERROR(IF(INDEX(CODIFICACION!$E$2:$E$500,MATCH("D3.14c|"&CAPTURA!BE3,CODIFICACION!$F$2:$F$500,0))="sin dato","",INDEX(CODIFICACION!$E$2:$E$500,MATCH("D3.14c|"&CAPTURA!BE3,CODIFICACION!$F$2:$F$500,0))),"⚠")) | AA3: =IF(CAPTURA!BF3="","",IFERROR(IF(INDEX(CODIFICACION!$E$2:$E$500,MATCH("D3.14d|"&CAPTURA!BF3,CODIFICACION!$F$2:$F$500,0))="sin dato","",INDEX(CODIFICACION!$E$2:$E$500,MATCH("D3.14d|"&CAPTURA!BF3,CODIFICACION!$F$2:$F$500,0))),"⚠")) | AB3: =IF(CAPTURA!BG3="","",IFERROR(IF(INDEX(CODIFICACION!$E$2:$E$500,MATCH("D3.14e|"&CAPTURA!BG3,CODIFICACION!$F$2:$F$500,0))="sin dato","",INDEX(CODIFICACION!$E$2:$E$500,MATCH("D3.14e|"&CAPTURA!BG3,CODIFICACION!$F$2:$F$500,0))),"⚠")) | AC3: =IF(CAPTURA!BH3="","",IFERROR(IF(INDEX(CODIFICACION!$E$2:$E$500,MATCH("D3.14f|"&CAPTURA!BH3,CODIFICACION!$F$2:$F$500,0))="sin dato","",INDEX(CODIFICACION!$E$2:$E$500,MATCH("D3.14f|"&CAPTURA!BH3,CODIFICACION!$F$2:$F$500,0))),"⚠")) | AD3: =IF(CAPTURA!BI3="","",IFERROR(IF(INDEX(CODIFICACION!$E$2:$E$500,MATCH("D3.14g|"&CAPTURA!BI3,CODIFICACION!$F$2:$F$500,0))="sin dato","",INDEX(CODIFICACION!$E$2:$E$500,MATCH("D3.14g|"&CAPTURA!BI3,CODIFICACION!$F$2:$F$500,0))),"⚠")) | AE3: =IF(CAPTURA!BJ3="","",IFERROR(IF(INDEX(CODIFICACION!$E$2:$E$500,MATCH("D3.14h|"&CAPTURA!BJ3,CODIFICACION!$F$2:$F$500,0))="sin dato","",INDEX(CODIFICACION!$E$2:$E$500,MATCH("D3.14h|"&CAPTURA!BJ3,CODIFICACION!$F$2:$F$500,0))),"⚠")) | AF3: =IF(CAPTURA!BK3="","",IFERROR(IF(INDEX(CODIFICACION!$E$2:$E$500,MATCH("D3.14i|"&CAPTURA!BK3,CODIFICACION!$F$2:$F$500,0))="sin dato","",INDEX(CODIFICACION!$E$2:$E$500,MATCH("D3.14i|"&CAPTURA!BK3,CODIFICACION!$F$2:$F$500,0))),"⚠")) | AG3: =IF(CAPTURA!BL3="","",IFERROR(IF(INDEX(CODIFICACION!$E$2:$E$500,MATCH("D4.15|"&CAPTURA!BL3,CODIFICACION!$F$2:$F$500,0))="sin dato","",INDEX(CODIFICACION!$E$2:$E$500,MATCH("D4.15|"&CAPTURA!BL3,CODIFICACION!$F$2:$F$500,0))),"⚠")) | AH3: =IF(CAPTURA!BM3="","",IF(AND(ISNUMBER(CAPTURA!BM3),CAPTURA!BM3>=0,CAPTURA!BM3<=4),CAPTURA!BM3*25,"⚠")) | AI3: =IF(CAPTURA!BN3="","",IFERROR(IF(INDEX(CODIFICACION!$E$2:$E$500,MATCH("D4.17|"&CAPTURA!BN3,CODIFICACION!$F$2:$F$500,0))="sin dato","",INDEX(CODIFICACION!$E$2:$E$500,MATCH("D4.17|"&CAPTURA!BN3,CODIFICACION!$F$2:$F$500,0))),"⚠")) | AJ3: =IF(CAPTURA!BO3="","",IFERROR(IF(INDEX(CODIFICACION!$E$2:$E$500,MATCH("D4.15a|"&CAPTURA!BO3,CODIFICACION!$F$2:$F$500,0))="sin dato","",INDEX(CODIFICACION!$E$2:$E$500,MATCH("D4.15a|"&CAPTURA!BO3,CODIFICACION!$F$2:$F$500,0))),"⚠")) | AK3: =IF(CAPTURA!BP3="","",IF(AND(ISNUMBER(CAPTURA!BP3),CAPTURA!BP3>=0,CAPTURA!BP3<=4),CAPTURA!BP3*25,"⚠")) | AL3: =IF(CAPTURA!BQ3="","",IF(AND(ISNUMBER(CAPTURA!BQ3),CAPTURA!BQ3>=0,CAPTURA!BQ3<=4),CAPTURA!BQ3*25,"⚠")) | AM3: =IF(CAPTURA!BR3="","",IFERROR(IF(INDEX(CODIFICACION!$E$2:$E$500,MATCH("D5.18b|"&CAPTURA!BR3,CODIFICACION!$F$2:$F$500,0))="sin dato","",INDEX(CODIFICACION!$E$2:$E$500,MATCH("D5.18b|"&CAPTURA!BR3,CODIFICACION!$F$2:$F$500,0))),"⚠")) | AN3: =IF(CAPTURA!BS3="","",IFERROR(IF(INDEX(CODIFICACION!$E$2:$E$500,MATCH("D5.19|"&CAPTURA!BS3,CODIFICACION!$F$2:$F$500,0))="sin dato","",INDEX(CODIFICACION!$E$2:$E$500,MATCH("D5.19|"&CAPTURA!BS3,CODIFICACION!$F$2:$F$500,0))),"⚠")) | AO3: =IF(CAPTURA!BT3="","",MIN(100,ROUND((LEN(CAPTURA!BT3)-LEN(SUBSTITUTE(CAPTURA!BT3,";",""))+1)/7*100,1))) | AP3: =IF(CAPTURA!BU3="","",IFERROR(IF(INDEX(CODIFICACION!$E$2:$E$500,MATCH("D5.20|"&CAPTURA!BU3,CODIFICACION!$F$2:$F$500,0))="sin dato","",INDEX(CODIFICACION!$E$2:$E$500,MATCH("D5.20|"&CAPTURA!BU3,CODIFICACION!$F$2:$F$500,0))),"⚠")) | AQ3: =IF(CAPTURA!BV3="","",IFERROR(IF(INDEX(CODIFICACION!$E$2:$E$500,MATCH("D5.21|"&CAPTURA!BV3,CODIFICACION!$F$2:$F$500,0))="sin dato","",INDEX(CODIFICACION!$E$2:$E$500,MATCH("D5.21|"&CAPTURA!BV3,CODIFICACION!$F$2:$F$500,0))),"⚠")) | AR3: =IF(CAPTURA!BW3="","",IFERROR(IF(INDEX(CODIFICACION!$E$2:$E$500,MATCH("D5.21a|"&CAPTURA!BW3,CODIFICACION!$F$2:$F$500,0))="sin dato","",INDEX(CODIFICACION!$E$2:$E$500,MATCH("D5.21a|"&CAPTURA!BW3,CODIFICACION!$F$2:$F$500,0))),"⚠")) | AS3: =IF(CAPTURA!BX3="","",IFERROR(IF(INDEX(CODIFICACION!$E$2:$E$500,MATCH("D5.21b|"&CAPTURA!BX3,CODIFICACION!$F$2:$F$500,0))="sin dato","",INDEX(CODIFICACION!$E$2:$E$500,MATCH("D5.21b|"&CAPTURA!BX3,CODIFICACION!$F$2:$F$500,0))),"⚠")) | AT3: =IF(CAPTURA!BY3="","",IFERROR(IF(INDEX(CODIFICACION!$E$2:$E$500,MATCH("D6.22|"&CAPTURA!BY3,CODIFICACION!$F$2:$F$500,0))="sin dato","",INDEX(CODIFICACION!$E$2:$E$500,MATCH("D6.22|"&CAPTURA!BY3,CODIFICACION!$F$2:$F$500,0))),"⚠")) | AU3: =IF(CAPTURA!BZ3="","",IFERROR(IF(INDEX(CODIFICACION!$E$2:$E$500,MATCH("D6.22a|"&CAPTURA!BZ3,CODIFICACION!$F$2:$F$500,0))="sin dato","",INDEX(CODIFICACION!$E$2:$E$500,MATCH("D6.22a|"&CAPTURA!BZ3,CODIFICACION!$F$2:$F$500,0))),"⚠")) | AV3: =IF(CAPTURA!CA3="","",IFERROR(IF(INDEX(CODIFICACION!$E$2:$E$500,MATCH("D6.22b|"&CAPTURA!CA3,CODIFICACION!$F$2:$F$500,0))="sin dato","",INDEX(CODIFICACION!$E$2:$E$500,MATCH("D6.22b|"&CAPTURA!CA3,CODIFICACION!$F$2:$F$500,0))),"⚠")) | AW3: =IF(CAPTURA!CB3="","",IFERROR(IF(INDEX(CODIFICACION!$E$2:$E$500,MATCH("D6.23|"&CAPTURA!CB3,CODIFICACION!$F$2:$F$500,0))="sin dato","",INDEX(CODIFICACION!$E$2:$E$500,MATCH("D6.23|"&CAPTURA!CB3,CODIFICACION!$F$2:$F$500,0))),"⚠")) | AX3: =IF(CAPTURA!CC3="","",IFERROR(IF(INDEX(CODIFICACION!$E$2:$E$500,MATCH("D6.24|"&CAPTURA!CC3,CODIFICACION!$F$2:$F$500,0))="sin dato","",INDEX(CODIFICACION!$E$2:$E$500,MATCH("D6.24|"&CAPTURA!CC3,CODIFICACION!$F$2:$F$500,0))),"⚠")) | AY3: =IF(CAPTURA!CD3="","",IFERROR(IF(INDEX(CODIFICACION!$E$2:$E$500,MATCH("D6.25|"&CAPTURA!CD3,CODIFICACION!$F$2:$F$500,0))="sin dato","",INDEX(CODIFICACION!$E$2:$E$500,MATCH("D6.25|"&CAPTURA!CD3,CODIFICACION!$F$2:$F$500,0))),"⚠")) | AZ3: =IF(CAPTURA!CE3="","",IFERROR(IF(INDEX(CODIFICACION!$E$2:$E$500,MATCH("D6.25a|"&CAPTURA!CE3,CODIFICACION!$F$2:$F$500,0))="sin dato","",INDEX(CODIFICACION!$E$2:$E$500,MATCH("D6.25a|"&CAPTURA!CE3,CODIFICACION!$F$2:$F$500,0))),"⚠")) | BA3: =IF(CAPTURA!CF3="","",IFERROR(IF(INDEX(CODIFICACION!$E$2:$E$500,MATCH("D6.25b|"&CAPTURA!CF3,CODIFICACION!$F$2:$F$500,0))="sin dato","",INDEX(CODIFICACION!$E$2:$E$500,MATCH("D6.25b|"&CAPTURA!CF3,CODIFICACION!$F$2:$F$500,0))),"⚠")) | BB3: =IF(CAPTURA!CG3="","",IFERROR(IF(INDEX(CODIFICACION!$E$2:$E$500,MATCH("D6.22c|"&CAPTURA!CG3,CODIFICACION!$F$2:$F$500,0))="sin dato","",INDEX(CODIFICACION!$E$2:$E$500,MATCH("D6.22c|"&CAPTURA!CG3,CODIFICACION!$F$2:$F$500,0))),"⚠")) | BC3: =IF(CAPTURA!CH3="","",IFERROR(IF(INDEX(CODIFICACION!$E$2:$E$500,MATCH("D7.26|"&CAPTURA!CH3,CODIFICACION!$F$2:$F$500,0))="sin dato","",INDEX(CODIFICACION!$E$2:$E$500,MATCH("D7.26|"&CAPTURA!CH3,CODIFICACION!$F$2:$F$500,0))),"⚠")) | BD3: =IF(CAPTURA!CI3="","",IFERROR(IF(INDEX(CODIFICACION!$E$2:$E$500,MATCH("D7.27|"&CAPTURA!CI3,CODIFICACION!$F$2:$F$500,0))="sin dato","",INDEX(CODIFICACION!$E$2:$E$500,MATCH("D7.27|"&CAPTURA!CI3,CODIFICACION!$F$2:$F$500,0))),"⚠")) | BE3: =IF(CAPTURA!CJ3="","",IFERROR(IF(INDEX(CODIFICACION!$E$2:$E$500,MATCH("D7.28|"&CAPTURA!CJ3,CODIFICACION!$F$2:$F$500,0))="sin dato","",INDEX(CODIFICACION!$E$2:$E$500,MATCH("D7.28|"&CAPTURA!CJ3,CODIFICACION!$F$2:$F$500,0))),"⚠")) | BF3: =IF(CAPTURA!CK3="","",IFERROR(IF(INDEX(CODIFICACION!$E$2:$E$500,MATCH("D7.28b|"&CAPTURA!CK3,CODIFICACION!$F$2:$F$500,0))="sin dato","",INDEX(CODIFICACION!$E$2:$E$500,MATCH("D7.28b|"&CAPTURA!CK3,CODIFICACION!$F$2:$F$500,0))),"⚠")) | BG3: =IF(CAPTURA!CL3="","",MIN(100,ROUND((LEN(CAPTURA!CL3)-LEN(SUBSTITUTE(CAPTURA!CL3,";",""))+1)/8*100,1))) | BH3: =IF(CAPTURA!CM3="","",IFERROR(IF(INDEX(CODIFICACION!$E$2:$E$500,MATCH("D7.26a|"&CAPTURA!CM3,CODIFICACION!$F$2:$F$500,0))="sin dato","",INDEX(CODIFICACION!$E$2:$E$500,MATCH("D7.26a|"&CAPTURA!CM3,CODIFICACION!$F$2:$F$500,0))),"⚠")) | BI3: =IF(CAPTURA!CN3="","",IFERROR(IF(INDEX(CODIFICACION!$E$2:$E$500,MATCH("D7.26b|"&CAPTURA!CN3,CODIFICACION!$F$2:$F$500,0))="sin dato","",INDEX(CODIFICACION!$E$2:$E$500,MATCH("D7.26b|"&CAPTURA!CN3,CODIFICACION!$F$2:$F$500,0))),"⚠")) | BJ3: =IF(CAPTURA!CO3="","",IF(AND(ISNUMBER(CAPTURA!CO3),CAPTURA!CO3>=0,CAPTURA!CO3<=4),CAPTURA!CO3*25,"⚠")) | BK3: =IF(CAPTURA!CP3="","",IF(ISNUMBER(CAPTURA!CP3),MAX(0,MIN(100,CAPTURA!CP3)),"⚠")) | BL3: =IF(CAPTURA!CQ3="","",IFERROR(IF(INDEX(CODIFICACION!$E$2:$E$500,MATCH("D8.31|"&CAPTURA!CQ3,CODIFICACION!$F$2:$F$500,0))="sin dato","",INDEX(CODIFICACION!$E$2:$E$500,MATCH("D8.31|"&CAPTURA!CQ3,CODIFICACION!$F$2:$F$500,0))),"⚠")) | BM3: =IF(CAPTURA!CR3="","",IFERROR(IF(INDEX(CODIFICACION!$E$2:$E$500,MATCH("D8.32|"&CAPTURA!CR3,CODIFICACION!$F$2:$F$500,0))="sin dato","",INDEX(CODIFICACION!$E$2:$E$500,MATCH("D8.32|"&CAPTURA!CR3,CODIFICACION!$F$2:$F$500,0))),"⚠")) | BN3: =IF(CAPTURA!CS3="","",IFERROR(IF(INDEX(CODIFICACION!$E$2:$E$500,MATCH("D9.33|"&CAPTURA!CS3,CODIFICACION!$F$2:$F$500,0))="sin dato","",INDEX(CODIFICACION!$E$2:$E$500,MATCH("D9.33|"&CAPTURA!CS3,CODIFICACION!$F$2:$F$500,0))),"⚠")) | BO3: =IF(CAPTURA!CT3="","",IFERROR(IF(INDEX(CODIFICACION!$E$2:$E$500,MATCH("D9.34|"&CAPTURA!CT3,CODIFICACION!$F$2:$F$500,0))="sin dato","",INDEX(CODIFICACION!$E$2:$E$500,MATCH("D9.34|"&CAPTURA!CT3,CODIFICACION!$F$2:$F$500,0))),"⚠")) | BP3: =IF(CAPTURA!CU3="","",IFERROR(IF(INDEX(CODIFICACION!$E$2:$E$500,MATCH("D9.35|"&CAPTURA!CU3,CODIFICACION!$F$2:$F$500,0))="sin dato","",INDEX(CODIFICACION!$E$2:$E$500,MATCH("D9.35|"&CAPTURA!CU3,CODIFICACION!$F$2:$F$500,0))),"⚠")) | BQ3: =IF(CAPTURA!CV3="","",IFERROR(IF(INDEX(CODIFICACION!$E$2:$E$500,MATCH("D10.36|"&CAPTURA!CV3,CODIFICACION!$F$2:$F$500,0))="sin dato","",INDEX(CODIFICACION!$E$2:$E$500,MATCH("D10.36|"&CAPTURA!CV3,CODIFICACION!$F$2:$F$500,0))),"⚠")) | BR3: =IF(CAPTURA!CW3="","",IFERROR(IF(INDEX(CODIFICACION!$E$2:$E$500,MATCH("D10.37|"&CAPTURA!CW3,CODIFICACION!$F$2:$F$500,0))="sin dato","",INDEX(CODIFICACION!$E$2:$E$500,MATCH("D10.37|"&CAPTURA!CW3,CODIFICACION!$F$2:$F$500,0))),"⚠")) | BS3: =IF(CAPTURA!CX3="","",IFERROR(IF(INDEX(CODIFICACION!$E$2:$E$500,MATCH("D10.36a|"&CAPTURA!CX3,CODIFICACION!$F$2:$F$500,0))="sin dato","",INDEX(CODIFICACION!$E$2:$E$500,MATCH("D10.36a|"&CAPTURA!CX3,CODIFICACION!$F$2:$F$500,0))),"⚠")) | BT3: =IF(CAPTURA!CY3="","",IF(ISNUMBER(SEARCH("Ninguno",CAPTURA!CY3)),0,MIN(100,ROUND((LEN(CAPTURA!CY3)-LEN(SUBSTITUTE(CAPTURA!CY3,";",""))+1)/6*100,1)))) | BU3: =IF(CAPTURA!DA3="","",IFERROR(IF(INDEX(CODIFICACION!$E$2:$E$500,MATCH("D11.39a|"&CAPTURA!DA3,CODIFICACION!$F$2:$F$500,0))="sin dato","",INDEX(CODIFICACION!$E$2:$E$500,MATCH("D11.39a|"&CAPTURA!DA3,CODIFICACION!$F$2:$F$500,0))),"⚠")) | BV3: =IF(CAPTURA!DB3="","",IFERROR(IF(INDEX(CODIFICACION!$E$2:$E$500,MATCH("D12.42|"&CAPTURA!DB3,CODIFICACION!$F$2:$F$500,0))="sin dato","",INDEX(CODIFICACION!$E$2:$E$500,MATCH("D12.42|"&CAPTURA!DB3,CODIFICACION!$F$2:$F$500,0))),"⚠")) | BW3: =IF(CAPTURA!DC3="","",IFERROR(IF(INDEX(CODIFICACION!$E$2:$E$500,MATCH("D13.45|"&CAPTURA!DC3,CODIFICACION!$F$2:$F$500,0))="sin dato","",INDEX(CODIFICACION!$E$2:$E$500,MATCH("D13.45|"&CAPTURA!DC3,CODIFICACION!$F$2:$F$500,0))),"⚠")) | BX3: =IF(CAPTURA!DD3="","",IFERROR(IF(INDEX(CODIFICACION!$E$2:$E$500,MATCH("D14.51|"&CAPTURA!DD3,CODIFICACION!$F$2:$F$500,0))="sin dato","",INDEX(CODIFICACION!$E$2:$E$500,MATCH("D14.51|"&CAPTURA!DD3,CODIFICACION!$F$2:$F$500,0))),"⚠")) | BY3: =IF(CAPTURA!DE3="","",IFERROR(IF(INDEX(CODIFICACION!$E$2:$E$500,MATCH("D15.58|"&CAPTURA!DE3,CODIFICACION!$F$2:$F$500,0))="sin dato","",INDEX(CODIFICACION!$E$2:$E$500,MATCH("D15.58|"&CAPTURA!DE3,CODIFICACION!$F$2:$F$500,0))),"⚠")) | BZ3: =IF(CAPTURA!DF3="","",IFERROR(IF(INDEX(CODIFICACION!$E$2:$E$500,MATCH("PP1|"&CAPTURA!DF3,CODIFICACION!$F$2:$F$500,0))="sin dato","",INDEX(CODIFICACION!$E$2:$E$500,MATCH("PP1|"&CAPTURA!DF3,CODIFICACION!$F$2:$F$500,0))),"⚠")) | CA3: =IF(CAPTURA!DG3="","",IFERROR(IF(INDEX(CODIFICACION!$E$2:$E$500,MATCH("PP2|"&CAPTURA!DG3,CODIFICACION!$F$2:$F$500,0))="sin dato","",INDEX(CODIFICACION!$E$2:$E$500,MATCH("PP2|"&CAPTURA!DG3,CODIFICACION!$F$2:$F$500,0))),"⚠")) | CB3: =IFERROR(AVERAGE(H3,I3,J3,K3),"") | CC3: =IFERROR(AVERAGE(L3,M3,N3,O3,P3,R3),"") | CD3: =IFERROR(AVERAGE(T3,U3,V3,W3,X3,Y3,Z3,AA3,AB3,AC3,AE3),"") | CE3: =IFERROR(AVERAGE(AG3,AH3,AI3),"") | CF3: =IFERROR(AVERAGE(AK3,AL3,AM3,AN3,AP3,AQ3,AR3,AS3),"") | CG3: =IFERROR(AVERAGE(AT3,AU3,AV3,BB3,AW3,AX3,AY3,AZ3,BA3),"") | CH3: =IFERROR(AVERAGE(BC3,BH3,BI3,BD3,BF3),"") | CI3: =IFERROR(AVERAGE(BJ3,BK3,BL3,BM3),"") | CJ3: =IFERROR(AVERAGE(BN3,BO3,BP3),"") | CK3: ="" | CL3: =""
A4: =CAPTURA!A4 -> 20129156083 | B4: =CAPTURA!C4 -> 0 | C4: =IF(CAPTURA!M4="","",ROUND((ISNUMBER(SEARCH("Alemania",CAPTURA!M4))+ISNUMBER(SEARCH("Bélgica",CAPTURA!M4))+ISNUMBER(SEARCH("Países Bajos",CAPTURA!M4))+ISNUMBER(SEARCH("Francia",CAPTURA!M4))+ISNUMBER(SEARCH("Italia",CAPTURA!M4))+ISNUMBER(SEARCH("España",CAPTURA!M4))+ISNUMBER(SEARCH("Suecia",CAPTURA!M4))+ISNUMBER(SEARCH("Dinamarca",CAPTURA!M4)))/((LEN(CAPTURA!M4)-LEN(SUBSTITUTE(CAPTURA!M4,";","")))+1)*100,1)) | D4: =IF(CAPTURA!AE4="","",IFERROR(IF(INDEX(CODIFICACION!$E$2:$E$500,MATCH("P8|"&CAPTURA!AE4,CODIFICACION!$F$2:$F$500,0))="sin dato","",INDEX(CODIFICACION!$E$2:$E$500,MATCH("P8|"&CAPTURA!AE4,CODIFICACION!$F$2:$F$500,0))),"⚠")) | E4: =IF(CAPTURA!AG4="","",IFERROR(IF(INDEX(CODIFICACION!$E$2:$E$500,MATCH("P10|"&CAPTURA!AG4,CODIFICACION!$F$2:$F$500,0))="sin dato","",INDEX(CODIFICACION!$E$2:$E$500,MATCH("P10|"&CAPTURA!AG4,CODIFICACION!$F$2:$F$500,0))),"⚠")) | F4: =IF(CAPTURA!AJ4="","",IFERROR(IF(INDEX(CODIFICACION!$E$2:$E$500,MATCH("P13|"&CAPTURA!AJ4,CODIFICACION!$F$2:$F$500,0))="sin dato","",INDEX(CODIFICACION!$E$2:$E$500,MATCH("P13|"&CAPTURA!AJ4,CODIFICACION!$F$2:$F$500,0))),"⚠")) | G4: =IF(CAPTURA!AK4="","",IFERROR(IF(INDEX(CODIFICACION!$E$2:$E$500,MATCH("P14|"&CAPTURA!AK4,CODIFICACION!$F$2:$F$500,0))="sin dato","",INDEX(CODIFICACION!$E$2:$E$500,MATCH("P14|"&CAPTURA!AK4,CODIFICACION!$F$2:$F$500,0))),"⚠")) | H4: =IF(CAPTURA!AL4="","",IFERROR(IF(INDEX(CODIFICACION!$E$2:$E$500,MATCH("D1.1|"&CAPTURA!AL4,CODIFICACION!$F$2:$F$500,0))="sin dato","",INDEX(CODIFICACION!$E$2:$E$500,MATCH("D1.1|"&CAPTURA!AL4,CODIFICACION!$F$2:$F$500,0))),"⚠")) | I4: =IF(CAPTURA!AN4="","",IFERROR(IF(INDEX(CODIFICACION!$E$2:$E$500,MATCH("D1.3|"&CAPTURA!AN4,CODIFICACION!$F$2:$F$500,0))="sin dato","",INDEX(CODIFICACION!$E$2:$E$500,MATCH("D1.3|"&CAPTURA!AN4,CODIFICACION!$F$2:$F$500,0))),"⚠")) | J4: =IF(CAPTURA!AO4="","",IFERROR(IF(INDEX(CODIFICACION!$E$2:$E$500,MATCH("D1.4|"&CAPTURA!AO4,CODIFICACION!$F$2:$F$500,0))="sin dato","",INDEX(CODIFICACION!$E$2:$E$500,MATCH("D1.4|"&CAPTURA!AO4,CODIFICACION!$F$2:$F$500,0))),"⚠")) | K4: =IF(CAPTURA!AP4="","",IFERROR(IF(INDEX(CODIFICACION!$E$2:$E$500,MATCH("D1.3a|"&CAPTURA!AP4,CODIFICACION!$F$2:$F$500,0))="sin dato","",INDEX(CODIFICACION!$E$2:$E$500,MATCH("D1.3a|"&CAPTURA!AP4,CODIFICACION!$F$2:$F$500,0))),"⚠")) | L4: =IF(CAPTURA!AQ4="","",IF(AND(ISNUMBER(CAPTURA!AQ4),CAPTURA!AQ4>=0,CAPTURA!AQ4<=4),CAPTURA!AQ4*25,"⚠")) | M4: =IF(CAPTURA!AR4="","",IF(ISNUMBER(CAPTURA!AR4),MAX(0,MIN(100,CAPTURA!AR4)),"⚠")) | N4: =IF(CAPTURA!AS4="","",IF(AND(ISNUMBER(CAPTURA!AS4),CAPTURA!AS4>=0,CAPTURA!AS4<=4),CAPTURA!AS4*25,"⚠")) | O4: =IF(CAPTURA!AT4="","",IFERROR(IF(INDEX(CODIFICACION!$E$2:$E$500,MATCH("D2.8|"&CAPTURA!AT4,CODIFICACION!$F$2:$F$500,0))="sin dato","",INDEX(CODIFICACION!$E$2:$E$500,MATCH("D2.8|"&CAPTURA!AT4,CODIFICACION!$F$2:$F$500,0))),"⚠")) | P4: =IF(CAPTURA!AU4="","",IFERROR(IF(INDEX(CODIFICACION!$E$2:$E$500,MATCH("D2.9|"&CAPTURA!AU4,CODIFICACION!$F$2:$F$500,0))="sin dato","",INDEX(CODIFICACION!$E$2:$E$500,MATCH("D2.9|"&CAPTURA!AU4,CODIFICACION!$F$2:$F$500,0))),"⚠")) | Q4: =IF(CAPTURA!AV4="","",IFERROR(IF(INDEX(CODIFICACION!$E$2:$E$500,MATCH("D2.10|"&CAPTURA!AV4,CODIFICACION!$F$2:$F$500,0))="sin dato","",INDEX(CODIFICACION!$E$2:$E$500,MATCH("D2.10|"&CAPTURA!AV4,CODIFICACION!$F$2:$F$500,0))),"⚠")) | R4: =IF(CAPTURA!AW4="","",IFERROR(IF(INDEX(CODIFICACION!$E$2:$E$500,MATCH("D2.5a|"&CAPTURA!AW4,CODIFICACION!$F$2:$F$500,0))="sin dato","",INDEX(CODIFICACION!$E$2:$E$500,MATCH("D2.5a|"&CAPTURA!AW4,CODIFICACION!$F$2:$F$500,0))),"⚠")) | S4: =IF(CAPTURA!AX4="","",IFERROR(IF(INDEX(CODIFICACION!$E$2:$E$500,MATCH("D2.5b|"&CAPTURA!AX4,CODIFICACION!$F$2:$F$500,0))="sin dato","",INDEX(CODIFICACION!$E$2:$E$500,MATCH("D2.5b|"&CAPTURA!AX4,CODIFICACION!$F$2:$F$500,0))),"⚠")) | T4: =IF(CAPTURA!AY4="","",IF(ISNUMBER(CAPTURA!AY4),MAX(0,MIN(100,CAPTURA!AY4)),"⚠")) | U4: =IF(CAPTURA!AZ4="","",IFERROR(IF(INDEX(CODIFICACION!$E$2:$E$500,MATCH("D3.12|"&CAPTURA!AZ4,CODIFICACION!$F$2:$F$500,0))="sin dato","",INDEX(CODIFICACION!$E$2:$E$500,MATCH("D3.12|"&CAPTURA!AZ4,CODIFICACION!$F$2:$F$500,0))),"⚠")) | V4: =IF(CAPTURA!BA4="","",IF(AND(ISNUMBER(CAPTURA!BA4),CAPTURA!BA4>=0,CAPTURA!BA4<=4),CAPTURA!BA4*25,"⚠")) | W4: =IF(CAPTURA!BB4="","",IFERROR(IF(INDEX(CODIFICACION!$E$2:$E$500,MATCH("D3.14|"&CAPTURA!BB4,CODIFICACION!$F$2:$F$500,0))="sin dato","",INDEX(CODIFICACION!$E$2:$E$500,MATCH("D3.14|"&CAPTURA!BB4,CODIFICACION!$F$2:$F$500,0))),"⚠")) | X4: =IF(CAPTURA!BC4="","",IFERROR(IF(INDEX(CODIFICACION!$E$2:$E$500,MATCH("D3.14a|"&CAPTURA!BC4,CODIFICACION!$F$2:$F$500,0))="sin dato","",INDEX(CODIFICACION!$E$2:$E$500,MATCH("D3.14a|"&CAPTURA!BC4,CODIFICACION!$F$2:$F$500,0))),"⚠")) | Y4: =IF(CAPTURA!BD4="","",IFERROR(IF(INDEX(CODIFICACION!$E$2:$E$500,MATCH("D3.14b|"&CAPTURA!BD4,CODIFICACION!$F$2:$F$500,0))="sin dato","",INDEX(CODIFICACION!$E$2:$E$500,MATCH("D3.14b|"&CAPTURA!BD4,CODIFICACION!$F$2:$F$500,0))),"⚠")) | Z4: =IF(CAPTURA!BE4="","",IFERROR(IF(INDEX(CODIFICACION!$E$2:$E$500,MATCH("D3.14c|"&CAPTURA!BE4,CODIFICACION!$F$2:$F$500,0))="sin dato","",INDEX(CODIFICACION!$E$2:$E$500,MATCH("D3.14c|"&CAPTURA!BE4,CODIFICACION!$F$2:$F$500,0))),"⚠")) | AA4: =IF(CAPTURA!BF4="","",IFERROR(IF(INDEX(CODIFICACION!$E$2:$E$500,MATCH("D3.14d|"&CAPTURA!BF4,CODIFICACION!$F$2:$F$500,0))="sin dato","",INDEX(CODIFICACION!$E$2:$E$500,MATCH("D3.14d|"&CAPTURA!BF4,CODIFICACION!$F$2:$F$500,0))),"⚠")) | AB4: =IF(CAPTURA!BG4="","",IFERROR(IF(INDEX(CODIFICACION!$E$2:$E$500,MATCH("D3.14e|"&CAPTURA!BG4,CODIFICACION!$F$2:$F$500,0))="sin dato","",INDEX(CODIFICACION!$E$2:$E$500,MATCH("D3.14e|"&CAPTURA!BG4,CODIFICACION!$F$2:$F$500,0))),"⚠")) | AC4: =IF(CAPTURA!BH4="","",IFERROR(IF(INDEX(CODIFICACION!$E$2:$E$500,MATCH("D3.14f|"&CAPTURA!BH4,CODIFICACION!$F$2:$F$500,0))="sin dato","",INDEX(CODIFICACION!$E$2:$E$500,MATCH("D3.14f|"&CAPTURA!BH4,CODIFICACION!$F$2:$F$500,0))),"⚠")) | AD4: =IF(CAPTURA!BI4="","",IFERROR(IF(INDEX(CODIFICACION!$E$2:$E$500,MATCH("D3.14g|"&CAPTURA!BI4,CODIFICACION!$F$2:$F$500,0))="sin dato","",INDEX(CODIFICACION!$E$2:$E$500,MATCH("D3.14g|"&CAPTURA!BI4,CODIFICACION!$F$2:$F$500,0))),"⚠")) | AE4: =IF(CAPTURA!BJ4="","",IFERROR(IF(INDEX(CODIFICACION!$E$2:$E$500,MATCH("D3.14h|"&CAPTURA!BJ4,CODIFICACION!$F$2:$F$500,0))="sin dato","",INDEX(CODIFICACION!$E$2:$E$500,MATCH("D3.14h|"&CAPTURA!BJ4,CODIFICACION!$F$2:$F$500,0))),"⚠")) | AF4: =IF(CAPTURA!BK4="","",IFERROR(IF(INDEX(CODIFICACION!$E$2:$E$500,MATCH("D3.14i|"&CAPTURA!BK4,CODIFICACION!$F$2:$F$500,0))="sin dato","",INDEX(CODIFICACION!$E$2:$E$500,MATCH("D3.14i|"&CAPTURA!BK4,CODIFICACION!$F$2:$F$500,0))),"⚠")) | AG4: =IF(CAPTURA!BL4="","",IFERROR(IF(INDEX(CODIFICACION!$E$2:$E$500,MATCH("D4.15|"&CAPTURA!BL4,CODIFICACION!$F$2:$F$500,0))="sin dato","",INDEX(CODIFICACION!$E$2:$E$500,MATCH("D4.15|"&CAPTURA!BL4,CODIFICACION!$F$2:$F$500,0))),"⚠")) | AH4: =IF(CAPTURA!BM4="","",IF(AND(ISNUMBER(CAPTURA!BM4),CAPTURA!BM4>=0,CAPTURA!BM4<=4),CAPTURA!BM4*25,"⚠")) | AI4: =IF(CAPTURA!BN4="","",IFERROR(IF(INDEX(CODIFICACION!$E$2:$E$500,MATCH("D4.17|"&CAPTURA!BN4,CODIFICACION!$F$2:$F$500,0))="sin dato","",INDEX(CODIFICACION!$E$2:$E$500,MATCH("D4.17|"&CAPTURA!BN4,CODIFICACION!$F$2:$F$500,0))),"⚠")) | AJ4: =IF(CAPTURA!BO4="","",IFERROR(IF(INDEX(CODIFICACION!$E$2:$E$500,MATCH("D4.15a|"&CAPTURA!BO4,CODIFICACION!$F$2:$F$500,0))="sin dato","",INDEX(CODIFICACION!$E$2:$E$500,MATCH("D4.15a|"&CAPTURA!BO4,CODIFICACION!$F$2:$F$500,0))),"⚠")) | AK4: =IF(CAPTURA!BP4="","",IF(AND(ISNUMBER(CAPTURA!BP4),CAPTURA!BP4>=0,CAPTURA!BP4<=4),CAPTURA!BP4*25,"⚠")) | AL4: =IF(CAPTURA!BQ4="","",IF(AND(ISNUMBER(CAPTURA!BQ4),CAPTURA!BQ4>=0,CAPTURA!BQ4<=4),CAPTURA!BQ4*25,"⚠")) | AM4: =IF(CAPTURA!BR4="","",IFERROR(IF(INDEX(CODIFICACION!$E$2:$E$500,MATCH("D5.18b|"&CAPTURA!BR4,CODIFICACION!$F$2:$F$500,0))="sin dato","",INDEX(CODIFICACION!$E$2:$E$500,MATCH("D5.18b|"&CAPTURA!BR4,CODIFICACION!$F$2:$F$500,0))),"⚠")) | AN4: =IF(CAPTURA!BS4="","",IFERROR(IF(INDEX(CODIFICACION!$E$2:$E$500,MATCH("D5.19|"&CAPTURA!BS4,CODIFICACION!$F$2:$F$500,0))="sin dato","",INDEX(CODIFICACION!$E$2:$E$500,MATCH("D5.19|"&CAPTURA!BS4,CODIFICACION!$F$2:$F$500,0))),"⚠")) | AO4: =IF(CAPTURA!BT4="","",MIN(100,ROUND((LEN(CAPTURA!BT4)-LEN(SUBSTITUTE(CAPTURA!BT4,";",""))+1)/7*100,1))) | AP4: =IF(CAPTURA!BU4="","",IFERROR(IF(INDEX(CODIFICACION!$E$2:$E$500,MATCH("D5.20|"&CAPTURA!BU4,CODIFICACION!$F$2:$F$500,0))="sin dato","",INDEX(CODIFICACION!$E$2:$E$500,MATCH("D5.20|"&CAPTURA!BU4,CODIFICACION!$F$2:$F$500,0))),"⚠")) | AQ4: =IF(CAPTURA!BV4="","",IFERROR(IF(INDEX(CODIFICACION!$E$2:$E$500,MATCH("D5.21|"&CAPTURA!BV4,CODIFICACION!$F$2:$F$500,0))="sin dato","",INDEX(CODIFICACION!$E$2:$E$500,MATCH("D5.21|"&CAPTURA!BV4,CODIFICACION!$F$2:$F$500,0))),"⚠")) | AR4: =IF(CAPTURA!BW4="","",IFERROR(IF(INDEX(CODIFICACION!$E$2:$E$500,MATCH("D5.21a|"&CAPTURA!BW4,CODIFICACION!$F$2:$F$500,0))="sin dato","",INDEX(CODIFICACION!$E$2:$E$500,MATCH("D5.21a|"&CAPTURA!BW4,CODIFICACION!$F$2:$F$500,0))),"⚠")) | AS4: =IF(CAPTURA!BX4="","",IFERROR(IF(INDEX(CODIFICACION!$E$2:$E$500,MATCH("D5.21b|"&CAPTURA!BX4,CODIFICACION!$F$2:$F$500,0))="sin dato","",INDEX(CODIFICACION!$E$2:$E$500,MATCH("D5.21b|"&CAPTURA!BX4,CODIFICACION!$F$2:$F$500,0))),"⚠")) | AT4: =IF(CAPTURA!BY4="","",IFERROR(IF(INDEX(CODIFICACION!$E$2:$E$500,MATCH("D6.22|"&CAPTURA!BY4,CODIFICACION!$F$2:$F$500,0))="sin dato","",INDEX(CODIFICACION!$E$2:$E$500,MATCH("D6.22|"&CAPTURA!BY4,CODIFICACION!$F$2:$F$500,0))),"⚠")) | AU4: =IF(CAPTURA!BZ4="","",IFERROR(IF(INDEX(CODIFICACION!$E$2:$E$500,MATCH("D6.22a|"&CAPTURA!BZ4,CODIFICACION!$F$2:$F$500,0))="sin dato","",INDEX(CODIFICACION!$E$2:$E$500,MATCH("D6.22a|"&CAPTURA!BZ4,CODIFICACION!$F$2:$F$500,0))),"⚠")) | AV4: =IF(CAPTURA!CA4="","",IFERROR(IF(INDEX(CODIFICACION!$E$2:$E$500,MATCH("D6.22b|"&CAPTURA!CA4,CODIFICACION!$F$2:$F$500,0))="sin dato","",INDEX(CODIFICACION!$E$2:$E$500,MATCH("D6.22b|"&CAPTURA!CA4,CODIFICACION!$F$2:$F$500,0))),"⚠")) | AW4: =IF(CAPTURA!CB4="","",IFERROR(IF(INDEX(CODIFICACION!$E$2:$E$500,MATCH("D6.23|"&CAPTURA!CB4,CODIFICACION!$F$2:$F$500,0))="sin dato","",INDEX(CODIFICACION!$E$2:$E$500,MATCH("D6.23|"&CAPTURA!CB4,CODIFICACION!$F$2:$F$500,0))),"⚠")) | AX4: =IF(CAPTURA!CC4="","",IFERROR(IF(INDEX(CODIFICACION!$E$2:$E$500,MATCH("D6.24|"&CAPTURA!CC4,CODIFICACION!$F$2:$F$500,0))="sin dato","",INDEX(CODIFICACION!$E$2:$E$500,MATCH("D6.24|"&CAPTURA!CC4,CODIFICACION!$F$2:$F$500,0))),"⚠")) | AY4: =IF(CAPTURA!CD4="","",IFERROR(IF(INDEX(CODIFICACION!$E$2:$E$500,MATCH("D6.25|"&CAPTURA!CD4,CODIFICACION!$F$2:$F$500,0))="sin dato","",INDEX(CODIFICACION!$E$2:$E$500,MATCH("D6.25|"&CAPTURA!CD4,CODIFICACION!$F$2:$F$500,0))),"⚠")) | AZ4: =IF(CAPTURA!CE4="","",IFERROR(IF(INDEX(CODIFICACION!$E$2:$E$500,MATCH("D6.25a|"&CAPTURA!CE4,CODIFICACION!$F$2:$F$500,0))="sin dato","",INDEX(CODIFICACION!$E$2:$E$500,MATCH("D6.25a|"&CAPTURA!CE4,CODIFICACION!$F$2:$F$500,0))),"⚠")) | BA4: =IF(CAPTURA!CF4="","",IFERROR(IF(INDEX(CODIFICACION!$E$2:$E$500,MATCH("D6.25b|"&CAPTURA!CF4,CODIFICACION!$F$2:$F$500,0))="sin dato","",INDEX(CODIFICACION!$E$2:$E$500,MATCH("D6.25b|"&CAPTURA!CF4,CODIFICACION!$F$2:$F$500,0))),"⚠")) | BB4: =IF(CAPTURA!CG4="","",IFERROR(IF(INDEX(CODIFICACION!$E$2:$E$500,MATCH("D6.22c|"&CAPTURA!CG4,CODIFICACION!$F$2:$F$500,0))="sin dato","",INDEX(CODIFICACION!$E$2:$E$500,MATCH("D6.22c|"&CAPTURA!CG4,CODIFICACION!$F$2:$F$500,0))),"⚠")) | BC4: =IF(CAPTURA!CH4="","",IFERROR(IF(INDEX(CODIFICACION!$E$2:$E$500,MATCH("D7.26|"&CAPTURA!CH4,CODIFICACION!$F$2:$F$500,0))="sin dato","",INDEX(CODIFICACION!$E$2:$E$500,MATCH("D7.26|"&CAPTURA!CH4,CODIFICACION!$F$2:$F$500,0))),"⚠")) | BD4: =IF(CAPTURA!CI4="","",IFERROR(IF(INDEX(CODIFICACION!$E$2:$E$500,MATCH("D7.27|"&CAPTURA!CI4,CODIFICACION!$F$2:$F$500,0))="sin dato","",INDEX(CODIFICACION!$E$2:$E$500,MATCH("D7.27|"&CAPTURA!CI4,CODIFICACION!$F$2:$F$500,0))),"⚠")) | BE4: =IF(CAPTURA!CJ4="","",IFERROR(IF(INDEX(CODIFICACION!$E$2:$E$500,MATCH("D7.28|"&CAPTURA!CJ4,CODIFICACION!$F$2:$F$500,0))="sin dato","",INDEX(CODIFICACION!$E$2:$E$500,MATCH("D7.28|"&CAPTURA!CJ4,CODIFICACION!$F$2:$F$500,0))),"⚠")) | BF4: =IF(CAPTURA!CK4="","",IFERROR(IF(INDEX(CODIFICACION!$E$2:$E$500,MATCH("D7.28b|"&CAPTURA!CK4,CODIFICACION!$F$2:$F$500,0))="sin dato","",INDEX(CODIFICACION!$E$2:$E$500,MATCH("D7.28b|"&CAPTURA!CK4,CODIFICACION!$F$2:$F$500,0))),"⚠")) | BG4: =IF(CAPTURA!CL4="","",MIN(100,ROUND((LEN(CAPTURA!CL4)-LEN(SUBSTITUTE(CAPTURA!CL4,";",""))+1)/8*100,1))) | BH4: =IF(CAPTURA!CM4="","",IFERROR(IF(INDEX(CODIFICACION!$E$2:$E$500,MATCH("D7.26a|"&CAPTURA!CM4,CODIFICACION!$F$2:$F$500,0))="sin dato","",INDEX(CODIFICACION!$E$2:$E$500,MATCH("D7.26a|"&CAPTURA!CM4,CODIFICACION!$F$2:$F$500,0))),"⚠")) | BI4: =IF(CAPTURA!CN4="","",IFERROR(IF(INDEX(CODIFICACION!$E$2:$E$500,MATCH("D7.26b|"&CAPTURA!CN4,CODIFICACION!$F$2:$F$500,0))="sin dato","",INDEX(CODIFICACION!$E$2:$E$500,MATCH("D7.26b|"&CAPTURA!CN4,CODIFICACION!$F$2:$F$500,0))),"⚠")) | BJ4: =IF(CAPTURA!CO4="","",IF(AND(ISNUMBER(CAPTURA!CO4),CAPTURA!CO4>=0,CAPTURA!CO4<=4),CAPTURA!CO4*25,"⚠")) | BK4: =IF(CAPTURA!CP4="","",IF(ISNUMBER(CAPTURA!CP4),MAX(0,MIN(100,CAPTURA!CP4)),"⚠")) | BL4: =IF(CAPTURA!CQ4="","",IFERROR(IF(INDEX(CODIFICACION!$E$2:$E$500,MATCH("D8.31|"&CAPTURA!CQ4,CODIFICACION!$F$2:$F$500,0))="sin dato","",INDEX(CODIFICACION!$E$2:$E$500,MATCH("D8.31|"&CAPTURA!CQ4,CODIFICACION!$F$2:$F$500,0))),"⚠")) | BM4: =IF(CAPTURA!CR4="","",IFERROR(IF(INDEX(CODIFICACION!$E$2:$E$500,MATCH("D8.32|"&CAPTURA!CR4,CODIFICACION!$F$2:$F$500,0))="sin dato","",INDEX(CODIFICACION!$E$2:$E$500,MATCH("D8.32|"&CAPTURA!CR4,CODIFICACION!$F$2:$F$500,0))),"⚠")) | BN4: =IF(CAPTURA!CS4="","",IFERROR(IF(INDEX(CODIFICACION!$E$2:$E$500,MATCH("D9.33|"&CAPTURA!CS4,CODIFICACION!$F$2:$F$500,0))="sin dato","",INDEX(CODIFICACION!$E$2:$E$500,MATCH("D9.33|"&CAPTURA!CS4,CODIFICACION!$F$2:$F$500,0))),"⚠")) | BO4: =IF(CAPTURA!CT4="","",IFERROR(IF(INDEX(CODIFICACION!$E$2:$E$500,MATCH("D9.34|"&CAPTURA!CT4,CODIFICACION!$F$2:$F$500,0))="sin dato","",INDEX(CODIFICACION!$E$2:$E$500,MATCH("D9.34|"&CAPTURA!CT4,CODIFICACION!$F$2:$F$500,0))),"⚠")) | BP4: =IF(CAPTURA!CU4="","",IFERROR(IF(INDEX(CODIFICACION!$E$2:$E$500,MATCH("D9.35|"&CAPTURA!CU4,CODIFICACION!$F$2:$F$500,0))="sin dato","",INDEX(CODIFICACION!$E$2:$E$500,MATCH("D9.35|"&CAPTURA!CU4,CODIFICACION!$F$2:$F$500,0))),"⚠")) | BQ4: =IF(CAPTURA!CV4="","",IFERROR(IF(INDEX(CODIFICACION!$E$2:$E$500,MATCH("D10.36|"&CAPTURA!CV4,CODIFICACION!$F$2:$F$500,0))="sin dato","",INDEX(CODIFICACION!$E$2:$E$500,MATCH("D10.36|"&CAPTURA!CV4,CODIFICACION!$F$2:$F$500,0))),"⚠")) | BR4: =IF(CAPTURA!CW4="","",IFERROR(IF(INDEX(CODIFICACION!$E$2:$E$500,MATCH("D10.37|"&CAPTURA!CW4,CODIFICACION!$F$2:$F$500,0))="sin dato","",INDEX(CODIFICACION!$E$2:$E$500,MATCH("D10.37|"&CAPTURA!CW4,CODIFICACION!$F$2:$F$500,0))),"⚠")) | BS4: =IF(CAPTURA!CX4="","",IFERROR(IF(INDEX(CODIFICACION!$E$2:$E$500,MATCH("D10.36a|"&CAPTURA!CX4,CODIFICACION!$F$2:$F$500,0))="sin dato","",INDEX(CODIFICACION!$E$2:$E$500,MATCH("D10.36a|"&CAPTURA!CX4,CODIFICACION!$F$2:$F$500,0))),"⚠")) | BT4: =IF(CAPTURA!CY4="","",IF(ISNUMBER(SEARCH("Ninguno",CAPTURA!CY4)),0,MIN(100,ROUND((LEN(CAPTURA!CY4)-LEN(SUBSTITUTE(CAPTURA!CY4,";",""))+1)/6*100,1)))) | BU4: =IF(CAPTURA!DA4="","",IFERROR(IF(INDEX(CODIFICACION!$E$2:$E$500,MATCH("D11.39a|"&CAPTURA!DA4,CODIFICACION!$F$2:$F$500,0))="sin dato","",INDEX(CODIFICACION!$E$2:$E$500,MATCH("D11.39a|"&CAPTURA!DA4,CODIFICACION!$F$2:$F$500,0))),"⚠")) | BV4: =IF(CAPTURA!DB4="","",IFERROR(IF(INDEX(CODIFICACION!$E$2:$E$500,MATCH("D12.42|"&CAPTURA!DB4,CODIFICACION!$F$2:$F$500,0))="sin dato","",INDEX(CODIFICACION!$E$2:$E$500,MATCH("D12.42|"&CAPTURA!DB4,CODIFICACION!$F$2:$F$500,0))),"⚠")) | BW4: =IF(CAPTURA!DC4="","",IFERROR(IF(INDEX(CODIFICACION!$E$2:$E$500,MATCH("D13.45|"&CAPTURA!DC4,CODIFICACION!$F$2:$F$500,0))="sin dato","",INDEX(CODIFICACION!$E$2:$E$500,MATCH("D13.45|"&CAPTURA!DC4,CODIFICACION!$F$2:$F$500,0))),"⚠")) | BX4: =IF(CAPTURA!DD4="","",IFERROR(IF(INDEX(CODIFICACION!$E$2:$E$500,MATCH("D14.51|"&CAPTURA!DD4,CODIFICACION!$F$2:$F$500,0))="sin dato","",INDEX(CODIFICACION!$E$2:$E$500,MATCH("D14.51|"&CAPTURA!DD4,CODIFICACION!$F$2:$F$500,0))),"⚠")) | BY4: =IF(CAPTURA!DE4="","",IFERROR(IF(INDEX(CODIFICACION!$E$2:$E$500,MATCH("D15.58|"&CAPTURA!DE4,CODIFICACION!$F$2:$F$500,0))="sin dato","",INDEX(CODIFICACION!$E$2:$E$500,MATCH("D15.58|"&CAPTURA!DE4,CODIFICACION!$F$2:$F$500,0))),"⚠")) | BZ4: =IF(CAPTURA!DF4="","",IFERROR(IF(INDEX(CODIFICACION!$E$2:$E$500,MATCH("PP1|"&CAPTURA!DF4,CODIFICACION!$F$2:$F$500,0))="sin dato","",INDEX(CODIFICACION!$E$2:$E$500,MATCH("PP1|"&CAPTURA!DF4,CODIFICACION!$F$2:$F$500,0))),"⚠")) | CA4: =IF(CAPTURA!DG4="","",IFERROR(IF(INDEX(CODIFICACION!$E$2:$E$500,MATCH("PP2|"&CAPTURA!DG4,CODIFICACION!$F$2:$F$500,0))="sin dato","",INDEX(CODIFICACION!$E$2:$E$500,MATCH("PP2|"&CAPTURA!DG4,CODIFICACION!$F$2:$F$500,0))),"⚠")) | CB4: =IFERROR(AVERAGE(H4,I4,J4,K4),"") | CC4: =IFERROR(AVERAGE(L4,M4,N4,O4,P4,R4),"") | CD4: =IFERROR(AVERAGE(T4,U4,V4,W4,X4,Y4,Z4,AA4,AB4,AC4,AE4),"") | CE4: =IFERROR(AVERAGE(AG4,AH4,AI4),"") | CF4: =IFERROR(AVERAGE(AK4,AL4,AM4,AN4,AP4,AQ4,AR4,AS4),"") | CG4: =IFERROR(AVERAGE(AT4,AU4,AV4,BB4,AW4,AX4,AY4,AZ4,BA4),"") | CH4: =IFERROR(AVERAGE(BC4,BH4,BI4,BD4,BF4),"") | CI4: =IFERROR(AVERAGE(BJ4,BK4,BL4,BM4),"") | CJ4: =IFERROR(AVERAGE(BN4,BO4,BP4),"") | CK4: ="" | CL4: =""
